Workbook

Sheet SetsEditor- Proc
A1: ~TFM_PSets
A2: t_pos_andor_forsets | B2: t_pos_andor | C2: t_neg_andor_forsets | D2: t_neg_andor | E2: setname | F2: setdesc | G2: pset_set | H2: pset_pn | I2: pset_pd | J2: pset_co | K2: pset_ci
E3: TM-H2 | H3: TMH2
A4: And | B4: And | C4: Or | D4: Or | E4: TH-H2 | H4: TH*H2
E5: TB-H2 | H5: TBTH* | K5: *H2*
A6: And | B6: And | C6: Or | D6: Or | E6: TH-ELC | H6: TH*ELC
E7: TM-ELC | H7: TMELC
E8: TC-ELC | H8: TCELC
A9: And | B9: And | C9: Or | D9: Or | E9: TB-ELC | H9: TBTEVC,TBSEVC
A10: And | B10: And | C10: Or | D10: Or | E10: TB-LPG | H10: TB*LPG*
A11: And | B11: And | C11: Or | D11: Or | E11: THL-GSL | H11: THLG*
A12: And | B12: And | C12: Or | D12: Or | E12: THL-ALL | H12: THL*
A13: And | B13: And | C13: And | D13: And | E13: THDNEW | F13: All new TB, TC, TM, THS, and THL techs. | H13: TB*, TC*, TM*, THS*, THL*, -TB*E, -TC*E, -TM*E, -THS*E, -THL*E, -T*ELCL3, -T*ELCL2,
A14: And | B14: And | C14: And | D14: And | E14: THDELC | F14: Just the ELCs covered by MOU | H14: TBSEVC, TBTEVC, TCELC, THLELC, THSELC, TMELC

Sheet VEDA_Sets-Comm
A1: ~TFM_Csets
A2: CSET_SET | B2: CSET_CN | C2: CSET_CD | D2: SetName | E2: SetDesc | F2: T_Pos_AndOr | G2: T_Neg_AndOr | H2: Comment
A3: =setrules!D2&IF(setrules!E2="","",",-"&setrules!E2) | B3: =setrules!F2&IF(setrules!G2="","",",-"&setrules!G2) -> *CH4 | C3: =setrules!H2&IF(setrules!I2="","",",-"&setrules!I2) | D3: =setrules!B2 -> CH4_ALL
A4: =setrules!D3&IF(setrules!E3="","",",-"&setrules!E3) -> NRG | B4: =setrules!F3&IF(setrules!G3="","",",-"&setrules!G3) -> *LPG* | C4: =setrules!H3&IF(setrules!I3="","",",-"&setrules!I3) | D4: =setrules!B3 -> NRG_LPG
A5: =setrules!D4&IF(setrules!E4="","",",-"&setrules!E4) -> ETH | B5: =setrules!F4&IF(setrules!G4="","",",-"&setrules!G4) | C5: =setrules!H4&IF(setrules!I4="","",",-"&setrules!I4) -> *E85* | D5: =setrules!B4 -> ETH_E85 SUMMARY
A6: =setrules!D5&IF(setrules!E5="","",",-"&setrules!E5) | B6: =setrules!F5&IF(setrules!G5="","",",-"&setrules!G5) -> *DSU* | C6: =setrules!H5&IF(setrules!I5="","",",-"&setrules!I5) | D6: =setrules!B5 -> DSU_ALL
A7: =setrules!D6&IF(setrules!E6="","",",-"&setrules!E6) | B7: =setrules!F6&IF(setrules!G6="","",",-"&setrules!G6) -> *DSH* | C7: =setrules!H6&IF(setrules!I6="","",",-"&setrules!I6) | D7: =setrules!B6 -> DSH_ALL
A8: =setrules!D7&IF(setrules!E7="","",",-"&setrules!E7) | B8: =setrules!F7&IF(setrules!G7="","",",-"&setrules!G7) -> C* | C8: =setrules!H7&IF(setrules!I7="","",",-"&setrules!I7) -> ,-*COMMERCIAL* | D8: =setrules!B7 -> COAL MOSTLY
A9: =setrules!D8&IF(setrules!E8="","",",-"&setrules!E8) -> IND_CHP | B9: =setrules!F8&IF(setrules!G8="","",",-"&setrules!G8) -> I* | C9: =setrules!H8&IF(setrules!I8="","",",-"&setrules!I8) | D9: =setrules!B8 -> IND_ALLCOMODITIES
A10: =setrules!D9&IF(setrules!E9="","",",-"&setrules!E9) | B10: =setrules!F9&IF(setrules!G9="","",",-"&setrules!G9) -> *CO2 | C10: =setrules!H9&IF(setrules!I9="","",",-"&setrules!I9) | D10: =setrules!B9 -> CO2_ALL
A11: =setrules!D10&IF(setrules!E10="","",",-"&setrules!E10) | B11: =setrules!F10&IF(setrules!G10="","",",-"&setrules!G10) -> *CHPELC | C11: =setrules!H10&IF(setrules!I10="","",",-"&setrules!I10) | D11: =setrules!B10 -> IND_CHP
A12: =setrules!D11&IF(setrules!E11="","",",-"&setrules!E11) | B12: =setrules!F11&IF(setrules!G11="","",",-"&setrules!G11) -> TLE85X,TLGSL,TRNCNGL,TRNDSL,TRNELC,TRNH2,TRNLPGEZ | C12: =setrules!H11&IF(setrules!I11="","",",-"&setrules!I11) | D12: =setrules!B11 -> CAFE
A13: =setrules!D12&IF(setrules!E12="","",",-"&setrules!E12) -> BIOMASS COLLECTED,BIOMASS COMMODITIES,BIOMASS DELIVERED | B13: =setrules!F12&IF(setrules!G12="","",",-"&setrules!G12) -> * | C13: =setrules!H12&IF(setrules!I12="","",",-"&setrules!I12) | D13: =setrules!B12 -> BIOMASS TOTAL
A14: =setrules!D13&IF(setrules!E13="","",",-"&setrules!E13) | B14: =setrules!F13&IF(setrules!G13="","",",-"&setrules!G13) | C14: =setrules!H13&IF(setrules!I13="","",",-"&setrules!I13) -> *DELIVERED* | D14: =setrules!B13 -> BIOMASS DELIVERED
... A43: =setrules!D42&IF(setrules!E42="","",",-"&setrules!E42) | B43: =setrules!F42&IF(setrules!G42="","",",-"&setrules!G42) -> *R | C43: =setrules!H42&IF(setrules!I42="","",",-"&setrules!I42) -> *REFINERIES | D43: =setrules!B42 -> REFOUTPUT_ALL
A44: =setrules!D43&IF(setrules!E43="","",",-"&setrules!E43) -> MAT | B44: IND___ | C44: =setrules!H43&IF(setrules!I43="","",",-"&setrules!I43) | D44: =setrules!B43 -> NRG_URN
A45: =setrules!D44&IF(setrules!E44="","",",-"&setrules!E44) | B45: T*,-*EA | C45: =setrules!H44&IF(setrules!I44="","",",-"&setrules!I44) | D45: =setrules!B44 -> PM10_ALL
A46: =setrules!D46&IF(setrules!E46="","",",-"&setrules!E46) -> NRG | B46: =setrules!F46&IF(setrules!G46="","",",-"&setrules!G46) -> *RF* | C46: =setrules!H46&IF(setrules!I46="","",",-"&setrules!I46) -> *OIL* | D46: =setrules!B46 -> NRG_RFO
A47: =setrules!D47&IF(setrules!E47="","",",-"&setrules!E47) | B47: =setrules!F47&IF(setrules!G47="","",",-"&setrules!G47) -> *ETH* | C47: =setrules!H47&IF(setrules!I47="","",",-"&setrules!I47) | D47: =setrules!B47 -> ETH
A48: =setrules!D48&IF(setrules!E48="","",",-"&setrules!E48) -> NRG | B48: =setrules!F48&IF(setrules!G48="","",",-"&setrules!G48) -> *NGA*,-S_* | C48: =setrules!H48&IF(setrules!I48="","",",-"&setrules!I48) | D48: =setrules!B48 -> NRG_NGA
A49: =setrules!D49&IF(setrules!E49="","",",-"&setrules!E49) -> NRG | B49: =setrules!F49&IF(setrules!G49="","",",-"&setrules!G49) -> *MTH* | C49: =setrules!H49&IF(setrules!I49="","",",-"&setrules!I49) | D49: =setrules!B49 -> NRG_MTH
A50: =setrules!D50&IF(setrules!E50="","",",-"&setrules!E50) | B50: =setrules!F50&IF(setrules!G50="","",",-"&setrules!G50) -> ELC,RESNGA,RESLPG,RESKER,RESDSL,RESBIO | C50: =setrules!H50&IF(setrules!I50="","",",-"&setrules!I50) | D50: =setrules!B50 -> RES_FUELS
A51: =setrules!D51&IF(setrules!E51="","",",-"&setrules!E51) | B51: =setrules!F51&IF(setrules!G51="","",",-"&setrules!G51) -> B*EA | C51: =setrules!H51&IF(setrules!I51="","",",-"&setrules!I51) | D51: =setrules!B51 -> TESTSET1_BIO
A52: =setrules!D52&IF(setrules!E52="","",",-"&setrules!E52) | B52: =setrules!F52&IF(setrules!G52="","",",-"&setrules!G52) -> *SO2 | C52: =setrules!H52&IF(setrules!I52="","",",-"&setrules!I52) | D52: =setrules!B52 -> SO2_ALL
A53: =setrules!D53&IF(setrules!E53="","",",-"&setrules!E53) -> NRG | B53: =setrules!F53&IF(setrules!G53="","",",-"&setrules!G53) -> *OIL* | C53: =setrules!H53&IF(setrules!I53="","",",-"&setrules!I53) | D53: =setrules!B53 -> NRG_OIL
A54: NRG | B54: T*CNG* | D54: Trn_CNG
A55: NRG | B55: T*DSL* | D55: Trn_Diesel
A56: NRG | B56: T*GSL* | D56: Trn_Gasoline
A57: NRG | B57: T*B20* | D57: Trn_B20
A58: NRG | B58: T*E85* | D58: Trn_E85
A59: NRG | B59: T*ELC* | D59: Trn_Electricity
A60: NRG | B60: T*JTF* | D60: Trn_Jetfuel
A61: NRG | B61: T*LPG* | D61: Trn_LPG
A62: NRG | B62: T*RFH* | D62: Trn_RFH
A63: NRG | B63: *DSL* | D63: ="All-"&MID(B63,2,3) -> All-DSL | E63: Diesel
A64: NRG | B64: *LPG* | D64: ="All-"&MID(B64,2,3) -> All-LPG | E64: LPG
A65: NRG | B65: *NGA* | D65: ="All-"&MID(B65,2,3) -> All-NGA | E65: Nat Gas
A66: NRG | B66: *RFL* | D66: ="All-"&MID(B66,2,3) -> All-RFL | E66: RFL
A67: NRG | B67: *AGR* | D67: ="All-"&MID(B67,2,3) -> All-AGR | E67: Ag residue
A68: NRG | B68: *ASP* | D68: ="All-"&MID(B68,2,3) -> All-ASP | E68: Asphalt
...

Sheet VEDA_Sets-Proc
A1: ~TFM_Psets
A2: PSet_set | B2: PSET_PN | C2: PSET_PD | D2: PSET_CI | E2: PSET_CO | F2: SetName | G2: SetDesc
A3: =setrules!D54&IF(setrules!E54="","",",-"&setrules!E54) | B3: =setrules!F54&IF(setrules!G54="","",",-"&setrules!G54)&IF(setrules!P54="","",",-"&setrules!P54) -> IMFS*OTH* | C3: =setrules!H54&IF(setrules!I54="","",",-"&setrules!I54) | D3: =setrules!J54&IF(setrules!K54="","",",-"&setrules!K54) | E3: =setrules!L54&IF(setrules!M54="","",",-"&setrules!M54) | F3: =setrules!B54 -> IMF_OTH
A4: =setrules!D55&IF(setrules!E55="","",",-"&setrules!E55) | B4: =setrules!F55&IF(setrules!G55="","",",-"&setrules!G55)&IF(setrules!P55="","",",-"&setrules!P55) -> IMLNREGNGA | C4: =setrules!H55&IF(setrules!I55="","",",-"&setrules!I55) | D4: =setrules!J55&IF(setrules!K55="","",",-"&setrules!K55) | E4: =setrules!L55&IF(setrules!M55="","",",-"&setrules!M55) | F4: =setrules!B55 -> IMLOH_NGA
A5: =setrules!D56&IF(setrules!E56="","",",-"&setrules!E56) | B5: =setrules!F56&IF(setrules!G56="","",",-"&setrules!G56)&IF(setrules!P56="","",",-"&setrules!P56) -> IMLEOHTLPG | C5: =setrules!H56&IF(setrules!I56="","",",-"&setrules!I56) | D5: =setrules!J56&IF(setrules!K56="","",",-"&setrules!K56) | E5: =setrules!L56&IF(setrules!M56="","",",-"&setrules!M56) | F5: =setrules!B56 -> IMLOH_LPG
A6: =setrules!D57&IF(setrules!E57="","",",-"&setrules!E57) | B6: =setrules!F57&IF(setrules!G57="","",",-"&setrules!G57)&IF(setrules!P57="","",",-"&setrules!P57) -> IMLEOHTCOA | C6: =setrules!H57&IF(setrules!I57="","",",-"&setrules!I57) | D6: =setrules!J57&IF(setrules!K57="","",",-"&setrules!K57) | E6: =setrules!L57&IF(setrules!M57="","",",-"&setrules!M57) | F6: =setrules!B57 -> IMLOH_COA
A7: =setrules!D58&IF(setrules!E58="","",",-"&setrules!E58) | B7: =setrules!F58&IF(setrules!G58="","",",-"&setrules!G58)&IF(setrules!P58="","",",-"&setrules!P58) -> IML*B*BIO,IML*B*WOD,IML*B*TOM,IMLEOHT*,IMLOHTOSTM,-IML*BST* | C7: =setrules!H58&IF(setrules!I58="","",",-"&setrules!I58) | D7: =setrules!J58&IF(setrules!K58="","",",-"&setrules!K58) | E7: =setrules!L58&IF(setrules!M58="","",",-"&setrules!M58) | F7: =setrules!B58 -> IMLOH_ALL
A8: =setrules!D59&IF(setrules!E59="","",",-"&setrules!E59) | B8: =setrules!F59&IF(setrules!G59="","",",-"&setrules!G59)&IF(setrules!P59="","",",-"&setrules!P59) -> IMFACNGA* | C8: =setrules!H59&IF(setrules!I59="","",",-"&setrules!I59) | D8: =setrules!J59&IF(setrules!K59="","",",-"&setrules!K59) | E8: =setrules!L59&IF(setrules!M59="","",",-"&setrules!M59) | F8: =setrules!B59 -> IMFA_NGA
A9: =setrules!D60&IF(setrules!E60="","",",-"&setrules!E60) | B9: =setrules!F60&IF(setrules!G60="","",",-"&setrules!G60)&IF(setrules!P60="","",",-"&setrules!P60) -> IMFACLPG* | C9: =setrules!H60&IF(setrules!I60="","",",-"&setrules!I60) | D9: =setrules!J60&IF(setrules!K60="","",",-"&setrules!K60) | E9: =setrules!L60&IF(setrules!M60="","",",-"&setrules!M60) | F9: =setrules!B60 -> IMFA_LPG
A10: =setrules!D61&IF(setrules!E61="","",",-"&setrules!E61) | B10: =setrules!F61&IF(setrules!G61="","",",-"&setrules!G61)&IF(setrules!P61="","",",-"&setrules!P61) -> IMFACELC* | C10: =setrules!H61&IF(setrules!I61="","",",-"&setrules!I61) | D10: =setrules!J61&IF(setrules!K61="","",",-"&setrules!K61) | E10: =setrules!L61&IF(setrules!M61="","",",-"&setrules!M61) | F10: =setrules!B61 -> IMFA_ELC
A11: =setrules!D62&IF(setrules!E62="","",",-"&setrules!E62) | B11: =setrules!F62&IF(setrules!G62="","",",-"&setrules!G62)&IF(setrules!P62="","",",-"&setrules!P62) -> IMFACDST* | C11: =setrules!H62&IF(setrules!I62="","",",-"&setrules!I62) | D11: =setrules!J62&IF(setrules!K62="","",",-"&setrules!K62) | E11: =setrules!L62&IF(setrules!M62="","",",-"&setrules!M62) | F11: =setrules!B62 -> IMFA_DST
A12: =setrules!D63&IF(setrules!E63="","",",-"&setrules!E63) | B12: =setrules!F63&IF(setrules!G63="","",",-"&setrules!G63)&IF(setrules!P63="","",",-"&setrules!P63) -> IMFAC* | C12: =setrules!H63&IF(setrules!I63="","",",-"&setrules!I63) | D12: =setrules!J63&IF(setrules!K63="","",",-"&setrules!K63) | E12: =setrules!L63&IF(setrules!M63="","",",-"&setrules!M63) | F12: =setrules!B63 -> IMFA_ALL
A13: =setrules!D64&IF(setrules!E64="","",",-"&setrules!E64) | B13: =setrules!F64&IF(setrules!G64="","",",-"&setrules!G64)&IF(setrules!P64="","",",-"&setrules!P64) -> IMLEPRHNGA | C13: =setrules!H64&IF(setrules!I64="","",",-"&setrules!I64) | D13: =setrules!J64&IF(setrules!K64="","",",-"&setrules!K64) | E13: =setrules!L64&IF(setrules!M64="","",",-"&setrules!M64) | F13: =setrules!B64 -> IMLPH_NGA
A14: =setrules!D65&IF(setrules!E65="","",",-"&setrules!E65) | B14: =setrules!F65&IF(setrules!G65="","",",-"&setrules!G65)&IF(setrules!P65="","",",-"&setrules!P65) -> IMFS*NGA* | C14: =setrules!H65&IF(setrules!I65="","",",-"&setrules!I65) | D14: =setrules!J65&IF(setrules!K65="","",",-"&setrules!K65) | E14: =setrules!L65&IF(setrules!M65="","",",-"&setrules!M65) | F14: =setrules!B65 -> IMF_NGA
... A98: =setrules!D149&IF(setrules!E149="","",",-"&setrules!E149) | B98: =setrules!F149&IF(setrules!G149="","",",-"&setrules!G149)&IF(setrules!P149="","",",-"&setrules!P149) -> IMAEPRH* | C98: =setrules!H149&IF(setrules!I149="","",",-"&setrules!I149) | D98: =setrules!J149&IF(setrules!K149="","",",-"&setrules!K149) | E98: =setrules!L149&IF(setrules!M149="","",",-"&setrules!M149) | F98: =setrules!B149 -> IMAPH_ALL
B99: TH*B20* | F99: TH-B20X
A100: =setrules!D151&IF(setrules!E151="","",",-"&setrules!E151) | B100: =setrules!F151&IF(setrules!G151="","",",-"&setrules!G151)&IF(setrules!P151="","",",-"&setrules!P151) -> IFP*ELC* | C100: =setrules!H151&IF(setrules!I151="","",",-"&setrules!I151) | D100: =setrules!J151&IF(setrules!K151="","",",-"&setrules!K151) | E100: =setrules!L151&IF(setrules!M151="","",",-"&setrules!M151) | F100: =setrules!B151 -> IFP_ELC
A101: =setrules!D152&IF(setrules!E152="","",",-"&setrules!E152) | B101: =setrules!F152&IF(setrules!G152="","",",-"&setrules!G152)&IF(setrules!P152="","",",-"&setrules!P152) -> IFOHBIO* | C101: =setrules!H152&IF(setrules!I152="","",",-"&setrules!I152) | D101: =setrules!J152&IF(setrules!K152="","",",-"&setrules!K152) | E101: =setrules!L152&IF(setrules!M152="","",",-"&setrules!M152) | F101: =setrules!B152 -> IFOH_BIO
A102: =setrules!D153&IF(setrules!E153="","",",-"&setrules!E153) | B102: =setrules!F153&IF(setrules!G153="","",",-"&setrules!G153)&IF(setrules!P153="","",",-"&setrules!P153) -> IFOHCOA* | C102: =setrules!H153&IF(setrules!I153="","",",-"&setrules!I153) | D102: =setrules!J153&IF(setrules!K153="","",",-"&setrules!K153) | E102: =setrules!L153&IF(setrules!M153="","",",-"&setrules!M153) | F102: =setrules!B153 -> IFOH_COA
A103: =setrules!D154&IF(setrules!E154="","",",-"&setrules!E154) | B103: =setrules!F154&IF(setrules!G154="","",",-"&setrules!G154)&IF(setrules!P154="","",",-"&setrules!P154) -> IFOHELC* | C103: =setrules!H154&IF(setrules!I154="","",",-"&setrules!I154) | D103: =setrules!J154&IF(setrules!K154="","",",-"&setrules!K154) | E103: =setrules!L154&IF(setrules!M154="","",",-"&setrules!M154) | F103: =setrules!B154 -> IFOH_ELC
A104: =setrules!D155&IF(setrules!E155="","",",-"&setrules!E155) | B104: =setrules!F155&IF(setrules!G155="","",",-"&setrules!G155)&IF(setrules!P155="","",",-"&setrules!P155) -> IFOHLPG* | C104: =setrules!H155&IF(setrules!I155="","",",-"&setrules!I155) | D104: =setrules!J155&IF(setrules!K155="","",",-"&setrules!K155) | E104: =setrules!L155&IF(setrules!M155="","",",-"&setrules!M155) | F104: =setrules!B155 -> IFOH_LPG
A105: =setrules!D156&IF(setrules!E156="","",",-"&setrules!E156) | B105: =setrules!F156&IF(setrules!G156="","",",-"&setrules!G156)&IF(setrules!P156="","",",-"&setrules!P156) -> IFOH*NGA* | C105: =setrules!H156&IF(setrules!I156="","",",-"&setrules!I156) | D105: =setrules!J156&IF(setrules!K156="","",",-"&setrules!K156) | E105: =setrules!L156&IF(setrules!M156="","",",-"&setrules!M156) | F105: =setrules!B156 -> IFOH_NGA
A106: =setrules!D157&IF(setrules!E157="","",",-"&setrules!E157) | B106: =setrules!F157&IF(setrules!G157="","",",-"&setrules!G157)&IF(setrules!P157="","",",-"&setrules!P157) -> *IFOHSTM* | C106: =setrules!H157&IF(setrules!I157="","",",-"&setrules!I157) | D106: =setrules!J157&IF(setrules!K157="","",",-"&setrules!K157) | E106: =setrules!L157&IF(setrules!M157="","",",-"&setrules!M157) | F106: =setrules!B157 -> IFOH_STM
A107: =setrules!D158&IF(setrules!E158="","",",-"&setrules!E158) | B107: =setrules!F158&IF(setrules!G158="","",",-"&setrules!G158)&IF(setrules!P158="","",",-"&setrules!P158) -> IFP* | C107: =setrules!H158&IF(setrules!I158="","",",-"&setrules!I158) | D107: =setrules!J158&IF(setrules!K158="","",",-"&setrules!K158) | E107: =setrules!L158&IF(setrules!M158="","",",-"&setrules!M158) | F107: =setrules!B158 -> IFP_ALL
A108: =setrules!D159&IF(setrules!E159="","",",-"&setrules!E159) | B108: =setrules!F159&IF(setrules!G159="","",",-"&setrules!G159)&IF(setrules!P159="","",",-"&setrules!P159) -> IFB*STM | C108: =setrules!H159&IF(setrules!I159="","",",-"&setrules!I159) | D108: =setrules!J159&IF(setrules!K159="","",",-"&setrules!K159) | E108: =setrules!L159&IF(setrules!M159="","",",-"&setrules!M159) | F108: =setrules!B159 -> IFS_FSTM
A109: =setrules!D160&IF(setrules!E160="","",",-"&setrules!E160) | B109: =setrules!F160&IF(setrules!G160="","",",-"&setrules!G160)&IF(setrules!P160="","",",-"&setrules!P160) -> IFP*DST* | C109: =setrules!H160&IF(setrules!I160="","",",-"&setrules!I160) | D109: =setrules!J160&IF(setrules!K160="","",",-"&setrules!K160) | E109: =setrules!L160&IF(setrules!M160="","",",-"&setrules!M160) | F109: =setrules!B160 -> IFP_DST
A110: =setrules!D161&IF(setrules!E161="","",",-"&setrules!E161) | B110: =setrules!F161&IF(setrules!G161="","",",-"&setrules!G161)&IF(setrules!P161="","",",-"&setrules!P161) -> IFB*ELC* | C110: =setrules!H161&IF(setrules!I161="","",",-"&setrules!I161) | D110: =setrules!J161&IF(setrules!K161="","",",-"&setrules!K161) | E110: =setrules!L161&IF(setrules!M161="","",",-"&setrules!M161) | F110: =setrules!B161 -> IFS_ELC
A111: =setrules!D162&IF(setrules!E162="","",",-"&setrules!E162) | B111: =setrules!F162&IF(setrules!G162="","",",-"&setrules!G162)&IF(setrules!P162="","",",-"&setrules!P162) -> IFP*LPG* | C111: =setrules!H162&IF(setrules!I162="","",",-"&setrules!I162) | D111: =setrules!J162&IF(setrules!K162="","",",-"&setrules!K162) | E111: =setrules!L162&IF(setrules!M162="","",",-"&setrules!M162) | F111: =setrules!B162 -> IFP_LPG
... A197: =setrules!D248&IF(setrules!E248="","",",-"&setrules!E248) | B197: =setrules!F248&IF(setrules!G248="","",",-"&setrules!G248)&IF(setrules!P248="","",",-"&setrules!P248) -> TLC* | C197: =setrules!H248&IF(setrules!I248="","",",-"&setrules!I248) | D197: =setrules!J248&IF(setrules!K248="","",",-"&setrules!K248) | E197: =setrules!L248&IF(setrules!M248="","",",-"&setrules!M248) | F197: =setrules!B248 -> TLC-ALL
B198: TL*CNG* | F198: TL-CNG
A199: =setrules!D250&IF(setrules!E250="","",",-"&setrules!E250) | B199: =setrules!F250&IF(setrules!G250="","",",-"&setrules!G250)&IF(setrules!P250="","",",-"&setrules!P250) -> TL* | C199: =setrules!H250&IF(setrules!I250="","",",-"&setrules!I250) -> *CNGX* | D199: =setrules!J250&IF(setrules!K250="","",",-"&setrules!K250) | E199: =setrules!L250&IF(setrules!M250="","",",-"&setrules!M250) | F199: =setrules!B250 -> TL-CNGX
A200: =setrules!D251&IF(setrules!E251="","",",-"&setrules!E251) | B200: =setrules!F251&IF(setrules!G251="","",",-"&setrules!G251)&IF(setrules!P251="","",",-"&setrules!P251) -> TLEM*,-,-TLEMCGSL,- | C200: =setrules!H251&IF(setrules!I251="","",",-"&setrules!I251) | D200: =setrules!J251&IF(setrules!K251="","",",-"&setrules!K251) | E200: =setrules!L251&IF(setrules!M251="","",",-"&setrules!M251) | F200: =setrules!B251 -> TLEM-ALL
A201: =setrules!D252&IF(setrules!E252="","",",-"&setrules!E252) | B201: =setrules!F252&IF(setrules!G252="","",",-"&setrules!G252)&IF(setrules!P252="","",",-"&setrules!P252) -> TL* | C201: =setrules!H252&IF(setrules!I252="","",",-"&setrules!I252) | D201: =setrules!J252&IF(setrules!K252="","",",-"&setrules!K252) -> TLDSL | E201: =setrules!L252&IF(setrules!M252="","",",-"&setrules!M252) | F201: =setrules!B252 -> TL-DSL
A202: =setrules!D253&IF(setrules!E253="","",",-"&setrules!E253) | B202: =setrules!F253&IF(setrules!G253="","",",-"&setrules!G253)&IF(setrules!P253="","",",-"&setrules!P253) -> THSC* | C202: =setrules!H253&IF(setrules!I253="","",",-"&setrules!I253) | D202: =setrules!J253&IF(setrules!K253="","",",-"&setrules!K253) | E202: =setrules!L253&IF(setrules!M253="","",",-"&setrules!M253) | F202: =setrules!B253 -> THS-CNG
A203: =setrules!D254&IF(setrules!E254="","",",-"&setrules!E254) | B203: =setrules!F254&IF(setrules!G254="","",",-"&setrules!G254)&IF(setrules!P254="","",",-"&setrules!P254) | C203: =setrules!H254&IF(setrules!I254="","",",-"&setrules!I254) | D203: =setrules!J254&IF(setrules!K254="","",",-"&setrules!K254) -> TLE85X | E203: =setrules!L254&IF(setrules!M254="","",",-"&setrules!M254) | F203: =setrules!B254 -> TL-E85X
A204: =setrules!D255&IF(setrules!E255="","",",-"&setrules!E255) | B204: =setrules!F255&IF(setrules!G255="","",",-"&setrules!G255)&IF(setrules!P255="","",",-"&setrules!P255) -> TLEC* | C204: =setrules!H255&IF(setrules!I255="","",",-"&setrules!I255) | D204: =setrules!J255&IF(setrules!K255="","",",-"&setrules!K255) | E204: =setrules!L255&IF(setrules!M255="","",",-"&setrules!M255) | F204: =setrules!B255 -> TLEC-ALL
A205: =setrules!D256&IF(setrules!E256="","",",-"&setrules!E256) | B205: =setrules!F256&IF(setrules!G256="","",",-"&setrules!G256)&IF(setrules!P256="","",",-"&setrules!P256) -> TLEF* | C205: =setrules!H256&IF(setrules!I256="","",",-"&setrules!I256) | D205: =setrules!J256&IF(setrules!K256="","",",-"&setrules!K256) | E205: =setrules!L256&IF(setrules!M256="","",",-"&setrules!M256) | F205: =setrules!B256 -> TLEF-ALL
A206: =setrules!D257&IF(setrules!E257="","",",-"&setrules!E257) | B206: =setrules!F257&IF(setrules!G257="","",",-"&setrules!G257)&IF(setrules!P257="","",",-"&setrules!P257) -> TL* | C206: =setrules!H257&IF(setrules!I257="","",",-"&setrules!I257) | D206: =setrules!J257&IF(setrules!K257="","",",-"&setrules!K257) -> *ELC | E206: =setrules!L257&IF(setrules!M257="","",",-"&setrules!M257) | F206: =setrules!B257 -> TL-ELC
A207: =setrules!D258&IF(setrules!E258="","",",-"&setrules!E258) | B207: =setrules!F258&IF(setrules!G258="","",",-"&setrules!G258)&IF(setrules!P258="","",",-"&setrules!P258) -> TL*ELC | C207: =setrules!H258&IF(setrules!I258="","",",-"&setrules!I258) | D207: =setrules!J258&IF(setrules!K258="","",",-"&setrules!K258) | E207: =setrules!L258&IF(setrules!M258="","",",-"&setrules!M258) | F207: =setrules!B258 -> TL-ELCA
A208: =setrules!D259&IF(setrules!E259="","",",-"&setrules!E259) | B208: =setrules!F259&IF(setrules!G259="","",",-"&setrules!G259)&IF(setrules!P259="","",",-"&setrules!P259) -> TL*ELCB | C208: =setrules!H259&IF(setrules!I259="","",",-"&setrules!I259) | D208: =setrules!J259&IF(setrules!K259="","",",-"&setrules!K259) | E208: =setrules!L259&IF(setrules!M259="","",",-"&setrules!M259) | F208: =setrules!B259 -> TL-ELCB
...

Sheet setrules
A1: DimName | B1: SetName | C1: Region | D1: Okey_IN | E1: Okey_NOTIN | F1: Name_LIKE | G1: Name_NOTLIKE | H1: Desc_LIKE | I1: Desc_NOTLIKE | J1: InputCom_LIKE | K1: InputCom_NOTLIKE | L1: OutputCom_LIKE | M1: OutputCom_NOTLIKE | N1: AndOr_Pos | O1: AndOr_Neg | P1: UnSelected | Q1: AndOr_Pos_forSets | R1: AndOr_Neg_forSets
A2: Commodity | B2: CH4_ALL | C2: - | F2: *CH4 | N2: AND | O2: OR | Q2: AND | R2: OR
A3: Commodity | B3: NRG_LPG | C3: - | D3: NRG | F3: *LPG* | N3: AND | O3: OR
A4: Commodity | B4: ETH_E85 SUMMARY | C4: - | D4: ETH | H4: *E85* | N4: AND | O4: OR
A5: Commodity | B5: DSU_ALL | C5: - | F5: *DSU* | N5: AND | O5: OR
A6: Commodity | B6: DSH_ALL | C6: - | F6: *DSH* | N6: AND | O6: OR
A7: Commodity | B7: COAL MOSTLY | C7: - | F7: C* | I7: *COMMERCIAL* | N7: AND | O7: OR
A8: Commodity | B8: IND_ALLCOMODITIES | C8: - | D8: IND_CHP | F8: I* | N8: AND | O8: OR | P8: ,-INDCO,-INDCO2,-INDBC,-INDCH4,-INDSO2,-INDVOC,-INDN2O,-INDNOX,-INDOC,-INDPM10,-INDPM25,-
A9: Commodity | B9: CO2_ALL | C9: - | F9: *CO2 | N9: AND | O9: OR | P9: ,-UPSCO2,- | Q9: AND | R9: OR
A10: Commodity | B10: IND_CHP | C10: - | F10: *CHPELC | N10: AND | O10: OR
A11: Commodity | B11: CAFE | C11: - | F11: TLE85X,TLGSL,TRNCNGL,TRNDSL,TRNELC,TRNH2,TRNLPGEZ | N11: AND | O11: OR
A12: Commodity | B12: BIOMASS TOTAL | C12: - | D12: BIOMASS COLLECTED,BIOMASS COMMODITIES,BIOMASS DELIVERED | F12: * | N12: AND | O12: OR | P12: ,-RESBIO,-
A13: Commodity | B13: BIOMASS DELIVERED | C13: - | H13: *DELIVERED* | N13: AND | O13: OR
A14: Commodity | B14: BIOMASS COMMODITIES | C14: - | H14: *BIOMASS* | N14: AND | O14: OR
A15: Commodity | B15: BIOMASS COLLECTED | C15: - | H15: *COLLECTED* | N15: AND | O15: OR
A16: Commodity | B16: ASP_ALL | C16: - | F16: *ASP* | N16: AND | O16: OR
A17: Commodity | B17: COAL COMMODITIES | C17: - | F17: CSTM* | N17: AND | O17: OR
A18: Commodity | B18: NRG_DSH | C18: - | D18: NRG | F18: *DSH* | N18: AND | O18: OR
A19: Commodity | B19: NRG_KER | C19: - | D19: NRG | F19: *KER* | N19: AND | O19: OR
A20: Commodity | B20: NRG_JET | C20: - | D20: NRG | F20: *JTF* | N20: AND | O20: OR
A21: Commodity | B21: NRG_H2 | C21: - | D21: NRG | F21: *H2* | H21: *H2* | N21: AND | O21: OR
A22: Commodity | B22: NRG_GSL | C22: - | D22: NRG | F22: *GS* | G22: S_*,-*LFG* | N22: AND | O22: OR
A23: Commodity | B23: NRG_ETH | C23: - | D23: NRG | F23: *ETH* | N23: AND | O23: OR
A24: Commodity | B24: GSL_ALL | C24: - | F24: *GSL* | N24: AND | O24: OR
A25: Commodity | B25: NRG_DSL | C25: - | D25: NRG | F25: *DSL*,*DSU* | G25: *BIO*,-S_* | I25: *OIL* | N25: AND | O25: OR
A26: Commodity | B26: DSL_ALL | C26: - | F26: *DSL* | N26: AND | O26: OR
A27: Commodity | B27: NRG_COAL | C27: - | D27: NRG | F27: C* | H27: *COA* | N27: AND | O27: OR
A28: Commodity | B28: NRG_BIO | C28: - | D28: NRG | F28: *BIO* | G28: S_*,-*DST*,-*ETH* | N28: AND | O28: OR
A29: Commodity | B29: NOX_ALL | C29: - | F29: *NOX | N29: AND | O29: OR | Q29: AND | R29: OR
A30: Commodity | B30: LPG_ALL | C30: - | F30: *LPG* | N30: AND | O30: OR
A31: Commodity | B31: KER_ALL | C31: - | F31: *KER* | N31: AND | O31: OR
A32: Commodity | B32: JTF_ALL | C32: - | F32: *JTF* | N32: AND | O32: OR
A33: Commodity | B33: NRG_ELC | C33: - | D33: elc | F33: *ELC* | N33: AND | O33: OR
A34: Commodity | B34: PTC_ALL | C34: - | F34: *PTC* | N34: AND | O34: OR
A35: Commodity | B35: Sfuel-RES | C35: - | D35: NRG | F35: RES* | G35: *EA | N35: AND | O35: AND
A36: Commodity | B36: Sfuel-IND | C36: - | D36: NRG | F36: IND* | G36: *EA | N36: AND | O36: AND
A37: Commodity | B37: Sfuel-COM | C37: - | D37: NRG | F37: COM* | G37: *EA | N37: AND | O37: AND
A38: Commodity | B38: RFL_ALL | C38: - | F38: *RFL* | N38: AND | O38: OR
A39: Commodity | B39: RFH_ALL | C39: - | F39: *RFH* | N39: AND | O39: OR
A40: Commodity | B40: RESIDENTIAL DMDS | C40: - | D40: DEM | F40: R* | G40: ROG,-ROE,-ROL | N40: AND | O40: OR | Q40: AND | R40: OR
...

Sheet Proc-clean
A1: ~TFM_Psets
A2: PSet_set | B2: PSET_PN | C2: PSET_PD | D2: PSET_CI | E2: PSET_CO | F2: SetName | G2: SetDesc
A3: -IRE | E3: =O3 -> CCK | F3: ="dd_"&LEFT(O3,1)&"_"&O3 -> dd_C_CCK | G3: =P3&" - demand devices" -> Commercial Cooking - demand devices | O3: CCK | P3: Commercial Cooking
A4: -IRE | E4: =O4 -> CLT | F4: ="dd_"&LEFT(O4,1)&"_"&O4 -> dd_C_CLT | G4: =P4&" - demand devices" -> Commercial Lighting - demand devices | O4: CLT | P4: Commercial Lighting
A5: -IRE | E5: CM? | F5: dd_C_CMS | G5: =P5&" - demand devices" -> Commercial Miscellaneous - demand devices | O5: CM? | P5: Commercial Miscellaneous
A6: -IRE | E6: =O6 -> COF | F6: ="dd_"&LEFT(O6,1)&"_"&O6 -> dd_C_COF | G6: =P6&" - demand devices" -> Commercial Office Equipment - demand devices | O6: COF | P6: Commercial Office Equipment
A7: -IRE | E7: =O7 -> CRF | F7: ="dd_"&LEFT(O7,1)&"_"&O7 -> dd_C_CRF | G7: =P7&" - demand devices" -> Commercial Refrigeration - demand devices | O7: CRF | P7: Commercial Refrigeration
A8: -IRE | E8: =O8 -> CSC | F8: ="dd_"&LEFT(O8,1)&"_"&O8 -> dd_C_CSC | G8: =P8&" - demand devices" -> Commercial Cooling - demand devices | O8: CSC | P8: Commercial Cooling
A9: -IRE | E9: =O9 -> CSH | F9: ="dd_"&LEFT(O9,1)&"_"&O9 -> dd_C_CSH | G9: =P9&" - demand devices" -> Commercial Heating - demand devices | O9: CSH | P9: Commercial Heating
A10: -IRE | E10: =O10 -> CVT | F10: ="dd_"&LEFT(O10,1)&"_"&O10 -> dd_C_CVT | G10: =P10&" - demand devices" -> Commercial Ventilation - demand devices | O10: CVT | P10: Commercial Ventilation
A11: -IRE | E11: =O11 -> CWH | F11: ="dd_"&LEFT(O11,1)&"_"&O11 -> dd_C_CWH | G11: =P11&" - demand devices" -> Commercial Water Heating - demand devices | O11: CWH | P11: Commercial Water Heating
B12: =O12&"*" -> ICA* | F12: ="dd_"&LEFT(O12,1)&"_"&O12 -> dd_I_ICA | G12: =P12&" - demand devices" -> Ag Chemicals Industry End Demand - demand devices | O12: ICA | P12: Ag Chemicals Industry End Demand
B13: =O13&"*" -> ICI* | F13: ="dd_"&LEFT(O13,1)&"_"&O13 -> dd_I_ICI | G13: =P13&" - demand devices" -> Inorganic Chemicals Industry End Demand - demand devices | O13: ICI | P13: Inorganic Chemicals Industry End Demand
B14: =O14&"*" -> ICO* | F14: ="dd_"&LEFT(O14,1)&"_"&O14 -> dd_I_ICO | G14: =P14&" - demand devices" -> Organic Chemicals Industry End Demand - demand devices | O14: ICO | P14: Organic Chemicals Industry End Demand
B15: =O15&"*" -> ICP* | F15: ="dd_"&LEFT(O15,1)&"_"&O15 -> dd_I_ICP | G15: =P15&" - demand devices" -> PFR Industry End Demand - demand devices | O15: ICP | P15: PFR Industry End Demand
B16: =O16&"*" -> ICT* | F16: ="dd_"&LEFT(O16,1)&"_"&O16 -> dd_I_ICT | G16: =P16&" - demand devices" -> Other Chemicals Industry End Demand - demand devices | O16: ICT | P16: Other Chemicals Industry End Demand
B17: =O17&"*" -> IFD* | F17: ="dd_"&LEFT(O17,1)&"_"&O17 -> dd_I_IFD | G17: =P17&" - demand devices" -> Food Industry End Demand - demand devices | O17: IFD | P17: Food Industry End Demand
B18: =O18&"*" -> IMA* | F18: ="dd_"&LEFT(O18,1)&"_"&O18 -> dd_I_IMA | G18: =P18&" - demand devices" -> Primary Aluminum Industry End Demand - demand devices | O18: IMA | P18: Primary Aluminum Industry End Demand
B19: =O19&"*" -> IML* | F19: ="dd_"&LEFT(O19,1)&"_"&O19 -> dd_I_IML | G19: =P19&" - demand devices" -> Secondary Aluminum Industry End Demand - demand devices | O19: IML | P19: Secondary Aluminum Industry End Demand
B20: =O20&"*" -> IMO* | F20: ="dd_"&LEFT(O20,1)&"_"&O20 -> dd_I_IMO | G20: =P20&" - demand devices" -> Other Metals Industry End Demand - demand devices | O20: IMO | P20: Other Metals Industry End Demand
B21: =O21&"*" -> IMS* | F21: ="dd_"&LEFT(O21,1)&"_"&O21 -> dd_I_IMS | G21: =P21&" - demand devices" -> Primary Steel Industry End Demand - demand devices | O21: IMS | P21: Primary Steel Industry End Demand
B22: =O22&"*" -> IMT* | F22: ="dd_"&LEFT(O22,1)&"_"&O22 -> dd_I_IMT | G22: =P22&" - demand devices" -> Secondary Steel Industry End Demand - demand devices | O22: IMT | P22: Secondary Steel Industry End Demand
B23: =O23&"*" -> INC* | F23: ="dd_"&LEFT(O23,1)&"_"&O23 -> dd_I_INC | G23: =P23&" - demand devices" -> Cement Industry End Demand - demand devices | O23: INC | P23: Cement Industry End Demand
... B30: =O30&"*" -> IPO* | F30: ="dd_"&LEFT(O30,1)&"_"&O30 -> dd_I_IPO | G30: =P30&" - demand devices" -> Other Pulp and Paper Industry End Demand - demand devices | O30: IPO | P30: Other Pulp and Paper Industry End Demand
A31: -IRE | E31: =O31 -> IXNONM | F31: ="dd_"&LEFT(O31,1)&"_"&O31 -> dd_I_IXNONM | G31: =P31&" - demand devices" -> Aggregate Non-Manufacturing Demand - demand devices | O31: IXNONM | P31: Aggregate Non-Manufacturing Demand
A32: -IRE | E32: =O32 -> RFZ | F32: ="dd_"&LEFT(O32,1)&"_"&O32 -> dd_R_RFZ | G32: =P32&" - demand devices" -> Residential Freezing - demand devices | O32: RFZ | P32: Residential Freezing
A33: -IRE | E33: =O33 -> RLT | F33: ="dd_"&LEFT(O33,1)&"_"&O33 -> dd_R_RLT | G33: =P33&" - demand devices" -> Residential Lighting - demand devices | O33: RLT | P33: Residential Lighting
A34: -IRE | E34: RO? | F34: dd_R_ROA | G34: =P34&" - demand devices" -> Residential Other Appliances - all - demand devices | O34: ROE | P34: Residential Other Appliances - all
A35: -IRE | E35: =O35 -> RRF | F35: ="dd_"&LEFT(O35,1)&"_"&O35 -> dd_R_RRF | G35: =P35&" - demand devices" -> Residential Refrigeration - demand devices | O35: RRF | P35: Residential Refrigeration
A36: -IRE | E36: =O36 -> RSC | F36: ="dd_"&LEFT(O36,1)&"_"&O36 -> dd_R_RSC | G36: =P36&" - demand devices" -> Residential Cooling - demand devices | O36: RSC | P36: Residential Cooling
A37: -IRE | E37: =O37 -> RSH | F37: ="dd_"&LEFT(O37,1)&"_"&O37 -> dd_R_RSH | G37: =P37&" - demand devices" -> Residential Heating - demand devices | O37: RSH | P37: Residential Heating
A38: -IRE | E38: =O38 -> RWH | F38: ="dd_"&LEFT(O38,1)&"_"&O38 -> dd_R_RWH | G38: =P38&" - demand devices" -> Residential Water Heating - demand devices | O38: RWH | P38: Residential Water Heating
A39: -IRE | E39: =O39 -> TA | F39: ="dd_"&LEFT(O39,1)&"_"&O39 -> dd_T_TA | G39: =P39&" - demand devices" -> TRN.AIR - demand devices | O39: TA | P39: TRN.AIR
A40: -IRE | E40: =O40 -> TB | F40: ="dd_"&LEFT(O40,1)&"_"&O40 -> dd_T_TB | G40: =P40&" - demand devices" -> TRN.BUS - demand devices | O40: TB | P40: TRN.BUS
A41: -IRE | E41: =O41 -> TC | F41: ="dd_"&LEFT(O41,1)&"_"&O41 -> dd_T_TC | G41: =P41&" - demand devices" -> TRN.TRUCK.COMMERCIAL - demand devices | O41: TC | P41: TRN.TRUCK.COMMERCIAL
A42: -IRE | E42: =O42 -> THL | F42: ="dd_"&LEFT(O42,1)&"_"&O42 -> dd_T_THL | G42: =P42&" - demand devices" -> TRN.TRUCK.HDV Long Haul - demand devices | O42: THL | P42: TRN.TRUCK.HDV Long Haul
A43: -IRE | E43: =O43 -> THS | F43: ="dd_"&LEFT(O43,1)&"_"&O43 -> dd_T_THS | G43: =P43&" - demand devices" -> TRN.TRUCK.HDV Short Haul - demand devices | O43: THS | P43: TRN.TRUCK.HDV Short Haul
A44: -IRE | E44: =O44 -> TL | F44: ="dd_"&LEFT(O44,1)&"_"&O44 -> dd_T_TL | G44: =P44&" - demand devices" -> TRN.LDV - demand devices | O44: TL | P44: TRN.LDV
A45: -IRE | E45: =O45 -> TM | F45: ="dd_"&LEFT(O45,1)&"_"&O45 -> dd_T_TM | G45: =P45&" - demand devices" -> TRN.TRUCK.MDV - demand devices | O45: TM | P45: TRN.TRUCK.MDV
A46: -IRE | E46: TOH??? | F46: dd_T_TOH | G46: =P46&" - demand devices" -> TRN.OH - demand devices | O46: TOH??? | P46: TRN.OH
...
