Workbook

Sheet Fill table
B2: ~TFM_FILL-R:w=BaseCoalPlants; Hcol=Region
B3: Scenario | C3: Attribute | D3: Year | E3: Attrib_Cond | F3: Val_Cond | G3: AllRegions | H3: Pset_PN | I3: Pset_PD
C4: ACT_COST | G4: 1 | H4: ECSTM* | I4: Residual*
C5: ENV_ACT | G5: 1 | H5: ECSTM* | I5: Residual*
C6: NCAP_AFA | G6: 1 | H6: ECSTM* | I6: Residual*
C7: NCAP_COST | G7: 1 | H7: ECSTM* | I7: Residual*
C8: NCAP_DRATE | G8: 1 | H8: ECSTM* | I8: Residual*
C9: NCAP_FOM | G9: 1 | H9: ECSTM* | I9: Residual*
C10: NCAP_PKCNT | G10: 1 | H10: ECSTM* | I10: Residual*
C11: PRC_CAPACT | G11: 1 | H11: ECSTM* | I11: Residual*
C12: EFF | G12: 1 | H12: ECSTM* | I12: Residual*
C13: LIFE | G13: 1 | H13: ECSTM* | I13: Residual*

Sheet BaseCoalPlants
A1: scenario | B1: attribute | C1: process | D1: commodity | E1: lim_type | F1: time_slice | G1: year | H1: commodity_group | I1: currency | J1: stage | K1: sow | L1: R0 | M1: R1 | N1: R2 | O1: R3 | P1: R4 | Q1: R5 | R1: R6 | S1: R7 | T1: R8 | U1: R9 | W1: R1 | X1: R2 | Y1: R3 | Z1: R4 | AA1: R5 | AB1: R6 | AC1: R7 | AD1: R8 | AE1: R9
A2: BASE | B2: ACT_COST | C2: ECSTMRBONR | D2: - | E2: - | F2: - | G2: 2010 | H2: - | I2: USD05 | J2: - | K2: - | M2: 1.0667559 | N2: 1.0667559 | O2: 1.0667559 | P2: 1.0667559 | Q2: 1.0667559 | R2: 1.0667559 | S2: 1.0667559 | T2: 1.0667559 | U2: 1.0667559 | W2: 0.96
A3: BASE | B3: ACT_COST | C3: ECSTMRBOO | D3: - | E3: - | F3: - | G3: 2010 | H3: - | I3: USD05 | J3: - | K3: - | M3: 2.11944 | N3: 1.8767671 | O3: 1.9392488 | P3: 1.840528 | Q3: 1.6386527 | R3: 1.7277413 | S3: 1.8940162 | T3: 1.8849702 | U3: 1.8196099
A4: BASE | B4: ACT_COST | C4: ECSTMRBOR | D4: - | E4: - | F4: - | G4: 2010 | H4: - | I4: USD05 | J4: - | K4: - | M4: 2.11944 | N4: 1.8767671 | O4: 1.9392488 | P4: 1.840528 | Q4: 1.6386527 | R4: 1.7277413 | S4: 1.8940162 | T4: 1.8849702 | U4: 1.8196099
A5: BASE | B5: ACT_COST | C5: ECSTMRBUO | D5: - | E5: - | F5: - | G5: 2010 | H5: - | I5: USD05 | J5: - | K5: - | M5: 2.11944 | N5: 1.8767671 | O5: 1.9392488 | P5: 1.840528 | Q5: 1.6386527 | R5: 1.7277413 | S5: 1.8940162 | T5: 1.8849702 | U5: 1.8196099
A6: BASE | B6: ACT_COST | C6: ECSTMRBUR | D6: - | E6: - | F6: - | G6: 2010 | H6: - | I6: USD05 | J6: - | K6: - | M6: 2.11944 | N6: 1.8767671 | O6: 1.9392488 | P6: 1.840528 | Q6: 1.6386527 | R6: 1.7277413 | S6: 1.8940162 | T6: 1.8849702 | U6: 1.8196099
A7: BASE | B7: ACT_COST | C7: ECSTMRLONR | D7: - | E7: - | F7: - | G7: 2010 | H7: - | I7: USD05 | J7: - | K7: - | M7: 1.0667559 | N7: 1.0667559 | O7: 1.0667559 | P7: 1.0667559 | Q7: 1.0667559 | R7: 1.0667559 | S7: 1.0667559 | T7: 1.0667559 | U7: 1.0667559
A8: BASE | B8: ACT_COST | C8: ECSTMRLOO | D8: - | E8: - | F8: - | G8: 2010 | H8: - | I8: USD05 | J8: - | K8: - | M8: 2.11944 | N8: 1.8767671 | O8: 1.9392488 | P8: 1.840528 | Q8: 1.6386527 | R8: 1.7277413 | S8: 1.8940162 | T8: 1.8849702 | U8: 1.8196099
A9: BASE | B9: ACT_COST | C9: ECSTMRLOR | D9: - | E9: - | F9: - | G9: 2010 | H9: - | I9: USD05 | J9: - | K9: - | M9: 2.11944 | N9: 1.8767671 | O9: 1.9392488 | P9: 1.840528 | Q9: 1.6386527 | R9: 1.7277413 | S9: 1.8940162 | T9: 1.8849702 | U9: 1.8196099
A10: BASE | B10: ACT_COST | C10: ECSTMRLUO | D10: - | E10: - | F10: - | G10: 2010 | H10: - | I10: USD05 | J10: - | K10: - | M10: 2.11944 | N10: 1.8767671 | O10: 1.9392488 | P10: 1.840528 | Q10: 1.6386527 | R10: 1.7277413 | S10: 1.8940162 | T10: 1.8849702 | U10: 1.8196099
A11: BASE | B11: ACT_COST | C11: ECSTMRLUR | D11: - | E11: - | F11: - | G11: 2010 | H11: - | I11: USD05 | J11: - | K11: - | M11: 2.11944 | N11: 1.8767671 | O11: 1.9392488 | P11: 1.840528 | Q11: 1.6386527 | R11: 1.7277413 | S11: 1.8940162 | T11: 1.8849702 | U11: 1.8196099
A12: BASE | B12: ACT_COST | C12: ECSTMRSONR | D12: - | E12: - | F12: - | G12: 2010 | H12: - | I12: USD05 | J12: - | K12: - | M12: 1.0667559 | N12: 1.0667559 | O12: 1.0667559 | P12: 1.0667559 | Q12: 1.0667559 | R12: 1.0667559 | S12: 1.0667559 | T12: 1.0667559 | U12: 1.0667559
A13: BASE | B13: ACT_COST | C13: ECSTMRSOO | D13: - | E13: - | F13: - | G13: 2010 | H13: - | I13: USD05 | J13: - | K13: - | M13: 2.11944 | N13: 1.8767671 | O13: 1.9392488 | P13: 1.840528 | Q13: 1.6386527 | R13: 1.7277413 | S13: 1.8940162 | T13: 1.8849702 | U13: 1.8196099
A14: BASE | B14: ACT_COST | C14: ECSTMRSOR | D14: - | E14: - | F14: - | G14: 2010 | H14: - | I14: USD05 | J14: - | K14: - | M14: 2.11944 | N14: 1.8767671 | O14: 1.9392488 | P14: 1.840528 | Q14: 1.6386527 | R14: 1.7277413 | S14: 1.8940162 | T14: 1.8849702 | U14: 1.8196099 | W14: =M14*$W$2 -> 2.0346624 | X14: =N14*$W$2 -> 1.8016964 | Y14: =O14*$W$2 -> 1.8616789 | Z14: =P14*$W$2 -> 1.7669069 | AA14: =Q14*$W$2 -> 1.5731066 | AB14: =R14*$W$2 -> 1.6586317 | AC14: =S14*$W$2 -> 1.8182555 | AD14: =T14*$W$2 -> 1.8095714 | AE14: =U14*$W$2 -> 1.7468255
A15: BASE | B15: ACT_COST | C15: ECSTMRSUO | D15: - | E15: - | F15: - | G15: 2010 | H15: - | I15: USD05 | J15: - | K15: - | M15: 2.11944 | N15: 1.8767671 | O15: 1.9392488 | P15: 1.840528 | Q15: 1.6386527 | R15: 1.7277413 | S15: 1.8940162 | T15: 1.8849702 | U15: 1.8196099 | W15: =M15*$W$2 -> 2.0346624 | X15: =N15*$W$2 -> 1.8016964 | Y15: =O15*$W$2 -> 1.8616789 | Z15: =P15*$W$2 -> 1.7669069 | AA15: =Q15*$W$2 -> 1.5731066 | AB15: =R15*$W$2 -> 1.6586317 | AC15: =S15*$W$2 -> 1.8182555 | AD15: =T15*$W$2 -> 1.8095714 | AE15: =U15*$W$2 -> 1.7468255
A16: BASE | B16: ACT_COST | C16: ECSTMRSUR | D16: - | E16: - | F16: - | G16: 2010 | H16: - | I16: USD05 | J16: - | K16: - | M16: 2.11944 | N16: 1.8767671 | O16: 1.9392488 | P16: 1.840528 | Q16: 1.6386527 | R16: 1.7277413 | S16: 1.8940162 | T16: 1.8849702 | U16: 1.8196099 | W16: =M16*$W$2 -> 2.0346624 | X16: =N16*$W$2 -> 1.8016964 | Y16: =O16*$W$2 -> 1.8616789 | Z16: =P16*$W$2 -> 1.7669069 | AA16: =Q16*$W$2 -> 1.5731066 | AB16: =R16*$W$2 -> 1.6586317 | AC16: =S16*$W$2 -> 1.8182555 | AD16: =T16*$W$2 -> 1.8095714 | AE16: =U16*$W$2 -> 1.7468255
A17: BASE | B17: EFF | C17: ECSTMRBOO | D17: - | E17: - | F17: ANNUAL | G17: 1950 | H17: - | I17: - | J17: - | K17: - | Q17: 0.33590808 | W17: =M17*$W$2 -> 0 | X17: =N17*$W$2 -> 0 | Y17: =O17*$W$2 -> 0 | Z17: =P17*$W$2 -> 0 | AA17: =Q17*$W$2 -> 0.32247176 | AB17: =R17*$W$2 -> 0 | AC17: =S17*$W$2 -> 0 | AD17: =T17*$W$2 -> 0 | AE17: =U17*$W$2 -> 0
A18: BASE | B18: EFF | C18: ECSTMRBOO | D18: - | E18: - | F18: ANNUAL | G18: 1951 | H18: - | I18: - | J18: - | K18: - | O18: 0.31613139 | Q18: 0.32620802 | R18: 0.28527456 | W18: =M18*$W$2 -> 0 | X18: =N18*$W$2 -> 0 | Y18: =O18*$W$2 -> 0.30348614 | Z18: =P18*$W$2 -> 0 | AA18: =Q18*$W$2 -> 0.3131597 | AB18: =R18*$W$2 -> 0.27386358 | AC18: =S18*$W$2 -> 0 | AD18: =T18*$W$2 -> 0 | AE18: =U18*$W$2 -> 0
A19: BASE | B19: EFF | C19: ECSTMRBOO | D19: - | E19: - | F19: ANNUAL | G19: 1952 | H19: - | I19: - | J19: - | K19: - | N19: 0.32415979 | O19: 0.32551009 | Q19: 0.32898732 | R19: 0.30698622 | W19: =M19*$W$2 -> 0 | X19: =N19*$W$2 -> 0.3111934 | Y19: =O19*$W$2 -> 0.31248969 | Z19: =P19*$W$2 -> 0 | AA19: =Q19*$W$2 -> 0.31582783 | AB19: =R19*$W$2 -> 0.29470677 | AC19: =S19*$W$2 -> 0 | AD19: =T19*$W$2 -> 0 | AE19: =U19*$W$2 -> 0
A20: BASE | B20: EFF | C20: ECSTMRBOO | D20: - | E20: - | F20: ANNUAL | G20: 1953 | H20: - | I20: - | J20: - | K20: - | N20: 0.31304606 | O20: 0.32760391 | Q20: 0.33734748 | R20: 0.32791965 | W20: =M20*$W$2 -> 0 | X20: =N20*$W$2 -> 0.30052422 | Y20: =O20*$W$2 -> 0.31449975 | Z20: =P20*$W$2 -> 0 | AA20: =Q20*$W$2 -> 0.32385358 | AB20: =R20*$W$2 -> 0.31480286 | AC20: =S20*$W$2 -> 0 | AD20: =T20*$W$2 -> 0 | AE20: =U20*$W$2 -> 0
A21: BASE | B21: EFF | C21: ECSTMRBOO | D21: - | E21: - | F21: ANNUAL | G21: 1954 | H21: - | I21: - | J21: - | K21: - | N21: 0.31772383 | O21: 0.33146073 | Q21: 0.3276621 | R21: 0.3356156 | W21: =M21*$W$2 -> 0 | X21: =N21*$W$2 -> 0.30501488 | Y21: =O21*$W$2 -> 0.3182023 | Z21: =P21*$W$2 -> 0 | AA21: =Q21*$W$2 -> 0.31455562 | AB21: =R21*$W$2 -> 0.32219098 | AC21: =S21*$W$2 -> 0 | AD21: =T21*$W$2 -> 0 | AE21: =U21*$W$2 -> 0
A22: BASE | B22: EFF | C22: ECSTMRBOO | D22: - | E22: - | F22: ANNUAL | G22: 1955 | H22: - | I22: - | J22: - | K22: - | N22: 0.34471384 | O22: 0.33901574 | Q22: 0.33273772 | R22: 0.33764607 | W22: =M22*$W$2 -> 0 | X22: =N22*$W$2 -> 0.33092528 | Y22: =O22*$W$2 -> 0.32545511 | Z22: =P22*$W$2 -> 0 | AA22: =Q22*$W$2 -> 0.31942821 | AB22: =R22*$W$2 -> 0.32414023 | AC22: =S22*$W$2 -> 0 | AD22: =T22*$W$2 -> 0 | AE22: =U22*$W$2 -> 0
A23: BASE | B23: EFF | C23: ECSTMRBOO | D23: - | E23: - | F23: ANNUAL | G23: 1956 | H23: - | I23: - | J23: - | K23: - | Q23: 0.33942006 | R23: 0.34838868 | W23: =M23*$W$2 -> 0 | X23: =N23*$W$2 -> 0 | Y23: =O23*$W$2 -> 0 | Z23: =P23*$W$2 -> 0 | AA23: =Q23*$W$2 -> 0.32584325 | AB23: =R23*$W$2 -> 0.33445313 | AC23: =S23*$W$2 -> 0 | AD23: =T23*$W$2 -> 0 | AE23: =U23*$W$2 -> 0
A24: BASE | B24: EFF | C24: ECSTMRBOO | D24: - | E24: - | F24: ANNUAL | G24: 1957 | H24: - | I24: - | J24: - | K24: - | O24: 0.3542601 | Q24: 0.34318037 | R24: 0.34534179 | W24: =M24*$W$2 -> 0 | X24: =N24*$W$2 -> 0 | Y24: =O24*$W$2 -> 0.3400897 | Z24: =P24*$W$2 -> 0 | AA24: =Q24*$W$2 -> 0.32945315 | AB24: =R24*$W$2 -> 0.33152812 | AC24: =S24*$W$2 -> 0 | AD24: =T24*$W$2 -> 0 | AE24: =U24*$W$2 -> 0
A25: BASE | B25: EFF | C25: ECSTMRBOO | D25: - | E25: - | F25: ANNUAL | G25: 1958 | H25: - | I25: - | J25: - | K25: - | M25: 0.32439607 | N25: 0.34303015 | O25: 0.35597945 | Q25: 0.33487423 | R25: 0.3434648 | W25: =M25*$W$2 -> 0.31142023 | X25: =N25*$W$2 -> 0.32930894 | Y25: =O25*$W$2 -> 0.34174027 | Z25: =P25*$W$2 -> 0 | AA25: =Q25*$W$2 -> 0.32147926 | AB25: =R25*$W$2 -> 0.32972621 | AC25: =S25*$W$2 -> 0 | AD25: =T25*$W$2 -> 0 | AE25: =U25*$W$2 -> 0
A26: BASE | B26: EFF | C26: ECSTMRBOO | D26: - | E26: - | F26: ANNUAL | G26: 1959 | H26: - | I26: - | J26: - | K26: - | N26: 0.32834381 | O26: 0.33372141 | Q26: 0.33329796 | R26: 0.34901639 | W26: =M26*$W$2 -> 0 | X26: =N26*$W$2 -> 0.31521006 | Y26: =O26*$W$2 -> 0.32037255 | Z26: =P26*$W$2 -> 0 | AA26: =Q26*$W$2 -> 0.31996605 | AB26: =R26*$W$2 -> 0.33505573 | AC26: =S26*$W$2 -> 0 | AD26: =T26*$W$2 -> 0 | AE26: =U26*$W$2 -> 0
A27: BASE | B27: EFF | C27: ECSTMRBOO | D27: - | E27: - | F27: ANNUAL | G27: 1960 | H27: - | I27: - | J27: - | K27: - | M27: 0.30418845 | N27: 0.33922864 | O27: 0.33527628 | Q27: 0.32485043 | W27: =M27*$W$2 -> 0.29202092 | X27: =N27*$W$2 -> 0.32565949 | Y27: =O27*$W$2 -> 0.32186523 | Z27: =P27*$W$2 -> 0 | AA27: =Q27*$W$2 -> 0.31185641 | AB27: =R27*$W$2 -> 0 | AC27: =S27*$W$2 -> 0 | AD27: =T27*$W$2 -> 0 | AE27: =U27*$W$2 -> 0
A28: BASE | B28: EFF | C28: ECSTMRBOO | D28: - | E28: - | F28: ANNUAL | G28: 1961 | H28: - | I28: - | J28: - | K28: - | N28: 0.36451001 | O28: 0.33137169 | Q28: 0.33671875 | R28: 0.33728598 | W28: =M28*$W$2 -> 0 | X28: =N28*$W$2 -> 0.34992961 | Y28: =O28*$W$2 -> 0.31811682 | Z28: =P28*$W$2 -> 0 | AA28: =Q28*$W$2 -> 0.32325 | AB28: =R28*$W$2 -> 0.32379454 | AC28: =S28*$W$2 -> 0 | AD28: =T28*$W$2 -> 0 | AE28: =U28*$W$2 -> 0
A29: BASE | B29: EFF | C29: ECSTMRBOO | D29: - | E29: - | F29: ANNUAL | G29: 1962 | H29: - | I29: - | J29: - | K29: - | N29: 0.33208281 | O29: 0.33499529 | Q29: 0.33104983 | R29: 0.31374791 | W29: =M29*$W$2 -> 0 | X29: =N29*$W$2 -> 0.3187995 | Y29: =O29*$W$2 -> 0.32159548 | Z29: =P29*$W$2 -> 0 | AA29: =Q29*$W$2 -> 0.31780784 | AB29: =R29*$W$2 -> 0.30119799 | AC29: =S29*$W$2 -> 0 | AD29: =T29*$W$2 -> 0 | AE29: =U29*$W$2 -> 0
A30: BASE | B30: EFF | C30: ECSTMRBOO | D30: - | E30: - | F30: ANNUAL | G30: 1963 | H30: - | I30: - | J30: - | K30: - | M30: 0.37456886 | N30: 0.32807637 | Q30: 0.34367925 | W30: =M30*$W$2 -> 0.3595861 | X30: =N30*$W$2 -> 0.31495331 | Y30: =O30*$W$2 -> 0 | Z30: =P30*$W$2 -> 0 | AA30: =Q30*$W$2 -> 0.32993208 | AB30: =R30*$W$2 -> 0 | AC30: =S30*$W$2 -> 0 | AD30: =T30*$W$2 -> 0 | AE30: =U30*$W$2 -> 0
A31: BASE | B31: EFF | C31: ECSTMRBOO | D31: - | E31: - | F31: ANNUAL | G31: 1964 | H31: - | I31: - | J31: - | K31: - | M31: 0.37456886 | N31: 0.3095242 | O31: 0.30973244 | Q31: 0.33556918 | R31: 0.36660102 | W31: =M31*$W$2 -> 0.3595861 | X31: =N31*$W$2 -> 0.29714324 | Y31: =O31*$W$2 -> 0.29734314 | Z31: =P31*$W$2 -> 0 | AA31: =Q31*$W$2 -> 0.32214642 | AB31: =R31*$W$2 -> 0.35193698 | AC31: =S31*$W$2 -> 0 | AD31: =T31*$W$2 -> 0 | AE31: =U31*$W$2 -> 0
A32: BASE | B32: EFF | C32: ECSTMRBOO | D32: - | E32: - | F32: ANNUAL | G32: 1965 | H32: - | I32: - | J32: - | K32: - | N32: 0.37106593 | O32: 0.30288676 | Q32: 0.33565195 | R32: 0.34316777 | W32: =M32*$W$2 -> 0 | X32: =N32*$W$2 -> 0.35622329 | Y32: =O32*$W$2 -> 0.29077129 | Z32: =P32*$W$2 -> 0 | AA32: =Q32*$W$2 -> 0.32222587 | AB32: =R32*$W$2 -> 0.32944106 | AC32: =S32*$W$2 -> 0 | AD32: =T32*$W$2 -> 0 | AE32: =U32*$W$2 -> 0
A33: BASE | B33: EFF | C33: ECSTMRBOO | D33: - | E33: - | F33: ANNUAL | G33: 1966 | H33: - | I33: - | J33: - | K33: - | Q33: 0.33843194 | R33: 0.32775848 | W33: =M33*$W$2 -> 0 | X33: =N33*$W$2 -> 0 | Y33: =O33*$W$2 -> 0 | Z33: =P33*$W$2 -> 0 | AA33: =Q33*$W$2 -> 0.32489466 | AB33: =R33*$W$2 -> 0.31464814 | AC33: =S33*$W$2 -> 0 | AD33: =T33*$W$2 -> 0 | AE33: =U33*$W$2 -> 0
A34: BASE | B34: EFF | C34: ECSTMRBOO | D34: - | E34: - | F34: ANNUAL | G34: 1967 | H34: - | I34: - | J34: - | K34: - | N34: 0.30299434 | O34: 0.35902698 | Q34: 0.33650849 | R34: 0.3784321 | W34: =M34*$W$2 -> 0 | X34: =N34*$W$2 -> 0.29087457 | Y34: =O34*$W$2 -> 0.3446659 | Z34: =P34*$W$2 -> 0 | AA34: =Q34*$W$2 -> 0.32304815 | AB34: =R34*$W$2 -> 0.36329482 | AC34: =S34*$W$2 -> 0 | AD34: =T34*$W$2 -> 0 | AE34: =U34*$W$2 -> 0
A35: BASE | B35: EFF | C35: ECSTMRBOO | D35: - | E35: - | F35: ANNUAL | G35: 1968 | H35: - | I35: - | J35: - | K35: - | M35: 0.32776124 | O35: 0.34704219 | Q35: 0.35991164 | R35: 0.35243981 | W35: =M35*$W$2 -> 0.31465079 | X35: =N35*$W$2 -> 0 | Y35: =O35*$W$2 -> 0.3331605 | Z35: =P35*$W$2 -> 0 | AA35: =Q35*$W$2 -> 0.34551518 | AB35: =R35*$W$2 -> 0.33834222 | AC35: =S35*$W$2 -> 0 | AD35: =T35*$W$2 -> 0 | AE35: =U35*$W$2 -> 0
A36: BASE | B36: EFF | C36: ECSTMRBOO | D36: - | E36: - | F36: ANNUAL | G36: 1969 | H36: - | I36: - | J36: - | K36: - | M36: 0.37456886 | O36: 0.34964951 | Q36: 0.35500006 | R36: 0.33865618 | W36: =M36*$W$2 -> 0.3595861 | X36: =N36*$W$2 -> 0 | Y36: =O36*$W$2 -> 0.33566353 | Z36: =P36*$W$2 -> 0 | AA36: =Q36*$W$2 -> 0.34080005 | AB36: =R36*$W$2 -> 0.32510994 | AC36: =S36*$W$2 -> 0 | AD36: =T36*$W$2 -> 0 | AE36: =U36*$W$2 -> 0
A37: BASE | B37: EFF | C37: ECSTMRBOO | D37: - | E37: - | F37: ANNUAL | G37: 1970 | H37: - | I37: - | J37: - | K37: - | N37: 0.34855182 | O37: 0.34532756 | Q37: 0.31394817 | R37: 0.31128647 | W37: =M37*$W$2 -> 0 | X37: =N37*$W$2 -> 0.33460974 | Y37: =O37*$W$2 -> 0.33151446 | Z37: =P37*$W$2 -> 0 | AA37: =Q37*$W$2 -> 0.30139025 | AB37: =R37*$W$2 -> 0.29883501 | AC37: =S37*$W$2 -> 0 | AD37: =T37*$W$2 -> 0 | AE37: =U37*$W$2 -> 0
A38: BASE | B38: EFF | C38: ECSTMRBOO | D38: - | E38: - | F38: ANNUAL | G38: 1971 | H38: - | I38: - | J38: - | K38: - | O38: 0.36149843 | R38: 0.3507882 | W38: =M38*$W$2 -> 0 | X38: =N38*$W$2 -> 0 | Y38: =O38*$W$2 -> 0.34703849 | Z38: =P38*$W$2 -> 0 | AA38: =Q38*$W$2 -> 0 | AB38: =R38*$W$2 -> 0.33675667 | AC38: =S38*$W$2 -> 0 | AD38: =T38*$W$2 -> 0 | AE38: =U38*$W$2 -> 0
A39: BASE | B39: EFF | C39: ECSTMRBOO | D39: - | E39: - | F39: ANNUAL | G39: 1972 | H39: - | I39: - | J39: - | K39: - | O39: 0.35101125 | Q39: 0.34419228 | R39: 0.34941638 | W39: =M39*$W$2 -> 0 | X39: =N39*$W$2 -> 0 | Y39: =O39*$W$2 -> 0.3369708 | Z39: =P39*$W$2 -> 0 | AA39: =Q39*$W$2 -> 0.33042459 | AB39: =R39*$W$2 -> 0.33543973 | AC39: =S39*$W$2 -> 0 | AD39: =T39*$W$2 -> 0 | AE39: =U39*$W$2 -> 0
A40: BASE | B40: EFF | C40: ECSTMRBOO | D40: - | E40: - | F40: ANNUAL | G40: 1973 | H40: - | I40: - | J40: - | K40: - | O40: 0.3536165 | Q40: 0.32050236 | R40: 0.35012084 | W40: =M40*$W$2 -> 0 | X40: =N40*$W$2 -> 0 | Y40: =O40*$W$2 -> 0.33947184 | Z40: =P40*$W$2 -> 0 | AA40: =Q40*$W$2 -> 0.30768227 | AB40: =R40*$W$2 -> 0.33611601 | AC40: =S40*$W$2 -> 0 | AD40: =T40*$W$2 -> 0 | AE40: =U40*$W$2 -> 0
...

Sheet LifeExtn techs
C2: ~TFM_INS
C3: Attribute | D3: PSET_PN | E3: CSET_CN | F3: LimType | G3: TimeSlice | H3: Year | I3: Other_Indexes | J3: Curr | K3: Stage | L3: SOW | M3: =BaseCoalPlants!L1 -> R0 | N3: =BaseCoalPlants!M1 -> R1 | O3: =BaseCoalPlants!N1 -> R2 | P3: =BaseCoalPlants!O1 -> R3 | Q3: =BaseCoalPlants!P1 -> R4 | R3: =BaseCoalPlants!Q1 -> R5 | S3: =BaseCoalPlants!R1 -> R6 | T3: =BaseCoalPlants!S1 -> R7 | ... V3: =BaseCoalPlants!U1 -> R9 | X3: Attribute | Y3: PSET_PN | Z3: AllRegions
C4: =IF(BaseCoalPlants!B3="VDA_FLOP",IF(BaseCoalPlants!D3="ELC","*","INPUT"),BaseCoalPlants!B3) -> ACT_COST | D4: =IF(BaseCoalPlants!C3="","\I:",BaseCoalPlants!C3&"_LE") -> ECSTMRBOO_LE | E4: =IF(BaseCoalPlants!D3="-","",BaseCoalPlants!D3) | F4: =IF(BaseCoalPlants!E3="-","",BaseCoalPlants!E3) | G4: =IF(BaseCoalPlants!F3="-","",BaseCoalPlants!F3) | H4: =IF(BaseCoalPlants!G3="-","",BaseCoalPlants!G3) -> 2010 | I4: =IF(BaseCoalPlants!H3="-","",BaseCoalPlants!H3) | J4: =IF(BaseCoalPlants!I3="-","",BaseCoalPlants!I3) -> USD05 | K4: =IF(BaseCoalPlants!J3="-","",BaseCoalPlants!J3) | L4: =IF(BaseCoalPlants!K3="-","",BaseCoalPlants!K3) | M4: =IF(BaseCoalPlants!L3=0,"",BaseCoalPlants!L3) | N4: =IF(BaseCoalPlants!M3=0,"",BaseCoalPlants!M3) -> 2.11944 | O4: =IF(BaseCoalPlants!N3=0,"",BaseCoalPlants!N3) -> 1.8767671 | P4: =IF(BaseCoalPlants!O3=0,"",BaseCoalPlants!O3) -> 1.9392488 | Q4: =IF(BaseCoalPlants!P3=0,"",BaseCoalPlants!P3) -> 1.840528 | R4: =IF(BaseCoalPlants!Q3=0,"",BaseCoalPlants!Q3) -> 1.6386527 | S4: =IF(BaseCoalPlants!R3=0,"",BaseCoalPlants!R3) -> 1.7277413 | T4: =IF(BaseCoalPlants!S3=0,"",BaseCoalPlants!S3) -> 1.8940162 | ... V4: =IF(BaseCoalPlants!U3=0,"",BaseCoalPlants!U3) -> 1.8196099 | X4: START | Y4: *LE | Z4: 2020
C5: =IF(BaseCoalPlants!B4="VDA_FLOP",IF(BaseCoalPlants!D4="ELC","*","INPUT"),BaseCoalPlants!B4) -> ACT_COST | D5: =IF(BaseCoalPlants!C4="","\I:",BaseCoalPlants!C4&"_LE") -> ECSTMRBOR_LE | E5: =IF(BaseCoalPlants!D4="-","",BaseCoalPlants!D4) | F5: =IF(BaseCoalPlants!E4="-","",BaseCoalPlants!E4) | G5: =IF(BaseCoalPlants!F4="-","",BaseCoalPlants!F4) | H5: =IF(BaseCoalPlants!G4="-","",BaseCoalPlants!G4) -> 2010 | I5: =IF(BaseCoalPlants!H4="-","",BaseCoalPlants!H4) | J5: =IF(BaseCoalPlants!I4="-","",BaseCoalPlants!I4) -> USD05 | K5: =IF(BaseCoalPlants!J4="-","",BaseCoalPlants!J4) | L5: =IF(BaseCoalPlants!K4="-","",BaseCoalPlants!K4) | M5: =IF(BaseCoalPlants!L4=0,"",BaseCoalPlants!L4) | N5: =IF(BaseCoalPlants!M4=0,"",BaseCoalPlants!M4) -> 2.11944 | O5: =IF(BaseCoalPlants!N4=0,"",BaseCoalPlants!N4) -> 1.8767671 | P5: =IF(BaseCoalPlants!O4=0,"",BaseCoalPlants!O4) -> 1.9392488 | Q5: =IF(BaseCoalPlants!P4=0,"",BaseCoalPlants!P4) -> 1.840528 | R5: =IF(BaseCoalPlants!Q4=0,"",BaseCoalPlants!Q4) -> 1.6386527 | S5: =IF(BaseCoalPlants!R4=0,"",BaseCoalPlants!R4) -> 1.7277413 | T5: =IF(BaseCoalPlants!S4=0,"",BaseCoalPlants!S4) -> 1.8940162 | ... V5: =IF(BaseCoalPlants!U4=0,"",BaseCoalPlants!U4) -> 1.8196099
C6: =IF(BaseCoalPlants!B5="VDA_FLOP",IF(BaseCoalPlants!D5="ELC","*","INPUT"),BaseCoalPlants!B5) -> ACT_COST | D6: =IF(BaseCoalPlants!C5="","\I:",BaseCoalPlants!C5&"_LE") -> ECSTMRBUO_LE | E6: =IF(BaseCoalPlants!D5="-","",BaseCoalPlants!D5) | F6: =IF(BaseCoalPlants!E5="-","",BaseCoalPlants!E5) | G6: =IF(BaseCoalPlants!F5="-","",BaseCoalPlants!F5) | H6: =IF(BaseCoalPlants!G5="-","",BaseCoalPlants!G5) -> 2010 | I6: =IF(BaseCoalPlants!H5="-","",BaseCoalPlants!H5) | J6: =IF(BaseCoalPlants!I5="-","",BaseCoalPlants!I5) -> USD05 | K6: =IF(BaseCoalPlants!J5="-","",BaseCoalPlants!J5) | L6: =IF(BaseCoalPlants!K5="-","",BaseCoalPlants!K5) | M6: =IF(BaseCoalPlants!L5=0,"",BaseCoalPlants!L5) | N6: =IF(BaseCoalPlants!M5=0,"",BaseCoalPlants!M5) -> 2.11944 | O6: =IF(BaseCoalPlants!N5=0,"",BaseCoalPlants!N5) -> 1.8767671 | P6: =IF(BaseCoalPlants!O5=0,"",BaseCoalPlants!O5) -> 1.9392488 | Q6: =IF(BaseCoalPlants!P5=0,"",BaseCoalPlants!P5) -> 1.840528 | R6: =IF(BaseCoalPlants!Q5=0,"",BaseCoalPlants!Q5) -> 1.6386527 | S6: =IF(BaseCoalPlants!R5=0,"",BaseCoalPlants!R5) -> 1.7277413 | T6: =IF(BaseCoalPlants!S5=0,"",BaseCoalPlants!S5) -> 1.8940162 | ... V6: =IF(BaseCoalPlants!U5=0,"",BaseCoalPlants!U5) -> 1.8196099
C7: =IF(BaseCoalPlants!B6="VDA_FLOP",IF(BaseCoalPlants!D6="ELC","*","INPUT"),BaseCoalPlants!B6) -> ACT_COST | D7: =IF(BaseCoalPlants!C6="","\I:",BaseCoalPlants!C6&"_LE") -> ECSTMRBUR_LE | E7: =IF(BaseCoalPlants!D6="-","",BaseCoalPlants!D6) | F7: =IF(BaseCoalPlants!E6="-","",BaseCoalPlants!E6) | G7: =IF(BaseCoalPlants!F6="-","",BaseCoalPlants!F6) | H7: =IF(BaseCoalPlants!G6="-","",BaseCoalPlants!G6) -> 2010 | I7: =IF(BaseCoalPlants!H6="-","",BaseCoalPlants!H6) | J7: =IF(BaseCoalPlants!I6="-","",BaseCoalPlants!I6) -> USD05 | K7: =IF(BaseCoalPlants!J6="-","",BaseCoalPlants!J6) | L7: =IF(BaseCoalPlants!K6="-","",BaseCoalPlants!K6) | M7: =IF(BaseCoalPlants!L6=0,"",BaseCoalPlants!L6) | N7: =IF(BaseCoalPlants!M6=0,"",BaseCoalPlants!M6) -> 2.11944 | O7: =IF(BaseCoalPlants!N6=0,"",BaseCoalPlants!N6) -> 1.8767671 | P7: =IF(BaseCoalPlants!O6=0,"",BaseCoalPlants!O6) -> 1.9392488 | Q7: =IF(BaseCoalPlants!P6=0,"",BaseCoalPlants!P6) -> 1.840528 | R7: =IF(BaseCoalPlants!Q6=0,"",BaseCoalPlants!Q6) -> 1.6386527 | S7: =IF(BaseCoalPlants!R6=0,"",BaseCoalPlants!R6) -> 1.7277413 | T7: =IF(BaseCoalPlants!S6=0,"",BaseCoalPlants!S6) -> 1.8940162 | ... V7: =IF(BaseCoalPlants!U6=0,"",BaseCoalPlants!U6) -> 1.8196099
C8: =IF(BaseCoalPlants!B8="VDA_FLOP",IF(BaseCoalPlants!D8="ELC","*","INPUT"),BaseCoalPlants!B8) -> ACT_COST | D8: =IF(BaseCoalPlants!C8="","\I:",BaseCoalPlants!C8&"_LE") -> ECSTMRLOO_LE | E8: =IF(BaseCoalPlants!D8="-","",BaseCoalPlants!D8) | F8: =IF(BaseCoalPlants!E8="-","",BaseCoalPlants!E8) | G8: =IF(BaseCoalPlants!F8="-","",BaseCoalPlants!F8) | H8: =IF(BaseCoalPlants!G8="-","",BaseCoalPlants!G8) -> 2010 | I8: =IF(BaseCoalPlants!H8="-","",BaseCoalPlants!H8) | J8: =IF(BaseCoalPlants!I8="-","",BaseCoalPlants!I8) -> USD05 | K8: =IF(BaseCoalPlants!J8="-","",BaseCoalPlants!J8) | L8: =IF(BaseCoalPlants!K8="-","",BaseCoalPlants!K8) | M8: =IF(BaseCoalPlants!L8=0,"",BaseCoalPlants!L8) | N8: =IF(BaseCoalPlants!M8=0,"",BaseCoalPlants!M8) -> 2.11944 | O8: =IF(BaseCoalPlants!N8=0,"",BaseCoalPlants!N8) -> 1.8767671 | P8: =IF(BaseCoalPlants!O8=0,"",BaseCoalPlants!O8) -> 1.9392488 | Q8: =IF(BaseCoalPlants!P8=0,"",BaseCoalPlants!P8) -> 1.840528 | R8: =IF(BaseCoalPlants!Q8=0,"",BaseCoalPlants!Q8) -> 1.6386527 | S8: =IF(BaseCoalPlants!R8=0,"",BaseCoalPlants!R8) -> 1.7277413 | T8: =IF(BaseCoalPlants!S8=0,"",BaseCoalPlants!S8) -> 1.8940162 | ... V8: =IF(BaseCoalPlants!U8=0,"",BaseCoalPlants!U8) -> 1.8196099
C9: =IF(BaseCoalPlants!B9="VDA_FLOP",IF(BaseCoalPlants!D9="ELC","*","INPUT"),BaseCoalPlants!B9) -> ACT_COST | D9: =IF(BaseCoalPlants!C9="","\I:",BaseCoalPlants!C9&"_LE") -> ECSTMRLOR_LE | E9: =IF(BaseCoalPlants!D9="-","",BaseCoalPlants!D9) | F9: =IF(BaseCoalPlants!E9="-","",BaseCoalPlants!E9) | G9: =IF(BaseCoalPlants!F9="-","",BaseCoalPlants!F9) | H9: =IF(BaseCoalPlants!G9="-","",BaseCoalPlants!G9) -> 2010 | I9: =IF(BaseCoalPlants!H9="-","",BaseCoalPlants!H9) | J9: =IF(BaseCoalPlants!I9="-","",BaseCoalPlants!I9) -> USD05 | K9: =IF(BaseCoalPlants!J9="-","",BaseCoalPlants!J9) | L9: =IF(BaseCoalPlants!K9="-","",BaseCoalPlants!K9) | M9: =IF(BaseCoalPlants!L9=0,"",BaseCoalPlants!L9) | N9: =IF(BaseCoalPlants!M9=0,"",BaseCoalPlants!M9) -> 2.11944 | O9: =IF(BaseCoalPlants!N9=0,"",BaseCoalPlants!N9) -> 1.8767671 | P9: =IF(BaseCoalPlants!O9=0,"",BaseCoalPlants!O9) -> 1.9392488 | Q9: =IF(BaseCoalPlants!P9=0,"",BaseCoalPlants!P9) -> 1.840528 | R9: =IF(BaseCoalPlants!Q9=0,"",BaseCoalPlants!Q9) -> 1.6386527 | S9: =IF(BaseCoalPlants!R9=0,"",BaseCoalPlants!R9) -> 1.7277413 | T9: =IF(BaseCoalPlants!S9=0,"",BaseCoalPlants!S9) -> 1.8940162 | ... V9: =IF(BaseCoalPlants!U9=0,"",BaseCoalPlants!U9) -> 1.8196099
C10: =IF(BaseCoalPlants!B10="VDA_FLOP",IF(BaseCoalPlants!D10="ELC","*","INPUT"),BaseCoalPlants!B10) -> ACT_COST | D10: =IF(BaseCoalPlants!C10="","\I:",BaseCoalPlants!C10&"_LE") -> ECSTMRLUO_LE | E10: =IF(BaseCoalPlants!D10="-","",BaseCoalPlants!D10) | F10: =IF(BaseCoalPlants!E10="-","",BaseCoalPlants!E10) | G10: =IF(BaseCoalPlants!F10="-","",BaseCoalPlants!F10) | H10: =IF(BaseCoalPlants!G10="-","",BaseCoalPlants!G10) -> 2010 | I10: =IF(BaseCoalPlants!H10="-","",BaseCoalPlants!H10) | J10: =IF(BaseCoalPlants!I10="-","",BaseCoalPlants!I10) -> USD05 | K10: =IF(BaseCoalPlants!J10="-","",BaseCoalPlants!J10) | L10: =IF(BaseCoalPlants!K10="-","",BaseCoalPlants!K10) | M10: =IF(BaseCoalPlants!L10=0,"",BaseCoalPlants!L10) | N10: =IF(BaseCoalPlants!M10=0,"",BaseCoalPlants!M10) -> 2.11944 | O10: =IF(BaseCoalPlants!N10=0,"",BaseCoalPlants!N10) -> 1.8767671 | P10: =IF(BaseCoalPlants!O10=0,"",BaseCoalPlants!O10) -> 1.9392488 | Q10: =IF(BaseCoalPlants!P10=0,"",BaseCoalPlants!P10) -> 1.840528 | R10: =IF(BaseCoalPlants!Q10=0,"",BaseCoalPlants!Q10) -> 1.6386527 | S10: =IF(BaseCoalPlants!R10=0,"",BaseCoalPlants!R10) -> 1.7277413 | T10: =IF(BaseCoalPlants!S10=0,"",BaseCoalPlants!S10) -> 1.8940162 | ... V10: =IF(BaseCoalPlants!U10=0,"",BaseCoalPlants!U10) -> 1.8196099
C11: =IF(BaseCoalPlants!B13="VDA_FLOP",IF(BaseCoalPlants!D13="ELC","*","INPUT"),BaseCoalPlants!B13) -> ACT_COST | D11: =IF(BaseCoalPlants!C13="","\I:",BaseCoalPlants!C13&"_LE") -> ECSTMRSOO_LE | E11: =IF(BaseCoalPlants!D13="-","",BaseCoalPlants!D13) | F11: =IF(BaseCoalPlants!E13="-","",BaseCoalPlants!E13) | G11: =IF(BaseCoalPlants!F13="-","",BaseCoalPlants!F13) | H11: =IF(BaseCoalPlants!G13="-","",BaseCoalPlants!G13) -> 2010 | I11: =IF(BaseCoalPlants!H13="-","",BaseCoalPlants!H13) | J11: =IF(BaseCoalPlants!I13="-","",BaseCoalPlants!I13) -> USD05 | K11: =IF(BaseCoalPlants!J13="-","",BaseCoalPlants!J13) | L11: =IF(BaseCoalPlants!K13="-","",BaseCoalPlants!K13) | M11: =IF(BaseCoalPlants!L13=0,"",BaseCoalPlants!L13) | N11: =IF(BaseCoalPlants!M13=0,"",BaseCoalPlants!M13) -> 2.11944 | O11: =IF(BaseCoalPlants!N13=0,"",BaseCoalPlants!N13) -> 1.8767671 | P11: =IF(BaseCoalPlants!O13=0,"",BaseCoalPlants!O13) -> 1.9392488 | Q11: =IF(BaseCoalPlants!P13=0,"",BaseCoalPlants!P13) -> 1.840528 | R11: =IF(BaseCoalPlants!Q13=0,"",BaseCoalPlants!Q13) -> 1.6386527 | S11: =IF(BaseCoalPlants!R13=0,"",BaseCoalPlants!R13) -> 1.7277413 | T11: =IF(BaseCoalPlants!S13=0,"",BaseCoalPlants!S13) -> 1.8940162 | ... V11: =IF(BaseCoalPlants!U13=0,"",BaseCoalPlants!U13) -> 1.8196099
C12: =IF(BaseCoalPlants!B14="VDA_FLOP",IF(BaseCoalPlants!D14="ELC","*","INPUT"),BaseCoalPlants!B14) -> ACT_COST | D12: =IF(BaseCoalPlants!C14="","\I:",BaseCoalPlants!C14&"_LE") -> ECSTMRSOR_LE | E12: =IF(BaseCoalPlants!D14="-","",BaseCoalPlants!D14) | F12: =IF(BaseCoalPlants!E14="-","",BaseCoalPlants!E14) | G12: =IF(BaseCoalPlants!F14="-","",BaseCoalPlants!F14) | H12: =IF(BaseCoalPlants!G14="-","",BaseCoalPlants!G14) -> 2010 | I12: =IF(BaseCoalPlants!H14="-","",BaseCoalPlants!H14) | J12: =IF(BaseCoalPlants!I14="-","",BaseCoalPlants!I14) -> USD05 | K12: =IF(BaseCoalPlants!J14="-","",BaseCoalPlants!J14) | L12: =IF(BaseCoalPlants!K14="-","",BaseCoalPlants!K14) | M12: =IF(BaseCoalPlants!L14=0,"",BaseCoalPlants!L14) | N12: =IF(BaseCoalPlants!W14=0,"",BaseCoalPlants!W14) -> 2.0346624 | O12: =IF(BaseCoalPlants!X14=0,"",BaseCoalPlants!X14) -> 1.8016964 | P12: =IF(BaseCoalPlants!Y14=0,"",BaseCoalPlants!Y14) -> 1.8616789 | Q12: =IF(BaseCoalPlants!Z14=0,"",BaseCoalPlants!Z14) -> 1.7669069 | R12: =IF(BaseCoalPlants!AA14=0,"",BaseCoalPlants!AA14) -> 1.5731066 | S12: =IF(BaseCoalPlants!AB14=0,"",BaseCoalPlants!AB14) -> 1.6586317 | T12: =IF(BaseCoalPlants!AC14=0,"",BaseCoalPlants!AC14) -> 1.8182555 | U12: =IF(BaseCoalPlants!AD14=0,"",BaseCoalPlants!AD14) -> 1.8095714 | V12: =IF(BaseCoalPlants!AE14=0,"",BaseCoalPlants!AE14) -> 1.7468255
C13: =IF(BaseCoalPlants!B15="VDA_FLOP",IF(BaseCoalPlants!D15="ELC","*","INPUT"),BaseCoalPlants!B15) -> ACT_COST | D13: =IF(BaseCoalPlants!C15="","\I:",BaseCoalPlants!C15&"_LE") -> ECSTMRSUO_LE | E13: =IF(BaseCoalPlants!D15="-","",BaseCoalPlants!D15) | F13: =IF(BaseCoalPlants!E15="-","",BaseCoalPlants!E15) | G13: =IF(BaseCoalPlants!F15="-","",BaseCoalPlants!F15) | H13: =IF(BaseCoalPlants!G15="-","",BaseCoalPlants!G15) -> 2010 | I13: =IF(BaseCoalPlants!H15="-","",BaseCoalPlants!H15) | J13: =IF(BaseCoalPlants!I15="-","",BaseCoalPlants!I15) -> USD05 | K13: =IF(BaseCoalPlants!J15="-","",BaseCoalPlants!J15) | L13: =IF(BaseCoalPlants!K15="-","",BaseCoalPlants!K15) | M13: =IF(BaseCoalPlants!L15=0,"",BaseCoalPlants!L15) | N13: =IF(BaseCoalPlants!W15=0,"",BaseCoalPlants!W15) -> 2.0346624 | O13: =IF(BaseCoalPlants!X15=0,"",BaseCoalPlants!X15) -> 1.8016964 | P13: =IF(BaseCoalPlants!Y15=0,"",BaseCoalPlants!Y15) -> 1.8616789 | Q13: =IF(BaseCoalPlants!Z15=0,"",BaseCoalPlants!Z15) -> 1.7669069 | R13: =IF(BaseCoalPlants!AA15=0,"",BaseCoalPlants!AA15) -> 1.5731066 | S13: =IF(BaseCoalPlants!AB15=0,"",BaseCoalPlants!AB15) -> 1.6586317 | T13: =IF(BaseCoalPlants!AC15=0,"",BaseCoalPlants!AC15) -> 1.8182555 | U13: =IF(BaseCoalPlants!AD15=0,"",BaseCoalPlants!AD15) -> 1.8095714 | V13: =IF(BaseCoalPlants!AE15=0,"",BaseCoalPlants!AE15) -> 1.7468255
C14: =IF(BaseCoalPlants!B16="VDA_FLOP",IF(BaseCoalPlants!D16="ELC","*","INPUT"),BaseCoalPlants!B16) -> ACT_COST | D14: =IF(BaseCoalPlants!C16="","\I:",BaseCoalPlants!C16&"_LE") -> ECSTMRSUR_LE | E14: =IF(BaseCoalPlants!D16="-","",BaseCoalPlants!D16) | F14: =IF(BaseCoalPlants!E16="-","",BaseCoalPlants!E16) | G14: =IF(BaseCoalPlants!F16="-","",BaseCoalPlants!F16) | H14: =IF(BaseCoalPlants!G16="-","",BaseCoalPlants!G16) -> 2010 | I14: =IF(BaseCoalPlants!H16="-","",BaseCoalPlants!H16) | J14: =IF(BaseCoalPlants!I16="-","",BaseCoalPlants!I16) -> USD05 | K14: =IF(BaseCoalPlants!J16="-","",BaseCoalPlants!J16) | L14: =IF(BaseCoalPlants!K16="-","",BaseCoalPlants!K16) | M14: =IF(BaseCoalPlants!L16=0,"",BaseCoalPlants!L16) | N14: =IF(BaseCoalPlants!W16=0,"",BaseCoalPlants!W16) -> 2.0346624 | O14: =IF(BaseCoalPlants!X16=0,"",BaseCoalPlants!X16) -> 1.8016964 | P14: =IF(BaseCoalPlants!Y16=0,"",BaseCoalPlants!Y16) -> 1.8616789 | Q14: =IF(BaseCoalPlants!Z16=0,"",BaseCoalPlants!Z16) -> 1.7669069 | R14: =IF(BaseCoalPlants!AA16=0,"",BaseCoalPlants!AA16) -> 1.5731066 | S14: =IF(BaseCoalPlants!AB16=0,"",BaseCoalPlants!AB16) -> 1.6586317 | T14: =IF(BaseCoalPlants!AC16=0,"",BaseCoalPlants!AC16) -> 1.8182555 | U14: =IF(BaseCoalPlants!AD16=0,"",BaseCoalPlants!AD16) -> 1.8095714 | V14: =IF(BaseCoalPlants!AE16=0,"",BaseCoalPlants!AE16) -> 1.7468255
C15: =IF(BaseCoalPlants!B17="VDA_FLOP",IF(BaseCoalPlants!D17="ELC","*","INPUT"),BaseCoalPlants!B17) -> EFF | D15: =IF(BaseCoalPlants!C17="","\I:",BaseCoalPlants!C17&"_LE") -> ECSTMRBOO_LE | E15: =IF(BaseCoalPlants!D17="-","",BaseCoalPlants!D17) | F15: =IF(BaseCoalPlants!E17="-","",BaseCoalPlants!E17) | G15: =IF(BaseCoalPlants!F17="-","",BaseCoalPlants!F17) -> ANNUAL | H15: =IF(BaseCoalPlants!G17="-","",BaseCoalPlants!G17) -> 1950 | I15: =IF(BaseCoalPlants!H17="-","",BaseCoalPlants!H17) | J15: =IF(BaseCoalPlants!I17="-","",BaseCoalPlants!I17) | K15: =IF(BaseCoalPlants!J17="-","",BaseCoalPlants!J17) | L15: =IF(BaseCoalPlants!K17="-","",BaseCoalPlants!K17) | M15: =IF(BaseCoalPlants!L17=0,"",BaseCoalPlants!L17) | N15: =IF(BaseCoalPlants!W17=0,"",BaseCoalPlants!W17) | O15: =IF(BaseCoalPlants!X17=0,"",BaseCoalPlants!X17) | P15: =IF(BaseCoalPlants!Y17=0,"",BaseCoalPlants!Y17) | Q15: =IF(BaseCoalPlants!Z17=0,"",BaseCoalPlants!Z17) | R15: =IF(BaseCoalPlants!AA17=0,"",BaseCoalPlants!AA17) -> 0.32247176 | S15: =IF(BaseCoalPlants!AB17=0,"",BaseCoalPlants!AB17) | T15: =IF(BaseCoalPlants!AC17=0,"",BaseCoalPlants!AC17) | U15: =IF(BaseCoalPlants!AD17=0,"",BaseCoalPlants!AD17) | V15: =IF(BaseCoalPlants!AE17=0,"",BaseCoalPlants!AE17)
C16: =IF(BaseCoalPlants!B18="VDA_FLOP",IF(BaseCoalPlants!D18="ELC","*","INPUT"),BaseCoalPlants!B18) -> EFF | D16: =IF(BaseCoalPlants!C18="","\I:",BaseCoalPlants!C18&"_LE") -> ECSTMRBOO_LE | E16: =IF(BaseCoalPlants!D18="-","",BaseCoalPlants!D18) | F16: =IF(BaseCoalPlants!E18="-","",BaseCoalPlants!E18) | G16: =IF(BaseCoalPlants!F18="-","",BaseCoalPlants!F18) -> ANNUAL | H16: =IF(BaseCoalPlants!G18="-","",BaseCoalPlants!G18) -> 1951 | I16: =IF(BaseCoalPlants!H18="-","",BaseCoalPlants!H18) | J16: =IF(BaseCoalPlants!I18="-","",BaseCoalPlants!I18) | K16: =IF(BaseCoalPlants!J18="-","",BaseCoalPlants!J18) | L16: =IF(BaseCoalPlants!K18="-","",BaseCoalPlants!K18) | M16: =IF(BaseCoalPlants!L18=0,"",BaseCoalPlants!L18) | N16: =IF(BaseCoalPlants!W18=0,"",BaseCoalPlants!W18) | O16: =IF(BaseCoalPlants!X18=0,"",BaseCoalPlants!X18) | P16: =IF(BaseCoalPlants!Y18=0,"",BaseCoalPlants!Y18) -> 0.30348614 | Q16: =IF(BaseCoalPlants!Z18=0,"",BaseCoalPlants!Z18) | R16: =IF(BaseCoalPlants!AA18=0,"",BaseCoalPlants!AA18) -> 0.3131597 | S16: =IF(BaseCoalPlants!AB18=0,"",BaseCoalPlants!AB18) -> 0.27386358 | T16: =IF(BaseCoalPlants!AC18=0,"",BaseCoalPlants!AC18) | U16: =IF(BaseCoalPlants!AD18=0,"",BaseCoalPlants!AD18) | V16: =IF(BaseCoalPlants!AE18=0,"",BaseCoalPlants!AE18)
C17: =IF(BaseCoalPlants!B19="VDA_FLOP",IF(BaseCoalPlants!D19="ELC","*","INPUT"),BaseCoalPlants!B19) -> EFF | D17: =IF(BaseCoalPlants!C19="","\I:",BaseCoalPlants!C19&"_LE") -> ECSTMRBOO_LE | E17: =IF(BaseCoalPlants!D19="-","",BaseCoalPlants!D19) | F17: =IF(BaseCoalPlants!E19="-","",BaseCoalPlants!E19) | G17: =IF(BaseCoalPlants!F19="-","",BaseCoalPlants!F19) -> ANNUAL | H17: =IF(BaseCoalPlants!G19="-","",BaseCoalPlants!G19) -> 1952 | I17: =IF(BaseCoalPlants!H19="-","",BaseCoalPlants!H19) | J17: =IF(BaseCoalPlants!I19="-","",BaseCoalPlants!I19) | K17: =IF(BaseCoalPlants!J19="-","",BaseCoalPlants!J19) | L17: =IF(BaseCoalPlants!K19="-","",BaseCoalPlants!K19) | M17: =IF(BaseCoalPlants!L19=0,"",BaseCoalPlants!L19) | N17: =IF(BaseCoalPlants!W19=0,"",BaseCoalPlants!W19) | O17: =IF(BaseCoalPlants!X19=0,"",BaseCoalPlants!X19) -> 0.3111934 | P17: =IF(BaseCoalPlants!Y19=0,"",BaseCoalPlants!Y19) -> 0.31248969 | Q17: =IF(BaseCoalPlants!Z19=0,"",BaseCoalPlants!Z19) | R17: =IF(BaseCoalPlants!AA19=0,"",BaseCoalPlants!AA19) -> 0.31582783 | S17: =IF(BaseCoalPlants!AB19=0,"",BaseCoalPlants!AB19) -> 0.29470677 | T17: =IF(BaseCoalPlants!AC19=0,"",BaseCoalPlants!AC19) | U17: =IF(BaseCoalPlants!AD19=0,"",BaseCoalPlants!AD19) | V17: =IF(BaseCoalPlants!AE19=0,"",BaseCoalPlants!AE19)
C18: =IF(BaseCoalPlants!B20="VDA_FLOP",IF(BaseCoalPlants!D20="ELC","*","INPUT"),BaseCoalPlants!B20) -> EFF | D18: =IF(BaseCoalPlants!C20="","\I:",BaseCoalPlants!C20&"_LE") -> ECSTMRBOO_LE | E18: =IF(BaseCoalPlants!D20="-","",BaseCoalPlants!D20) | F18: =IF(BaseCoalPlants!E20="-","",BaseCoalPlants!E20) | G18: =IF(BaseCoalPlants!F20="-","",BaseCoalPlants!F20) -> ANNUAL | H18: =IF(BaseCoalPlants!G20="-","",BaseCoalPlants!G20) -> 1953 | I18: =IF(BaseCoalPlants!H20="-","",BaseCoalPlants!H20) | J18: =IF(BaseCoalPlants!I20="-","",BaseCoalPlants!I20) | K18: =IF(BaseCoalPlants!J20="-","",BaseCoalPlants!J20) | L18: =IF(BaseCoalPlants!K20="-","",BaseCoalPlants!K20) | M18: =IF(BaseCoalPlants!L20=0,"",BaseCoalPlants!L20) | N18: =IF(BaseCoalPlants!W20=0,"",BaseCoalPlants!W20) | O18: =IF(BaseCoalPlants!X20=0,"",BaseCoalPlants!X20) -> 0.30052422 | P18: =IF(BaseCoalPlants!Y20=0,"",BaseCoalPlants!Y20) -> 0.31449975 | Q18: =IF(BaseCoalPlants!Z20=0,"",BaseCoalPlants!Z20) | R18: =IF(BaseCoalPlants!AA20=0,"",BaseCoalPlants!AA20) -> 0.32385358 | S18: =IF(BaseCoalPlants!AB20=0,"",BaseCoalPlants!AB20) -> 0.31480286 | T18: =IF(BaseCoalPlants!AC20=0,"",BaseCoalPlants!AC20) | U18: =IF(BaseCoalPlants!AD20=0,"",BaseCoalPlants!AD20) | V18: =IF(BaseCoalPlants!AE20=0,"",BaseCoalPlants!AE20)
C19: =IF(BaseCoalPlants!B21="VDA_FLOP",IF(BaseCoalPlants!D21="ELC","*","INPUT"),BaseCoalPlants!B21) -> EFF | D19: =IF(BaseCoalPlants!C21="","\I:",BaseCoalPlants!C21&"_LE") -> ECSTMRBOO_LE | E19: =IF(BaseCoalPlants!D21="-","",BaseCoalPlants!D21) | F19: =IF(BaseCoalPlants!E21="-","",BaseCoalPlants!E21) | G19: =IF(BaseCoalPlants!F21="-","",BaseCoalPlants!F21) -> ANNUAL | H19: =IF(BaseCoalPlants!G21="-","",BaseCoalPlants!G21) -> 1954 | I19: =IF(BaseCoalPlants!H21="-","",BaseCoalPlants!H21) | J19: =IF(BaseCoalPlants!I21="-","",BaseCoalPlants!I21) | K19: =IF(BaseCoalPlants!J21="-","",BaseCoalPlants!J21) | L19: =IF(BaseCoalPlants!K21="-","",BaseCoalPlants!K21) | M19: =IF(BaseCoalPlants!L21=0,"",BaseCoalPlants!L21) | N19: =IF(BaseCoalPlants!W21=0,"",BaseCoalPlants!W21) | O19: =IF(BaseCoalPlants!X21=0,"",BaseCoalPlants!X21) -> 0.30501488 | P19: =IF(BaseCoalPlants!Y21=0,"",BaseCoalPlants!Y21) -> 0.3182023 | Q19: =IF(BaseCoalPlants!Z21=0,"",BaseCoalPlants!Z21) | R19: =IF(BaseCoalPlants!AA21=0,"",BaseCoalPlants!AA21) -> 0.31455562 | S19: =IF(BaseCoalPlants!AB21=0,"",BaseCoalPlants!AB21) -> 0.32219098 | T19: =IF(BaseCoalPlants!AC21=0,"",BaseCoalPlants!AC21) | U19: =IF(BaseCoalPlants!AD21=0,"",BaseCoalPlants!AD21) | V19: =IF(BaseCoalPlants!AE21=0,"",BaseCoalPlants!AE21)
C20: =IF(BaseCoalPlants!B22="VDA_FLOP",IF(BaseCoalPlants!D22="ELC","*","INPUT"),BaseCoalPlants!B22) -> EFF | D20: =IF(BaseCoalPlants!C22="","\I:",BaseCoalPlants!C22&"_LE") -> ECSTMRBOO_LE | E20: =IF(BaseCoalPlants!D22="-","",BaseCoalPlants!D22) | F20: =IF(BaseCoalPlants!E22="-","",BaseCoalPlants!E22) | G20: =IF(BaseCoalPlants!F22="-","",BaseCoalPlants!F22) -> ANNUAL | H20: =IF(BaseCoalPlants!G22="-","",BaseCoalPlants!G22) -> 1955 | I20: =IF(BaseCoalPlants!H22="-","",BaseCoalPlants!H22) | J20: =IF(BaseCoalPlants!I22="-","",BaseCoalPlants!I22) | K20: =IF(BaseCoalPlants!J22="-","",BaseCoalPlants!J22) | L20: =IF(BaseCoalPlants!K22="-","",BaseCoalPlants!K22) | M20: =IF(BaseCoalPlants!L22=0,"",BaseCoalPlants!L22) | N20: =IF(BaseCoalPlants!W22=0,"",BaseCoalPlants!W22) | O20: =IF(BaseCoalPlants!X22=0,"",BaseCoalPlants!X22) -> 0.33092528 | P20: =IF(BaseCoalPlants!Y22=0,"",BaseCoalPlants!Y22) -> 0.32545511 | Q20: =IF(BaseCoalPlants!Z22=0,"",BaseCoalPlants!Z22) | R20: =IF(BaseCoalPlants!AA22=0,"",BaseCoalPlants!AA22) -> 0.31942821 | S20: =IF(BaseCoalPlants!AB22=0,"",BaseCoalPlants!AB22) -> 0.32414023 | T20: =IF(BaseCoalPlants!AC22=0,"",BaseCoalPlants!AC22) | U20: =IF(BaseCoalPlants!AD22=0,"",BaseCoalPlants!AD22) | V20: =IF(BaseCoalPlants!AE22=0,"",BaseCoalPlants!AE22)
C21: =IF(BaseCoalPlants!B23="VDA_FLOP",IF(BaseCoalPlants!D23="ELC","*","INPUT"),BaseCoalPlants!B23) -> EFF | D21: =IF(BaseCoalPlants!C23="","\I:",BaseCoalPlants!C23&"_LE") -> ECSTMRBOO_LE | E21: =IF(BaseCoalPlants!D23="-","",BaseCoalPlants!D23) | F21: =IF(BaseCoalPlants!E23="-","",BaseCoalPlants!E23) | G21: =IF(BaseCoalPlants!F23="-","",BaseCoalPlants!F23) -> ANNUAL | H21: =IF(BaseCoalPlants!G23="-","",BaseCoalPlants!G23) -> 1956 | I21: =IF(BaseCoalPlants!H23="-","",BaseCoalPlants!H23) | J21: =IF(BaseCoalPlants!I23="-","",BaseCoalPlants!I23) | K21: =IF(BaseCoalPlants!J23="-","",BaseCoalPlants!J23) | L21: =IF(BaseCoalPlants!K23="-","",BaseCoalPlants!K23) | M21: =IF(BaseCoalPlants!L23=0,"",BaseCoalPlants!L23) | N21: =IF(BaseCoalPlants!W23=0,"",BaseCoalPlants!W23) | O21: =IF(BaseCoalPlants!X23=0,"",BaseCoalPlants!X23) | P21: =IF(BaseCoalPlants!Y23=0,"",BaseCoalPlants!Y23) | Q21: =IF(BaseCoalPlants!Z23=0,"",BaseCoalPlants!Z23) | R21: =IF(BaseCoalPlants!AA23=0,"",BaseCoalPlants!AA23) -> 0.32584325 | S21: =IF(BaseCoalPlants!AB23=0,"",BaseCoalPlants!AB23) -> 0.33445313 | T21: =IF(BaseCoalPlants!AC23=0,"",BaseCoalPlants!AC23) | U21: =IF(BaseCoalPlants!AD23=0,"",BaseCoalPlants!AD23) | V21: =IF(BaseCoalPlants!AE23=0,"",BaseCoalPlants!AE23)
C22: =IF(BaseCoalPlants!B24="VDA_FLOP",IF(BaseCoalPlants!D24="ELC","*","INPUT"),BaseCoalPlants!B24) -> EFF | D22: =IF(BaseCoalPlants!C24="","\I:",BaseCoalPlants!C24&"_LE") -> ECSTMRBOO_LE | E22: =IF(BaseCoalPlants!D24="-","",BaseCoalPlants!D24) | F22: =IF(BaseCoalPlants!E24="-","",BaseCoalPlants!E24) | G22: =IF(BaseCoalPlants!F24="-","",BaseCoalPlants!F24) -> ANNUAL | H22: =IF(BaseCoalPlants!G24="-","",BaseCoalPlants!G24) -> 1957 | I22: =IF(BaseCoalPlants!H24="-","",BaseCoalPlants!H24) | J22: =IF(BaseCoalPlants!I24="-","",BaseCoalPlants!I24) | K22: =IF(BaseCoalPlants!J24="-","",BaseCoalPlants!J24) | L22: =IF(BaseCoalPlants!K24="-","",BaseCoalPlants!K24) | M22: =IF(BaseCoalPlants!L24=0,"",BaseCoalPlants!L24) | N22: =IF(BaseCoalPlants!W24=0,"",BaseCoalPlants!W24) | O22: =IF(BaseCoalPlants!X24=0,"",BaseCoalPlants!X24) | P22: =IF(BaseCoalPlants!Y24=0,"",BaseCoalPlants!Y24) -> 0.3400897 | Q22: =IF(BaseCoalPlants!Z24=0,"",BaseCoalPlants!Z24) | R22: =IF(BaseCoalPlants!AA24=0,"",BaseCoalPlants!AA24) -> 0.32945315 | S22: =IF(BaseCoalPlants!AB24=0,"",BaseCoalPlants!AB24) -> 0.33152812 | T22: =IF(BaseCoalPlants!AC24=0,"",BaseCoalPlants!AC24) | U22: =IF(BaseCoalPlants!AD24=0,"",BaseCoalPlants!AD24) | V22: =IF(BaseCoalPlants!AE24=0,"",BaseCoalPlants!AE24)
C23: =IF(BaseCoalPlants!B25="VDA_FLOP",IF(BaseCoalPlants!D25="ELC","*","INPUT"),BaseCoalPlants!B25) -> EFF | D23: =IF(BaseCoalPlants!C25="","\I:",BaseCoalPlants!C25&"_LE") -> ECSTMRBOO_LE | E23: =IF(BaseCoalPlants!D25="-","",BaseCoalPlants!D25) | F23: =IF(BaseCoalPlants!E25="-","",BaseCoalPlants!E25) | G23: =IF(BaseCoalPlants!F25="-","",BaseCoalPlants!F25) -> ANNUAL | H23: =IF(BaseCoalPlants!G25="-","",BaseCoalPlants!G25) -> 1958 | I23: =IF(BaseCoalPlants!H25="-","",BaseCoalPlants!H25) | J23: =IF(BaseCoalPlants!I25="-","",BaseCoalPlants!I25) | K23: =IF(BaseCoalPlants!J25="-","",BaseCoalPlants!J25) | L23: =IF(BaseCoalPlants!K25="-","",BaseCoalPlants!K25) | M23: =IF(BaseCoalPlants!L25=0,"",BaseCoalPlants!L25) | N23: =IF(BaseCoalPlants!W25=0,"",BaseCoalPlants!W25) -> 0.31142023 | O23: =IF(BaseCoalPlants!X25=0,"",BaseCoalPlants!X25) -> 0.32930894 | P23: =IF(BaseCoalPlants!Y25=0,"",BaseCoalPlants!Y25) -> 0.34174027 | Q23: =IF(BaseCoalPlants!Z25=0,"",BaseCoalPlants!Z25) | R23: =IF(BaseCoalPlants!AA25=0,"",BaseCoalPlants!AA25) -> 0.32147926 | S23: =IF(BaseCoalPlants!AB25=0,"",BaseCoalPlants!AB25) -> 0.32972621 | T23: =IF(BaseCoalPlants!AC25=0,"",BaseCoalPlants!AC25) | U23: =IF(BaseCoalPlants!AD25=0,"",BaseCoalPlants!AD25) | V23: =IF(BaseCoalPlants!AE25=0,"",BaseCoalPlants!AE25)
... C310: =IF(BaseCoalPlants!B312="VDA_FLOP",IF(BaseCoalPlants!D312="ELC","*","INPUT"),BaseCoalPlants!B312) -> EFF | D310: =IF(BaseCoalPlants!C312="","\I:",BaseCoalPlants!C312&"_LE") -> ECSTMRSUR_LE | E310: =IF(BaseCoalPlants!D312="-","",BaseCoalPlants!D312) | F310: =IF(BaseCoalPlants!E312="-","",BaseCoalPlants!E312) | G310: =IF(BaseCoalPlants!F312="-","",BaseCoalPlants!F312) -> ANNUAL | H310: =IF(BaseCoalPlants!G312="-","",BaseCoalPlants!G312) -> 1976 | I310: =IF(BaseCoalPlants!H312="-","",BaseCoalPlants!H312) | J310: =IF(BaseCoalPlants!I312="-","",BaseCoalPlants!I312) | K310: =IF(BaseCoalPlants!J312="-","",BaseCoalPlants!J312) | L310: =IF(BaseCoalPlants!K312="-","",BaseCoalPlants!K312) | M310: =IF(BaseCoalPlants!L312=0,"",BaseCoalPlants!L312) | N310: =IF(BaseCoalPlants!W312=0,"",BaseCoalPlants!W312) | O310: =IF(BaseCoalPlants!X312=0,"",BaseCoalPlants!X312) | P310: =IF(BaseCoalPlants!Y312=0,"",BaseCoalPlants!Y312) | Q310: =IF(BaseCoalPlants!Z312=0,"",BaseCoalPlants!Z312) -> 0.29183335 | R310: =IF(BaseCoalPlants!AA312=0,"",BaseCoalPlants!AA312) | S310: =IF(BaseCoalPlants!AB312=0,"",BaseCoalPlants!AB312) | T310: =IF(BaseCoalPlants!AC312=0,"",BaseCoalPlants!AC312) | U310: =IF(BaseCoalPlants!AD312=0,"",BaseCoalPlants!AD312) | V310: =IF(BaseCoalPlants!AE312=0,"",BaseCoalPlants!AE312)
C311: =IF(BaseCoalPlants!B313="VDA_FLOP",IF(BaseCoalPlants!D313="ELC","*","INPUT"),BaseCoalPlants!B313) -> EFF | D311: =IF(BaseCoalPlants!C313="","\I:",BaseCoalPlants!C313&"_LE") -> ECSTMRSUR_LE | E311: =IF(BaseCoalPlants!D313="-","",BaseCoalPlants!D313) | F311: =IF(BaseCoalPlants!E313="-","",BaseCoalPlants!E313) | G311: =IF(BaseCoalPlants!F313="-","",BaseCoalPlants!F313) -> ANNUAL | H311: =IF(BaseCoalPlants!G313="-","",BaseCoalPlants!G313) -> 1982 | I311: =IF(BaseCoalPlants!H313="-","",BaseCoalPlants!H313) | J311: =IF(BaseCoalPlants!I313="-","",BaseCoalPlants!I313) | K311: =IF(BaseCoalPlants!J313="-","",BaseCoalPlants!J313) | L311: =IF(BaseCoalPlants!K313="-","",BaseCoalPlants!K313) | M311: =IF(BaseCoalPlants!L313=0,"",BaseCoalPlants!L313) | N311: =IF(BaseCoalPlants!M313=0,"",BaseCoalPlants!M313) | O311: =IF(BaseCoalPlants!N313=0,"",BaseCoalPlants!N313) | P311: =IF(BaseCoalPlants!O313=0,"",BaseCoalPlants!O313) | Q311: =IF(BaseCoalPlants!P313=0,"",BaseCoalPlants!P313) -> 0.26398904 | R311: =IF(BaseCoalPlants!Q313=0,"",BaseCoalPlants!Q313) | S311: =IF(BaseCoalPlants!R313=0,"",BaseCoalPlants!R313) | T311: =IF(BaseCoalPlants!S313=0,"",BaseCoalPlants!S313) | ... V311: =IF(BaseCoalPlants!U313=0,"",BaseCoalPlants!U313)
C312: =IF(BaseCoalPlants!B314="VDA_FLOP",IF(BaseCoalPlants!D314="ELC","*","INPUT"),BaseCoalPlants!B314) -> EFF | D312: =IF(BaseCoalPlants!C314="","\I:",BaseCoalPlants!C314&"_LE") -> ECSTMRSUR_LE | E312: =IF(BaseCoalPlants!D314="-","",BaseCoalPlants!D314) | F312: =IF(BaseCoalPlants!E314="-","",BaseCoalPlants!E314) | G312: =IF(BaseCoalPlants!F314="-","",BaseCoalPlants!F314) -> ANNUAL | H312: =IF(BaseCoalPlants!G314="-","",BaseCoalPlants!G314) -> 1995 | I312: =IF(BaseCoalPlants!H314="-","",BaseCoalPlants!H314) | J312: =IF(BaseCoalPlants!I314="-","",BaseCoalPlants!I314) | K312: =IF(BaseCoalPlants!J314="-","",BaseCoalPlants!J314) | L312: =IF(BaseCoalPlants!K314="-","",BaseCoalPlants!K314) | M312: =IF(BaseCoalPlants!L314=0,"",BaseCoalPlants!L314) | N312: =IF(BaseCoalPlants!M314=0,"",BaseCoalPlants!M314) | O312: =IF(BaseCoalPlants!N314=0,"",BaseCoalPlants!N314) | P312: =IF(BaseCoalPlants!O314=0,"",BaseCoalPlants!O314) | Q312: =IF(BaseCoalPlants!P314=0,"",BaseCoalPlants!P314) | R312: =IF(BaseCoalPlants!Q314=0,"",BaseCoalPlants!Q314) | S312: =IF(BaseCoalPlants!R314=0,"",BaseCoalPlants!R314) | T312: =IF(BaseCoalPlants!S314=0,"",BaseCoalPlants!S314) | ... V312: =IF(BaseCoalPlants!U314=0,"",BaseCoalPlants!U314)
C313: =IF(BaseCoalPlants!B315="VDA_FLOP",IF(BaseCoalPlants!D315="ELC","*","INPUT"),BaseCoalPlants!B315) -> EFF | D313: =IF(BaseCoalPlants!C315="","\I:",BaseCoalPlants!C315&"_LE") -> ECSTMRSUR_LE | E313: =IF(BaseCoalPlants!D315="-","",BaseCoalPlants!D315) | F313: =IF(BaseCoalPlants!E315="-","",BaseCoalPlants!E315) | G313: =IF(BaseCoalPlants!F315="-","",BaseCoalPlants!F315) -> ANNUAL | H313: =IF(BaseCoalPlants!G315="-","",BaseCoalPlants!G315) -> 2003 | I313: =IF(BaseCoalPlants!H315="-","",BaseCoalPlants!H315) | J313: =IF(BaseCoalPlants!I315="-","",BaseCoalPlants!I315) | K313: =IF(BaseCoalPlants!J315="-","",BaseCoalPlants!J315) | L313: =IF(BaseCoalPlants!K315="-","",BaseCoalPlants!K315) | M313: =IF(BaseCoalPlants!L315=0,"",BaseCoalPlants!L315) | N313: =IF(BaseCoalPlants!M315=0,"",BaseCoalPlants!M315) | O313: =IF(BaseCoalPlants!N315=0,"",BaseCoalPlants!N315) | P313: =IF(BaseCoalPlants!O315=0,"",BaseCoalPlants!O315) | Q313: =IF(BaseCoalPlants!P315=0,"",BaseCoalPlants!P315) | R313: =IF(BaseCoalPlants!Q315=0,"",BaseCoalPlants!Q315) | S313: =IF(BaseCoalPlants!R315=0,"",BaseCoalPlants!R315) | T313: =IF(BaseCoalPlants!S315=0,"",BaseCoalPlants!S315) | ... V313: =IF(BaseCoalPlants!U315=0,"",BaseCoalPlants!U315)
C314: =IF(BaseCoalPlants!B318="VDA_FLOP",IF(BaseCoalPlants!D318="ELC","*","INPUT"),BaseCoalPlants!B318) -> ENV_ACT | D314: =IF(BaseCoalPlants!C318="","\I:",BaseCoalPlants!C318&"_LE") -> ECSTMRBOO_LE | E314: =IF(BaseCoalPlants!D318="-","",BaseCoalPlants!D318) -> ELCH2OC | F314: =IF(BaseCoalPlants!E318="-","",BaseCoalPlants!E318) | G314: =IF(BaseCoalPlants!F318="-","",BaseCoalPlants!F318) -> ANNUAL | H314: =IF(BaseCoalPlants!G318="-","",BaseCoalPlants!G318) -> 2010 | I314: =IF(BaseCoalPlants!H318="-","",BaseCoalPlants!H318) | J314: =IF(BaseCoalPlants!I318="-","",BaseCoalPlants!I318) | K314: =IF(BaseCoalPlants!J318="-","",BaseCoalPlants!J318) | L314: =IF(BaseCoalPlants!K318="-","",BaseCoalPlants!K318) | M314: =IF(BaseCoalPlants!L318=0,"",BaseCoalPlants!L318) -> 31.388898 | N314: =IF(BaseCoalPlants!M318=0,"",BaseCoalPlants!M318) -> 31.388898 | O314: =IF(BaseCoalPlants!N318=0,"",BaseCoalPlants!N318) -> 31.388898 | P314: =IF(BaseCoalPlants!O318=0,"",BaseCoalPlants!O318) -> 31.388898 | Q314: =IF(BaseCoalPlants!P318=0,"",BaseCoalPlants!P318) -> 31.388898 | R314: =IF(BaseCoalPlants!Q318=0,"",BaseCoalPlants!Q318) -> 31.388898 | S314: =IF(BaseCoalPlants!R318=0,"",BaseCoalPlants!R318) -> 31.388898 | T314: =IF(BaseCoalPlants!S318=0,"",BaseCoalPlants!S318) -> 31.388898 | ... V314: =IF(BaseCoalPlants!U318=0,"",BaseCoalPlants!U318) -> 31.388898
C315: =IF(BaseCoalPlants!B319="VDA_FLOP",IF(BaseCoalPlants!D319="ELC","*","INPUT"),BaseCoalPlants!B319) -> ENV_ACT | D315: =IF(BaseCoalPlants!C319="","\I:",BaseCoalPlants!C319&"_LE") -> ECSTMRBOO_LE | E315: =IF(BaseCoalPlants!D319="-","",BaseCoalPlants!D319) -> ELCH2OW | F315: =IF(BaseCoalPlants!E319="-","",BaseCoalPlants!E319) | G315: =IF(BaseCoalPlants!F319="-","",BaseCoalPlants!F319) -> ANNUAL | H315: =IF(BaseCoalPlants!G319="-","",BaseCoalPlants!G319) -> 2010 | I315: =IF(BaseCoalPlants!H319="-","",BaseCoalPlants!H319) | J315: =IF(BaseCoalPlants!I319="-","",BaseCoalPlants!I319) | K315: =IF(BaseCoalPlants!J319="-","",BaseCoalPlants!J319) | L315: =IF(BaseCoalPlants!K319="-","",BaseCoalPlants!K319) | M315: =IF(BaseCoalPlants!L319=0,"",BaseCoalPlants!L319) -> 7524.4465 | N315: =IF(BaseCoalPlants!M319=0,"",BaseCoalPlants!M319) -> 7524.4465 | O315: =IF(BaseCoalPlants!N319=0,"",BaseCoalPlants!N319) -> 7524.4465 | P315: =IF(BaseCoalPlants!O319=0,"",BaseCoalPlants!O319) -> 7524.4465 | Q315: =IF(BaseCoalPlants!P319=0,"",BaseCoalPlants!P319) -> 7524.4465 | R315: =IF(BaseCoalPlants!Q319=0,"",BaseCoalPlants!Q319) -> 7524.4465 | S315: =IF(BaseCoalPlants!R319=0,"",BaseCoalPlants!R319) -> 7524.4465 | T315: =IF(BaseCoalPlants!S319=0,"",BaseCoalPlants!S319) -> 7524.4465 | ... V315: =IF(BaseCoalPlants!U319=0,"",BaseCoalPlants!U319) -> 7524.4465
C316: =IF(BaseCoalPlants!B320="VDA_FLOP",IF(BaseCoalPlants!D320="ELC","*","INPUT"),BaseCoalPlants!B320) -> ENV_ACT | D316: =IF(BaseCoalPlants!C320="","\I:",BaseCoalPlants!C320&"_LE") -> ECSTMRBOR_LE | E316: =IF(BaseCoalPlants!D320="-","",BaseCoalPlants!D320) -> ELCH2OC | F316: =IF(BaseCoalPlants!E320="-","",BaseCoalPlants!E320) | G316: =IF(BaseCoalPlants!F320="-","",BaseCoalPlants!F320) -> ANNUAL | H316: =IF(BaseCoalPlants!G320="-","",BaseCoalPlants!G320) -> 2010 | I316: =IF(BaseCoalPlants!H320="-","",BaseCoalPlants!H320) | J316: =IF(BaseCoalPlants!I320="-","",BaseCoalPlants!I320) | K316: =IF(BaseCoalPlants!J320="-","",BaseCoalPlants!J320) | L316: =IF(BaseCoalPlants!K320="-","",BaseCoalPlants!K320) | M316: =IF(BaseCoalPlants!L320=0,"",BaseCoalPlants!L320) -> 130.83337 | N316: =IF(BaseCoalPlants!M320=0,"",BaseCoalPlants!M320) -> 130.83337 | O316: =IF(BaseCoalPlants!N320=0,"",BaseCoalPlants!N320) -> 130.83337 | P316: =IF(BaseCoalPlants!O320=0,"",BaseCoalPlants!O320) -> 130.83337 | Q316: =IF(BaseCoalPlants!P320=0,"",BaseCoalPlants!P320) -> 130.83337 | R316: =IF(BaseCoalPlants!Q320=0,"",BaseCoalPlants!Q320) -> 130.83337 | S316: =IF(BaseCoalPlants!R320=0,"",BaseCoalPlants!R320) -> 130.83337 | T316: =IF(BaseCoalPlants!S320=0,"",BaseCoalPlants!S320) -> 130.83337 | ... V316: =IF(BaseCoalPlants!U320=0,"",BaseCoalPlants!U320) -> 130.83337
C317: =IF(BaseCoalPlants!B321="VDA_FLOP",IF(BaseCoalPlants!D321="ELC","*","INPUT"),BaseCoalPlants!B321) -> ENV_ACT | D317: =IF(BaseCoalPlants!C321="","\I:",BaseCoalPlants!C321&"_LE") -> ECSTMRBOR_LE | E317: =IF(BaseCoalPlants!D321="-","",BaseCoalPlants!D321) -> ELCH2OW | F317: =IF(BaseCoalPlants!E321="-","",BaseCoalPlants!E321) | G317: =IF(BaseCoalPlants!F321="-","",BaseCoalPlants!F321) -> ANNUAL | H317: =IF(BaseCoalPlants!G321="-","",BaseCoalPlants!G321) -> 2010 | I317: =IF(BaseCoalPlants!H321="-","",BaseCoalPlants!H321) | J317: =IF(BaseCoalPlants!I321="-","",BaseCoalPlants!I321) | K317: =IF(BaseCoalPlants!J321="-","",BaseCoalPlants!J321) | L317: =IF(BaseCoalPlants!K321="-","",BaseCoalPlants!K321) | M317: =IF(BaseCoalPlants!L321=0,"",BaseCoalPlants!L321) -> 147.50004 | N317: =IF(BaseCoalPlants!M321=0,"",BaseCoalPlants!M321) -> 147.50004 | O317: =IF(BaseCoalPlants!N321=0,"",BaseCoalPlants!N321) -> 147.50004 | P317: =IF(BaseCoalPlants!O321=0,"",BaseCoalPlants!O321) -> 147.50004 | Q317: =IF(BaseCoalPlants!P321=0,"",BaseCoalPlants!P321) -> 147.50004 | R317: =IF(BaseCoalPlants!Q321=0,"",BaseCoalPlants!Q321) -> 147.50004 | S317: =IF(BaseCoalPlants!R321=0,"",BaseCoalPlants!R321) -> 147.50004 | T317: =IF(BaseCoalPlants!S321=0,"",BaseCoalPlants!S321) -> 147.50004 | ... V317: =IF(BaseCoalPlants!U321=0,"",BaseCoalPlants!U321) -> 147.50004
C318: =IF(BaseCoalPlants!B322="VDA_FLOP",IF(BaseCoalPlants!D322="ELC","*","INPUT"),BaseCoalPlants!B322) -> ENV_ACT | D318: =IF(BaseCoalPlants!C322="","\I:",BaseCoalPlants!C322&"_LE") -> ECSTMRBUO_LE | E318: =IF(BaseCoalPlants!D322="-","",BaseCoalPlants!D322) -> ELCH2OC | F318: =IF(BaseCoalPlants!E322="-","",BaseCoalPlants!E322) | G318: =IF(BaseCoalPlants!F322="-","",BaseCoalPlants!F322) -> ANNUAL | H318: =IF(BaseCoalPlants!G322="-","",BaseCoalPlants!G322) -> 2010 | I318: =IF(BaseCoalPlants!H322="-","",BaseCoalPlants!H322) | J318: =IF(BaseCoalPlants!I322="-","",BaseCoalPlants!I322) | K318: =IF(BaseCoalPlants!J322="-","",BaseCoalPlants!J322) | L318: =IF(BaseCoalPlants!K322="-","",BaseCoalPlants!K322) | M318: =IF(BaseCoalPlants!L322=0,"",BaseCoalPlants!L322) -> 31.388898 | N318: =IF(BaseCoalPlants!M322=0,"",BaseCoalPlants!M322) -> 31.388898 | O318: =IF(BaseCoalPlants!N322=0,"",BaseCoalPlants!N322) -> 31.388898 | P318: =IF(BaseCoalPlants!O322=0,"",BaseCoalPlants!O322) -> 31.388898 | Q318: =IF(BaseCoalPlants!P322=0,"",BaseCoalPlants!P322) -> 31.388898 | R318: =IF(BaseCoalPlants!Q322=0,"",BaseCoalPlants!Q322) -> 31.388898 | S318: =IF(BaseCoalPlants!R322=0,"",BaseCoalPlants!R322) -> 31.388898 | T318: =IF(BaseCoalPlants!S322=0,"",BaseCoalPlants!S322) -> 31.388898 | ... V318: =IF(BaseCoalPlants!U322=0,"",BaseCoalPlants!U322) -> 31.388898
C319: =IF(BaseCoalPlants!B323="VDA_FLOP",IF(BaseCoalPlants!D323="ELC","*","INPUT"),BaseCoalPlants!B323) -> ENV_ACT | D319: =IF(BaseCoalPlants!C323="","\I:",BaseCoalPlants!C323&"_LE") -> ECSTMRBUO_LE | E319: =IF(BaseCoalPlants!D323="-","",BaseCoalPlants!D323) -> ELCH2OW | F319: =IF(BaseCoalPlants!E323="-","",BaseCoalPlants!E323) | G319: =IF(BaseCoalPlants!F323="-","",BaseCoalPlants!F323) -> ANNUAL | H319: =IF(BaseCoalPlants!G323="-","",BaseCoalPlants!G323) -> 2010 | I319: =IF(BaseCoalPlants!H323="-","",BaseCoalPlants!H323) | J319: =IF(BaseCoalPlants!I323="-","",BaseCoalPlants!I323) | K319: =IF(BaseCoalPlants!J323="-","",BaseCoalPlants!J323) | L319: =IF(BaseCoalPlants!K323="-","",BaseCoalPlants!K323) | M319: =IF(BaseCoalPlants!L323=0,"",BaseCoalPlants!L323) -> 7524.4465 | N319: =IF(BaseCoalPlants!M323=0,"",BaseCoalPlants!M323) -> 7524.4465 | O319: =IF(BaseCoalPlants!N323=0,"",BaseCoalPlants!N323) -> 7524.4465 | P319: =IF(BaseCoalPlants!O323=0,"",BaseCoalPlants!O323) -> 7524.4465 | Q319: =IF(BaseCoalPlants!P323=0,"",BaseCoalPlants!P323) -> 7524.4465 | R319: =IF(BaseCoalPlants!Q323=0,"",BaseCoalPlants!Q323) -> 7524.4465 | S319: =IF(BaseCoalPlants!R323=0,"",BaseCoalPlants!R323) -> 7524.4465 | T319: =IF(BaseCoalPlants!S323=0,"",BaseCoalPlants!S323) -> 7524.4465 | ... V319: =IF(BaseCoalPlants!U323=0,"",BaseCoalPlants!U323) -> 7524.4465
C320: =IF(BaseCoalPlants!B324="VDA_FLOP",IF(BaseCoalPlants!D324="ELC","*","INPUT"),BaseCoalPlants!B324) -> ENV_ACT | D320: =IF(BaseCoalPlants!C324="","\I:",BaseCoalPlants!C324&"_LE") -> ECSTMRBUR_LE | E320: =IF(BaseCoalPlants!D324="-","",BaseCoalPlants!D324) -> ELCH2OC | F320: =IF(BaseCoalPlants!E324="-","",BaseCoalPlants!E324) | G320: =IF(BaseCoalPlants!F324="-","",BaseCoalPlants!F324) -> ANNUAL | H320: =IF(BaseCoalPlants!G324="-","",BaseCoalPlants!G324) -> 2010 | I320: =IF(BaseCoalPlants!H324="-","",BaseCoalPlants!H324) | J320: =IF(BaseCoalPlants!I324="-","",BaseCoalPlants!I324) | K320: =IF(BaseCoalPlants!J324="-","",BaseCoalPlants!J324) | L320: =IF(BaseCoalPlants!K324="-","",BaseCoalPlants!K324) | M320: =IF(BaseCoalPlants!L324=0,"",BaseCoalPlants!L324) -> 130.83337 | N320: =IF(BaseCoalPlants!M324=0,"",BaseCoalPlants!M324) -> 130.83337 | O320: =IF(BaseCoalPlants!N324=0,"",BaseCoalPlants!N324) -> 130.83337 | P320: =IF(BaseCoalPlants!O324=0,"",BaseCoalPlants!O324) -> 130.83337 | Q320: =IF(BaseCoalPlants!P324=0,"",BaseCoalPlants!P324) -> 130.83337 | R320: =IF(BaseCoalPlants!Q324=0,"",BaseCoalPlants!Q324) -> 130.83337 | S320: =IF(BaseCoalPlants!R324=0,"",BaseCoalPlants!R324) -> 130.83337 | T320: =IF(BaseCoalPlants!S324=0,"",BaseCoalPlants!S324) -> 130.83337 | ... V320: =IF(BaseCoalPlants!U324=0,"",BaseCoalPlants!U324) -> 130.83337
C321: =IF(BaseCoalPlants!B325="VDA_FLOP",IF(BaseCoalPlants!D325="ELC","*","INPUT"),BaseCoalPlants!B325) -> ENV_ACT | D321: =IF(BaseCoalPlants!C325="","\I:",BaseCoalPlants!C325&"_LE") -> ECSTMRBUR_LE | E321: =IF(BaseCoalPlants!D325="-","",BaseCoalPlants!D325) -> ELCH2OW | F321: =IF(BaseCoalPlants!E325="-","",BaseCoalPlants!E325) | G321: =IF(BaseCoalPlants!F325="-","",BaseCoalPlants!F325) -> ANNUAL | H321: =IF(BaseCoalPlants!G325="-","",BaseCoalPlants!G325) -> 2010 | I321: =IF(BaseCoalPlants!H325="-","",BaseCoalPlants!H325) | J321: =IF(BaseCoalPlants!I325="-","",BaseCoalPlants!I325) | K321: =IF(BaseCoalPlants!J325="-","",BaseCoalPlants!J325) | L321: =IF(BaseCoalPlants!K325="-","",BaseCoalPlants!K325) | M321: =IF(BaseCoalPlants!L325=0,"",BaseCoalPlants!L325) -> 147.50004 | N321: =IF(BaseCoalPlants!M325=0,"",BaseCoalPlants!M325) -> 147.50004 | O321: =IF(BaseCoalPlants!N325=0,"",BaseCoalPlants!N325) -> 147.50004 | P321: =IF(BaseCoalPlants!O325=0,"",BaseCoalPlants!O325) -> 147.50004 | Q321: =IF(BaseCoalPlants!P325=0,"",BaseCoalPlants!P325) -> 147.50004 | R321: =IF(BaseCoalPlants!Q325=0,"",BaseCoalPlants!Q325) -> 147.50004 | S321: =IF(BaseCoalPlants!R325=0,"",BaseCoalPlants!R325) -> 147.50004 | T321: =IF(BaseCoalPlants!S325=0,"",BaseCoalPlants!S325) -> 147.50004 | ... V321: =IF(BaseCoalPlants!U325=0,"",BaseCoalPlants!U325) -> 147.50004
C322: =IF(BaseCoalPlants!B328="VDA_FLOP",IF(BaseCoalPlants!D328="ELC","*","INPUT"),BaseCoalPlants!B328) -> ENV_ACT | D322: =IF(BaseCoalPlants!C328="","\I:",BaseCoalPlants!C328&"_LE") -> ECSTMRLOO_LE | E322: =IF(BaseCoalPlants!D328="-","",BaseCoalPlants!D328) -> ELCH2OC | F322: =IF(BaseCoalPlants!E328="-","",BaseCoalPlants!E328) | G322: =IF(BaseCoalPlants!F328="-","",BaseCoalPlants!F328) -> ANNUAL | H322: =IF(BaseCoalPlants!G328="-","",BaseCoalPlants!G328) -> 2010 | I322: =IF(BaseCoalPlants!H328="-","",BaseCoalPlants!H328) | J322: =IF(BaseCoalPlants!I328="-","",BaseCoalPlants!I328) | K322: =IF(BaseCoalPlants!J328="-","",BaseCoalPlants!J328) | L322: =IF(BaseCoalPlants!K328="-","",BaseCoalPlants!K328) | M322: =IF(BaseCoalPlants!L328=0,"",BaseCoalPlants!L328) -> 31.388898 | N322: =IF(BaseCoalPlants!M328=0,"",BaseCoalPlants!M328) -> 31.388898 | O322: =IF(BaseCoalPlants!N328=0,"",BaseCoalPlants!N328) -> 31.388898 | P322: =IF(BaseCoalPlants!O328=0,"",BaseCoalPlants!O328) -> 31.388898 | Q322: =IF(BaseCoalPlants!P328=0,"",BaseCoalPlants!P328) -> 31.388898 | R322: =IF(BaseCoalPlants!Q328=0,"",BaseCoalPlants!Q328) -> 31.388898 | S322: =IF(BaseCoalPlants!R328=0,"",BaseCoalPlants!R328) -> 31.388898 | T322: =IF(BaseCoalPlants!S328=0,"",BaseCoalPlants!S328) -> 31.388898 | ... V322: =IF(BaseCoalPlants!U328=0,"",BaseCoalPlants!U328) -> 31.388898
