Workbook

Sheet INS
A1: Trans - Insert
B2: ~TFM_INS
B3: TimeSlice | C3: LimType | D3: Attribute | E3: Year | F3: Attrib_Cond | G3: Val_Cond | H3: AllRegions | I3: R0 | J3: R1 | K3: R2 | L3: R3 | M3: R4 | N3: R5 | O3: R6 | P3: R7 | Q3: R8 | R3: R9 | S3: Pset_Set | T3: Pset_PN | U3: Pset_PD | V3: Pset_CI | W3: Pset_CO | X3: Cset_Set | Y3: Cset_CN | Z3: Cset_CD
D4: STOCK | E4: 2010 | K4: =NGCap!B3*NGCap!$O$3*NGCap!$O$5*10^9*1.2 -> 1035.4936 | T4: Trd_NGA_R2-R1-Existing
D5: STOCK | E5: 2010 | L5: =NGCap!B6*NGCap!$O$3*NGCap!$O$5*10^9*1.2 -> 818.64554 | T5: Trd_NGA_R3-R2-Existing
D6: STOCK | E6: 2010 | L6: =NGCap!B8*NGCap!$O$3*NGCap!$O$5*10^9*1.2 -> 988.11155 | T6: Trd_NGA_R3-R5-Existing
D7: STOCK | E7: 2010 | M7: =NGCap!B10*NGCap!$O$3*NGCap!$O$5*10^9*1.2 -> 4770.2793 | T7: Trd_NGA_R4-R3-Existing
D8: STOCK | E8: 2010 | N8: =NGCap!B12*NGCap!$O$3*NGCap!$O$5*10^9*1.2 -> 2235.5148 | T8: Trd_NGA_R5-R2-Existing
D9: STOCK | E9: 2010 | O9: =NGCap!B14*NGCap!$O$3*NGCap!$O$5*10^9*1.2 -> 2370.5098 | T9: Trd_NGA_R6-R3-Existing
D10: STOCK | E10: 2010 | O10: =NGCap!B15*NGCap!$O$3*NGCap!$O$5*10^9*1.2 -> 4330.2068 | T10: Trd_NGA_R6-R5-Existing
D11: STOCK | E11: 2010 | P11: =NGCap!B17*NGCap!$O$3*NGCap!$O$5*10^9*1.2 -> 1902.0346 | T11: Trd_NGA_R7-R4-Existing
D12: STOCK | E12: 2010 | P12: =NGCap!B18*NGCap!$O$3*NGCap!$O$5*10^9*1.2 -> 8357.7351 | T12: Trd_NGA_R7-R6-Existing
D13: STOCK | E13: 2010 | Q13: =NGCap!B19*NGCap!$O$3*NGCap!$O$5*10^9*1.2 -> 3121.6761 | T13: Trd_NGA_R8-R4-Existing
D14: STOCK | E14: 2010 | Q14: =NGCap!B20*NGCap!$O$3*NGCap!$O$5*10^9*1.2 -> 505.32407 | T14: Trd_NGA_R8-R7-Existing
D15: STOCK | E15: 2010 | Q15: =NGCap!B21*NGCap!$O$3*NGCap!$O$5*10^9*1.2 -> 2258.4386 | T15: Trd_NGA_R8-R9-Existing
D16: STOCK | E16: 2055 | K16: =K4 -> 1035.4936 | T16: Trd_NGA_R2-R1-Existing
D17: STOCK | E17: 2055 | L17: 0 | T17: Trd_NGA_R3-R2-Existing
D18: STOCK | E18: 2055 | L18: 0 | T18: Trd_NGA_R3-R5-Existing
D19: STOCK | E19: 2055 | M19: =M7 -> 4770.2793 | T19: Trd_NGA_R4-R3-Existing
D20: STOCK | E20: 2055 | N20: 0 | T20: Trd_NGA_R5-R2-Existing
D21: STOCK | E21: 2055 | O21: =O9 -> 2370.5098 | T21: Trd_NGA_R6-R3-Existing
D22: STOCK | E22: 2055 | O22: =O10 -> 4330.2068 | T22: Trd_NGA_R6-R5-Existing
D23: STOCK | E23: 2055 | P23: =P11 -> 1902.0346 | T23: Trd_NGA_R7-R4-Existing
D24: STOCK | E24: 2055 | P24: =P12 -> 8357.7351 | T24: Trd_NGA_R7-R6-Existing
D25: STOCK | E25: 2055 | Q25: =Q13 -> 3121.6761 | T25: Trd_NGA_R8-R4-Existing
D26: STOCK | E26: 2055 | Q26: =Q14 -> 505.32407 | T26: Trd_NGA_R8-R7-Existing
D27: STOCK | E27: 2055 | Q27: =Q15 -> 2258.4386 | T27: Trd_NGA_R8-R9-Existing
D28: STOCK | E28: 0 | K28: 5 | T28: Trd_NGA_R2-R1-Existing
D29: STOCK | E29: 0 | L29: 5 | T29: Trd_NGA_R3-R2-Existing
D30: STOCK | E30: 0 | L30: 5 | T30: Trd_NGA_R3-R5-Existing
D31: STOCK | E31: 0 | M31: 5 | T31: Trd_NGA_R4-R3-Existing
D32: STOCK | E32: 0 | N32: 5 | T32: Trd_NGA_R5-R2-Existing
D33: STOCK | E33: 0 | O33: 5 | T33: Trd_NGA_R6-R3-Existing
D34: STOCK | E34: 0 | O34: 5 | T34: Trd_NGA_R6-R5-Existing
D35: STOCK | E35: 0 | P35: 5 | T35: Trd_NGA_R7-R4-Existing
D36: STOCK | E36: 0 | P36: 5 | T36: Trd_NGA_R7-R6-Existing
D37: STOCK | E37: 0 | Q37: 5 | T37: Trd_NGA_R8-R4-Existing
D38: STOCK | E38: 0 | Q38: 5 | T38: Trd_NGA_R8-R7-Existing
D39: STOCK | E39: 0 | Q39: 5 | T39: Trd_NGA_R8-R9-Existing
D40: NCAP_BND | K40: 0 | T40: Trd_NGA_R2-R1-Existing
...

Sheet UPD
A1: Trans - Update
B2: ~TFM_UPD
B3: TimeSlice | C3: LimType | D3: Attribute | E3: Year | F3: Attrib_Cond | G3: Val_Cond | H3: AllRegions | I3: R0 | J3: R1 | K3: R2 | L3: R3 | M3: R4 | N3: R5 | O3: R6 | P3: R7 | Q3: R8 | R3: R9 | S3: Pset_Set | T3: Pset_PN | U3: Pset_PD | V3: Pset_CI | W3: Pset_CO | X3: Cset_Set | Y3: Cset_CN | Z3: Cset_CD

Sheet ELC data
G1: START | H1: LIFE | I1: INP(ENT)c | J1: OUT(ELC)_TID | K1: RESID | M1: IBOND(UP) | N1: INVCOST | O1: VAROM | P1: BOUND(UP)
B3: TechName | C3: TechDesc | D3: Units | E3: CommIN | F3: CommOUT | G3: TID | H3: TID | J3: TID | P3: 2005-2055
A4: * Domestic Trade Processes, Infastructure - Existing
A5: R2 | B5: XELCR1E | C5: Electricity Imports from R1 to R2 - Existing | D5: PJ, GW | E5: ELCR1 | F5: ELC | G5: 2005 | H5: 50 | I5: 1.11 | J5: 1 | K5: 1.425 | L5: =K5*31.536 -> 44.9388 | M5: 0 | O5: 1
A6: R1 | B6: XELCR2E | C6: Electricity Imports from R2 to R1 - Existing | D6: PJ, GW | E6: ELCR2 | F6: ELC | G6: 2005 | H6: 50 | I6: 1.11 | J6: 1 | K6: 1.6 | L6: =K6*31.536 -> 50.4576 | M6: 0 | O6: 1
A7: R3 | B7: XELCR2E | C7: Electricity Imports from R2 to R3 - Existing | D7: PJ, GW | E7: ELCR2 | F7: ELC | G7: 2005 | H7: 50 | I7: 1.11 | J7: 1 | K7: 3.546 | L7: =K7*31.536 -> 111.82666 | M7: 0 | O7: 1
A8: R5 | B8: XELCR2E | C8: Electricity Imports from R2 to R5 - Existing | D8: PJ, GW | E8: ELCR2 | F8: ELC | G8: 2005 | H8: 50 | I8: 1 | J8: 1 | K8: 2.4 | L8: =K8*31.536 -> 75.6864 | M8: 0 | O8: 1
A9: R2 | B9: XELCR3E | C9: Electricity Imports from R3 to R2 - Existing | D9: PJ, GW | E9: ELCR3 | F9: ELC | G9: 2005 | H9: 50 | I9: 1.11 | J9: 1 | K9: 4.706 | L9: =K9*31.536 -> 148.40842 | M9: 0 | O9: 1
A10: R4 | B10: XELCR3E | C10: Electricity Imports from R3 to R4 - Existing | D10: PJ, GW | E10: ELCR3 | F10: ELC | G10: 2005 | H10: 50 | I10: 1.11 | J10: 1 | K10: 2.915 | L10: =K10*31.536 -> 91.92744 | M10: 0 | O10: 1
A11: R5 | B11: XELCR3E | C11: Electricity Imports from R3 to R5 - Existing | D11: PJ, GW | E11: ELCR3 | F11: ELC | G11: 2005 | H11: 50 | I11: 1.11 | J11: 1 | K11: 4.428 | L11: =K11*31.536 -> 139.64141 | M11: 0 | O11: 1
A12: R6 | B12: XELCR3E | C12: Electricity Imports from R3 to R6 - Existing | D12: PJ, GW | E12: ELCR3 | F12: ELC | G12: 2005 | H12: 50 | I12: 1 | J12: 1 | K12: 1.425 | L12: =K12*31.536 -> 44.9388 | M12: 0 | O12: 1
A13: R7 | B13: XELCR3E | C13: Electricity Imports from R3 to R7 - Existing | D13: PJ, GW | E13: ELCR3 | F13: ELC | G13: 2005 | H13: 50 | I13: 1 | J13: 1 | K13: 1.53 | L13: =K13*31.536 -> 48.25008 | M13: 0 | O13: 1
A14: R3 | B14: XELCR4E | C14: Electricity Imports from R4 to R3 - Existing | D14: PJ, GW | E14: ELCR4 | F14: ELC | G14: 2005 | H14: 50 | I14: 1.11 | J14: 1 | K14: 1.748 | L14: =K14*31.536 -> 55.124928 | M14: 0 | O14: 1
A15: R6 | B15: XELCR4E | C15: Electricity Imports from R4 to R6 - Existing | D15: PJ, GW | E15: ELCR4 | F15: ELC | G15: 2005 | H15: 50 | I15: 1.11 | J15: 1 | K15: 2.428 | L15: =K15*31.536 -> 76.569408 | M15: 0 | O15: 1
A16: R7 | B16: XELCR4E | C16: Electricity Imports from R4 to R7 - Existing | D16: PJ, GW | E16: ELCR4 | F16: ELC | G16: 2005 | H16: 50 | I16: 1.11 | J16: 1 | K16: 3.843 | L16: =K16*31.536 -> 121.19285 | M16: 0 | O16: 1
... A32: R8 | B32: XELCR9E | C32: Electricity Imports from R9 to R8 - Existing | D32: PJ, GW | E32: ELCR9 | F32: ELC | G32: 2005 | H32: 50 | I32: 1.11 | J32: 1 | K32: 12.247 | L32: =K32*31.536 -> 386.22139 | M32: 0 | O32: 1
A34: * Domestic Trade Processes, Infastructure - New
A35: *** R1
A36: R2 | B36: XELCR1N | C36: Electricity Imports from R1 to R2 - New | D36: PJ, GW | E36: ELCR1 | F36: ELC | G36: 2005 | H36: 50 | I36: 1.11 | J36: 1 | N36: 500 | O36: 1 | P36: 10 | Q36: =P36*31.536 -> 315.36
A37: R1 | B37: XELCR2N | C37: Electricity Imports from R2 to R1 - New | D37: PJ, GW | E37: ELCR2 | F37: ELC | G37: 2005 | H37: 50 | I37: 1.11 | J37: 1 | N37: 500 | O37: 1 | Q37: =P37*31.536 -> 0
A38: R3 | B38: XELCR2N | C38: Electricity Imports from R2 to R3 - New | D38: PJ, GW | E38: ELCR2 | F38: ELC | G38: 2005 | H38: 50 | I38: 1.11 | J38: 1 | N38: 500 | O38: 1 | P38: 10 | Q38: =P38*31.536 -> 315.36
A39: R5 | B39: XELCR2N | C39: Electricity Imports from R2 to R5 - New | D39: PJ, GW | E39: ELCR2 | F39: ELC | G39: 2005 | H39: 50 | I39: 1 | J39: 1 | N39: 999 | O39: 1 | Q39: =P39*31.536 -> 0
A40: R2 | B40: XELCR3N | C40: Electricity Imports from R3 to R2 - New | D40: PJ, GW | E40: ELCR3 | F40: ELC | G40: 2005 | H40: 50 | I40: 1.11 | J40: 1 | N40: 500 | O40: 1 | P40: 10 | Q40: =P40*31.536 -> 315.36
A41: R4 | B41: XELCR3N | C41: Electricity Imports from R3 to R4 - New | D41: PJ, GW | E41: ELCR3 | F41: ELC | G41: 2005 | H41: 50 | I41: 1.11 | J41: 1 | N41: 500 | O41: 1 | P41: 10 | Q41: =P41*31.536 -> 315.36
A42: R5 | B42: XELCR3N | C42: Electricity Imports from R3 to R5 - New | D42: PJ, GW | E42: ELCR3 | F42: ELC | G42: 2005 | H42: 50 | I42: 1.11 | J42: 1 | N42: 500 | O42: 1 | P42: 10 | Q42: =P42*31.536 -> 315.36
A43: R6 | B43: XELCR3N | C43: Electricity Imports from R3 to R6 - New | D43: PJ, GW | E43: ELCR3 | F43: ELC | G43: 2005 | H43: 50 | I43: 1 | J43: 1 | N43: 999 | O43: 1 | Q43: =P43*31.536 -> 0
A44: R7 | B44: XELCR3N | C44: Electricity Imports from R3 to R7 - New | D44: PJ, GW | E44: ELCR3 | F44: ELC | G44: 2005 | H44: 50 | I44: 1 | J44: 1 | N44: 999 | O44: 1 | Q44: =P44*31.536 -> 0
A45: R3 | B45: XELCR4N | C45: Electricity Imports from R4 to R3 - New | D45: PJ, GW | E45: ELCR4 | F45: ELC | G45: 2005 | H45: 50 | I45: 1.11 | J45: 1 | N45: 500 | O45: 1 | P45: 10 | Q45: =P45*31.536 -> 315.36
A46: R6 | B46: XELCR4N | C46: Electricity Imports from R4 to R6 - New | D46: PJ, GW | E46: ELCR4 | F46: ELC | G46: 2005 | H46: 50 | I46: 1.11 | J46: 1 | N46: 500 | O46: 1 | P46: 10 | Q46: =P46*31.536 -> 315.36
A47: R7 | B47: XELCR4N | C47: Electricity Imports from R4 to R7 - New | D47: PJ, GW | E47: ELCR4 | F47: ELC | G47: 2005 | H47: 50 | I47: 1.11 | J47: 1 | N47: 500 | O47: 1 | P47: 10 | Q47: =P47*31.536 -> 315.36
A48: R8 | B48: XELCR4N | C48: Electricity Imports from R4 to R8 - New | D48: PJ, GW | E48: ELCR4 | F48: ELC | G48: 2005 | H48: 50 | I48: 1 | J48: 1 | N48: 999 | O48: 1 | Q48: =P48*31.536 -> 0
A49: R2 | B49: XELCR5N | C49: Electricity Imports from R5 to R2 - New | D49: PJ, GW | E49: ELCR5 | F49: ELC | G49: 2005 | H49: 50 | I49: 1 | J49: 1 | N49: 999 | O49: 1 | Q49: =P49*31.536 -> 0
A50: R3 | B50: XELCR5N | C50: Electricity Imports from R5 to R3 - New | D50: PJ, GW | E50: ELCR5 | F50: ELC | G50: 2005 | H50: 50 | I50: 1.11 | J50: 1 | N50: 500 | O50: 1 | P50: 10 | Q50: =P50*31.536 -> 315.36
A51: R6 | B51: XELCR5N | C51: Electricity Imports from R5 to R6 - New | D51: PJ, GW | E51: ELCR5 | F51: ELC | G51: 2005 | H51: 50 | I51: 1.11 | J51: 1 | N51: 500 | O51: 1 | P51: 10 | Q51: =P51*31.536 -> 315.36
A52: R3 | B52: XELCR6N | C52: Electricity Imports from R6 to R3 - New | D52: PJ, GW | E52: ELCR6 | F52: ELC | G52: 2005 | H52: 50 | I52: 1 | J52: 1 | N52: 999 | O52: 1 | Q52: =P52*31.536 -> 0
A53: R4 | B53: XELCR6N | C53: Electricity Imports from R6 to R4 - New | D53: PJ, GW | E53: ELCR6 | F53: ELC | G53: 2005 | H53: 50 | I53: 1.11 | J53: 1 | N53: 500 | O53: 1 | P53: 10 | Q53: =P53*31.536 -> 315.36
A54: R5 | B54: XELCR6N | C54: Electricity Imports from R6 to R5 - New | D54: PJ, GW | E54: ELCR6 | F54: ELC | G54: 2005 | H54: 50 | I54: 1.11 | J54: 1 | N54: 500 | O54: 1 | P54: 10 | Q54: =P54*31.536 -> 315.36
A55: R7 | B55: XELCR6N | C55: Electricity Imports from R6 to R7 - New | D55: PJ, GW | E55: ELCR6 | F55: ELC | G55: 2005 | H55: 50 | I55: 1.11 | J55: 1 | N55: 500 | O55: 1 | P55: 10 | Q55: =P55*31.536 -> 315.36
A56: R3 | B56: XELCR7N | C56: Electricity Imports from R7 to R3 - New | D56: PJ, GW | E56: ELCR7 | F56: ELC | G56: 2005 | H56: 50 | I56: 1 | J56: 1 | N56: 999 | O56: 1 | Q56: =P56*31.536 -> 0
A57: R4 | B57: XELCR7N | C57: Electricity Imports from R7 to R4 - New | D57: PJ, GW | E57: ELCR7 | F57: ELC | G57: 2005 | H57: 50 | I57: 1.11 | J57: 1 | N57: 500 | O57: 1 | P57: 10 | Q57: =P57*31.536 -> 315.36
...

Sheet NGCap
A1: Trade Links
B2: 2010 Capacity (billion cubic feet per year) | C2: 2011 | D2: 2015 | E2: 2020 | F2: 2025 | G2: 2030 | H2: 2035 | I2: 2040 | J2: 2045 | K2: 2050 | L2: 2050-2010
A3: R2 to R1 | B3: =SUMIFS(C$39:C$92,$A$39:$A$92,$A3) -> 803.2879 | C3: =SUMIFS(D$39:D$92,$A$39:$A$92,$A3) -> 890.94684 | D3: =SUMIFS(E$39:E$92,$A$39:$A$92,$A3) -> 870.14172 | E3: =SUMIFS(F$39:F$92,$A$39:$A$92,$A3) -> 719.4339 | F3: =SUMIFS(G$39:G$92,$A$39:$A$92,$A3) -> 735.6947 | G3: =SUMIFS(H$39:H$92,$A$39:$A$92,$A3) -> 767.86969 | H3: =SUMIFS(I$39:I$92,$A$39:$A$92,$A3) -> 783.24164 | I3: =SUMIFS(J$39:J$92,$A$39:$A$92,$A3) -> 809.85529 | ... K3: =SUMIFS(L$39:L$92,$A$39:$A$92,$A3) -> 882.5202 | L3: =K3-B3 -> 79.2323 | N3: MMBTU per cf (natural gas) | O3: 0.001022 | P3: (production)
A4: R2 to R3 | B4: =SUMIFS(C$39:C$92,$A$39:$A$92,$A4) -> 0 | C4: =SUMIFS(D$39:D$92,$A$39:$A$92,$A4) -> 0 | D4: =SUMIFS(E$39:E$92,$A$39:$A$92,$A4) -> 382.12701 | E4: =SUMIFS(F$39:F$92,$A$39:$A$92,$A4) -> 993.61163 | F4: =SUMIFS(G$39:G$92,$A$39:$A$92,$A4) -> 1859.999 | G4: =SUMIFS(H$39:H$92,$A$39:$A$92,$A4) -> 3636.8315 | H4: =SUMIFS(I$39:I$92,$A$39:$A$92,$A4) -> 4410.2061 | I4: =SUMIFS(J$39:J$92,$A$39:$A$92,$A4) -> 5226.0234 | ... K4: =SUMIFS(L$39:L$92,$A$39:$A$92,$A4) -> 7016.3174 | L4: =K4-B4 -> 7016.3174 | O4: 0.001025 | P4: (imports)
A5: R2 to R5 | B5: =SUMIFS(C$39:C$92,$A$39:$A$92,$A5) -> 0 | C5: =SUMIFS(D$39:D$92,$A$39:$A$92,$A5) -> 0 | D5: =SUMIFS(E$39:E$92,$A$39:$A$92,$A5) -> 554.35113 | E5: =SUMIFS(F$39:F$92,$A$39:$A$92,$A5) -> 2123.3215 | F5: =SUMIFS(G$39:G$92,$A$39:$A$92,$A5) -> 3199.1108 | G5: =SUMIFS(H$39:H$92,$A$39:$A$92,$A5) -> 2855.3599 | H5: =SUMIFS(I$39:I$92,$A$39:$A$92,$A5) -> 2705.9258 | I5: =SUMIFS(J$39:J$92,$A$39:$A$92,$A5) -> 2591.1631 | ... K5: =SUMIFS(L$39:L$92,$A$39:$A$92,$A5) -> 2433.0078 | L5: =K5-B5 -> 2433.0078 | N5: MMBTU per pj | O5: 1.0511e-06
A6: R3 to R2 | B6: =SUMIFS(C$39:C$92,$A$39:$A$92,$A6) -> 635.06726 | C6: =SUMIFS(D$39:D$92,$A$39:$A$92,$A6) -> 556.9754 | D6: =SUMIFS(E$39:E$92,$A$39:$A$92,$A6) -> 0 | E6: =SUMIFS(F$39:F$92,$A$39:$A$92,$A6) -> 0 | F6: =SUMIFS(G$39:G$92,$A$39:$A$92,$A6) -> 0 | G6: =SUMIFS(H$39:H$92,$A$39:$A$92,$A6) -> 0 | H6: =SUMIFS(I$39:I$92,$A$39:$A$92,$A6) -> 0 | I6: =SUMIFS(J$39:J$92,$A$39:$A$92,$A6) -> 0 | ... K6: =SUMIFS(L$39:L$92,$A$39:$A$92,$A6) -> 0 | L6: =K6-B6 -> -635.06726
A7: R3 to R4 | B7: =SUMIFS(C$39:C$92,$A$39:$A$92,$A7) -> 0 | C7: =SUMIFS(D$39:D$92,$A$39:$A$92,$A7) -> 0 | D7: =SUMIFS(E$39:E$92,$A$39:$A$92,$A7) -> 3.099 | E7: =SUMIFS(F$39:F$92,$A$39:$A$92,$A7) -> 0 | F7: =SUMIFS(G$39:G$92,$A$39:$A$92,$A7) -> 0 | G7: =SUMIFS(H$39:H$92,$A$39:$A$92,$A7) -> 57.478882 | H7: =SUMIFS(I$39:I$92,$A$39:$A$92,$A7) -> 72.601357 | I7: =SUMIFS(J$39:J$92,$A$39:$A$92,$A7) -> 84.217232 | ... K7: =SUMIFS(L$39:L$92,$A$39:$A$92,$A7) -> 182.09943 | L7: =K7-B7 -> 182.09943
A8: R3 to R5 | B8: =SUMIFS(C$39:C$92,$A$39:$A$92,$A8) -> 766.53113 | C8: =SUMIFS(D$39:D$92,$A$39:$A$92,$A8) -> 660.31354 | D8: =SUMIFS(E$39:E$92,$A$39:$A$92,$A8) -> 19.952679 | E8: =SUMIFS(F$39:F$92,$A$39:$A$92,$A8) -> 0 | F8: =SUMIFS(G$39:G$92,$A$39:$A$92,$A8) -> 0 | G8: =SUMIFS(H$39:H$92,$A$39:$A$92,$A8) -> 0 | H8: =SUMIFS(I$39:I$92,$A$39:$A$92,$A8) -> 0 | I8: =SUMIFS(J$39:J$92,$A$39:$A$92,$A8) -> 0 | ... K8: =SUMIFS(L$39:L$92,$A$39:$A$92,$A8) -> 0 | L8: =K8-B8 -> -766.53113
A9: R3 to R6 | B9: =SUMIFS(C$39:C$92,$A$39:$A$92,$A9) -> 0 | C9: =SUMIFS(D$39:D$92,$A$39:$A$92,$A9) -> 0 | D9: =SUMIFS(E$39:E$92,$A$39:$A$92,$A9) -> 641.44012 | E9: =SUMIFS(F$39:F$92,$A$39:$A$92,$A9) -> 190.37256 | F9: =SUMIFS(G$39:G$92,$A$39:$A$92,$A9) -> 1167.4193 | G9: =SUMIFS(H$39:H$92,$A$39:$A$92,$A9) -> 2292.6726 | H9: =SUMIFS(I$39:I$92,$A$39:$A$92,$A9) -> 2653.9321 | I9: =SUMIFS(J$39:J$92,$A$39:$A$92,$A9) -> 2867.2231 | ... K9: =SUMIFS(L$39:L$92,$A$39:$A$92,$A9) -> 3635.7361 | L9: =K9-B9 -> 3635.7361
A10: R4 to R3 | B10: =SUMIFS(C$39:C$92,$A$39:$A$92,$A10) -> 3700.5615 | C10: =SUMIFS(D$39:D$92,$A$39:$A$92,$A10) -> 3876.4404 | D10: =SUMIFS(E$39:E$92,$A$39:$A$92,$A10) -> 2398.1172 | E10: =SUMIFS(F$39:F$92,$A$39:$A$92,$A10) -> 2258.9976 | F10: =SUMIFS(G$39:G$92,$A$39:$A$92,$A10) -> 1620.8055 | G10: =SUMIFS(H$39:H$92,$A$39:$A$92,$A10) -> 1182.2509 | H10: =SUMIFS(I$39:I$92,$A$39:$A$92,$A10) -> 976.10181 | I10: =SUMIFS(J$39:J$92,$A$39:$A$92,$A10) -> 752.70508 | ... K10: =SUMIFS(L$39:L$92,$A$39:$A$92,$A10) -> 302.31201 | L10: =K10-B10 -> -3398.2495
A11: R4 to R7 | B11: =SUMIFS(C$39:C$92,$A$39:$A$92,$A11) -> 0 | C11: =SUMIFS(D$39:D$92,$A$39:$A$92,$A11) -> 0 | D11: =SUMIFS(E$39:E$92,$A$39:$A$92,$A11) -> 6.483 | E11: =SUMIFS(F$39:F$92,$A$39:$A$92,$A11) -> 0 | F11: =SUMIFS(G$39:G$92,$A$39:$A$92,$A11) -> 0 | G11: =SUMIFS(H$39:H$92,$A$39:$A$92,$A11) -> 23.246014 | H11: =SUMIFS(I$39:I$92,$A$39:$A$92,$A11) -> 14.154186 | I11: =SUMIFS(J$39:J$92,$A$39:$A$92,$A11) -> 9.329961 | ... K11: =SUMIFS(L$39:L$92,$A$39:$A$92,$A11) -> 0 | L11: =K11-B11 -> 0
A12: R5 to R2 | B12: =SUMIFS(C$39:C$92,$A$39:$A$92,$A12) -> 1734.2087 | C12: =SUMIFS(D$39:D$92,$A$39:$A$92,$A12) -> 1538.6575 | D12: =SUMIFS(E$39:E$92,$A$39:$A$92,$A12) -> 0 | E12: =SUMIFS(F$39:F$92,$A$39:$A$92,$A12) -> 0 | F12: =SUMIFS(G$39:G$92,$A$39:$A$92,$A12) -> 0 | G12: =SUMIFS(H$39:H$92,$A$39:$A$92,$A12) -> 0 | H12: =SUMIFS(I$39:I$92,$A$39:$A$92,$A12) -> 0 | I12: =SUMIFS(J$39:J$92,$A$39:$A$92,$A12) -> 0 | ... K12: =SUMIFS(L$39:L$92,$A$39:$A$92,$A12) -> 0 | L12: =K12-B12 -> -1734.2087
A13: R5 to R6 | B13: =SUMIFS(C$39:C$92,$A$39:$A$92,$A13) -> 0 | C13: =SUMIFS(D$39:D$92,$A$39:$A$92,$A13) -> 0 | D13: =SUMIFS(E$39:E$92,$A$39:$A$92,$A13) -> 83.915291 | E13: =SUMIFS(F$39:F$92,$A$39:$A$92,$A13) -> 1176.8667 | F13: =SUMIFS(G$39:G$92,$A$39:$A$92,$A13) -> 1637.3507 | G13: =SUMIFS(H$39:H$92,$A$39:$A$92,$A13) -> 1577.5996 | H13: =SUMIFS(I$39:I$92,$A$39:$A$92,$A13) -> 1513.1655 | I13: =SUMIFS(J$39:J$92,$A$39:$A$92,$A13) -> 1521.427 | ... K13: =SUMIFS(L$39:L$92,$A$39:$A$92,$A13) -> 1512.3253 | L13: =K13-B13 -> 1512.3253
A14: R6 to R3 | B14: =SUMIFS(C$39:C$92,$A$39:$A$92,$A14) -> 1838.9316 | C14: =SUMIFS(D$39:D$92,$A$39:$A$92,$A14) -> 1995.3987 | D14: =SUMIFS(E$39:E$92,$A$39:$A$92,$A14) -> 1094.4344 | E14: =SUMIFS(F$39:F$92,$A$39:$A$92,$A14) -> 144.89494 | F14: =SUMIFS(G$39:G$92,$A$39:$A$92,$A14) -> 236.53589 | G14: =SUMIFS(H$39:H$92,$A$39:$A$92,$A14) -> 438.95221 | H14: =SUMIFS(I$39:I$92,$A$39:$A$92,$A14) -> 542.9032 | I14: =SUMIFS(J$39:J$92,$A$39:$A$92,$A14) -> 621.05219 | ... K14: =SUMIFS(L$39:L$92,$A$39:$A$92,$A14) -> 818.39166 | L14: =K14-B14 -> -1020.54
A15: R6 to R5 | B15: =SUMIFS(C$39:C$92,$A$39:$A$92,$A15) -> 3359.1737 | C15: =SUMIFS(D$39:D$92,$A$39:$A$92,$A15) -> 3341.9423 | D15: =SUMIFS(E$39:E$92,$A$39:$A$92,$A15) -> 2671.3029 | E15: =SUMIFS(F$39:F$92,$A$39:$A$92,$A15) -> 2361.2946 | F15: =SUMIFS(G$39:G$92,$A$39:$A$92,$A15) -> 2230.7334 | G15: =SUMIFS(H$39:H$92,$A$39:$A$92,$A15) -> 2228.7909 | H15: =SUMIFS(I$39:I$92,$A$39:$A$92,$A15) -> 2287.0612 | I15: =SUMIFS(J$39:J$92,$A$39:$A$92,$A15) -> 2296.3717 | ... K15: =SUMIFS(L$39:L$92,$A$39:$A$92,$A15) -> 2455.229 | L15: =K15-B15 -> -903.9447
A16: R6 to R7 | B16: =SUMIFS(C$39:C$92,$A$39:$A$92,$A16) -> 0 | C16: =SUMIFS(D$39:D$92,$A$39:$A$92,$A16) -> 0 | D16: =SUMIFS(E$39:E$92,$A$39:$A$92,$A16) -> 51.532066 | E16: =SUMIFS(F$39:F$92,$A$39:$A$92,$A16) -> 0 | F16: =SUMIFS(G$39:G$92,$A$39:$A$92,$A16) -> 0 | G16: =SUMIFS(H$39:H$92,$A$39:$A$92,$A16) -> 21.636526 | H16: =SUMIFS(I$39:I$92,$A$39:$A$92,$A16) -> 80.933334 | I16: =SUMIFS(J$39:J$92,$A$39:$A$92,$A16) -> 149.49989 | ... K16: =SUMIFS(L$39:L$92,$A$39:$A$92,$A16) -> 397.37936 | L16: =K16-B16 -> 397.37936
A17: R7 to R4 | B17: =SUMIFS(C$39:C$92,$A$39:$A$92,$A17) -> 1475.5103 | C17: =SUMIFS(D$39:D$92,$A$39:$A$92,$A17) -> 1638.5508 | D17: =SUMIFS(E$39:E$92,$A$39:$A$92,$A17) -> 1761.5397 | E17: =SUMIFS(F$39:F$92,$A$39:$A$92,$A17) -> 824.29102 | F17: =SUMIFS(G$39:G$92,$A$39:$A$92,$A17) -> 458.60672 | G17: =SUMIFS(H$39:H$92,$A$39:$A$92,$A17) -> 328.25684 | H17: =SUMIFS(I$39:I$92,$A$39:$A$92,$A17) -> 413.22742 | I17: =SUMIFS(J$39:J$92,$A$39:$A$92,$A17) -> 504.60947 | ... K17: =SUMIFS(L$39:L$92,$A$39:$A$92,$A17) -> 934.1648 | L17: =K17-B17 -> -541.34546
... A19: R8 to R4 | B19: =SUMIFS(C$39:C$92,$A$39:$A$92,$A19) -> 2421.6516 | C19: =SUMIFS(D$39:D$92,$A$39:$A$92,$A19) -> 2465.95 | D19: =SUMIFS(E$39:E$92,$A$39:$A$92,$A19) -> 991.18121 | E19: =SUMIFS(F$39:F$92,$A$39:$A$92,$A19) -> 1547.4204 | F19: =SUMIFS(G$39:G$92,$A$39:$A$92,$A19) -> 1411.7443 | G19: =SUMIFS(H$39:H$92,$A$39:$A$92,$A19) -> 1159.4485 | H19: =SUMIFS(I$39:I$92,$A$39:$A$92,$A19) -> 968.3927 | I19: =SUMIFS(J$39:J$92,$A$39:$A$92,$A19) -> 863.72394 | ... K19: =SUMIFS(L$39:L$92,$A$39:$A$92,$A19) -> 490.46365 | L19: =K19-B19 -> -1931.188
A20: R8 to R7 | B20: =SUMIFS(C$39:C$92,$A$39:$A$92,$A20) -> 392.00699 | C20: =SUMIFS(D$39:D$92,$A$39:$A$92,$A20) -> 288.18565 | D20: =SUMIFS(E$39:E$92,$A$39:$A$92,$A20) -> 925.73569 | E20: =SUMIFS(F$39:F$92,$A$39:$A$92,$A20) -> 330.61512 | F20: =SUMIFS(G$39:G$92,$A$39:$A$92,$A20) -> 280.49626 | G20: =SUMIFS(H$39:H$92,$A$39:$A$92,$A20) -> 266.21397 | H20: =SUMIFS(I$39:I$92,$A$39:$A$92,$A20) -> 185.26766 | I20: =SUMIFS(J$39:J$92,$A$39:$A$92,$A20) -> 133.50718 | ... K20: =SUMIFS(L$39:L$92,$A$39:$A$92,$A20) -> 3.429176 | L20: =K20-B20 -> -388.57781 | V20: * Taken from the AEO2007
A21: R8 to R9 | B21: =SUMIFS(C$39:C$92,$A$39:$A$92,$A21) -> 1751.992 | C21: =SUMIFS(D$39:D$92,$A$39:$A$92,$A21) -> 1776.845 | D21: =SUMIFS(E$39:E$92,$A$39:$A$92,$A21) -> 1689.8249 | E21: =SUMIFS(F$39:F$92,$A$39:$A$92,$A21) -> 2323.8833 | F21: =SUMIFS(G$39:G$92,$A$39:$A$92,$A21) -> 2307.3871 | G21: =SUMIFS(H$39:H$92,$A$39:$A$92,$A21) -> 2288.0345 | H21: =SUMIFS(I$39:I$92,$A$39:$A$92,$A21) -> 2376.2982 | I21: =SUMIFS(J$39:J$92,$A$39:$A$92,$A21) -> 2420.3849 | ... K21: =SUMIFS(L$39:L$92,$A$39:$A$92,$A21) -> 2679.5755 | L21: =K21-B21 -> 927.58353
A23: C to R1 | B23: =SUMIFS(C$39:C$92,$A$39:$A$92,$A23) -> 212.44701 | C23: =SUMIFS(D$39:D$92,$A$39:$A$92,$A23) -> 228.65195 | D23: =SUMIFS(E$39:E$92,$A$39:$A$92,$A23) -> 133.79437 | E23: =SUMIFS(F$39:F$92,$A$39:$A$92,$A23) -> 87.592781 | F23: =SUMIFS(G$39:G$92,$A$39:$A$92,$A23) -> 80.620499 | G23: =SUMIFS(H$39:H$92,$A$39:$A$92,$A23) -> 83.207558 | H23: =SUMIFS(I$39:I$92,$A$39:$A$92,$A23) -> 83.897675 | I23: =SUMIFS(J$39:J$92,$A$39:$A$92,$A23) -> 84.144768 | ... K23: =SUMIFS(L$39:L$92,$A$39:$A$92,$A23) -> 84.600792 | L23: =K23-B23 -> -127.84621 | V23: * For more information on capacity use see
A24: C to R2 | B24: =SUMIFS(C$39:C$92,$A$39:$A$92,$A24) -> 434.526 | C24: =SUMIFS(D$39:D$92,$A$39:$A$92,$A24) -> 324.50354 | D24: =SUMIFS(E$39:E$92,$A$39:$A$92,$A24) -> 0 | E24: =SUMIFS(F$39:F$92,$A$39:$A$92,$A24) -> 0 | F24: =SUMIFS(G$39:G$92,$A$39:$A$92,$A24) -> 0 | G24: =SUMIFS(H$39:H$92,$A$39:$A$92,$A24) -> 0 | H24: =SUMIFS(I$39:I$92,$A$39:$A$92,$A24) -> 0 | I24: =SUMIFS(J$39:J$92,$A$39:$A$92,$A24) -> 0 | ... K24: =SUMIFS(L$39:L$92,$A$39:$A$92,$A24) -> 0 | L24: =K24-B24 -> -434.526 | V24: http://www.eia.gov/pub/oil_gas/natural_gas/analysis_publications/ngpipeline/usage.html
A25: C to R4 | B25: =SUMIFS(C$39:C$92,$A$39:$A$92,$A25) -> 1862.3105 | C25: =SUMIFS(D$39:D$92,$A$39:$A$92,$A25) -> 1884.2112 | D25: =SUMIFS(E$39:E$92,$A$39:$A$92,$A25) -> 1162.2148 | E25: =SUMIFS(F$39:F$92,$A$39:$A$92,$A25) -> 999.65997 | F25: =SUMIFS(G$39:G$92,$A$39:$A$92,$A25) -> 931.302 | G25: =SUMIFS(H$39:H$92,$A$39:$A$92,$A25) -> 850.40729 | H25: =SUMIFS(I$39:I$92,$A$39:$A$92,$A25) -> 783.49915 | I25: =SUMIFS(J$39:J$92,$A$39:$A$92,$A25) -> 678.9469 | ... K25: =SUMIFS(L$39:L$92,$A$39:$A$92,$A25) -> 290.64163 | L25: =K25-B25 -> -1571.6689
A26: C to R8 | B26: =SUMIFS(C$39:C$92,$A$39:$A$92,$A26) -> 33.186462 | C26: =SUMIFS(D$39:D$92,$A$39:$A$92,$A26) -> 20.10022 | D26: =SUMIFS(E$39:E$92,$A$39:$A$92,$A26) -> 25.572746 | E26: =SUMIFS(F$39:F$92,$A$39:$A$92,$A26) -> 571.06995 | F26: =SUMIFS(G$39:G$92,$A$39:$A$92,$A26) -> 529.08887 | G26: =SUMIFS(H$39:H$92,$A$39:$A$92,$A26) -> 436.24896 | H26: =SUMIFS(I$39:I$92,$A$39:$A$92,$A26) -> 354.38364 | I26: =SUMIFS(J$39:J$92,$A$39:$A$92,$A26) -> 250.61052 | ... K26: =SUMIFS(L$39:L$92,$A$39:$A$92,$A26) -> 51.98991 | L26: =K26-B26 -> 18.803448
A27: C to R9 | B27: =SUMIFS(C$39:C$92,$A$39:$A$92,$A27) -> 1041.164 | C27: =SUMIFS(D$39:D$92,$A$39:$A$92,$A27) -> 920.0101 | D27: =SUMIFS(E$39:E$92,$A$39:$A$92,$A27) -> 1103.5586 | E27: =SUMIFS(F$39:F$92,$A$39:$A$92,$A27) -> 989.01172 | F27: =SUMIFS(G$39:G$92,$A$39:$A$92,$A27) -> 978.49558 | G27: =SUMIFS(H$39:H$92,$A$39:$A$92,$A27) -> 949.57526 | H27: =SUMIFS(I$39:I$92,$A$39:$A$92,$A27) -> 929.11478 | I27: =SUMIFS(J$39:J$92,$A$39:$A$92,$A27) -> 871.62527 | ... K27: =SUMIFS(L$39:L$92,$A$39:$A$92,$A27) -> 679.67635 | L27: =K27-B27 -> -361.48769
B28: =SUM(B3:B27) -> 28946.1 | C28: =SUM(C3:C27) -> 29153.9 | D28: =SUM(D3:D27) -> 21503.413 | E28: =SUM(E3:E27) -> 20257.756 | F28: =SUM(F3:F27) -> 20991.447 | G28: =SUM(G3:G27) -> 21853.669 | H28: =SUM(H3:H27) -> 22441.812 | I28: =SUM(I3:I27) -> 22979.216 | ... K28: =SUM(K3:K27) -> 25006.781
B29: =SUM(C39:C92)-C91-C87 -> 28946.1 | C29: =SUM(D39:D92)-D91-D87 -> 29153.9 | D29: =SUM(E39:E92)-E91-E87 -> 21503.413 | E29: =SUM(F39:F92)-F91-F87 -> 20257.756 | F29: =SUM(G39:G92)-G91-G87 -> 20991.447 | G29: =SUM(H39:H92)-H91-H87 -> 21853.669 | H29: =SUM(I39:I92)-I91-I87 -> 22441.812 | I29: =SUM(J39:J92)-J91-J87 -> 22979.216 | ... K29: =SUM(L39:L92)-L91-L87 -> 25006.781
B30: =B29-B28 -> 0 | C30: =C29-C28 -> 0 | D30: =D29-D28 -> 0 | E30: =E29-E28 -> 0 | F30: =F29-F28 -> 0 | G30: =G29-G28 -> 0 | H30: =H29-H28 -> 0 | I30: =I29-I28 -> 0 | ... K30: =K29-K28 -> 0
B33: Primary Natural Gas Flows Entering NGTDM Region from Neighboring Regions, Reference case
B34: (billion cubic feet per year)
C36: 2010 | D36: 2011 | E36: 2015 | F36: 2020 | G36: 2025 | H36: 2030 | I36: 2035 | J36: 2040 | K36: 2045 | L36: 2050 | M36: 2055
B38: Into New England From:
A39: R2 to R1 | B39: Middle Atlantic | C39: 803.2879 | D39: 890.94684 | E39: 870.14172 | F39: 719.4339 | G39: 735.6947 | H39: 767.86969 | I39: 783.24164 | J39: 809.85529 | K39: 839.76569 | L39: 882.5202 | M39: =L39*(AVERAGE((L39/K39),(K39/J39))) -> 921.2829
A40: C to R1 | B40: Canada | C40: 212.44701 | D40: 228.65195 | E40: 133.79437 | F40: 87.592781 | G40: 80.620499 | H40: 83.207558 | I40: 83.897675 | J40: 84.144768 | K40: 83.890495 | L40: 84.600792 | M40: =L40*(AVERAGE((L40/K40),(K40/J40))) -> 84.831122
B42: Into Middle Atlantic From:
A43: R3 to R2 | B43: East North Central | C43: 635.06726 | D43: 556.9754
A44: R5 to R2 | B44: South Atlantic | C44: 1734.2087 | D44: 1538.6575
A45: C to R2 | B45: Canada | C45: 434.526 | D45: 324.50354
B47: Into East North Central From:
A48: R2 to R3 | B48: Middle Atlantic | E48: 382.12701 | F48: 993.61163 | G48: 1859.999 | H48: 3636.8315 | I48: 4410.2061 | J48: 5226.0234 | K48: 6076.4629 | L48: 7016.3174
...

Sheet NGExpansion
A1: NG Pipeline Expansion Cost Data (NEMS ngptar input file)
A2: Source: Foster Associates, "Capital Costs for Gas Pipeline and Storage Project
A3: Expansions, May 1999. Anayst judgement.
A4: Derivation:
A5: Units: fraction
A7: Variables: PCNT_C -- Average percentage (fraction) for compressor costs (read but not used)
A8: PCNT_L -- Average percentage (fraction) for looping costs (read but not used)
A9: PCNT_N -- Average percentage (fraction) for new pipeline costs (read but not used)
A10: PCNT_R -- Assumed average percentage (fraction) for replacement costs
A11: MILE_FAC --Factor to compute effective or real mileage (read but not used)
A13: DOCUMENTATION UPDATES: DATE--AUTHOR--COMMENT
A14: -------------------------------------------------------------------------------
... A18: -------------------------------------------------------------------------------
B19: PCNT_C, | C19: PCNT_L, | D19: PCNT_N, | E19: PCNT_R, | F19: MILE_FAC,
A20: @
B21: 0.25 | C21: 0.21 | D21: 0.54 | E21: 0.023 | F21: 0.5
A23: ===============================================================================
A24: Data: Parameters for Capital Costs for Pipeline Expansion by arc.
A25: 1998 Average Tariffs will not be used. CCOST1 and CCOST2 will not be used.
A26: Geographical Mileage by arc.
A27: Source: Foster Associates, "Capital Costs for Gas Pipeline and Storage Project
A28: Expansions, May 1999
A29: Derivation:
A30: Units: Capital Costs in 1998$-day per (Mcf-Mile);
A31: Average Tariff in 1998$/Mcf
A32: Mileage in Miles;
A34: Notes:
A35: Variables: MILES -- Length of an arc
... A37: CC_LOOPI -- Capital Cost for Looping
A38: CC_NEWPI -- Capital Cost for New Pipeline | M38: Price Adjustment
B39: Start Region | C39: End Region | H39: Capital Cost for Capacity Expansion | M39: 1.8
B40: AF | C40: AT | D40: MILES | E40: CC_COMP | F40: CC_LOOP | G40: CC_NEWP | H40: 1998$-day per (Mcf-Mile); | I40: M 2005$/PJ /a | J40: R from | K40: R to | O40: NGTDM network | P40: Region
B41: 1 | C41: 1 | D41: 141 | E41: 2.396 | F41: 5.554 | G41: 7.81 | H41: =E41*$B$21+F41*$C$21+G41*$D$21 -> 5.98274 | I41: =H41*D41*[1]Conv!$D$31/365/[1]Conv!$D$6/[1]Conv!$J$5/10^9 -> 2.497619 | J41: =VLOOKUP(B41,$O$41:$P$62,2,FALSE) -> R1 | K41: =VLOOKUP(C41,$O$41:$P$62,2,FALSE) -> R1 | M41: =I41*$M$39 -> 4.4957141 | O41: 1 | P41: R1
B42: 2 | C42: 1 | D42: 208 | E42: 2.396 | F42: 5.554 | G42: 7.81 | H42: =E42*$B$21+F42*$C$21+G42*$D$21 -> 5.98274 | I42: =H42*D42*[1]Conv!$D$31/365/[1]Conv!$D$6/[1]Conv!$J$5/10^9 -> 3.6844308 | J42: =VLOOKUP(B42,$O$41:$P$62,2,FALSE) -> R2 | K42: =VLOOKUP(C42,$O$41:$P$62,2,FALSE) -> R1 | M42: =I42*$M$39 -> 6.6319754 | O42: 2 | P42: R2
B43: 2 | C43: 2 | D43: 268 | E43: 2.396 | F43: 5.554 | G43: 7.81 | H43: =E43*$B$21+F43*$C$21+G43*$D$21 -> 5.98274 | I43: =H43*D43*[1]Conv!$D$31/365/[1]Conv!$D$6/[1]Conv!$J$5/10^9 -> 4.7472474 | J43: =VLOOKUP(B43,$O$41:$P$62,2,FALSE) -> R2 | K43: =VLOOKUP(C43,$O$41:$P$62,2,FALSE) -> R2 | M43: =I43*$M$39 -> 8.5450453 | O43: 3 | P43: R3
B44: 3 | C44: 2 | D44: 264 | E44: 2.396 | F44: 5.554 | G44: 5.263 | H44: =E44*$B$21+F44*$C$21+G44*$D$21 -> 4.60736 | I44: =H44*D44*[1]Conv!$D$31/365/[1]Conv!$D$6/[1]Conv!$J$5/10^9 -> 3.6013308 | J44: =VLOOKUP(B44,$O$41:$P$62,2,FALSE) -> R3 | K44: =VLOOKUP(C44,$O$41:$P$62,2,FALSE) -> R2 | M44: =I44*$M$39 -> 6.4823954 | O44: 4 | P44: R4
B45: 3 | C45: 3 | D45: 238 | E45: 2.26 | F45: 2.353 | G45: 3.243 | H45: =E45*$B$21+F45*$C$21+G45*$D$21 -> 2.81035 | I45: =H45*D45*[1]Conv!$D$31/365/[1]Conv!$D$6/[1]Conv!$J$5/10^9 -> 1.9803607 | J45: =VLOOKUP(B45,$O$41:$P$62,2,FALSE) -> R3 | K45: =VLOOKUP(C45,$O$41:$P$62,2,FALSE) -> R3 | M45: =I45*$M$39 -> 3.5646493 | O45: 5 | P45: R5
B46: 3 | C46: 5 | D46: 510 | E46: 1.674 | F46: 5.059 | G46: 6.787 | H46: =E46*$B$21+F46*$C$21+G46*$D$21 -> 5.14587 | I46: =H46*D46*[1]Conv!$D$31/365/[1]Conv!$D$6/[1]Conv!$J$5/10^9 -> 7.7702667 | J46: =VLOOKUP(B46,$O$41:$P$62,2,FALSE) -> R3 | K46: =VLOOKUP(C46,$O$41:$P$62,2,FALSE) -> R5 | M46: =I46*$M$39 -> 13.98648 | O46: 6 | P46: R6
B47: 4 | C47: 3 | D47: 604 | E47: 2.012 | F47: 4.638 | G47: 6.34 | H47: =E47*$B$21+F47*$C$21+G47*$D$21 -> 4.90058 | I47: =H47*D47*[1]Conv!$D$31/365/[1]Conv!$D$6/[1]Conv!$J$5/10^9 -> 8.7637779 | J47: =VLOOKUP(B47,$O$41:$P$62,2,FALSE) -> R4 | K47: =VLOOKUP(C47,$O$41:$P$62,2,FALSE) -> R3 | M47: =I47*$M$39 -> 15.7748 | O47: 7 | P47: R7
B48: 4 | C48: 4 | D48: 338 | E48: 1.987 | F48: 4.638 | G48: 6.34 | H48: =E48*$B$21+F48*$C$21+G48*$D$21 -> 4.89433 | I48: =H48*D48*[1]Conv!$D$31/365/[1]Conv!$D$6/[1]Conv!$J$5/10^9 -> 4.8979787 | J48: =VLOOKUP(B48,$O$41:$P$62,2,FALSE) -> R4 | K48: =VLOOKUP(C48,$O$41:$P$62,2,FALSE) -> R4 | M48: =I48*$M$39 -> 8.8163616 | O48: 8 | P48: R8
...

Sheet NG data
G1: START | H1: LIFE | I1: INP(ENT)p | J1: OUT(ENC)p | K1: BOUND(UP) | L1: VAROM | M1: VAROM | N1: VAROM | O1: VAROM | P1: VAROM | Q1: VAROM | R1: VAROM | S1: VAROM | T1: VAROM | U1: VAROM | V1: VAROM | W1: INVCOST
B3: TechName | C3: TechDesc | D3: Units | E3: CommIN | F3: CommOUT | G3: TID | H3: TID | L3: 2005 | M3: 2010 | N3: 2015 | O3: 2020 | P3: 2025 | Q3: 2030 | R3: 2035 | S3: 2040 | T3: 2045 | U3: 2050 | V3: 2055
A4: * Traded natural gas Pipeline technologies
A5: * Imported natural gas Pipeline technologies
A6: R1 | B6: XNGAC1E | C6: Existing Pipeline for Import Canadian natural gas to R1 | D6: PJ, PJ/a | E6: NGAC1 | F6: NGA | G6: 2005 | H6: 55 | I6: 1 | J6: 1 | K6: =NGCap!B23*NGCap!$O$4*NGCap!$O$5*10^9 -> 228.88562
A7: R2 | B7: XNGAC2E | C7: Existing Pipeline for Import Canadian natural gas to R2 | E7: NGAC2 | F7: NGA | G7: 2005 | H7: 55 | I7: 1 | J7: 1 | K7: =NGCap!B24*NGCap!$O$4*NGCap!$O$5*10^9 -> 468.14854
A8: R4 | B8: XNGAC4E | C8: Existing Pipeline for Import Canadian natural gas to R4 | E8: NGAC4 | F8: NGA | G8: 2005 | H8: 55 | I8: 1 | J8: 1 | K8: =NGCap!B25*NGCap!$O$4*NGCap!$O$5*10^9 -> 2006.4115
A9: R8 | B9: XNGAC8E | C9: Existing Pipeline for Import Canadian natural gas to R8 | E9: NGAC8 | F9: NGA | G9: 2005 | H9: 55 | I9: 1 | J9: 1 | K9: =NGCap!B26*NGCap!$O$4*NGCap!$O$5*10^9 -> 35.754347
A10: R9 | B10: XNGAC9E | C10: Existing Pipeline for Import Canadian natural gas to R9 | E10: NGAC9 | F10: NGA | G10: 2005 | H10: 55 | I10: 1 | J10: 1 | K10: =NGCap!B27*NGCap!$O$4*NGCap!$O$5*10^9 -> 1121.7267
A11: R1 | B11: XNGAC1N | C11: New Pipeline for Import Canadian natural gas to R1 | E11: NGAC1 | F11: NGA | G11: 2005 | H11: 55 | I11: 1 | J11: 1 | W11: 4.2380354
A12: R2 | B12: XNGAC2N | C12: New Pipeline for Import Canadian natural gas to R2 | E12: NGAC2 | F12: NGA | G12: 2005 | H12: 55 | I12: 1 | J12: 1 | W12: 2.62137
A13: R4 | B13: XNGAC4N | C13: New Pipeline for Import Canadian natural gas to R4 | E13: NGAC4 | F13: NGA | G13: 2005 | H13: 55 | I13: 1 | J13: 1 | W13: 8.5091105
A14: R8 | B14: XNGAC8N | C14: New Pipeline for Import Canadian natural gas to R8 | E14: NGAC8 | F14: NGA | G14: 2005 | H14: 55 | I14: 1 | J14: 1 | W14: 7.9762289
A15: R9 | B15: XNGAC9N | C15: New Pipeline for Import Canadian natural gas to R9 | E15: NGAC9 | F15: NGA | G15: 2005 | H15: 55 | I15: 1 | J15: 1 | W15: 8.512558
A16: *
A17: R1 | B17: XNGALE1E | C17: Infrastructure for Import LNG to Existing terminal in R1 | E17: NGALE1 | F17: NGA | G17: 2005 | H17: 55 | I17: 1 | J17: 1 | K17: =NGCap!B125*NGCap!$O$4*NGCap!$O$5*10^12 -> 215.4755
A18: R5 | B18: XNGALE5E | C18: Infrastructure for Import LNG to Existing terminal in R5 | E18: NGALE5 | F18: NGA | G18: 2005 | H18: 55 | I18: 1 | J18: 1 | K18: =(NGCap!B126+NGCap!B127)*NGCap!$O$4*NGCap!$O$5*10^12 -> 660.43243
A19: R7 | B19: XNGALE7E | C19: Infrastructure for Import LNG to Existing terminal in R7 | E19: NGALE7 | F19: NGA | G19: 2005 | H19: 55 | I19: 1 | J19: 1 | K19: =(NGCap!B128+NGCap!B133)*NGCap!$O$4*NGCap!$O$5*10^12 -> 590.40288
A20: R1 | B20: XNGALE1N | C20: New Infrastructure for Import LNG to Existing terminal in R1 | E20: NGALE1 | F20: NGA | G20: 2005 | H20: 55 | I20: 1 | J20: 1 | W20: 4.4957141
A21: R5 | B21: XNGALE5N | C21: New Infrastructure for Import LNG to Existing terminal in R5 | E21: NGALE5 | F21: NGA | G21: 2005 | H21: 55 | I21: 1 | J21: 1 | W21: 4.4957141
A22: R7 | B22: XNGALE7N | C22: New Infrastructure for Import LNG to Existing terminal in R7 | E22: NGALE7 | F22: NGA | G22: 2005 | H22: 55 | I22: 1 | J22: 1 | W22: 4.4957141
A23: *
