Workbook

Sheet TFM_INS
B2: ~TFM_INS-TS
B3: Attribute | C3: CSET_CN | D3: Other_Indexes | E3: 2010 | F3: 2015 | G3: 2020
B4: VDA_EMCB | C4: LPGR | D4: REFNOX | E4: ='raw data'!U7 -> 0.015043976 | F4: ='raw data'!U24 -> 0.012121795 | G4: ='raw data'!U41 -> 0.0098775254
B5: VDA_EMCB | C5: GSCR | D5: REFNOX | E5: ='raw data'!U8 -> 0.021956426 | F5: ='raw data'!U25 -> 0.018229894 | G5: ='raw data'!U42 -> 0.015165813
B6: VDA_EMCB | C6: GSRR | D6: REFNOX | E6: ='raw data'!U9 -> 0.015839295 | F6: ='raw data'!U26 -> 0.012973181 | G6: ='raw data'!U43 -> 0.010654375
B7: VDA_EMCB | C7: JTFR | D7: REFNOX | E7: ='raw data'!U10 -> 0.0029131506 | F7: ='raw data'!U27 -> 0.0025959115 | G7: ='raw data'!U44 -> 0.0023130078
B8: VDA_EMCB | C8: DSHR | D8: REFNOX | E8: ='raw data'!U11 -> 0.0083160462 | F8: ='raw data'!U28 -> 0.007187393 | G8: ='raw data'!U45 -> 0.006182739
B9: VDA_EMCB | C9: RFLR | D9: REFNOX | E9: ='raw data'!U12 -> 0.0088888596 | F9: ='raw data'!U29 -> 0.0080016243 | G9: ='raw data'!U46 -> 0.0072117874
B10: VDA_EMCB | C10: RFHR | D10: REFNOX | E10: ='raw data'!U13 -> 0.0088888596 | F10: ='raw data'!U30 -> 0.0080016243 | G10: ='raw data'!U47 -> 0.0072117874
B11: VDA_EMCB | C11: KERR | D11: REFNOX | E11: ='raw data'!U14 -> 0.0029131506 | F11: ='raw data'!U31 -> 0.0025959115 | G11: ='raw data'!U48 -> 0.0023130078
B12: VDA_EMCB | C12: PFSR | D12: REFNOX | E12: ='raw data'!U15 -> 0.0083160462 | F12: ='raw data'!U32 -> 0.012973181 | G12: ='raw data'!U49 -> 0.010654375
B13: VDA_EMCB | C13: ASPR | D13: REFNOX | E13: ='raw data'!U16 -> 0.001810687 | F13: ='raw data'!U33 -> 0.0016301768 | G13: ='raw data'!U50 -> 0.001488222
B14: VDA_EMCB | C14: DSLR | D14: REFNOX | E14: ='raw data'!U17 -> 0.0083249264 | F14: ='raw data'!U34 -> 0.0071946939 | G14: ='raw data'!U51 -> 0.0061886896
B15: VDA_EMCB | C15: DSUR | D15: REFNOX | E15: ='raw data'!U18 -> 0.0083249264 | F15: ='raw data'!U35 -> 0.0071946939 | G15: ='raw data'!U52 -> 0.0061886896
B16: VDA_EMCB | C16: PTCR | D16: REFNOX | E16: ='raw data'!U19 -> 0.0048614015 | F16: ='raw data'!U36 -> 0.0043852209 | G16: ='raw data'!U53 -> 0.0039781364
B17: VDA_EMCB | C17: LPGR | D17: REFPM10 | E17: ='raw data'!V7 -> 0.0019239011 | F17: ='raw data'!V24 -> 0.0015144386 | G17: ='raw data'!V41 -> 0.0013561951
B18: VDA_EMCB | C18: GSCR | D18: REFPM10 | E18: ='raw data'!V8 -> 0.0029977952 | F18: ='raw data'!V25 -> 0.0024431779 | G18: ='raw data'!V42 -> 0.0022408423
B19: VDA_EMCB | C19: GSRR | D19: REFPM10 | E19: ='raw data'!V9 -> 0.0019070258 | F19: ='raw data'!V26 -> 0.0014928444 | G19: ='raw data'!V43 -> 0.0013365585
B20: VDA_EMCB | C20: JTFR | D20: REFPM10 | E20: ='raw data'!V10 -> 0.0004227423 | F20: ='raw data'!V27 -> 0.00035096749 | G20: ='raw data'!V44 -> 0.00032870032
B21: VDA_EMCB | C21: DSHR | D21: REFPM10 | E21: ='raw data'!V11 -> 0.00095797614 | F21: ='raw data'!V28 -> 0.00076387954 | G21: ='raw data'!V45 -> 0.00069744441
B22: VDA_EMCB | C22: RFLR | D22: REFPM10 | E22: ='raw data'!V12 -> 0.00095653566 | F22: ='raw data'!V29 -> 0.00084030061 | G22: ='raw data'!V46 -> 0.0007960363
B23: VDA_EMCB | C23: RFHR | D23: REFPM10 | E23: ='raw data'!V13 -> 0.00095653566 | F23: ='raw data'!V30 -> 0.00084030061 | G23: ='raw data'!V47 -> 0.0007960363
B24: VDA_EMCB | C24: KERR | D24: REFPM10 | E24: ='raw data'!V14 -> 0.0004227423 | F24: ='raw data'!V31 -> 0.00035096749 | G24: ='raw data'!V48 -> 0.00032870032
B25: VDA_EMCB | C25: PFSR | D25: REFPM10 | E25: ='raw data'!V15 -> 0.00095797614 | F25: ='raw data'!V32 -> 0.0014928444 | G25: ='raw data'!V49 -> 0.0013365585
B26: VDA_EMCB | C26: ASPR | D26: REFPM10 | E26: ='raw data'!V16 -> 0.00030987616 | F26: ='raw data'!V33 -> 0.00028378642 | G26: ='raw data'!V50 -> 0.00027398008
B27: VDA_EMCB | C27: DSLR | D27: REFPM10 | E27: ='raw data'!V17 -> 0.00095846382 | F27: ='raw data'!V34 -> 0.00076421482 | G27: ='raw data'!V51 -> 0.00069771495
B28: VDA_EMCB | C28: DSUR | D28: REFPM10 | E28: ='raw data'!V18 -> 0.00095846382 | F28: ='raw data'!V35 -> 0.00076421482 | G28: ='raw data'!V52 -> 0.00069771495
B29: VDA_EMCB | C29: PTCR | D29: REFPM10 | E29: ='raw data'!V19 -> 0.00076563532 | F29: ='raw data'!V36 -> 0.0006613301 | G29: ='raw data'!V53 -> 0.00062905078
B30: VDA_EMCB | C30: LPGR | D30: REFPM25 | E30: ='raw data'!W7 -> 0.0015851326 | F30: ='raw data'!W24 -> 0.0012764054 | G30: ='raw data'!W41 -> 0.0011573468
B31: VDA_EMCB | C31: GSCR | D31: REFPM25 | E31: ='raw data'!W8 -> 0.0019445182 | F31: ='raw data'!W25 -> 0.0015585773 | G31: ='raw data'!W42 -> 0.0014080622
B32: VDA_EMCB | C32: GSRR | D32: REFPM25 | E32: ='raw data'!W9 -> 0.0015728887 | F32: ='raw data'!W26 -> 0.0012584981 | G32: ='raw data'!W43 -> 0.0011408935
B33: VDA_EMCB | C33: JTFR | D33: REFPM25 | E33: ='raw data'!W10 -> 0.00034366918 | F33: ='raw data'!W27 -> 0.00029352348 | G33: ='raw data'!W44 -> 0.00027947837
B34: VDA_EMCB | C34: DSHR | D34: REFPM25 | E34: ='raw data'!W11 -> 0.00077453922 | F34: ='raw data'!W28 -> 0.00063418449 | G34: ='raw data'!W45 -> 0.0005881837
B35: VDA_EMCB | C35: RFLR | D35: REFPM25 | E35: ='raw data'!W12 -> 0.00082469307 | F35: ='raw data'!W29 -> 0.00073741694 | G35: ='raw data'!W46 -> 0.00070432113
B36: VDA_EMCB | C36: RFHR | D36: REFPM25 | E36: ='raw data'!W13 -> 0.00082469307 | F36: ='raw data'!W30 -> 0.00073741694 | G36: ='raw data'!W47 -> 0.00070432113
B37: VDA_EMCB | C37: KERR | D37: REFPM25 | E37: ='raw data'!W14 -> 0.00034366918 | F37: ='raw data'!W31 -> 0.00029352348 | G37: ='raw data'!W48 -> 0.00027947837
B38: VDA_EMCB | C38: PFSR | D38: REFPM25 | E38: ='raw data'!W15 -> 0.00077453922 | F38: ='raw data'!W32 -> 0.0012584981 | G38: ='raw data'!W49 -> 0.0011408935
B39: VDA_EMCB | C39: ASPR | D39: REFPM25 | E39: ='raw data'!W16 -> 0.00025019945 | F39: ='raw data'!W33 -> 0.00023027012 | G39: ='raw data'!W50 -> 0.00022283751
B40: VDA_EMCB | C40: DSLR | D40: REFPM25 | E40: ='raw data'!W17 -> 0.00077493995 | F40: ='raw data'!W34 -> 0.00063446478 | G40: ='raw data'!W51 -> 0.00058841127
B41: VDA_EMCB | C41: DSUR | D41: REFPM25 | E41: ='raw data'!W18 -> 0.00077493995 | F41: ='raw data'!W35 -> 0.00063446478 | G41: ='raw data'!W52 -> 0.00058841127
...

Sheet raw data
A4: * Values associate with commodities
R5: 2010
C6: LPGR | D6: GSCR | E6: GSRR | F6: JTFR | G6: DSHR | H6: RFLR | I6: RFHR | J6: KERR | K6: PFSR | L6: ASPR | M6: DSLR | N6: DSUR | O6: PTCR | S6: CommName | T6: * Units | U6: REFNOX | V6: REFPM10 | W6: REFPM25 | X6: REFSO2
B7: CommName | C7: LPGR~2010 | D7: GSCR~2010 | E7: GSRR~2010 | F7: JTFR~2010 | G7: DSHR~2010 | H7: RFLR~2010 | I7: RFHR~2010 | J7: KERR~2010 | K7: PFSR~2010 | L7: ASPR~2010 | M7: DSLR~2010 | N7: DSUR~2010 | O7: PTCR~2010 | R7: LPGR | S7: LPGR~2010 | T7: Kt/PJ | U7: 0.015043976 | V7: 0.0019239011 | W7: 0.0015851326 | X7: 0.0091222432
B8: * Units | C8: Kt/PJ | D8: Kt/PJ | E8: Kt/PJ | F8: Kt/PJ | G8: Kt/PJ | H8: Kt/PJ | I8: Kt/PJ | J8: Kt/PJ | K8: Kt/PJ | L8: Kt/PJ | M8: Kt/PJ | N8: Kt/PJ | O8: Kt/PJ | R8: GSCR | S8: GSCR~2010 | T8: Kt/PJ | U8: 0.021956426 | V8: 0.0029977952 | W8: 0.0019445182 | X8: 0.013755736
A9: 2010 | B9: REFNOX | C9: 0.015043976 | D9: 0.021956426 | E9: 0.015839295 | F9: 0.0029131506 | G9: 0.0083160462 | H9: 0.0088888596 | I9: 0.0088888596 | J9: 0.0029131506 | K9: 0.0083160462 | L9: 0.001810687 | M9: 0.0083249264 | N9: 0.0083249264 | O9: 0.0048614015 | R9: GSRR | S9: GSRR~2010 | T9: Kt/PJ | U9: 0.015839295 | V9: 0.0019070258 | W9: 0.0015728887 | X9: 0.00820494
A10: 2010 | B10: REFPM10 | C10: 0.0019239011 | D10: 0.0029977952 | E10: 0.0019070258 | F10: 0.0004227423 | G10: 0.00095797614 | H10: 0.00095653566 | I10: 0.00095653566 | J10: 0.0004227423 | K10: 0.00095797614 | L10: 0.00030987616 | M10: 0.00095846382 | N10: 0.00095846382 | O10: 0.00076563532 | R10: JTFR | S10: JTFR~2010 | T10: Kt/PJ | U10: 0.0029131506 | V10: 0.0004227423 | W10: 0.00034366918 | X10: 0.0017180413
A11: 2010 | B11: REFPM25 | C11: 0.0015851326 | D11: 0.0019445182 | E11: 0.0015728887 | F11: 0.00034366918 | G11: 0.00077453922 | H11: 0.00082469307 | I11: 0.00082469307 | J11: 0.00034366918 | K11: 0.00077453922 | L11: 0.00025019945 | M11: 0.00077493995 | N11: 0.00077493995 | O11: 0.00060144284 | R11: DSHR | S11: DSHR~2010 | T11: Kt/PJ | U11: 0.0083160462 | V11: 0.00095797614 | W11: 0.00077453922 | X11: 0.0040787919
A12: 2010 | B12: REFSO2 | C12: 0.0091222432 | D12: 0.013755736 | E12: 0.00820494 | F12: 0.0017180413 | G12: 0.0040787919 | H12: 0.0046552927 | I12: 0.0046552927 | J12: 0.0017180413 | K12: 0.0040787919 | L12: 0.00099865379 | M12: 0.0040808154 | N12: 0.0040808154 | O12: 0.002652554 | R12: RFLR | S12: RFLR~2010 | T12: Kt/PJ | U12: 0.0088888596 | V12: 0.00095653566 | W12: 0.00082469307 | X12: 0.0046552927
R13: RFHR | S13: RFHR~2010 | T13: Kt/PJ | U13: 0.0088888596 | V13: 0.00095653566 | W13: 0.00082469307 | X13: 0.0046552927
C14: LPGR | D14: GSCR | E14: GSRR | F14: JTFR | G14: DSHR | H14: RFLR | I14: RFHR | J14: KERR | K14: PFSR | L14: ASPR | M14: DSLR | N14: DSUR | O14: PTCR | R14: KERR | S14: KERR~2010 | T14: Kt/PJ | U14: 0.0029131506 | V14: 0.0004227423 | W14: 0.00034366918 | X14: 0.0017180413
B15: CommName | C15: LPGR~2015 | D15: GSCR~2015 | E15: GSRR~2015 | F15: JTFR~2015 | G15: DSHR~2015 | H15: RFLR~2015 | I15: RFHR~2015 | J15: KERR~2015 | K15: PFSR~2015 | L15: ASPR~2015 | M15: DSLR~2015 | N15: DSUR~2015 | O15: PTCR~2015 | R15: PFSR | S15: PFSR~2010 | T15: Kt/PJ | U15: 0.0083160462 | V15: 0.00095797614 | W15: 0.00077453922 | X15: 0.0040787919
B16: * Units | C16: Kt/PJ | D16: Kt/PJ | E16: Kt/PJ | F16: Kt/PJ | G16: Kt/PJ | H16: Kt/PJ | I16: Kt/PJ | J16: Kt/PJ | K16: Kt/PJ | L16: Kt/PJ | M16: Kt/PJ | N16: Kt/PJ | O16: Kt/PJ | R16: ASPR | S16: ASPR~2010 | T16: Kt/PJ | U16: 0.001810687 | V16: 0.00030987616 | W16: 0.00025019945 | X16: 0.00099865379
A17: 2015 | B17: REFNOX | C17: 0.012121795 | D17: 0.018229894 | E17: 0.012973181 | F17: 0.0025959115 | G17: 0.007187393 | H17: 0.0080016243 | I17: 0.0080016243 | J17: 0.0025959115 | K17: 0.012973181 | L17: 0.0016301768 | M17: 0.0071946939 | N17: 0.0071946939 | O17: 0.0043852209 | R17: DSLR | S17: DSLR~2010 | T17: Kt/PJ | U17: 0.0083249264 | V17: 0.00095846382 | W17: 0.00077493995 | X17: 0.0040808154
A18: 2015 | B18: REFPM10 | C18: 0.0015144386 | D18: 0.0024431779 | E18: 0.0014928444 | F18: 0.00035096749 | G18: 0.00076387954 | H18: 0.00084030061 | I18: 0.00084030061 | J18: 0.00035096749 | K18: 0.0014928444 | L18: 0.00028378642 | M18: 0.00076421482 | N18: 0.00076421482 | O18: 0.0006613301 | R18: DSUR | S18: DSUR~2010 | T18: Kt/PJ | U18: 0.0083249264 | V18: 0.00095846382 | W18: 0.00077493995 | X18: 0.0040808154
A19: 2015 | B19: REFPM25 | C19: 0.0012764054 | D19: 0.0015585773 | E19: 0.0012584981 | F19: 0.00029352348 | G19: 0.00063418449 | H19: 0.00073741694 | I19: 0.00073741694 | J19: 0.00029352348 | K19: 0.0012584981 | L19: 0.00023027012 | M19: 0.00063446478 | N19: 0.00063446478 | O19: 0.00052836117 | R19: PTCR | S19: PTCR~2010 | T19: Kt/PJ | U19: 0.0048614015 | V19: 0.00076563532 | W19: 0.00060144284 | X19: 0.002652554
A20: 2015 | B20: REFSO2 | C20: 0.0065313911 | D20: 0.01062858 | E20: 0.0056345631 | F20: 0.0012857598 | G20: 0.0029664139 | H20: 0.0040078093 | I20: 0.0040078093 | J20: 0.0012857598 | K20: 0.0056345631 | L20: 0.00082992154 | M20: 0.0029677964 | N20: 0.0029677964 | O20: 0.0020236359
C22: LPGR | D22: GSCR | E22: GSRR | F22: JTFR | G22: DSHR | H22: RFLR | I22: RFHR | J22: KERR | K22: PFSR | L22: ASPR | M22: DSLR | N22: DSUR | O22: PTCR | R22: 2015
B23: CommName | C23: LPGR~2020~2025~2030~2035~2040~2045~2050~2055 | D23: GSCR~2020~2025~2030~2035~2040~2045~2050~2055 | E23: GSRR~2020~2025~2030~2035~2040~2045~2050~2055 | F23: JTFR~2020~2025~2030~2035~2040~2045~2050~2055 | G23: DSHR~2020~2025~2030~2035~2040~2045~2050~2055 | H23: RFLR~2020~2025~2030~2035~2040~2045~2050~2055 | I23: RFHR~2020~2025~2030~2035~2040~2045~2050~2055 | J23: KERR~2020~2025~2030~2035~2040~2045~2050~2055 | K23: PFSR~2020~2025~2030~2035~2040~2045~2050~2055 | L23: ASPR~2020~2025~2030~2035~2040~2045~2050~2055 | M23: DSLR~2020~2025~2030~2035~2040~2045~2050~2055 | N23: DSUR~2020~2025~2030~2035~2040~2045~2050~2055 | O23: PTCR~2020~2025~2030~2035~2040~2045~2050~2055 | S23: CommName | T23: * Units | U23: REFNOX | V23: REFPM10 | W23: REFPM25 | X23: REFSO2
B24: * Units | C24: Kt/PJ | D24: Kt/PJ | E24: Kt/PJ | F24: Kt/PJ | G24: Kt/PJ | H24: Kt/PJ | I24: Kt/PJ | J24: Kt/PJ | K24: Kt/PJ | L24: Kt/PJ | M24: Kt/PJ | N24: Kt/PJ | O24: Kt/PJ | R24: LPGR | S24: LPGR~2015 | T24: Kt/PJ | U24: 0.012121795 | V24: 0.0015144386 | W24: 0.0012764054 | X24: 0.0065313911
A25: 2020 | B25: REFNOX | C25: 0.0098775254 | D25: 0.015165813 | E25: 0.010654375 | F25: 0.0023130078 | G25: 0.006182739 | H25: 0.0072117874 | I25: 0.0072117874 | J25: 0.0023130078 | K25: 0.010654375 | L25: 0.001488222 | M25: 0.0061886896 | N25: 0.0061886896 | O25: 0.0039781364 | R25: GSCR | S25: GSCR~2015 | T25: Kt/PJ | U25: 0.018229894 | V25: 0.0024431779 | W25: 0.0015585773 | X25: 0.01062858
A26: 2020 | B26: REFPM10 | C26: 0.0013561951 | D26: 0.0022408423 | E26: 0.0013365585 | F26: 0.00032870032 | G26: 0.00069744441 | H26: 0.0007960363 | I26: 0.0007960363 | J26: 0.00032870032 | K26: 0.0013365585 | L26: 0.00027398008 | M26: 0.00069771495 | N26: 0.00069771495 | O26: 0.00062905078 | R26: GSRR | S26: GSRR~2015 | T26: Kt/PJ | U26: 0.012973181 | V26: 0.0014928444 | W26: 0.0012584981 | X26: 0.0056345631
A27: 2020 | B27: REFPM25 | C27: 0.0011573468 | D27: 0.0014080622 | E27: 0.0011408935 | F27: 0.00027947837 | G27: 0.0005881837 | H27: 0.00070432113 | I27: 0.00070432113 | J27: 0.00027947837 | K27: 0.0011408935 | L27: 0.00022283751 | M27: 0.00058841127 | N27: 0.00058841127 | O27: 0.00050801295 | R27: JTFR | S27: JTFR~2015 | T27: Kt/PJ | U27: 0.0025959115 | V27: 0.00035096749 | W27: 0.00029352348 | X27: 0.0012857598
A28: 2020 | B28: REFSO2 | C28: 0.0049282483 | D28: 0.0076866905 | E28: 0.0040579207 | F28: 0.0010061995 | G28: 0.0022650893 | H28: 0.0036071232 | I28: 0.0036071232 | J28: 0.0010061995 | K28: 0.0040579207 | L28: 0.00072742261 | M28: 0.0022661157 | N28: 0.0022661157 | O28: 0.0016159339 | R28: DSHR | S28: DSHR~2015 | T28: Kt/PJ | U28: 0.007187393 | V28: 0.00076387954 | W28: 0.00063418449 | X28: 0.0029664139
R29: RFLR | S29: RFLR~2015 | T29: Kt/PJ | U29: 0.0080016243 | V29: 0.00084030061 | W29: 0.00073741694 | X29: 0.0040078093
R30: RFHR | S30: RFHR~2015 | T30: Kt/PJ | U30: 0.0080016243 | V30: 0.00084030061 | W30: 0.00073741694 | X30: 0.0040078093
R31: KERR | S31: KERR~2015 | T31: Kt/PJ | U31: 0.0025959115 | V31: 0.00035096749 | W31: 0.00029352348 | X31: 0.0012857598
R32: PFSR | S32: PFSR~2015 | T32: Kt/PJ | U32: 0.012973181 | V32: 0.0014928444 | W32: 0.0012584981 | X32: 0.0056345631
I33: 2010 | J33: 2015 | K33: 2020+ | L33: 2010 | M33: 2015 | N33: 2020+ | O33: 2010 | P33: 2015 | Q33: 2020+ | R33: ASPR | S33: ASPR~2015 | T33: Kt/PJ | U33: 0.0016301768 | V33: 0.00028378642 | W33: 0.00023027012 | X33: 0.00082992154
D34: VOC | E34: CO | F34: CH4 | G34: N2O | H34: CO2 | I34: NOX | J34: NOX | K34: NOX | L34: PM10 | M34: PM10 | N34: PM10 | O34: PM25 | P34: PM25 | Q34: PM25 | R34: DSLR | S34: DSLR~2015 | T34: Kt/PJ | U34: 0.0071946939 | V34: 0.00076421482 | W34: 0.00063446478 | X34: 0.0029677964
C35: DLG | D35: #REF! | E35: #REF! | F35: #REF! | G35: #REF! | H35: #REF! | I35: 0.015839295 | J35: 0.012973181 | K35: 0.010654375 | L35: 0.0019070258 | M35: 0.0014928444 | N35: 0.0013365585 | O35: 0.0015728887 | P35: =E19 -> 0.0012584981 | Q35: =E27 -> 0.0011408935 | R35: DSUR | S35: DSUR~2015 | T35: Kt/PJ | U35: 0.0071946939 | V35: 0.00076421482 | W35: 0.00063446478 | X35: 0.0029677964
R36: PTCR | S36: PTCR~2015 | T36: Kt/PJ | U36: 0.0043852209 | V36: 0.0006613301 | W36: 0.00052836117 | X36: 0.0020236359
R39: 2020
S40: CommName | T40: * Units | U40: REFNOX | V40: REFPM10 | W40: REFPM25 | X40: REFSO2
R41: LPGR | S41: LPGR~2020~2025~2030~2035~2040~2045~2050~2055 | T41: Kt/PJ | U41: 0.0098775254 | V41: 0.0013561951 | W41: 0.0011573468 | X41: 0.0049282483
R42: GSCR | S42: GSCR~2020~2025~2030~2035~2040~2045~2050~2055 | T42: Kt/PJ | U42: 0.015165813 | V42: 0.0022408423 | W42: 0.0014080622 | X42: 0.0076866905
R43: GSRR | S43: GSRR~2020~2025~2030~2035~2040~2045~2050~2055 | T43: Kt/PJ | U43: 0.010654375 | V43: 0.0013365585 | W43: 0.0011408935 | X43: 0.0040579207
R44: JTFR | S44: JTFR~2020~2025~2030~2035~2040~2045~2050~2055 | T44: Kt/PJ | U44: 0.0023130078 | V44: 0.00032870032 | W44: 0.00027947837 | X44: 0.0010061995
R45: DSHR | S45: DSHR~2020~2025~2030~2035~2040~2045~2050~2055 | T45: Kt/PJ | U45: 0.006182739 | V45: 0.00069744441 | W45: 0.0005881837 | X45: 0.0022650893
R46: RFLR | S46: RFLR~2020~2025~2030~2035~2040~2045~2050~2055 | T46: Kt/PJ | U46: 0.0072117874 | V46: 0.0007960363 | W46: 0.00070432113 | X46: 0.0036071232
...
