Workbook

Sheet Home
C3: v16.1.0 was created from EPAUS9r_TRNHDV_v16.1.0_05 ConstrData tab

Sheet HDV_share_national
B2: UC - Each Region/Period | D2: Share of a group of processes within a market (see attribute FLO_MARK if you want to constrain the market share of a single process)
C3: ~UC_Sets: R_E: AllRegions
C4: ~UC_Sets: T_E:
K5: ~UC_T
C6: UC_N | D6: Pset_Set | E6: Pset_PN | F6: Pset_CI | G6: Pset_CO | H6: Cset_CN | I6: Attribute | J6: Year | K6: LimType | L6: UC_FLO | M6: UC_COMPRD | N6: UC_RHSRT | O6: UC_RHSRT~0 | P6: UC_Desc
C7: UC_S_TCGSL | E7: TCGSL* | G7: TC | H7: TC | J7: 2011 | K7: LO | L7: 1 | M7: =-'AEO20 data'!N51*0.98 -> -0.58772409 | N7: 0 | O7: 5 | P7: HDV-Commercial Truck-GSL
C8: UC_S_TCGSL | E8: TCGSL* | G8: TC | H8: TC | J8: 2015 | K8: LO | L8: 1 | M8: =-'AEO20 data'!O51*0.98 -> -0.52774968 | N8: 0 | O8: 5 | P8: HDV-Commercial Truck-GSL
C9: UC_S_TCGSL | E9: TCGSL* | G9: TC | H9: TC | J9: 2020 | K9: LO | L9: 1 | M9: =-'AEO20 data'!P51 -> -0.37934834 | N9: 0 | O9: 5 | P9: HDV-Commercial Truck-GSL
C10: UC_S_TCGSL | E10: TCGSL* | G10: TC | H10: TC | J10: 2030 | K10: LO | L10: 1 | M10: 0 | N10: 0 | O10: 5 | P10: HDV-Commercial Truck-GSL
C11: UC_S_TCGSL | E11: TCGSL* | G11: TC | H11: TC | J11: 2050 | K11: LO | L11: 1 | M11: 0 | N11: 0 | O11: 5 | P11: HDV-Commercial Truck-GSL
C12: UC_S_TCGSL | E12: TCGSL* | G12: TC | H12: TC | J12: 2080 | K12: LO | L12: 1 | M12: 0 | N12: 0 | O12: 5 | P12: HDV-Commercial Truck-GSL
C13: UC_S_TCDSL | E13: TCDSL* | G13: TC | H13: TC | J13: 2011 | K13: LO | L13: 1 | M13: =-'AEO20 data'!N52*0.98 -> -0.39227591 | N13: 0 | O13: 5 | P13: HDV-Commercial Truck-DSL
C14: UC_S_TCDSL | E14: TCDSL* | G14: TC | H14: TC | J14: 2015 | K14: LO | L14: 1 | M14: =-'AEO20 data'!O52*0.98 -> -0.34415217 | N14: 0 | O14: 5 | P14: HDV-Commercial Truck-DSL
C15: UC_S_TCDSL | E15: TCDSL* | G15: TC | H15: TC | J15: 2020 | K15: LO | L15: 1 | M15: =-'AEO20 data'!P52*0.98 -> -0.36481295 | N15: 0 | O15: 5 | P15: HDV-Commercial Truck-DSL
C16: UC_S_TCDSL | E16: TCDSL* | G16: TC | H16: TC | J16: 2030 | K16: LO | L16: 1 | M16: 0 | N16: 0 | O16: 5 | P16: HDV-Commercial Truck-DSL
C17: UC_S_TCDSL | E17: TCDSL* | G17: TC | H17: TC | J17: 2050 | K17: LO | L17: 1 | M17: 0 | N17: 0 | O17: 5 | P17: HDV-Commercial Truck-DSL
C18: UC_S_TCDSL | E18: TCDSL* | G18: TC | H18: TC | J18: 2080 | K18: LO | L18: 1 | M18: 0 | N18: 0 | O18: 5 | P18: HDV-Commercial Truck-DSL
C19: UC_S_TCLPG | E19: TCLPG* | G19: TC | H19: TC | J19: 2020 | K19: LO | L19: 1 | M19: =-'AEO20 data'!P53*0.98 -> -0.00029434175 | N19: 0 | O19: 5 | P19: HDV-Commercial Truck-LPG
C20: UC_S_TCLPG | E20: TCLPG* | G20: TC | H20: TC | J20: 2030 | K20: LO | L20: 1 | M20: 0 | N20: 0 | O20: 5 | P20: HDV-Commercial Truck-LPG
C21: UC_S_TCLPG | E21: TCLPG* | G21: TC | H21: TC | J21: 2050 | K21: LO | L21: 1 | M21: 0 | N21: 0 | O21: 5 | P21: HDV-Commercial Truck-LPG
C22: UC_S_TCLPG | E22: TCLPG* | G22: TC | H22: TC | J22: 2080 | K22: LO | L22: 1 | M22: 0 | N22: 0 | O22: 5 | P22: HDV-Commercial Truck-LPG
C23: UC_S_TCCNG | E23: TCCNG* | G23: TC | H23: TC | J23: 2015 | K23: LO | L23: 1 | M23: =-'AEO20 data'!O54*0.98 -> -0.0013862036 | N23: 0 | O23: 5 | P23: HDV-Commercial Truck-CNG
C24: UC_S_TCCNG | E24: TCCNG* | G24: TC | H24: TC | J24: 2020 | K24: LO | L24: 1 | M24: =-'AEO20 data'!P54*0.98 -> -0.00084685763 | N24: 0 | O24: 5 | P24: HDV-Commercial Truck-CNG
C25: UC_S_TCCNG | E25: TCCNG* | G25: TC | H25: TC | J25: 2030 | K25: LO | L25: 1 | M25: 0 | N25: 0 | O25: 5 | P25: HDV-Commercial Truck-CNG
C26: UC_S_TCCNG | E26: TCCNG* | G26: TC | H26: TC | J26: 2050 | K26: LO | L26: 1 | M26: 0 | N26: 0 | O26: 5 | P26: HDV-Commercial Truck-CNG
C27: UC_S_TCCNG | E27: TCCNG* | G27: TC | H27: TC | J27: 2080 | K27: LO | L27: 1 | M27: 0 | N27: 0 | O27: 5 | P27: HDV-Commercial Truck-CNG
C28: UC_S_TCE85 | E28: TCE85* | G28: TC | H28: TC | J28: 2015 | K28: LO | L28: 1 | M28: =-'AEO20 data'!O55 -> -0.10888818 | N28: 0 | O28: 5 | P28: HDV-Commercial Truck-E85
C29: UC_S_TCE85 | E29: TCE85* | G29: TC | H29: TC | J29: 2020 | K29: LO | L29: 1 | M29: =-'AEO20 data'!P55 -> -0.24677468 | N29: 0 | O29: 5 | P29: HDV-Commercial Truck-E85
C30: UC_S_TCE85 | E30: TCE85* | G30: TC | H30: TC | J30: 2030 | K30: LO | L30: 1 | M30: 0 | N30: 0 | O30: 5 | P30: HDV-Commercial Truck-E85
C31: UC_S_TCE85 | E31: TCE85* | G31: TC | H31: TC | J31: 2050 | K31: LO | L31: 1 | M31: 0 | N31: 0 | O31: 5 | P31: HDV-Commercial Truck-E85
C32: UC_S_TCE85 | E32: TCE85* | G32: TC | H32: TC | J32: 2080 | K32: LO | L32: 1 | M32: 0 | N32: 0 | O32: 5 | P32: HDV-Commercial Truck-E85
C33: UC_S_TCELC | E33: TCELC | G33: TC | H33: TC | J33: 2020 | K33: LO | L33: 1 | M33: =-'AEO20 data'!P56 -> -0.00014272943 | N33: 0 | O33: 5 | P33: HDV-Commercial Truck-ELC
C34: UC_S_TCELC | E34: TCELC | G34: TC | H34: TC | J34: 2030 | K34: LO | L34: 1 | M34: 0 | N34: 0 | O34: 5 | P34: HDV-Commercial Truck-ELC
C35: UC_S_TCELC | E35: TCELC | G35: TC | H35: TC | J35: 2050 | K35: LO | L35: 1 | M35: 0 | N35: 0 | O35: 5 | P35: HDV-Commercial Truck-ELC
C36: UC_S_TCELC | E36: TCELC | G36: TC | H36: TC | J36: 2080 | K36: LO | L36: 1 | M36: 0 | N36: 0 | O36: 5 | P36: HDV-Commercial Truck-ELC
C37: UC_S_TCDHEV | E37: TCDHEV | G37: TC | H37: TC | J37: 2025 | K37: LO | L37: 1 | M37: =-'AEO20 data'!P58 -> -0.00015658279 | N37: 0 | O37: 5 | P37: HDV-Commercial Truck-HEV
C38: UC_S_TCDHEV | E38: TCDHEV | G38: TC | H38: TC | J38: 2030 | K38: LO | L38: 1 | M38: 0 | N38: 0 | O38: 5 | P38: HDV-Commercial Truck-HEV
C39: UC_S_TCDHEV | E39: TCDHEV | G39: TC | H39: TC | J39: 2050 | K39: LO | L39: 1 | M39: 0 | N39: 0 | O39: 5 | P39: HDV-Commercial Truck-HEV
C40: UC_S_TCDHEV | E40: TCDHEV | G40: TC | H40: TC | J40: 2080 | K40: LO | L40: 1 | M40: 0 | N40: 0 | O40: 5 | P40: HDV-Commercial Truck-HEV
C41: UC_S_TMDSL | E41: TMDSL* | G41: TM | H41: TM | J41: 2011 | K41: LO | L41: 1 | M41: =-'AEO20 data'!N10 -> -0.71918841 | N41: 0 | O41: 5 | P41: HDV-Medium Truck-DSL
...

Sheet HDV_share_regional
B2: UC - Each Region/Period | D2: Share of a group of processes within a market (see attribute FLO_MARK if you want to constrain the market share of a single process)
C3: ~UC_Sets: R_E: AllRegions
C4: ~UC_Sets: T_E:
K5: ~UC_T
C6: UC_N | D6: Pset_Set | E6: Pset_PN | F6: Pset_CI | G6: Pset_CO | H6: Cset_CN | I6: Year | J6: Region | K6: LimType | L6: UC_FLO | M6: UC_COMPRD | N6: UC_RHSRT | O6: UC_RHSRT~0 | P6: UC_Desc
C7: UC_S_TRPCR | E7: TPDSLCR,TPELCCR | G7: TRP | H7: =G$7 -> TRP | I7: 2010 | J7: R1 | K7: LO | L7: 1 | M7: =ConstrData!S17+(ConstrData!AC17-ConstrData!S17)/10 -> -0.272 | N7: 0 | O7: 5 | P7: =ConstrData!C17 -> Transportation Rail - Commuter
C8: UC_S_TRPCR | E8: TPDSLCR,TPELCCR | G8: TRP | H8: =G$7 -> TRP | I8: 2055 | J8: R1 | K8: LO | L8: 1 | M8: =ConstrData!AC17 -> -0.272 | N8: 0 | P8: =P7 -> Transportation Rail - Commuter
C9: UC_S_TRPCR | E9: TPDSLCR,TPELCCR | G9: TRP | H9: =G$7 -> TRP | I9: 2010 | J9: R2 | K9: LO | L9: 1 | M9: =ConstrData!T17+(ConstrData!AD17-ConstrData!T17)/10 -> -0.2576 | N9: 0 | O9: 5 | P9: =P8 -> Transportation Rail - Commuter
C10: UC_S_TRPCR | E10: TPDSLCR,TPELCCR | G10: TRP | H10: =G$7 -> TRP | I10: 2055 | J10: R2 | K10: LO | L10: 1 | M10: =ConstrData!AD17 -> -0.2576 | N10: 0 | P10: =P9 -> Transportation Rail - Commuter
C11: UC_S_TRPCR | E11: TPDSLCR,TPELCCR | G11: TRP | H11: =G$7 -> TRP | I11: 2010 | J11: R3 | K11: LO | L11: 1 | M11: =ConstrData!U17+(ConstrData!AE17-ConstrData!U17)/10 -> -0.4273 | N11: 0 | O11: 5 | P11: =P10 -> Transportation Rail - Commuter
C12: UC_S_TRPCR | E12: TPDSLCR,TPELCCR | G12: TRP | H12: =G$7 -> TRP | I12: 2055 | J12: R3 | K12: LO | L12: 1 | M12: =ConstrData!AE17 -> -0.4273 | N12: 0 | P12: =P11 -> Transportation Rail - Commuter
C13: UC_S_TRPCR | E13: TPDSLCR,TPELCCR | G13: TRP | H13: =G$7 -> TRP | I13: 2010 | J13: R4 | K13: LO | L13: 1 | M13: =ConstrData!V17+(ConstrData!AF17-ConstrData!V17)/10 -> 0 | N13: 0 | O13: 5 | P13: =P12 -> Transportation Rail - Commuter
C14: UC_S_TRPCR | E14: TPDSLCR,TPELCCR | G14: TRP | H14: =G$7 -> TRP | I14: 2055 | J14: R4 | K14: LO | L14: 1 | M14: =ConstrData!AF17 -> 0 | N14: 0 | P14: =P13 -> Transportation Rail - Commuter
C15: UC_S_TRPCR | E15: TPDSLCR,TPELCCR | G15: TRP | H15: =G$7 -> TRP | I15: 2010 | J15: R5 | K15: LO | L15: 1 | M15: =ConstrData!W17+(ConstrData!AG17-ConstrData!W17)/10 -> -0.0672 | N15: 0 | O15: 5 | P15: =P14 -> Transportation Rail - Commuter
C16: UC_S_TRPCR | E16: TPDSLCR,TPELCCR | G16: TRP | H16: =G$7 -> TRP | I16: 2055 | J16: R5 | K16: LO | L16: 1 | M16: =ConstrData!AG17 -> -0.0672 | N16: 0 | P16: =P15 -> Transportation Rail - Commuter
C17: UC_S_TRPCR | E17: TPDSLCR,TPELCCR | G17: TRP | H17: =G$7 -> TRP | I17: 2010 | J17: R6 | K17: LO | L17: 1 | M17: =ConstrData!X17+(ConstrData!AH17-ConstrData!X17)/10 -> 0 | N17: 0 | O17: 5 | P17: =P16 -> Transportation Rail - Commuter
C18: UC_S_TRPCR | E18: TPDSLCR,TPELCCR | G18: TRP | H18: =G$7 -> TRP | I18: 2055 | J18: R6 | K18: LO | L18: 1 | M18: =ConstrData!AH17 -> 0 | N18: 0 | P18: =P17 -> Transportation Rail - Commuter
C19: UC_S_TRPCR | E19: TPDSLCR,TPELCCR | G19: TRP | H19: =G$7 -> TRP | I19: 2010 | J19: R7 | K19: LO | L19: 1 | M19: =ConstrData!Y17+(ConstrData!AI17-ConstrData!Y17)/10 -> -0.1147 | N19: 0 | O19: 5 | P19: =P18 -> Transportation Rail - Commuter
C20: UC_S_TRPCR | E20: TPDSLCR,TPELCCR | G20: TRP | H20: =G$7 -> TRP | I20: 2055 | J20: R7 | K20: LO | L20: 1 | M20: =ConstrData!AI17 -> -0.1147 | N20: 0 | P20: =P19 -> Transportation Rail - Commuter
C21: UC_S_TRPCR | E21: TPDSLCR,TPELCCR | G21: TRP | H21: =G$7 -> TRP | I21: 2010 | J21: R8 | K21: LO | L21: 1 | M21: =ConstrData!Z17+(ConstrData!AJ17-ConstrData!Z17)/10 -> 0 | N21: 0 | O21: 5 | P21: =P20 -> Transportation Rail - Commuter
C22: UC_S_TRPCR | E22: TPDSLCR,TPELCCR | G22: TRP | H22: =G$7 -> TRP | I22: 2055 | J22: R8 | K22: LO | L22: 1 | M22: =ConstrData!AJ17 -> 0 | N22: 0 | P22: =P21 -> Transportation Rail - Commuter
C23: UC_S_TRPCR | E23: TPDSLCR,TPELCCR | G23: TRP | H23: =G$7 -> TRP | I23: 2010 | J23: R9 | K23: LO | L23: 1 | M23: =ConstrData!AA17+(ConstrData!AK17-ConstrData!AA17)/10 -> -0.11 | N23: 0 | O23: 5 | P23: =P22 -> Transportation Rail - Commuter
C24: UC_S_TRPCR | E24: TPDSLCR,TPELCCR | G24: TRP | H24: =G$7 -> TRP | I24: 2055 | J24: R9 | K24: LO | L24: 1 | M24: =ConstrData!AK17 -> -0.11 | N24: 0 | P24: =P23 -> Transportation Rail - Commuter
C25: UC_S_TRPSUB | E25: TPELCSUB | G25: TRP | H25: =G$7 -> TRP | I25: 2010 | J25: R1 | K25: LO | L25: 1 | M25: =ConstrData!S19+(ConstrData!AC19-ConstrData!S19)/10 -> -0.4544 | N25: 0 | O25: 5 | P25: =ConstrData!C19 -> Transportation Rail - Subways and Streetcars
C26: UC_S_TRPSUB | E26: TPELCSUB | G26: TRP | H26: =G$7 -> TRP | I26: 2055 | J26: R1 | K26: LO | L26: 1 | M26: =ConstrData!AC19 -> -0.4544 | N26: 0 | P26: =P25 -> Transportation Rail - Subways and Streetcars
C27: UC_S_TRPSUB | E27: TPELCSUB | G27: TRP | H27: =G$7 -> TRP | I27: 2010 | J27: R2 | K27: LO | L27: 1 | M27: =ConstrData!T19+(ConstrData!AD19-ConstrData!T19)/10 -> -0.6055 | N27: 0 | O27: 5 | P27: =P26 -> Transportation Rail - Subways and Streetcars
C28: UC_S_TRPSUB | E28: TPELCSUB | G28: TRP | H28: =G$7 -> TRP | I28: 2055 | J28: R2 | K28: LO | L28: 1 | M28: =ConstrData!AD19 -> -0.6055 | N28: 0 | P28: =P27 -> Transportation Rail - Subways and Streetcars
C29: UC_S_TRPSUB | E29: TPELCSUB | G29: TRP | H29: =G$7 -> TRP | I29: 2010 | J29: R3 | K29: LO | L29: 1 | M29: =ConstrData!U19+(ConstrData!AE19-ConstrData!U19)/10 -> -0.3685 | N29: 0 | O29: 5 | P29: =P28 -> Transportation Rail - Subways and Streetcars
C30: UC_S_TRPSUB | E30: TPELCSUB | G30: TRP | H30: =G$7 -> TRP | I30: 2055 | J30: R3 | K30: LO | L30: 1 | M30: =ConstrData!AE19 -> -0.3685 | N30: 0 | P30: =P29 -> Transportation Rail - Subways and Streetcars
C31: UC_S_TRPSUB | E31: TPELCSUB | G31: TRP | H31: =G$7 -> TRP | I31: 2010 | J31: R4 | K31: LO | L31: 1 | M31: =ConstrData!V19+(ConstrData!AF19-ConstrData!V19)/10 -> -0.3349 | N31: 0 | O31: 5 | P31: =P30 -> Transportation Rail - Subways and Streetcars
C32: UC_S_TRPSUB | E32: TPELCSUB | G32: TRP | H32: =G$7 -> TRP | I32: 2055 | J32: R4 | K32: LO | L32: 1 | M32: =ConstrData!AF19 -> -0.3349 | N32: 0 | P32: =P31 -> Transportation Rail - Subways and Streetcars
C33: UC_S_TRPSUB | E33: TPELCSUB | G33: TRP | H33: =G$7 -> TRP | I33: 2010 | J33: R5 | K33: LO | L33: 1 | M33: =ConstrData!W19+(ConstrData!AG19-ConstrData!W19)/10 -> -0.5883 | N33: 0 | O33: 5 | P33: =P32 -> Transportation Rail - Subways and Streetcars
C34: UC_S_TRPSUB | E34: TPELCSUB | G34: TRP | H34: =G$7 -> TRP | I34: 2055 | J34: R5 | K34: LO | L34: 1 | M34: =ConstrData!AG19 -> -0.5883 | N34: 0 | P34: =P33 -> Transportation Rail - Subways and Streetcars
C35: UC_S_TRPSUB | E35: TPELCSUB | G35: TRP | H35: =G$7 -> TRP | I35: 2010 | J35: R6 | K35: LO | L35: 1 | M35: =ConstrData!X19+(ConstrData!AH19-ConstrData!X19)/10 -> -0.0242 | N35: 0 | O35: 5 | P35: =P34 -> Transportation Rail - Subways and Streetcars
C36: UC_S_TRPSUB | E36: TPELCSUB | G36: TRP | H36: =G$7 -> TRP | I36: 2055 | J36: R6 | K36: LO | L36: 1 | M36: =ConstrData!AH19 -> -0.0242 | N36: 0 | P36: =P35 -> Transportation Rail - Subways and Streetcars
C37: UC_S_TRPSUB | E37: TPELCSUB | G37: TRP | H37: =G$7 -> TRP | I37: 2010 | J37: R7 | K37: LO | L37: 1 | M37: =ConstrData!Y19+(ConstrData!AI19-ConstrData!Y19)/10 -> -0.357 | N37: 0 | O37: 5 | P37: =P36 -> Transportation Rail - Subways and Streetcars
C38: UC_S_TRPSUB | E38: TPELCSUB | G38: TRP | H38: =G$7 -> TRP | I38: 2055 | J38: R7 | K38: LO | L38: 1 | M38: =ConstrData!AI19 -> -0.357 | N38: 0 | P38: =P37 -> Transportation Rail - Subways and Streetcars
C39: UC_S_TRPSUB | E39: TPELCSUB | G39: TRP | H39: =G$7 -> TRP | I39: 2010 | J39: R8 | K39: LO | L39: 1 | M39: =ConstrData!Z19+(ConstrData!AJ19-ConstrData!Z19)/10 -> -0.3758 | N39: 0 | O39: 5 | P39: =P38 -> Transportation Rail - Subways and Streetcars
C40: UC_S_TRPSUB | E40: TPELCSUB | G40: TRP | H40: =G$7 -> TRP | I40: 2055 | J40: R8 | K40: LO | L40: 1 | M40: =ConstrData!AJ19 -> -0.3758 | N40: 0 | P40: =P39 -> Transportation Rail - Subways and Streetcars
C41: UC_S_TRPSUB | E41: TPELCSUB | G41: TRP | H41: =G$7 -> TRP | I41: 2010 | J41: R9 | K41: LO | L41: 1 | M41: =ConstrData!AA19+(ConstrData!AK19-ConstrData!AA19)/10 -> -0.4377 | N41: 0 | O41: 5 | P41: =P40 -> Transportation Rail - Subways and Streetcars
...

Sheet AEO20 data
B1: This worksheet contains data from AEO tables which are used to establish national demands and some constraint data.
E3: * Start of 2020 AEO Data | AM3: 2008-
B4: 2010 | C4: 2011 | D4: 2015 | E4: 2020 | F4: 2025 | G4: 2030 | H4: 2035 | I4: 2040 | J4: 2045 | K4: 2050
A6: 49. Freight Transportation Energy Use
A8: Vehicle Miles Traveled (billion miles)
A9: Light Medium | M9: % | N9: 2011 | O9: 2015 | P9: 2020 | Q9: 2025
A10: Diesel | B10: 34.570259 | C10: 35.094997 | D10: 37.718689 | E10: 45.579323 | F10: 49.203506 | G10: 52.507008 | H10: 56.425732 | I10: 59.236855 | J10: 61.204712 | K10: 63.422764 | M10: =(B10+B21)/($B$19+$B$30) -> 0.73412141 | N10: =(C10+C21)/($C$19+$C$30)*0.98 -> 0.71918841 | O10: =(D10+D21)/($D$19+$D$30)*0.98 -> 0.68217876 | P10: =(E10+E21)/($E$19+$E$30)*0.98 -> 0.69451908 | R10: TMDSL*
A11: Motor Gasoline | B11: 9.9136826 | C11: 10.398741 | D11: 12.824033 | E11: 13.030306 | F11: 14.483568 | G11: 16.345461 | H11: 19.073824 | I11: 22.008989 | J11: 24.690767 | K11: 27.608847 | M11: =(B11+B22)/($B$19+$B$30) -> 0.25777127 | N11: =(C11+C22)/($C$19+$C$30)*0.98 -> 0.25311531 | O11: =(D11+D22)/($D$19+$D$30)*0.98 -> 0.26898725 | P11: =(E11+E22)/($E$19+$E$30)*0.98 -> 0.2454913 | R11: TMGSL*
A12: Propane | B12: 0 | C12: 0 | D12: 0.001896 | E12: 0.015478 | F12: 0.03619 | G12: 0.056956 | H12: 0.080747 | I12: 0.107873 | J12: 0.138169 | K12: 0.177141 | M12: =(B12+B23)/($B$19+$B$30) -> 0.0038743676 | N12: =(C12+C23)/($C$19+$C$30)*0.98 -> 0.0037649771 | O12: =(D12+D23)/($D$19+$D$30)*0.98 -> 0.00015215497 | P12: =(E12+E23)/($E$19+$E$30)*0.98 -> 0.00061544013 | R12: TMLPG*
A13: Compressed/Liquefied Natural Gas | B13: 0 | C13: 0 | D13: 0 | E13: 0.009248 | F13: 0.020767 | G13: 0.03014 | H13: 0.039713 | I13: 0.052462 | J13: 0.072901 | K13: 0.111553 | M13: =(B13+B24)/($B$19+$B$30) -> 0.0043818442 | N13: =(C13+C24)/($C$19+$C$30)*0.98 -> 0.0040453834 | O13: =(D13+D24)/($D$19+$D$30)*0.98 -> 0.00042285429 | P13: =(E13+E24)/($E$19+$E$30)*0.98 -> 0.00061948907 | R13: TMCNG*
A14: Ethanol-Flex Fuel | B14: 0 | C14: 0 | D14: 2.614672 | E14: 4.008557 | F14: 5.359395 | G14: 6.944709 | H14: 9.014732 | I14: 11.404234 | J14: 14.487895 | K14: 18.551462 | O14: =(D14+D25)/($D$19+$D$30)*0.98 -> 0.028244246 | P14: =(E14+E25)/($E$19+$E$30)*0.98 -> 0.038409259 | R14: TME85
A15: Electric | B15: 0 | C15: 0 | D15: 0.001614 | E15: 0.006334 | F15: 0.034109 | G15: 0.063562 | H15: 0.095546 | I15: 0.132967 | J15: 0.175099 | K15: 0.225251 | O15: =(D15+D26)/($D$19+$D$30)*0.98 -> 1.5093923e-05 | P15: =(E15+E26)/($E$19+$E$30)*0.98 -> 9.5560197e-05 | R15: TMELC
A16: Plug-in Diesel Hybrid | B16: 0 | C16: 0 | D16: 0 | E16: 0.005774 | F16: 0.036742 | G16: 0.069341 | H16: 0.104876 | I16: 0.146234 | J16: 0.192647 | K16: 0.247881 | P16: =(E16+E27)/($E$19+$E$30)*0.98 -> 9.4472669e-05 | R16: TMDHEV
A17: Plug-in Gasoline Hybrid | B17: 0 | C17: 0 | D17: 0 | E17: 0.005354 | F17: 0.034068 | G17: 0.064296 | H17: 0.097244 | I17: 0.135593 | J17: 0.178628 | K17: 0.229844 | P17: =(E17+E28)/($E$19+$E$30)*0.98 -> 8.457617e-05 | R17: TMHEV
A18: Fuel Cell | B18: 0 | C18: 0 | D18: 0 | E18: 4e-06 | F18: 2.2e-05 | G18: 3.7e-05 | H18: 4.8e-05 | I18: 5.5e-05 | J18: 5.8e-05 | K18: 5.8e-05 | P18: =(E18+E29)/($E$19+$E$30)*0.98 -> 7.0990443e-05 | R18: TMH2
A19: Light Medium Subtotal | B19: 44.468476 | C19: 45.481166 | D19: 53.160873 | E19: 62.660362 | F19: 69.208374 | G19: 76.081268 | H19: 84.932426 | I19: 93.225075 | J19: 101.14086 | K19: 110.57488 | N19: =SUM(N10:N18) -> 0.98011408 | O19: =SUM(O10:O18) -> 0.98000036 | P19: =SUM(P10:P18) -> 0.98000017
A20: Medium
A21: Diesel | B21: 41.638676 | C21: 44.229389 | D21: 35.226994 | E21: 37.441555 | F21: 40.546951 | G21: 45.142582 | H21: 50.785698 | I21: 56.869289 | J21: 64.629585 | K21: 73.386978
A22: Motor Gasoline | B22: 16.84548 | C22: 17.51914 | D22: 15.938895 | E22: 16.315041 | F22: 16.780432 | G22: 18.386461 | H22: 20.665295 | I22: 23.110014 | J22: 26.020405 | K22: 28.9914
A23: Propane | B23: 0.402197 | C23: 0.415266 | D23: 0.014374 | E23: 0.05809 | F23: 0.070231 | G23: 0.080858 | H23: 0.097659 | I23: 0.1229 | J23: 0.160525 | K23: 0.209
A24: Compressed/Liquefied Natural Gas | B24: 0.454878 | C24: 0.446194 | D24: 0.045216 | E24: 0.064804 | F24: 0.107875 | G24: 0.144907 | H24: 0.177677 | I24: 0.212148 | J24: 0.259298 | K24: 0.321946
A25: Ethanol-Flex Fuel | B25: 0 | C25: 0 | D25: 0.405498 | E25: 0.582779 | F25: 0.817522 | G25: 1.069855 | H25: 1.418526 | I25: 1.866067 | J25: 2.470707 | K25: 3.235718
A26: Electric | B26: 0 | C26: 0 | D26: 0 | E26: 0.005089 | F26: 0.027609 | G26: 0.050639 | H26: 0.077011 | I26: 0.108192 | J26: 0.148579 | K26: 0.199153
A27: Plug-in Diesel Hybrid | B27: 0 | C27: 0 | D27: 0 | E27: 0.005519 | F27: 0.030336 | G27: 0.055706 | H27: 0.084749 | I27: 0.11908 | J27: 0.163544 | K27: 0.219225
A28: Plug-in Gasoline Hybrid | B28: 0 | C28: 0 | D28: 0 | E28: 0.004756 | F28: 0.026143 | G28: 0.048007 | H28: 0.073036 | I28: 0.102622 | J28: 0.140941 | K28: 0.188926
A29: Fuel Cell | B29: 0 | C29: 0 | D29: 0 | E29: 0.008482 | F29: 0.046626 | G29: 0.085619 | H29: 0.130256 | I29: 0.183023 | J29: 0.251362 | K29: 0.336943
A30: Medium Subtotal | B30: 59.34124 | C30: 62.609978 | D30: 51.63097 | E30: 54.486111 | F30: 58.453629 | G30: 65.064636 | H30: 73.509865 | I30: 82.693192 | J30: 94.244682 | K30: 107.0894
A31: Heavy
A32: Diesel | B32: 170.8652 | C32: 172.72415 | D32: 175.41458 | E32: 186.35144 | F32: 193.70581 | G32: 199.7095 | H32: 204.73438 | I32: 207.31074 | J32: 211.29189 | K32: 212.10809 | M32: =B32/$B$41 -> 0.97013483 | N32: =C32/$C$41*0.98 -> 0.95180477 | O32: =D32/$D$41*0.98 -> 0.97124416 | P32: =E32/$E$41*0.98 -> 0.96698144 | R32: THDSL*
A33: Motor Gasoline | B33: 4.544584 | C33: 4.42272 | D33: 0.283188 | E33: 0.16338 | F33: 0.10239 | G33: 0.080884 | H33: 0.073337 | I33: 0.070521 | J33: 0.070007 | K33: 0.07181 | M33: =B33/$B$41 -> 0.025803143 | N33: =C33/$C$41*0.98 -> 0.024371612 | O33: =D33/$D$41*0.98 -> 0.0015679694 | P33: =E33/$E$41*0.98 -> 0.00084778217 | R33: THGSL*
A34: Propane | B34: 0.623432 | C34: 0.585659 | D34: 0.011711 | E34: 0.041971 | F34: 0.052448 | G34: 0.056097 | H34: 0.057472 | I34: 0.059604 | J34: 0.063912 | K34: 0.068751 | M34: =B34/$B$41 -> 0.003539709 | N34: =C34/$C$41*0.98 -> 0.0032273022 | O34: =D34/$D$41*0.98 -> 6.4842046e-05 | P34: =E34/$E$41*0.98 -> 0.00021778838 | R34: THLPG*
A35: Compressed/Liquefied Natural Gas | B35: 0.092053 | C35: 0.108249 | D35: 1.286899 | E35: 2.294092 | F35: 2.289191 | G35: 2.262235 | H35: 2.630856 | I35: 3.635866 | J35: 5.510164 | K35: 8.48447 | M35: =B35/$B$41 -> 0.00052265657 | N35: =C35/$C$41*0.98 -> 0.00059651134 | O35: =D35/$D$41*0.98 -> 0.0071253663 | P35: =E35/$E$41*0.98 -> 0.01190409 | R35: THCNG*
A36: Ethanol-Flex Fuel | B36: 0 | C36: 0 | D36: 0 | E36: 0 | F36: 0 | G36: 0 | H36: 0 | I36: 0 | J36: 0 | K36: 0
A37: Electric | B37: 0 | C37: 0 | D37: 0 | E37: 0.001117 | F37: 0.006408 | G37: 0.011978 | H37: 0.017076 | I37: 0.021418 | J37: 0.026086 | K37: 0.031376 | P37: =E37/$E$41*0.98 -> 5.7961359e-06 | Q37: =F37/$F$41*0.98 -> 3.2009043e-05 | R37: THELC
A38: Plug-in Diesel Hybrid | B38: 0 | C38: 0 | D38: 0 | E38: 0.002483 | F38: 0.00966 | G38: 0.017038 | H38: 0.023709 | I38: 0.029509 | J38: 0.035875 | K38: 0.043085 | P38: =E38/$E$41*0.98 -> 1.2884338e-05 | R38: THDHEV
A39: Plug-in Gasoline Hybrid | B39: 0 | C39: 0 | D39: 0 | E39: 0.002627 | F39: 0.010131 | G39: 0.017841 | H39: 0.02481 | I39: 0.030872 | J39: 0.037529 | K39: 0.045071 | P39: =E39/$E$41*0.98 -> 1.3631557e-05 | R39: THHEV
A40: Fuel Cell | B40: 0 | C40: 0 | D40: 0 | E40: 0.003277 | F40: 0.013439 | G40: 0.02393 | H40: 0.033437 | I40: 0.041672 | J40: 0.050677 | K40: 0.060879 | P40: =E40/$E$41*0.98 -> 1.700442e-05 | R40: THH2
A41: Heavy Subtotal | B41: 176.12521 | C41: 177.84074 | D41: 176.99596 | E41: 188.86031 | F41: 196.18956 | G41: 202.17931 | H41: 207.5945 | I41: 211.20003 | J41: 217.08588 | K41: 220.91301 | N41: =SUM(N32:N40) -> 0.9800002 | O41: =SUM(O32:O40) -> 0.98000234 | P41: =SUM(P32:P40) -> 0.98000042
A42: Total Vehicle Miles Traveled | B42: 279.93498 | C42: 285.93189 | D42: 281.78809 | E42: 306.00613 | F42: 323.85065 | G42: 343.32422 | H42: 366.03659 | I42: 387.11658 | J42: 412.4696 | K42: 438.57507
A45: 46. Transportation Fleet Car and Truck Vehicle Miles Traveled by Type and Technology
...

Sheet ConstrData
S1: R1 | T1: R2 | U1: R3 | V1: R4 | W1: R5 | X1: R6 | Y1: R7 | Z1: R8 | AA1: R9 | AC1: R1 | AD1: R2 | AE1: R3 | AF1: R4 | AG1: R5 | AH1: R6 | AI1: R7 | AJ1: R8 | AK1: R9
F5: RAT__RHS | G5: RAT__RHS | H5: RATRULE_ACT | I5: RATRULE_ACT | J5: RATRULE_ACT | K5: RATRULE_ACT | L5: RATRULE_ACT | M5: RATRULE_ACT | N5: RATRULE_ACT | O5: RATRULE_ACT | P5: RATRULE_ACT | Q5: RATRULE_ACT | S5: RATRULE_ACT | T5: RATRULE_ACT | U5: RATRULE_ACT | V5: RATRULE_ACT | W5: RATRULE_ACT | X5: RATRULE_ACT | Y5: RATRULE_ACT | Z5: RATRULE_ACT | AA5: RATRULE_ACT | AC5: RATRULE_ACT | AD5: RATRULE_ACT | AE5: RATRULE_ACT | AF5: RATRULE_ACT | AG5: RATRULE_ACT | AH5: RATRULE_ACT | AI5: RATRULE_ACT | AJ5: RATRULE_ACT | AK5: RATRULE_ACT
F6: LO | G6: UP
B7: ConstrName | C7: ConstrDesc | D7: Units | E7: TechName | F7: 2005-2055 | G7: 2010-2055 | H7: 2010 | I7: 2015 | J7: 2020 | K7: 2025 | L7: 2030 | M7: 2035 | N7: 2040 | O7: 2045 | P7: 2050 | Q7: 2055 | S7: 2005 | T7: 2005 | U7: 2005 | V7: 2005 | W7: 2005 | X7: 2005 | Y7: 2005 | Z7: 2005 | AA7: 2005 | AC7: 2055 | AD7: 2055 | AE7: 2055 | AF7: 2055 | AG7: 2055 | AH7: 2055 | AI7: 2055 | AJ7: 2055 | AK7: 2055
A8: * HDV Shares
B9: S_TAGSL | C9: Transportation Air - GSL | D9: uconstraint | E9: TA-ALL | G9: 0 | H9: -0.012485716 | I9: -0.012111144 | J9: -0.01174781 | K9: -0.011395376 | L9: -0.011053514 | M9: -0.010721909 | N9: -0.010400252 | O9: -0.010088244 | P9: -0.0097855968 | Q9: -0.0094920289
E10: TA-GSL | H10: 1 | I10: 1 | J10: 1 | K10: 1 | L10: 1 | M10: 1 | N10: 1 | O10: 1 | P10: 1 | Q10: 1
B11: S_TAJTF | C11: Transportation Air - JTF | D11: uconstraint | E11: TA-ALL | F11: 0 | H11: -0.98709292 | I11: -0.98709292 | J11: -0.98709292 | K11: -0.98709292 | L11: -0.98709292 | M11: -0.98709292 | N11: -0.98709292 | O11: -0.98709292 | P11: -0.98709292 | Q11: -0.98709292
E12: TA-JTF | H12: 1 | I12: 1 | J12: 1 | K12: 1 | L12: 1 | M12: 1 | N12: 1 | O12: 1 | P12: 1 | Q12: 1
B13: S_TBGSL | C13: Transportation Bus - GSL | D13: uconstraint | E13: TB-ALL | F13: 0 | H13: -0.037885612 | I13: -0.036749043 | J13: -0.035646572 | K13: -0.034577175 | L13: -0.03353986 | M13: -0.032533664 | N13: -0.031557654 | O13: -0.030610924 | P13: -0.029692597 | Q13: -0.028801819
E14: TB-GSL | H14: 1 | I14: 1 | J14: 1 | K14: 1 | L14: 1 | M14: 1 | N14: 1 | O14: 1 | P14: 1 | Q14: 1
B15: S_TBCNG | C15: Transportation Bus- CNG | D15: uconstraint | E15: TB-ALL | F15: 0 | H15: -0.081995472 | M15: -0.24963802 | Q15: -0.2591844
E16: TB-CNG | H16: 1 | M16: 1 | Q16: 1
B17: S_TRPCR | C17: Transportation Rail - Commuter | D17: uconstraint | E17: TRP-ALL | F17: 0 | S17: -0.272 | T17: -0.2576 | U17: -0.4273 | V17: 0 | W17: -0.0672 | X17: 0 | Y17: -0.1147 | Z17: 0 | AA17: -0.11 | AC17: -0.272 | AD17: -0.2576 | AE17: -0.4273 | AF17: 0 | AG17: -0.0672 | AH17: 0 | AI17: -0.1147 | AJ17: 0 | AK17: -0.11
E18: TRP-CR | S18: 1 | T18: 1 | U18: 1 | V18: 1 | W18: 1 | X18: 1 | Y18: 1 | Z18: 1 | AA18: 1 | AC18: 1 | AD18: 1 | AE18: 1 | AF18: 1 | AG18: 1 | AH18: 1 | AI18: 1 | AJ18: 1 | AK18: 1
B19: S_TRPSUB | C19: Transportation Rail - Subways and Streetcars | D19: uconstraint | E19: TRP-ALL | F19: 0 | S19: -0.4544 | T19: -0.6055 | U19: -0.3685 | V19: -0.3349 | W19: -0.5883 | X19: -0.0242 | Y19: -0.357 | Z19: -0.3758 | AA19: -0.4377 | AC19: -0.4544 | AD19: -0.6055 | AE19: -0.3685 | AF19: -0.3349 | AG19: -0.5883 | AH19: -0.0242 | AI19: -0.357 | AJ19: -0.3758 | AK19: -0.4377
E20: TRP-PT | S20: 1 | T20: 1 | U20: 1 | V20: 1 | W20: 1 | X20: 1 | Y20: 1 | Z20: 1 | AA20: 1 | AC20: 1 | AD20: 1 | AE20: 1 | AF20: 1 | AG20: 1 | AH20: 1 | AI20: 1 | AJ20: 1 | AK20: 1
B21: S_TRPIR | C21: Transportation Rail - Intercity | D21: uconstraint | E21: TRP-ALL | F21: 0 | S21: -0.2736 | T21: -0.1369 | U21: -0.2042 | V21: -0.6651 | W21: -0.3445 | X21: -0.9758 | Y21: -0.5283 | Z21: -0.6242 | AA21: -0.4523 | AC21: -0.2736 | AD21: -0.1369 | AE21: -0.2042 | AF21: -0.6651 | AG21: -0.3445 | AH21: -0.9758 | AI21: -0.5283 | AJ21: -0.6242 | AK21: -0.4523
E22: TRP-IR | S22: 1 | T22: 1 | U22: 1 | V22: 1 | W22: 1 | X22: 1 | Y22: 1 | Z22: 1 | AA22: 1 | AC22: 1 | AD22: 1 | AE22: 1 | AF22: 1 | AG22: 1 | AH22: 1 | AI22: 1 | AJ22: 1 | AK22: 1
B23: S_TRPDSL | C23: Transportation Commuter Rail - DSL | D23: uconstraint | E23: TRP-CR | F23: 0 | S23: -0.66682251 | T23: -0.66682251 | U23: -0.66682251 | V23: 0 | W23: -0.66682251 | X23: 0 | Y23: -0.66682251 | Z23: 0 | AA23: -0.66682251 | AC23: -0.66251983 | AD23: -0.66251983 | AE23: -0.66251983 | AF23: 0 | AG23: -0.66251983 | AH23: 0 | AI23: -0.66251983 | AJ23: 0 | AK23: -0.66251983
E24: TRP-DSL | S24: 1 | T24: 1 | U24: 1 | V24: 1 | W24: 1 | X24: 1 | Y24: 1 | Z24: 1 | AA24: 1 | AC24: 1 | AD24: 1 | AE24: 1 | AF24: 1 | AG24: 1 | AH24: 1 | AI24: 1 | AJ24: 1 | AK24: 1
B25: S_TRPELC | C25: Transportation Commuter Rail - ELC | D25: uconstraint | E25: TRP-CR | F25: 0 | S25: -0.33317749 | T25: -0.33317749 | U25: -0.33317749 | V25: 0 | W25: -0.33317749 | X25: 0 | Y25: -0.33317749 | Z25: 0 | AA25: -0.33317749 | AC25: -0.33748017 | AD25: -0.33748017 | AE25: -0.33748017 | AF25: 0 | AG25: -0.33748017 | AH25: 0 | AI25: -0.33748017 | AJ25: 0 | AK25: -0.33748017
E26: TRP-ELC | S26: 1 | T26: 1 | U26: 1 | V26: 1 | W26: 1 | X26: 1 | Y26: 1 | Z26: 1 | AA26: 1 | AC26: 1 | AD26: 1 | AE26: 1 | AF26: 1 | AG26: 1 | AH26: 1 | AI26: 1 | AJ26: 1 | AK26: 1
B27: S_TSDSL | C27: Transportation Shipping - DSL | D27: uconstraint | E27: TS-ALL | F27: 0 | H27: -0.65115981 | I27: -0.64985749 | J27: -0.64855778 | K27: -0.64726066 | L27: -0.64596614 | M27: -0.64467421 | N27: -0.64338486 | O27: -0.64209809 | P27: -0.64081389 | Q27: -0.63953226
E28: TS-DSL | H28: 1 | I28: 1 | J28: 1 | K28: 1 | L28: 1 | M28: 1 | N28: 1 | O28: 1 | P28: 1 | Q28: 1
B29: S_TSDSH | C29: Transportation Shipping - DSH | D29: uconstraint | E29: TS-ALL | F29: 0 | H29: -0.34684019 | I29: -0.34614651 | J29: -0.34545422 | K29: -0.34476331 | L29: -0.34407378 | M29: -0.34338563 | N29: -0.34269886 | O29: -0.34201346 | P29: -0.34132944 | Q29: -0.34064678
E30: TS-DSH | H30: 1 | I30: 1 | J30: 1 | K30: 1 | L30: 1 | M30: 1 | N30: 1 | O30: 1 | P30: 1 | Q30: 1
B31: S_THSCNG | C31: Transportation Truck - CNG | D31: uconstraint | E31: THS-ALL | G31: 0 | H31: -0.00052689522 | M31: -0.019408766 | N31: -0.048973028 | O31: -0.050029313 | P31: -0.051029899 | Q31: -0.052050497
E32: THS-CNG | H32: 1 | M32: 1 | N32: 1 | O32: 1 | P32: 1 | Q32: 1
B33: S_THSGSL | C33: Transportation - Short Haul GSL | D33: uconstraint | E33: THS-ALL | G33: 0 | H33: -0.0090622432 | M33: -0.0085187126 | Q33: -0.0081074555
E34: THS-GSL | H34: 1 | M34: 1 | Q34: 1
B35: S_TMCNG | C35: Transportation-Medium Duty CNG | D35: uconstraint | E35: TM-ALL | F35: 0 | H35: -0.0076244662 | M35: -0.0023649041 | Q35: -0.0021284137
E36: TM-CNG | H36: 1 | M36: 1 | Q36: 1
B37: S_TMLPG | C37: Transportation-Medium Duty LPG | D37: uconstraint | E37: TM-ALL | F37: 0 | H37: -0.0067414503 | M37: -0.0019121599 | Q37: -0.0017209439
E38: TM-LPG | H38: 1 | M38: 1 | Q38: 1
B39: S_TMGSL | C39: Transportation - Medium Duty GSL | D39: uconstraint | E39: TM-ALL | F39: 0 | H39: -0.28357217 | M39: -0.21411407 | Q39: -0.19270266
E40: TM-GSL | H40: 1 | M40: 1 | Q40: 1
B41: S_TRFB20 | C41: Transportation - Rail Freight B20 | D41: uconstraint | E41: TRF-ALL | G41: 0 | H41: 0 | M41: -0.15 | Q41: -0.3
E42: TRF-B20 | H42: 1 | M42: 1 | Q42: 1
A43: * Choose first set if renewables do not count in satisfying constraints.
...
