Workbook

Sheet LDV_sizeshare
B2: UC - Each Region/Period | D2: Share of a group of processes within a market (see attribute FLO_MARK if you want to constrain the market share of a single process)
C3: ~UC_Sets: R_E: AllRegions
C4: ~UC_Sets: T_E:
L5: ~UC_T
C6: UC_N | D6: Pset_Set | E6: Pset_PN | F6: Pset_CI | G6: Pset_CO | H6: Cset_CN | I6: Attribute | J6: Year | K6: Region | L6: LimType | M6: UC_FLO | N6: UC_COMPRD | O6: UC_RHSRT | P6: UC_RHSRT~0 | Q6: UC_Desc
C7: UC_S_TLMC | E7: TLMC*,TLEMC* | G7: TL | H7: =G$15 -> TL | J7: 2011 | K7: R1,R2,R3,R4,R5,R6,R7,R8,R9 | L7: LO | M7: 1 | N7: =-(SUMIFS('initial results'!$I:$I,'initial results'!$A:$A,$T7)+SUMIFS('initial results'!$I:$I,'initial results'!$A:$A,$U7))/SUMIFS('initial results'!I:I,'initial results'!$H:$H,"TL")*0.98 -> 0 | O7: 0 | P7: =5 -> 5 | Q7: Transportation LDV Shares - MiniCompact | S7: 19 | T7: TLEM | U7: TLM
C8: UC_S_TLMC | E8: TLMC*,TLEMC* | G8: TL | H8: =G$15 -> TL | J8: 2015 | K8: R1,R2,R3,R4,R5,R6,R7,R8,R9 | L8: LO | M8: 1 | N8: =N7*0.95 -> 0 | O8: 0 | P8: =5 -> 5 | Q8: Transportation LDV Shares - MiniCompact | S8: 19 | T8: TLEM | U8: TLM
C9: UC_S_TLMC | E9: TLMC*,TLEMC* | G9: TL | H9: =G$15 -> TL | J9: 2020 | K9: R1,R2,R3,R4,R5,R6,R7,R8,R9 | L9: LO | M9: 1 | N9: =N8*0.8 -> 0 | O9: 0 | P9: =5 -> 5 | Q9: Transportation LDV Shares - MiniCompact | S9: =S8+9 -> 28 | T9: TLEM | U9: TLM
C10: UC_S_TLMC | E10: TLMC*,TLEMC* | G10: TL | H10: =G$15 -> TL | J10: 2030 | K10: R1,R2,R3,R4,R5,R6,R7,R8,R9 | L10: LO | M10: 1 | N10: =N9*0.8 -> 0 | O10: 0 | P10: =5 -> 5 | Q10: Transportation LDV Shares - MiniCompact | S10: =S9+9 -> 37 | T10: TLEM | U10: TLM
C11: UC_S_TLMC | E11: TLMC*,TLEMC* | G11: TL | H11: =G$15 -> TL | J11: 2040 | K11: R1,R2,R3,R4,R5,R6,R7,R8,R9 | L11: LO | M11: 1 | N11: =N10 -> 0 | O11: 0 | P11: =5 -> 5 | Q11: Transportation LDV Shares - MiniCompact | S11: =S10+9 -> 46 | T11: TLEM | U11: TLM
C12: UC_S_TLMC | E12: TLMC*,TLEMC* | G12: TL | H12: =G$15 -> TL | J12: 2050 | K12: R1,R2,R3,R4,R5,R6,R7,R8,R9 | L12: LO | M12: 1 | N12: =N11 -> 0 | O12: 0 | P12: =5 -> 5 | Q12: Transportation LDV Shares - MiniCompact | S12: =S11+9 -> 55 | T12: TLEM | U12: TLM
C13: UC_S_TLMC | E13: TLMC*,TLEMC* | G13: TL | H13: =G$15 -> TL | J13: 2055 | K13: R1,R2,R3,R4,R5,R6,R7,R8,R9 | L13: LO | M13: 1 | N13: =N12 -> 0 | O13: 0 | P13: =5 -> 5 | Q13: Transportation LDV Shares - MiniCompact | T13: TLEM | U13: TLM
C14: UC_S_TLC | E14: TLC*,TLEC*,-TLCCO* | G14: TL | H14: =G$15 -> TL | J14: 2011 | K14: R1,R2,R3,R4,R5,R6,R7,R8,R9 | L14: LO | M14: 1 | N14: =-(SUMIFS('initial results'!$I:$I,'initial results'!$A:$A,$T14)+SUMIFS('initial results'!$I:$I,'initial results'!$A:$A,$U14))/SUMIFS('initial results'!I:I,'initial results'!$H:$H,"TL")*0.98 -> -0.0066719548 | O14: 0 | P14: =5 -> 5 | Q14: Transportation LDV Shares - Compact | S14: 19 | T14: TLEC | U14: TLC
C15: UC_S_TLC | E15: TLC*,TLEC*,-TLCCO* | G15: TL | H15: =G$15 -> TL | J15: 2015 | K15: R1,R2,R3,R4,R5,R6,R7,R8,R9 | L15: LO | M15: 1 | N15: =N14*0.92 -> -0.0061381984 | O15: 0 | P15: =5 -> 5 | Q15: Transportation LDV Shares - Compact | S15: 19 | T15: TLEC | U15: TLC
C16: UC_S_TLC | E16: TLC*,TLEC*,-TLCCO* | G16: TL | H16: =G$15 -> TL | J16: 2020 | K16: R1,R2,R3,R4,R5,R6,R7,R8,R9 | L16: LO | M16: 1 | N16: =N15*0.9 -> -0.0055243786 | O16: 0 | P16: =5 -> 5 | Q16: Transportation LDV Shares - Compact | S16: =S15+9 -> 28 | T16: TLEC | U16: TLC
C17: UC_S_TLC | E17: TLC*,TLEC*,-TLCCO* | G17: TL | H17: =G$15 -> TL | J17: 2030 | K17: R1,R2,R3,R4,R5,R6,R7,R8,R9 | L17: LO | M17: 1 | N17: =N16 -> -0.0055243786 | O17: 0 | P17: =5 -> 5 | Q17: Transportation LDV Shares - Compact | S17: =S16+9 -> 37 | T17: TLEC | U17: TLC
C18: UC_S_TLC | E18: TLC*,TLEC*,-TLCCO* | G18: TL | H18: =G$15 -> TL | J18: 2040 | K18: R1,R2,R3,R4,R5,R6,R7,R8,R9 | L18: LO | M18: 1 | N18: =N17 -> -0.0055243786 | O18: 0 | P18: =5 -> 5 | Q18: Transportation LDV Shares - Compact | S18: =S17+9 -> 46 | T18: TLEC | U18: TLC
C19: UC_S_TLC | E19: TLC*,TLEC*,-TLCCO* | G19: TL | H19: =G$15 -> TL | J19: 2050 | K19: R1,R2,R3,R4,R5,R6,R7,R8,R9 | L19: LO | M19: 1 | N19: =N18 -> -0.0055243786 | O19: 0 | P19: =5 -> 5 | Q19: Transportation LDV Shares - Compact | S19: =S18+9 -> 55 | T19: TLEC | U19: TLC
C20: UC_S_TLC | E20: TLC*,TLEC*,-TLCCO* | G20: TL | H20: =G$15 -> TL | J20: 2055 | K20: R1,R2,R3,R4,R5,R6,R7,R8,R9 | L20: LO | M20: 1 | N20: =N19 -> -0.0055243786 | O20: 0 | P20: =5 -> 5 | Q20: Transportation LDV Shares - Compact | T20: TLEC | U20: TLC
C21: UC_S_TLF | E21: TLF*,TLEF* | G21: TL | H21: =G$15 -> TL | J21: 2011 | K21: R1,R2,R3,R4,R5,R6,R7,R8,R9 | L21: LO | M21: 1 | N21: =-(SUMIFS('initial results'!$I:$I,'initial results'!$A:$A,$T21)+SUMIFS('initial results'!$I:$I,'initial results'!$A:$A,$U21))/SUMIFS('initial results'!I:I,'initial results'!$H:$H,"TL")*0.98 -> -0.006867162 | O21: 0 | P21: =5 -> 5 | Q21: Transportation LDV Shares - Full Size | S21: 19 | T21: TLEF | U21: TLF
C22: UC_S_TLF | E22: TLF*,TLEF* | G22: TL | H22: =G$15 -> TL | J22: 2015 | K22: R1,R2,R3,R4,R5,R6,R7,R8,R9 | L22: LO | M22: 1 | N22: =N21*0.98 -> -0.0067298188 | O22: 0 | P22: =5 -> 5 | Q22: Transportation LDV Shares - Full Size | S22: 19 | T22: TLEF | U22: TLF
C23: UC_S_TLF | E23: TLF*,TLEF* | G23: TL | H23: =G$15 -> TL | J23: 2020 | K23: R1,R2,R3,R4,R5,R6,R7,R8,R9 | L23: LO | M23: 1 | N23: =N22 -> -0.0067298188 | O23: 0 | P23: =5 -> 5 | Q23: Transportation LDV Shares - Full Size | S23: =S22+9 -> 28 | T23: TLEF | U23: TLF
C24: UC_S_TLF | E24: TLF*,TLEF* | G24: TL | H24: =G$15 -> TL | J24: 2030 | K24: R1,R2,R3,R4,R5,R6,R7,R8,R9 | L24: LO | M24: 1 | N24: =N23 -> -0.0067298188 | O24: 0 | P24: =5 -> 5 | Q24: Transportation LDV Shares - Full Size | S24: =S23+9 -> 37 | T24: TLEF | U24: TLF
C25: UC_S_TLF | E25: TLF*,TLEF* | G25: TL | H25: =G$15 -> TL | J25: 2040 | K25: R1,R2,R3,R4,R5,R6,R7,R8,R9 | L25: LO | M25: 1 | N25: =N24 -> -0.0067298188 | O25: 0 | P25: =5 -> 5 | Q25: Transportation LDV Shares - Full Size | S25: =S24+9 -> 46 | T25: TLEF | U25: TLF
C26: UC_S_TLF | E26: TLF*,TLEF* | G26: TL | H26: =G$15 -> TL | J26: 2050 | K26: R1,R2,R3,R4,R5,R6,R7,R8,R9 | L26: LO | M26: 1 | N26: =N25 -> -0.0067298188 | O26: 0 | P26: =5 -> 5 | Q26: Transportation LDV Shares - Full Size | S26: =S25+9 -> 55 | T26: TLEF | U26: TLF
C27: UC_S_TLF | E27: TLF*,TLEF* | G27: TL | H27: =G$15 -> TL | J27: 2055 | K27: R1,R2,R3,R4,R5,R6,R7,R8,R9 | L27: LO | M27: 1 | N27: =N26 -> -0.0067298188 | O27: 0 | P27: =5 -> 5 | Q27: Transportation LDV Shares - Full Size | S27: =S26+9 -> 64 | T27: TLEF | U27: TLF
C28: UC_S_TLCCO | E28: TLCCO*,TLECCO* | G28: TL | H28: =G$15 -> TL | J28: 2015 | K28: R1,R2,R3,R4,R5,R6,R7,R8,R9 | L28: LO | M28: 1 | N28: -0.03 | O28: 0 | P28: =5 -> 5 | Q28: Transportation LDV Shares - Car Crossover | S28: 20 | T28: TLECCO | U28: TLCCO
C29: UC_S_TLCCO | E29: TLCCO*,TLECCO* | G29: TL | H29: =G$15 -> TL | J29: 2020 | K29: R1,R2,R3,R4,R5,R6,R7,R8,R9 | L29: LO | M29: 1 | N29: -0.05 | O29: 0 | P29: =5 -> 5 | Q29: Transportation LDV Shares - Car Crossover | S29: =S28+9 -> 29 | T29: TLECCO | U29: TLCCO
C30: UC_S_TLCCO | E30: TLCCO*,TLECCO* | G30: TL | H30: =G$15 -> TL | J30: 2030 | K30: R1,R2,R3,R4,R5,R6,R7,R8,R9 | L30: LO | M30: 1 | N30: =N29*1.05 -> -0.0525 | O30: 0 | P30: =5 -> 5 | Q30: Transportation LDV Shares - Car Crossover | S30: =S29+9 -> 38 | T30: TLECCO | U30: TLCCO
C31: UC_S_TLCCO | E31: TLCCO*,TLECCO* | G31: TL | H31: =G$15 -> TL | J31: 2040 | K31: R1,R2,R3,R4,R5,R6,R7,R8,R9 | L31: LO | M31: 1 | N31: =N30*1.08 -> -0.0567 | O31: 0 | P31: =5 -> 5 | Q31: Transportation LDV Shares - Car Crossover | S31: =S30+9 -> 47 | T31: TLECCO | U31: TLCCO
C32: UC_S_TLCCO | E32: TLCCO*,TLECCO* | G32: TL | H32: =G$15 -> TL | J32: 2050 | K32: R1,R2,R3,R4,R5,R6,R7,R8,R9 | L32: LO | M32: 1 | N32: =N31*1.1 -> -0.06237 | O32: 0 | P32: =5 -> 5 | Q32: Transportation LDV Shares - Car Crossover | S32: =S31+9 -> 56 | T32: TLECCO | U32: TLCCO
C33: UC_S_TLCCO | E33: TLCCO*,TLECCO* | G33: TL | H33: =G$15 -> TL | J33: 2055 | K33: R1,R2,R3,R4,R5,R6,R7,R8,R9 | L33: LO | M33: 1 | N33: =N32 -> -0.06237 | O33: 0 | P33: =5 -> 5 | Q33: Transportation LDV Shares - Car Crossover | T33: TLECCO | U33: TLCCO
C34: UC_S_TLP | E34: TLP*,TLEP* | G34: TL | H34: =G$15 -> TL | J34: 2011 | K34: R1,R2,R3,R4,R5,R6,R7,R8,R9 | L34: LO | M34: 1 | N34: =-(SUMIFS('initial results'!$I:$I,'initial results'!$A:$A,$T34)+SUMIFS('initial results'!$I:$I,'initial results'!$A:$A,$U34))/SUMIFS('initial results'!I:I,'initial results'!$H:$H,"TL")*0.98 -> -0.0094762859 | O34: 0 | P34: =5 -> 5 | Q34: Transportation LDV Shares - Pickup | S34: 19 | T34: TLEP | U34: TLP
C35: UC_S_TLP | E35: TLP*,TLEP* | G35: TL | H35: =G$15 -> TL | J35: 2015 | K35: R1,R2,R3,R4,R5,R6,R7,R8,R9 | L35: LO | M35: 1 | N35: =N34*0.95 -> -0.0090024716 | O35: 0 | P35: =5 -> 5 | Q35: Transportation LDV Shares - Pickup | S35: 19 | T35: TLEP | U35: TLP
C36: UC_S_TLP | E36: TLP*,TLEP* | G36: TL | H36: =G$15 -> TL | J36: 2020 | K36: R1,R2,R3,R4,R5,R6,R7,R8,R9 | L36: LO | M36: 1 | N36: =N35*0.95 -> -0.008552348 | O36: 0 | P36: =5 -> 5 | Q36: Transportation LDV Shares - Pickup | S36: =S35+9 -> 28 | T36: TLEP | U36: TLP
C37: UC_S_TLP | E37: TLP*,TLEP* | G37: TL | H37: =G$15 -> TL | J37: 2030 | K37: R1,R2,R3,R4,R5,R6,R7,R8,R9 | L37: LO | M37: 1 | N37: =N36 -> -0.008552348 | O37: 0 | P37: =5 -> 5 | Q37: Transportation LDV Shares - Pickup | S37: =S36+9 -> 37 | T37: TLEP | U37: TLP
C38: UC_S_TLP | E38: TLP*,TLEP* | G38: TL | H38: =G$15 -> TL | J38: 2040 | K38: R1,R2,R3,R4,R5,R6,R7,R8,R9 | L38: LO | M38: 1 | N38: =N37 -> -0.008552348 | O38: 0 | P38: =5 -> 5 | Q38: Transportation LDV Shares - Pickup | S38: =S37+9 -> 46 | T38: TLEP | U38: TLP
C39: UC_S_TLP | E39: TLP*,TLEP* | G39: TL | H39: =G$15 -> TL | J39: 2050 | K39: R1,R2,R3,R4,R5,R6,R7,R8,R9 | L39: LO | M39: 1 | N39: =N38 -> -0.008552348 | O39: 0 | P39: =5 -> 5 | Q39: Transportation LDV Shares - Pickup | S39: =S38+9 -> 55 | T39: TLEP | U39: TLP
C40: UC_S_TLP | E40: TLP*,TLEP* | G40: TL | H40: =G$15 -> TL | J40: 2055 | K40: R1,R2,R3,R4,R5,R6,R7,R8,R9 | L40: LO | M40: 1 | N40: =N39 -> -0.008552348 | O40: 0 | P40: =5 -> 5 | Q40: Transportation LDV Shares - Pickup | T40: TLEP | U40: TLP
C41: UC_S_TLV | E41: TLV*,TLEV* | G41: TL | H41: =G$15 -> TL | J41: 2011 | K41: R1,R2,R3,R4,R5,R6,R7,R8,R9 | L41: LO | M41: 1 | N41: =-(SUMIFS('initial results'!$I:$I,'initial results'!$A:$A,$T41)+SUMIFS('initial results'!$I:$I,'initial results'!$A:$A,$U41))/SUMIFS('initial results'!I:I,'initial results'!$H:$H,"TL")*0.98 -> -0.0031327732 | O41: 0 | P41: =5 -> 5 | Q41: Transportation LDV Shares - Minivan | S41: 19 | T41: TLEV | U41: TLV
...

Sheet Fueluse
B2: UC - Each Region/Period | D2: Share of a group of processes within a market (see attribute FLO_MARK if you want to constrain the market share of a single process)
C3: ~UC_Sets: R_E: AllRegions
C4: ~UC_Sets: T_E:
K5: ~UC_T
C6: UC_N | D6: Pset_Set | E6: Pset_PN | F6: Pset_CI | G6: Pset_CO | H6: Cset_CN | I6: Attribute | J6: Year | K6: LimType | L6: UC_FLO | M6: UC_COMPRD | N6: UC_RHSRT | O6: UC_RHSRT~0 | P6: UC_Desc
C7: UC_S_TLCCONV | E7: TLECCONV,TLCCONV | G7: TL | H7: TL | J7: 2011 | K7: LO | L7: 1 | M7: =-'initial results'!O9*0.98 -> -0.23790874 | N7: 0 | O7: 5 | P7: =_xlfn.CONCAT(RIGHT(C7,7)," share") -> TLCCONV share
C8: UC_S_TLCCONV | E8: TLECCONV,TLCCONV | G8: TL | H8: TL | J8: 2015 | K8: LO | L8: 1 | M8: =M7*0.9 -> -0.21411786 | N8: 0 | O8: 5 | P8: =_xlfn.CONCAT(RIGHT(C8,7)," share") -> TLCCONV share
C9: UC_S_TLCCONV | E9: TLECCONV,TLCCONV | G9: TL | H9: TL | J9: 2020 | K9: LO | L9: 1 | M9: =M7*0.85 -> -0.20222242 | N9: 0 | O9: 5 | P9: =_xlfn.CONCAT(RIGHT(C9,7)," share") -> TLCCONV share
C10: UC_S_TLCCONV | E10: TLECCONV,TLCCONV | G10: TL | H10: TL | J10: 2025 | K10: LO | L10: 1 | M10: =M7*0.6 -> -0.14274524 | N10: 0 | O10: 5 | P10: =_xlfn.CONCAT(RIGHT(C10,7)," share") -> TLCCONV share
C11: UC_S_TLCCONV | E11: TLECCONV,TLCCONV | G11: TL | H11: TL | J11: 2030 | K11: LO | L11: 1 | M11: 0 | N11: 0 | O11: 5 | P11: =_xlfn.CONCAT(RIGHT(C11,7)," share") -> TLCCONV share
C12: UC_S_TLFCONV | E12: TLEFCONV,TLFCONV | G12: TL | H12: TL | J12: 2011 | K12: LO | L12: 1 | M12: =-'initial results'!O17*0.98 -> -0.24610833 | N12: 0 | O12: 5 | P12: =_xlfn.CONCAT(RIGHT(C12,7)," share") -> TLFCONV share
C13: UC_S_TLFCONV | E13: TLEFCONV,TLFCONV | G13: TL | H13: TL | J13: 2015 | K13: LO | L13: 1 | M13: =M12*0.95 -> -0.23380292 | N13: 0 | O13: 5 | P13: =_xlfn.CONCAT(RIGHT(C13,7)," share") -> TLFCONV share
C14: UC_S_TLFCONV | E14: TLEFCONV,TLFCONV | G14: TL | H14: TL | J14: 2020 | K14: LO | L14: 1 | M14: =M12*0.85 -> -0.20919208 | N14: 0 | O14: 5 | P14: =_xlfn.CONCAT(RIGHT(C14,7)," share") -> TLFCONV share
C15: UC_S_TLFCONV | E15: TLEFCONV,TLFCONV | G15: TL | H15: TL | J15: 2025 | K15: LO | L15: 1 | M15: =M12*0.75 -> -0.18458125 | N15: 0 | O15: 5 | P15: =_xlfn.CONCAT(RIGHT(C15,7)," share") -> TLFCONV share
C16: UC_S_TLFCONV | E16: TLEFCONV,TLFCONV | G16: TL | H16: TL | J16: 2030 | K16: LO | L16: 1 | M16: 0 | N16: 0 | O16: 5 | P16: =_xlfn.CONCAT(RIGHT(C16,7)," share") -> TLFCONV share
C17: UC_S_TLLSCONV | E17: TLELSCONV,TLLSCONV | G17: TL | H17: TL | J17: 2011 | K17: LO | L17: 1 | M17: =-'initial results'!O22*0.9 -> -0.0205101 | N17: 0 | O17: 5 | P17: =_xlfn.CONCAT(RIGHT(C17,8)," share") -> TLLSCONV share
C18: UC_S_TLLSCONV | E18: TLELSCONV,TLLSCONV | G18: TL | H18: TL | J18: 2015 | K18: LO | L18: 1 | M18: =M17*0.95 -> -0.019484595 | N18: 0 | O18: 5 | P18: =_xlfn.CONCAT(RIGHT(C18,8)," share") -> TLLSCONV share
C19: UC_S_TLLSCONV | E19: TLELSCONV,TLLSCONV | G19: TL | H19: TL | J19: 2020 | K19: LO | L19: 1 | M19: =M17*0.85 -> -0.017433585 | N19: 0 | O19: 5 | P19: =_xlfn.CONCAT(RIGHT(C19,8)," share") -> TLLSCONV share
C20: UC_S_TLLSCONV | E20: TLELSCONV,TLLSCONV | G20: TL | H20: TL | J20: 2025 | K20: LO | L20: 1 | M20: =M17*0.75 -> -0.015382575 | N20: 0 | O20: 5 | P20: =_xlfn.CONCAT(RIGHT(C20,8)," share") -> TLLSCONV share
C21: UC_S_TLLSCONV | E21: TLELSCONV,TLLSCONV | G21: TL | H21: TL | J21: 2030 | K21: LO | L21: 1 | M21: 0 | N21: 0 | O21: 5 | P21: =_xlfn.CONCAT(RIGHT(C21,8)," share") -> TLLSCONV share
C22: UC_S_TLMCCONV | E22: TLEMCCONV,TLMCCONV | G22: TL | H22: TL | J22: 2011 | K22: LO | L22: 1 | M22: =-'initial results'!O26*0.9 -> -0.0066052307 | N22: 0 | O22: 5 | P22: =_xlfn.CONCAT(RIGHT(C22,8)," share") -> TLMCCONV share
C23: UC_S_TLMCCONV | E23: TLEMCCONV,TLMCCONV | G23: TL | H23: TL | J23: 2015 | K23: LO | L23: 1 | M23: =M22*0.95 -> -0.0062749691 | N23: 0 | O23: 5 | P23: =_xlfn.CONCAT(RIGHT(C23,8)," share") -> TLMCCONV share
C24: UC_S_TLMCCONV | E24: TLEMCCONV,TLMCCONV | G24: TL | H24: TL | J24: 2020 | K24: LO | L24: 1 | M24: =M22*0.85 -> -0.0056144461 | N24: 0 | O24: 5 | P24: =_xlfn.CONCAT(RIGHT(C24,8)," share") -> TLMCCONV share
C25: UC_S_TLMCCONV | E25: TLEMCCONV,TLMCCONV | G25: TL | H25: TL | J25: 2025 | K25: LO | L25: 1 | M25: =M22*0.75 -> -0.004953923 | N25: 0 | O25: 5 | P25: =_xlfn.CONCAT(RIGHT(C25,8)," share") -> TLMCCONV share
C26: UC_S_TLMCCONV | E26: TLEMCCONV,TLMCCONV | G26: TL | H26: TL | J26: 2030 | K26: LO | L26: 1 | M26: 0 | N26: 0 | O26: 5 | P26: =_xlfn.CONCAT(RIGHT(C26,8)," share") -> TLMCCONV share
C27: UC_S_TLPCONV | E27: TLEPCONV,TLPCONV | G27: TL | H27: TL | J27: 2011 | K27: LO | L27: 1 | M27: =-'initial results'!O29*0.98 -> -0.10979341 | N27: 0 | O27: 5 | P27: =_xlfn.CONCAT(RIGHT(C27,7)," share") -> TLPCONV share
C28: UC_S_TLPCONV | E28: TLEPCONV,TLPCONV | G28: TL | H28: TL | J28: 2015 | K28: LO | L28: 1 | M28: =M27*0.95 -> -0.10430374 | N28: 0 | O28: 5 | P28: =_xlfn.CONCAT(RIGHT(C28,7)," share") -> TLPCONV share
C29: UC_S_TLPCONV | E29: TLEPCONV,TLPCONV | G29: TL | H29: TL | J29: 2020 | K29: LO | L29: 1 | M29: =M27*0.85 -> -0.093324402 | N29: 0 | O29: 5 | P29: =_xlfn.CONCAT(RIGHT(C29,7)," share") -> TLPCONV share
C30: UC_S_TLPCONV | E30: TLEPCONV,TLPCONV | G30: TL | H30: TL | J30: 2025 | K30: LO | L30: 1 | M30: =M27*0.75 -> -0.08234506 | N30: 0 | O30: 5 | P30: =_xlfn.CONCAT(RIGHT(C30,7)," share") -> TLPCONV share
C31: UC_S_TLPCONV | E31: TLEPCONV,TLPCONV | G31: TL | H31: TL | J31: 2030 | K31: LO | L31: 1 | M31: 0 | N31: 0 | O31: 5 | P31: =_xlfn.CONCAT(RIGHT(C31,7)," share") -> TLPCONV share
C32: UC_S_TLSSCONV | E32: TLESSCONV,TLSSCONV | G32: TL | H32: TL | J32: 2011 | K32: LO | L32: 1 | M32: =-'initial results'!O34*0.98 -> -0.09019185 | N32: 0 | O32: 5 | P32: =_xlfn.CONCAT(RIGHT(C32,8)," share") -> TLSSCONV share
C33: UC_S_TLSSCONV | E33: TLESSCONV,TLSSCONV | G33: TL | H33: TL | J33: 2015 | K33: LO | L33: 1 | M33: =M32*0.95 -> -0.085682258 | N33: 0 | O33: 5 | P33: =_xlfn.CONCAT(RIGHT(C33,8)," share") -> TLSSCONV share
C34: UC_S_TLSSCONV | E34: TLESSCONV,TLSSCONV | G34: TL | H34: TL | J34: 2020 | K34: LO | L34: 1 | M34: =M32*0.85 -> -0.076663073 | N34: 0 | O34: 5 | P34: =_xlfn.CONCAT(RIGHT(C34,8)," share") -> TLSSCONV share
C35: UC_S_TLSSCONV | E35: TLESSCONV,TLSSCONV | G35: TL | H35: TL | J35: 2025 | K35: LO | L35: 1 | M35: =M32*0.75 -> -0.067643888 | N35: 0 | O35: 5 | P35: =_xlfn.CONCAT(RIGHT(C35,8)," share") -> TLSSCONV share
C36: UC_S_TLSSCONV | E36: TLESSCONV,TLSSCONV | G36: TL | H36: TL | J36: 2030 | K36: LO | L36: 1 | M36: 0 | N36: 0 | O36: 5 | P36: =_xlfn.CONCAT(RIGHT(C36,8)," share") -> TLSSCONV share
C37: UC_S_TLTCOCONV | E37: TLETCOCONV,TLTCOCONV | G37: TL | H37: TL | J37: 2011 | K37: LO | L37: 1 | M37: =-'initial results'!O38*0.98 -> -0.16258371 | N37: 0 | O37: 5 | P37: =_xlfn.CONCAT(RIGHT(C37,9)," share") -> TLTCOCONV share
C38: UC_S_TLTCOCONV | E38: TLETCOCONV,TLTCOCONV | G38: TL | H38: TL | J38: 2015 | K38: LO | L38: 1 | M38: =M37*0.95 -> -0.15445453 | N38: 0 | O38: 5 | P38: =_xlfn.CONCAT(RIGHT(C38,9)," share") -> TLTCOCONV share
C39: UC_S_TLTCOCONV | E39: TLETCOCONV,TLTCOCONV | G39: TL | H39: TL | J39: 2020 | K39: LO | L39: 1 | M39: =M37*0.85 -> -0.13819616 | N39: 0 | O39: 5 | P39: =_xlfn.CONCAT(RIGHT(C39,9)," share") -> TLTCOCONV share
C40: UC_S_TLTCOCONV | E40: TLETCOCONV,TLTCOCONV | G40: TL | H40: TL | J40: 2025 | K40: LO | L40: 1 | M40: =M37*0.75 -> -0.12193778 | N40: 0 | O40: 5 | P40: =_xlfn.CONCAT(RIGHT(C40,9)," share") -> TLTCOCONV share
C41: UC_S_TLTCOCONV | E41: TLETCOCONV,TLTCOCONV | G41: TL | H41: TL | J41: 2030 | K41: LO | L41: 1 | M41: 0 | N41: 0 | O41: 5 | P41: =_xlfn.CONCAT(RIGHT(C41,9)," share") -> TLTCOCONV share
...

Sheet CAFE
A2: UC - Each Region/Period | C2: Share of a group of processes within a market (see attribute FLO_MARK if you want to constrain the market share of a single process)
B3: ~UC_Sets: R_E: AllRegions
B4: ~UC_Sets: T_E:
F5: ~UC_T
B6: UC_N | C6: Pset_Set | D6: Cset_CN | E6: Year | F6: LimType | G6: UC_COMCON | H6: UC_RHSTS | I6: UC_RHSTS~0 | J6: UC_Desc
B7: UC_CAFE_STDYYY | D7: TRNE85L,TLGSL,TRNCNGL,TLDSL,TLELC,TLH2,TLLPG | E7: 2011 | F7: UP | G7: 1 | H7: ='CAFE calcs'!D14 -> 17262.287 | I7: 5 | J7: National CAFE standardYYY
B8: UC_CAFE_STDYYY | D8: TRNE85L,TLGSL,TRNCNGL,TLDSL,TLELC,TLH2,TLLPG | E8: 2015 | F8: UP | G8: 1 | H8: ='CAFE calcs'!E14 -> 17024.394 | I8: 5 | J8: National CAFE standardYYY
B9: UC_CAFE_STDYYY | D9: TRNE85L,TLGSL,TRNCNGL,TLDSL,TLELC,TLH2,TLLPG | E9: 2020 | F9: UP | G9: 1 | H9: ='CAFE calcs'!F14 -> 15203.888 | I9: 5 | J9: National CAFE standardYYY
B10: UC_CAFE_STDYYY | D10: TRNE85L,TLGSL,TRNCNGL,TLDSL,TLELC,TLH2,TLLPG | E10: 2025 | F10: UP | G10: 1 | H10: ='CAFE calcs'!G14 -> 14472.132 | I10: 5 | J10: National CAFE standardYYY
B11: UC_CAFE_STDYYY | D11: TRNE85L,TLGSL,TRNCNGL,TLDSL,TLELC,TLH2,TLLPG | E11: 2030 | F11: UP | G11: 1 | H11: ='CAFE calcs'!H14 -> 14322.809 | I11: 5 | J11: National CAFE standardYYY
B12: UC_CAFE_STDYYY | D12: TRNE85L,TLGSL,TRNCNGL,TLDSL,TLELC,TLH2,TLLPG | E12: 2035 | F12: UP | G12: 1 | H12: ='CAFE calcs'!I14 -> 14344.21 | I12: 5 | J12: National CAFE standardYYY
B13: UC_CAFE_STDYYY | D13: TRNE85L,TLGSL,TRNCNGL,TLDSL,TLELC,TLH2,TLLPG | E13: 2040 | F13: UP | G13: 1 | H13: ='CAFE calcs'!J14 -> 14339.446 | I13: 5 | J13: National CAFE standardYYY
B14: UC_CAFE_STDYYY | D14: TRNE85L,TLGSL,TRNCNGL,TLDSL,TLELC,TLH2,TLLPG | E14: 2045 | F14: UP | G14: 1 | H14: ='CAFE calcs'!K14 -> 14388.256 | I14: 5 | J14: National CAFE standardYYY
B15: UC_CAFE_STDYYY | D15: TRNE85L,TLGSL,TRNCNGL,TLDSL,TLELC,TLH2,TLLPG | E15: 2050 | F15: UP | G15: 1 | H15: ='CAFE calcs'!L14 -> 14507.662 | I15: 5 | J15: National CAFE standardYYY
B16: UC_CAFE_STDYYY | D16: TRNE85L,TLGSL,TRNCNGL,TLDSL,TLELC,TLH2,TLLPG | E16: 2055 | F16: UP | G16: 1 | H16: ='CAFE calcs'!M14 -> 14799.209 | I16: 5 | J16: National CAFE standardYYY

Sheet CAFE calcs
B2: MMBTU/gallon (gasoline) | C2: 0.125 | D2: (AEO Tables H1 and H2)
B3: PJ per MMBTU | C3: =1055.056*10 ^ 6/10 ^15 -> 1.055056e-06 | D3: (AEO Table H2)
D5: 2011 | E5: 2015 | F5: 2020 | G5: 2025 | H5: 2030 | I5: 2035 | J5: 2040 | K5: 2045 | L5: 2050
B6: AEO data - total fleet | D6: =AEOT40!C68 -> 20.088326 | E6: =AEOT40!D68 -> 21.339816 | F6: =AEOT40!E68 -> 23.745687 | G6: =AEOT40!F68 -> 26.696793 | H6: =AEOT40!G68 -> 29.705198 | I6: =AEOT40!H68 -> 32.067429 | J6: =AEOT40!I68 -> 33.720768 | K6: =AEOT40!J68 -> 34.66869 | L6: =AEOT40!K68 -> 35.230957
B7: AEO data - new vehicles | F7: =AEOT40!E66 -> 33.650864 | G7: =AEOT40!F66 -> 40.743183 | H7: =AEOT40!G66 -> 41.616318 | I7: =AEOT40!H66 -> 42.443111 | J7: =AEOT40!I66 -> 42.865616 | K7: =AEOT40!J66 -> 43.098072 | L7: =AEOT40!K66 -> 43.422623
F8: =(F6-F7)/F7 -> -0.29435134 | G8: =(G6-G7)/G7 -> -0.34475436 | H8: =(H6-H7)/H7 -> -0.28621273 | I8: =(I6-I7)/I7 -> -0.24446092 | J8: =(J6-J7)/J7 -> -0.21333761 | K8: =(K6-K7)/K7 -> -0.19558606 | L8: =(L6-L7)/L7 -> -0.18864973
B9: SAFE standard | F9: 36.8 | G9: 39.8 | H9: 40.5 | I9: =H9 -> 40.5 | J9: =I9 -> 40.5 | K9: =J9 -> 40.5 | L9: =K9 -> 40.5
F10: =F9*0.7 -> 25.76 | G10: =G9*0.7 -> 27.86 | H10: =H9*0.72 -> 29.16 | I10: =I9*0.74 -> 29.97 | J10: =J9*0.76 -> 30.78 | K10: =K9*0.78 -> 31.59 | L10: =L9*0.8 -> 32.4
B13: * Total DMDS from LDV workbook | C13: 2654.1128 | D13: 2629.3994 | E13: 2754.7158 | F13: 2969.7166 | G13: 3057.23 | H13: 3166.8696 | I13: 3259.7017 | J13: 3346.6899 | K13: 3446.4521 | L13: 3564.1577 | M13: 3635.7834
D14: =D13*10^9/D6*$C$2*$C$3 -> 17262.287 | E14: =E13*10^9/E6*$C$2*$C$3 -> 17024.394 | F14: =F13*10^9/F10*$C$2*$C$3 -> 15203.888 | G14: =G13*10^9/G10*$C$2*$C$3 -> 14472.132 | H14: =H13*10^9/H10*$C$2*$C$3 -> 14322.809 | I14: =I13*10^9/I10*$C$2*$C$3 -> 14344.21 | J14: =J13*10^9/J10*$C$2*$C$3 -> 14339.446 | K14: =K13*10^9/K10*$C$2*$C$3 -> 14388.256 | L14: =L13*10^9/L10*$C$2*$C$3 -> 14507.662 | M14: =M13*10^9/L10*$C$2*$C$3 -> 14799.209

Sheet AEOT40
B1: ref2020.d112119a | E1: 2020 | F1: 2025 | G1: 2030 | H1: 2035 | I1: 2040 | J1: 2045 | K1: 2050
E3: Annual Energy Outlook 2020
E4: ref2020
E5: d112119a
A7: MPG000 | B7: 40. Light-Duty Vehicle Miles per Gallon by Technology Type
B8: (miles per gallon gasoline equivalent)
B10: Technology Type | C10: 2011 | D10: 2015 | E10: 2020 | F10: 2025 | G10: 2030 | H10: 2035 | I10: 2040 | J10: 2045 | K10: 2050
B12: New Car Miles per Gallon 1/
B13: Conventional Cars
A14: MPG000:ba_GasolineICEVe | B14: Gasoline ICE Vehicles | C14: 34.919041 | D14: 36.640209 | E14: 40.929665 | F14: 49.371426 | G14: 49.183315 | H14: 48.90831 | I14: 48.441616 | J14: 48.021725 | K14: 47.575485
A15: MPG000:ba_TDIDieselICE | B15: TDI Diesel ICE | C15: 44.021965 | D15: 45.929188 | E15: 50.945549 | F15: 58.204987 | G15: 57.895905 | H15: 57.655411 | I15: 57.002861 | J15: 55.735245 | K15: 54.455967
B17: Alternative-Fuel Cars
A18: MPG000:ca_Ethanol-FlexF | B18: Ethanol-Flex Fuel ICE | C18: 35.229412 | D18: 35.950359 | E18: 41.68227 | F18: 50.5285 | G18: 50.364971 | H18: 50.155849 | I18: 49.724712 | J18: 49.311462 | K18: 48.90575
A19: MPG000:ca_100mileEV | B19: 100 Mile Electric Vehicle | C19: 162.38754 | D19: 97.425339 | E19: 112.41158 | F19: 124.68407 | G19: 124.67096 | H19: 124.8131 | I19: 124.97594 | J19: 124.98581 | K19: 124.98227
A20: MPG000:ca_ElectricVehic | B20: 200 Mile Electric Vehicle | C20: 72.248917 | D20: 93.360863 | E20: 122.91127 | F20: 133.16118 | G20: 133.06892 | H20: 132.94386 | I20: 133.00323 | J20: 133.07178 | K20: 133.13046
A21: MPG000:ea_FuelCellGasol | B21: 300 Mile Electric Vehicle | E21: 121.3287 | F21: 131.80449 | G21: 131.28569 | H21: 130.86124 | I21: 130.71677 | J21: 130.65817 | K21: 130.59328
A22: MPG000:ca_Plug-inGasoli | B22: Plug-in 10 Gasoline Hybrid | C22: 0 | D22: 55.378021 | E22: 61.356583 | F22: 73.119972 | G22: 74.547997 | H22: 74.14888 | I22: 73.77388 | J22: 73.367188 | K22: 72.88063
A23: MPG000:ca_Plug-in40Hybd | B23: Plug-in 40 Gasoline Hybrid | C23: 66.905952 | D23: 67.001404 | E23: 74.559662 | F23: 85.209808 | G23: 86.573502 | H23: 85.935448 | I23: 85.556068 | J23: 85.206055 | K23: 84.769035
A24: MPG000:ca_Electric-Dies | B24: Electric-Diesel Hybrid | C24: 0 | D24: 0 | E24: 0 | F24: 0 | G24: 84.608391 | H24: 84.684349 | I24: 84.182487 | J24: 83.348747 | K24: 82.647331
A25: MPG000:ca_Electric-Gaso | B25: Electric-Gasoline Hybrid | C25: 50.556793 | D25: 53.407799 | E25: 58.284882 | F25: 72.929459 | G25: 72.241074 | H25: 71.303665 | I25: 70.733154 | J25: 70.101471 | K25: 69.469078
A26: MPG000:ca_CompressedNat | B26: Natural Gas ICE | C26: 36.065582 | D26: 37.692646 | E26: 43.743561 | F26: 53.806141 | G26: 53.654404 | H26: 53.620228 | I26: 53.290493 | J26: 52.908714 | K26: 52.496624
A27: MPG000:da_CompressedNat | B27: Natural Gas Bi-fuel | C27: 33.325092 | D27: 33.672596 | E27: 41.049843 | F27: 50.015305 | G27: 49.915249 | H27: 49.839428 | I27: 49.501095 | J27: 49.126881 | K27: 48.728306
A28: MPG000:da_LiquefiedPetr | B28: Propane ICE | C28: 33.310162 | D28: 34.549286 | E28: 42.244034 | F28: 51.844082 | G28: 51.698788 | H28: 51.568142 | I28: 51.188473 | J28: 50.816872 | K28: 50.388245
A29: MPG000:ea_LiquefiedPetr | B29: Propane Bi-fuel | C29: 33.621998 | D29: 33.864937 | E29: 41.427727 | F29: 50.288071 | G29: 50.175247 | H29: 50.001881 | I29: 49.585846 | J29: 49.191479 | K29: 48.787109
A30: MPG000:ea_FuelCellMetha | B30: Fuel Cell Methanol | C30: 0 | D30: 0 | E30: 0 | F30: 0 | G30: 0 | H30: 0 | I30: 0 | J30: 0 | K30: 0
A31: MPG000:ea_FuelCellHydro | B31: Fuel Cell Hydrogen | C31: 0 | D31: 52.181145 | E31: 54.531342 | F31: 58.182266 | G31: 58.404175 | H31: 58.462635 | I31: 58.562168 | J31: 58.693649 | K31: 58.799644
A33: MPG000:fa_TotalNewCarSa | B33: Average New Cars Miles per Gallon | C33: 37.390011 | D33: 38.763268 | E33: 43.52203 | F33: 54.055927 | G33: 54.867836 | H33: 56.773605 | I33: 58.017147 | J33: 58.640144 | K33: 59.473419
B35: New Light Truck Miles per Gallon 1/
B36: Conventional Light Trucks
A37: MPG000:ga_GasolineICEVe | B37: Gasoline ICE Vehicles | C37: 26.947384 | D37: 26.459158 | E37: 30.697212 | F37: 37.945351 | G37: 38.060776 | H37: 37.991756 | I37: 37.743504 | J37: 37.516323 | K37: 37.279438
A38: MPG000:ga_TDIDieselICE | B38: TDI Diesel ICE | C38: 34.307472 | D38: 34.139297 | E38: 37.637753 | F38: 43.932316 | G38: 43.578102 | H38: 43.30209 | I38: 42.896099 | J38: 42.586014 | K38: 42.079144
B40: Alternative-Fuel Light Trucks
A41: MPG000:ha_Ethanol-FlexF | B41: Ethanol-Flex Fuel ICE | C41: 27.264317 | D41: 26.693085 | E41: 30.86261 | F41: 38.334999 | G41: 38.449604 | H41: 38.381935 | I41: 38.125351 | J41: 37.889862 | K41: 37.651413
A42: MPG000:ha_100mileEV | B42: 100 Mile Electric Vehicle | C42: 123.76682 | D42: 71.180328 | E42: 0 | F42: 89.040321 | G42: 88.96833 | H42: 89.138214 | I42: 89.192093 | J42: 89.4524 | K42: 89.989502
A43: MPG000:ha_ElectricVehic | B43: 200 Mile Electric Vehicle | C43: 0 | D43: 0 | E43: 104.85597 | F43: 114.55919 | G43: 113.48865 | H43: 112.89884 | I43: 112.67402 | J43: 112.63536 | K43: 112.70972
A44: MPG000:ja_FuelCellGasol | B44: 300 Mile Electric Vehicle | E44: 90.565613 | F44: 99.962753 | G44: 99.907516 | H44: 100.05299 | I44: 100.0753 | J44: 100.12376 | K44: 100.18023
A45: MPG000:ha_Plug-inGasoli | B45: Plug-in 10 Gasoline Hybrid | C45: 0 | D45: 0 | E45: 46.874249 | F45: 56.049454 | G45: 56.473595 | H45: 56.769737 | I45: 57.293194 | J45: 58.108685 | K45: 58.743637
A46: MPG000:ha_Plug-in40Hybd | B46: Plug-in 40 Gasoline Hybrid | C46: 0 | D46: 0 | E46: 54.805172 | F46: 72.945267 | G46: 78.287773 | H46: 77.759346 | I46: 77.441711 | J46: 77.123802 | K46: 76.701424
A47: MPG000:ha_Electric-Dies | B47: Electric-Diesel Hybrid | C47: 0 | D47: 0 | E47: 0 | F47: 0 | G47: 58.466736 | H47: 58.599491 | I47: 58.613171 | J47: 58.483162 | K47: 58.338261
A48: MPG000:ha_Electric-Gaso | B48: Electric-Gasoline Hybrid | C48: 39.538395 | D48: 38.900272 | E48: 43.998367 | F48: 56.394413 | G48: 56.405994 | H48: 56.118427 | I48: 55.812092 | J48: 55.470554 | K48: 55.126511
...

Sheet AEOT43
A2: Table 43. Summary of New Light-Duty Vehicle Size Class Attributes
B6: *2010 | C6: *2011 | D6: 2015 | E6: 2020 | F6: 2025 | G6: 2030 | H6: 2035 | I6: 2040 | J6: 2045 | K6: 2050 | N6: *2010 | O6: *2011 | P6: 2015 | Q6: 2020 | R6: 2025 | S6: 2030 | T6: 2035 | U6: 2040 | V6: 2045 | W6: 2050 | Y6: 2015 | Z6: 2020 | AA6: 2025 | AB6: 2030 | AC6: 2035 | AD6: 2040 | AE6: 2045 | AF6: 2050
A7: Degradation Factors 1/
A8: Cars | B8: 0.818 | C8: 0.822 | D8: 0.816825 | E8: 0.816615 | F8: 0.816615 | G8: 0.816615 | H8: 0.816615 | I8: 0.816615 | J8: 0.816615 | K8: 0.816615
A9: Light Trucks | B9: 0.8 | C9: 0.8 | D9: 0.80045 | E9: 0.815358 | F9: 0.815358 | G9: 0.815358 | H9: 0.815358 | I9: 0.815358 | J9: 0.815358 | K9: 0.815358
A11: New Vehicle Sales Shares (%) | B11: Assumptions made in spreadsheet to give values for CSUVs
A12: Conventional Cars
A13: Minicompact | B13: 0.888373 | C13: 1.062523 | D13: 0.740655 | E13: 0.450464 | F13: 0.486585 | G13: 0.506041 | H13: 0.503782 | I13: 0.507516 | J13: 0.513723 | K13: 0.516078 | M13: Minicompact | N13: =B13/B$31 -> 0.0044418486 | O13: =C13/C$31 -> 0.005312743 | P13: =D13/D$31 -> 0.0037032241 | Q13: =E13/E$31 -> 0.0022523201 | R13: =F13/F$31 -> 0.0024329247 | S13: =G13/G$31 -> 0.0025302052 | T13: =H13/H$31 -> 0.0025189098 | U13: =I13/I$31 -> 0.0025375801 | ... W13: =K13/K$31 -> 0.0025803901 | Y13: =(P13-N13)/N13 -> -0.16628764 | Z13: =(Q13-P13)/P13 -> -0.39179481 | AA13: =(R13-Q13)/Q13 -> 0.080186041 | AB13: =(S13-R13)/R13 -> 0.039984984 | AC13: =(T13-S13)/S13 -> -0.0044642095 | AD13: =(U13-T13)/T13 -> 0.0074120318 | AE13: =(V13-U13)/U13 -> 0.012229858 | AF13: =(W13-V13)/V13 -> 0.004584509
A14: Subcompact | B14: 11.767998 | C14: 13.809377 | D14: 4.427053 | E14: 4.573545 | F14: 4.62386 | G14: 4.550842 | H14: 4.460354 | I14: 4.424255 | J14: 4.430149 | K14: 4.404425 | M14: Subcompact | N14: =B14/B$31 -> 0.058839772 | O14: =C14/C$31 -> 0.069048548 | P14: =D14/D$31 -> 0.022134961 | Q14: =E14/E$31 -> 0.022867726 | R14: =F14/F$31 -> 0.023119297 | S14: =G14/G$31 -> 0.022754212 | T14: =H14/H$31 -> 0.022301768 | U14: =I14/I$31 -> 0.022121275 | ... W14: =K14/K$31 -> 0.022022126 | Y14: =(P14-N14)/N14 -> -0.62380955 | Z14: =(Q14-P14)/P14 -> 0.033104436 | AA14: =(R14-Q14)/Q14 -> 0.011001156 | AB14: =(S14-R14)/R14 -> -0.015791386 | AC14: =(T14-S14)/S14 -> -0.019883935 | AD14: =(U14-T14)/T14 -> -0.0080932096 | AE14: =(V14-U14)/U14 -> 0.0013319063 | AF14: =(W14-V14)/V14 -> -0.0058062536
A15: Compact | B15: 36.66526 | C15: 39.855232 | D15: 22.504461 | E15: 14.720455 | F15: 14.4741 | G15: 14.407166 | H15: 14.117389 | I15: 13.982598 | J15: 13.959742 | K15: 13.86565 | M15: Compact | N15: =B15/B$31 -> 0.18332562 | O15: =C15/C$31 -> 0.19928096 | P15: =D15/D$31 -> 0.11252076 | Q15: =E15/E$31 -> 0.073602278 | R15: =F15/F$31 -> 0.072370492 | S15: =G15/G$31 -> 0.072035835 | T15: =H15/H$31 -> 0.07058694 | U15: =I15/I$31 -> 0.069912991 | ... W15: =K15/K$31 -> 0.069328253 | Y15: =(P15-N15)/N15 -> -0.3862246 | Z15: =(Q15-P15)/P15 -> -0.34587822 | AA15: =(R15-Q15)/Q15 -> -0.016735708 | AB15: =(S15-R15)/R15 -> -0.0046242139 | AC15: =(T15-S15)/S15 -> -0.020113536 | AD15: =(U15-T15)/T15 -> -0.0095477763 | AE15: =(V15-U15)/U15 -> -0.0016348978 | AF15: =(W15-V15)/V15 -> -0.0067399164
A16: Midsize | B16: 40.131821 | C16: 36.427887 | D16: 35.548019 | E16: 36.790703 | F16: 34.771198 | G16: 34.104324 | H16: 34.005501 | I16: 33.79594 | J16: 33.438225 | K16: 33.319206 | M16: Midsize | N16: =B16/B$31 -> 0.20065836 | O16: =C16/C$31 -> 0.18214382 | P16: =D16/D$31 -> 0.17773765 | Q16: =E16/E$31 -> 0.18395352 | R16: =F16/F$31 -> 0.17385597 | S16: =G16/G$31 -> 0.17052163 | T16: =H16/H$31 -> 0.17002749 | U16: =I16/I$31 -> 0.1689797 | ... W16: =K16/K$31 -> 0.16659604 | Y16: =(P16-N16)/N16 -> -0.11422755 | Z16: =(Q16-P16)/P16 -> 0.034972175 | AA16: =(R16-Q16)/Q16 -> -0.054891867 | AB16: =(S16-R16)/R16 -> -0.019178738 | AC16: =(T16-S16)/S16 -> -0.0028978123 | AD16: =(U16-T16)/T16 -> -0.0061624673 | AE16: =(V16-U16)/U16 -> -0.010584847 | AF16: =(W16-V16)/V16 -> -0.0035590457
A17: Large | B17: 9.970704 | C17: 8.284777 | D17: 9.362244 | E17: 13.754198 | F17: 12.401965 | G17: 11.879538 | H17: 11.783389 | I17: 11.620789 | J17: 11.389194 | K17: 11.297884 | M17: Large | N17: =B17/B$31 -> 0.049853336 | O17: =C17/C$31 -> 0.041424883 | P17: =D17/D$31 -> 0.046810576 | Q17: =E17/E$31 -> 0.068770993 | R17: =F17/F$31 -> 0.062009818 | S17: =G17/G$31 -> 0.059397694 | T17: =H17/H$31 -> 0.058916941 | U17: =I17/I$31 -> 0.058103946 | ... W17: =K17/K$31 -> 0.056489423 | Y17: =(P17-N17)/N17 -> -0.061034219 | Z17: =(Q17-P17)/P17 -> 0.46913365 | AA17: =(R17-Q17)/Q17 -> -0.098314342 | AB17: =(S17-R17)/R17 -> -0.042124357 | AC17: =(T17-S17)/S17 -> -0.0080938087 | AD17: =(U17-T17)/T17 -> -0.013798992 | AE17: =(V17-U17)/U17 -> -0.019929659 | AF17: =(W17-V17)/V17 -> -0.0080169262
A18: Two Seater | B18: 0.575842 | C18: 0.560219 | D18: 0.91757 | E18: 0.945679 | F18: 0.93963 | G18: 0.920001 | H18: 0.916785 | I18: 0.913246 | J18: 0.908347 | K18: 0.906159 | M18: Two Seater | N18: =B18/B$31 -> 0.0028791993 | O18: =C18/C$31 -> 0.0028011625 | P18: =D18/D$31 -> 0.0045877869 | Q18: =E18/E$31 -> 0.0047283952 | R18: =F18/F$31 -> 0.0046981495 | S18: =G18/G$31 -> 0.0046000053 | T18: =H18/H$31 -> 0.0045839247 | U18: =I18/I$31 -> 0.0045662301 | ... W18: =K18/K$31 -> 0.0045307952 | Y18: =(P18-N18)/N18 -> 0.59342454 | Z18: =(Q18-P18)/P18 -> 0.030648393 | AA18: =(R18-Q18)/Q18 -> -0.0063966162 | AB18: =(S18-R18)/R18 -> -0.020889956 | AC18: =(T18-S18)/S18 -> -0.0034957929 | AD18: =(U18-T18)/T18 -> -0.0038601343 | AE18: =(V18-U18)/U18 -> -0.005364675 | AF18: =(W18-V18)/V18 -> -0.0024084469
A19: Small Crossover Utility | D19: =22 -> 22 | E19: 23.842644 | F19: 26.687304 | G19: 27.802261 | H19: 28.128895 | I19: 28.519258 | J19: 29.031044 | K19: 29.250595 | M19: Small Crossover Utility | N19: =B19/B$31 -> 0 | O19: =C19/C$31 -> 0 | P19: =D19/D$31 -> 0.10999849 | Q19: =E19/E$31 -> 0.11921322 | R19: =F19/F$31 -> 0.1334365 | S19: =G19/G$31 -> 0.13901131 | T19: =H19/H$31 -> 0.14064446 | U19: =I19/I$31 -> 0.14259629 | ... W19: =K19/K$31 -> 0.14625298 | Y19: =(P19-N19)/N19 -> #DIV/0! | Z19: =(Q19-P19)/P19 -> 0.083771496 | AA19: =(R19-Q19)/Q19 -> 0.11930958 | AB19: =(S19-R19)/R19 -> 0.041778748 | AC19: =(T19-S19)/S19 -> 0.011748322 | AD19: =(U19-T19)/T19 -> 0.013877748 | AE19: =(V19-U19)/U19 -> 0.017944977 | AF19: =(W19-V19)/V19 -> 0.0075629559
A20: Large Crossover Utility | D20: =4.5 -> 4.5 | E20: 4.922301 | F20: 5.615386 | G20: 5.82982 | H20: 6.083911 | I20: 6.236391 | J20: 6.329605 | K20: 6.44 | M20: Large Crossover Utility | N20: =B20/B$31 -> 0 | O20: =C20/C$31 -> 0 | P20: =D20/D$31 -> 0.022499691 | Q20: =E20/E$31 -> 0.024611506 | R20: =F20/F$31 -> 0.028076927 | S20: =G20/G$31 -> 0.029149102 | T20: =H20/H$31 -> 0.030419553 | U20: =I20/I$31 -> 0.031181956 | ... W20: =K20/K$31 -> 0.032200002 | Y20: =(P20-N20)/N20 -> #DIV/0! | Z20: =(Q20-P20)/P20 -> 0.093859756 | AA20: =(R20-Q20)/Q20 -> 0.14080491 | AB20: =(S20-R20)/R20 -> 0.038187059 | AC20: =(T20-S20)/S20 -> 0.043584556 | AD20: =(U20-T20)/T20 -> 0.025062923 | AE20: =(V20-U20)/U20 -> 0.014946486 | AF20: =(W20-V20)/V20 -> 0.017441387
A22: Conventional Light Trucks
A23: Small Pickup | B23: 4.296283 | C23: 3.681458 | D23: 4.805742 | E23: 3.625221 | F23: 3.471024 | G23: 3.415575 | H23: 3.412992 | I23: 3.394814 | J23: 3.356288 | K23: 3.347577 | M23: Small Pickup | N23: =B23/B$31 -> 0.021481336 | O23: =C23/C$31 -> 0.018407733 | P23: =D23/D$31 -> 0.024028379 | Q23: =E23/E$31 -> 0.018126106 | R23: =F23/F$31 -> 0.017355118 | S23: =G23/G$31 -> 0.017077876 | T23: =H23/H$31 -> 0.017064959 | U23: =I23/I$31 -> 0.01697407 | ... W23: =K23/K$31 -> 0.016737886 | Y23: =(P23-N23)/N23 -> 0.11857009 | Z23: =(Q23-P23)/P23 -> -0.24563761 | AA23: =(R23-Q23)/Q23 -> -0.042534659 | AB23: =(S23-R23)/R23 -> -0.015974643 | AC23: =(T23-S23)/S23 -> -0.00075638652 | AD23: =(U23-T23)/T23 -> -0.0053260241 | AE23: =(V23-U23)/U23 -> -0.011348778 | AF23: =(W23-V23)/V23 -> -0.0025951027
A24: Large Pickup | B24: 23.124727 | C24: 23.398491 | D24: 22.435198 | E24: 19.81151 | F24: 20.655067 | G24: 20.935188 | H24: 21.12112 | I24: 21.241117 | J24: 21.344679 | K24: 21.422119 | M24: Large Pickup | N24: =B24/B$31 -> 0.11562321 | O24: =C24/C$31 -> 0.11699527 | P24: =D24/D$31 -> 0.11217445 | Q24: =E24/E$31 -> 0.099057554 | R24: =F24/F$31 -> 0.10327532 | S24: =G24/G$31 -> 0.10467595 | T24: =H24/H$31 -> 0.10560559 | U24: =I24/I$31 -> 0.10620559 | ... W24: =K24/K$31 -> 0.1071106 | Y24: =(P24-N24)/N24 -> -0.029827577 | Z24: =(Q24-P24)/P24 -> -0.11693299 | AA24: =(R24-Q24)/Q24 -> 0.042578975 | AB24: =(S24-R24)/R24 -> 0.013562041 | AC24: =(T24-S24)/S24 -> 0.0088811687 | AD24: =(U24-T24)/T24 -> 0.0056814704 | AE24: =(V24-U24)/U24 -> 0.0048752475 | AF24: =(W24-V24)/V24 -> 0.0036283967
A25: Small Van | B25: 0.984396 | C25: 1.185597 | D25: 1.318286 | E25: 3.601504 | F25: 3.774787 | G25: 3.865441 | H25: 3.846262 | I25: 3.834877 | J25: 3.862952 | K25: 3.852597 | M25: Small Van | N25: =B25/B$31 -> 0.0049219618 | O25: =C25/C$31 -> 0.0059281278 | P25: =D25/D$31 -> 0.0065913393 | Q25: =E25/E$31 -> 0.018007521 | R25: =F25/F$31 -> 0.018873933 | S25: =G25/G$31 -> 0.019327206 | T25: =H25/H$31 -> 0.019231309 | U25: =I25/I$31 -> 0.019174385 | ... W25: =K25/K$31 -> 0.019262986 | Y25: =(P25-N25)/N25 -> 0.33916914 | Z25: =(Q25-P25)/P25 -> 1.7319972 | AA25: =(R25-Q25)/Q25 -> 0.048113903 | AB25: =(S25-R25)/R25 -> 0.024015849 | AC25: =(T25-S25)/S25 -> -0.0049618032 | AD25: =(U25-T25)/T25 -> -0.002959922 | AE25: =(V25-U25)/U25 -> 0.0073206678 | AF25: =(W25-V25)/V25 -> -0.0026802683
A26: Large Van | B26: 8.735336 | C26: 8.809622 | D26: 7.383523 | E26: 4.153485 | F26: 4.075902 | G26: 4.032054 | H26: 4.003776 | I26: 3.976437 | J26: 3.955323 | K26: 3.93839 | M26: Large Van | N26: =B26/B$31 -> 0.043676518 | O26: =C26/C$31 -> 0.044049171 | P26: =D26/D$31 -> 0.036917107 | Q26: =E26/E$31 -> 0.020767426 | R26: =F26/F$31 -> 0.020379508 | S26: =G26/G$31 -> 0.020160271 | T26: =H26/H$31 -> 0.020018878 | U26: =I26/I$31 -> 0.019882185 | ... W26: =K26/K$31 -> 0.019691951 | Y26: =(P26-N26)/N26 -> -0.15476076 | Z26: =(Q26-P26)/P26 -> -0.43745793 | AA26: =(R26-Q26)/Q26 -> -0.018679165 | AB26: =(S26-R26)/R26 -> -0.010757681 | AC26: =(T26-S26)/S26 -> -0.0070134429 | AD26: =(U26-T26)/T26 -> -0.0068282097 | AE26: =(V26-U26)/U26 -> -0.005310072 | AF26: =(W26-V26)/V26 -> -0.0042807427
A27: Small Utility | B27: 5.16 | C27: 5 | D27: 4.8 | E27: 4.737535 | F27: 4.342774 | G27: 4.173527 | H27: 4.078921 | I27: 4.010399 | J27: 3.948282 | K27: 3.903986 | M27: Small Utility | N27: =B27/B$31 -> 0.025799905 | O27: =C27/C$31 -> 0.025000602 | P27: =D27/D$31 -> 0.02399967 | Q27: =E27/E$31 -> 0.023687676 | R27: =F27/F$31 -> 0.021713868 | S27: =G27/G$31 -> 0.020867636 | T27: =H27/H$31 -> 0.020394603 | U27: =I27/I$31 -> 0.020051995 | ... W27: =K27/K$31 -> 0.019519931 | Y27: =(P27-N27)/N27 -> -0.069776795 | Z27: =(Q27-P27)/P27 -> -0.012999926 | AA27: =(R27-Q27)/Q27 -> -0.083326387 | AB27: =(S27-R27)/R27 -> -0.038971917 | AC27: =(T27-S27)/S27 -> -0.022668259 | AD27: =(U27-T27)/T27 -> -0.016798957 | AE27: =(V27-U27)/U27 -> -0.015489273 | AF27: =(W27-V27)/V27 -> -0.011218735
A28: Large Utility | B28: 5.2 | C28: 5.1 | D28: 4.9 | E28: 4.8219 | F28: 4.605722 | G28: 4.495563 | H28: 4.428885 | I28: 4.382504 | J28: 4.347377 | K28: 4.316301 | M28: Large Utility | N28: =B28/B$31 -> 0.025999904 | O28: =C28/C$31 -> 0.025500614 | P28: =D28/D$31 -> 0.024499663 | Q28: =E28/E$31 -> 0.024109501 | R28: =F28/F$31 -> 0.023028607 | S28: =G28/G$31 -> 0.022477817 | T28: =H28/H$31 -> 0.022144423 | U28: =I28/I$31 -> 0.02191252 | ... W28: =K28/K$31 -> 0.021581506 | Y28: =(P28-N28)/N28 -> -0.057701782 | Z28: =(Q28-P28)/P28 -> -0.0159252 | AA28: =(R28-Q28)/Q28 -> -0.044832683 | AB28: =(S28-R28)/R28 -> -0.023917676 | AC28: =(T28-S28)/S28 -> -0.0148321 | AD28: =(U28-T28)/T28 -> -0.010472294 | AE28: =(V28-U28)/U28 -> -0.0080155734 | AF28: =(W28-V28)/V28 -> -0.0071478957
A29: Small Crossover Utility | B29: 21 | C29: 21 | D29: 22 | E29: 22.595913 | F29: 22.502846 | G29: 22.578991 | H29: 22.615633 | I29: 22.645882 | J29: 22.642023 | K29: 22.659422 | M29: Small Crossover Utility | N29: =B29/B$31 -> 0.10499961 | O29: =C29/C$31 -> 0.10500253 | P29: =D29/D$31 -> 0.10999849 | Q29: =E29/E$31 -> 0.11297957 | R29: =F29/F$31 -> 0.11251422 | S29: =G29/G$31 -> 0.11289496 | T29: =H29/H$31 -> 0.11307816 | U29: =I29/I$31 -> 0.11322941 | ... W29: =K29/K$31 -> 0.11329712 | Y29: =(P29-N29)/N29 -> 0.047608514 | Z29: =(Q29-P29)/P29 -> 0.027101123 | AA29: =(R29-Q29)/Q29 -> -0.004118908 | AB29: =(S29-R29)/R29 -> 0.0033839798 | AC29: =(T29-S29)/S29 -> 0.0016226908 | AD29: =(U29-T29)/T29 -> 0.0013376213 | AE29: =(V29-U29)/U29 -> -0.00017070121 | AF29: =(W29-V29)/V29 -> 0.00076876365
A30: Large Crossover Utility | B30: 31.5 | C30: 31.82 | D30: 32.36 | E30: 36.652935 | F30: 36.571873 | G30: 36.503654 | H30: 36.49242 | I30: 36.513973 | J30: 36.543102 | K30: 36.559601 | M30: Large Crossover Utility | N30: =B30/B$31 -> 0.15749942 | O30: =C30/C$31 -> 0.15910383 | P30: =D30/D$31 -> 0.16179777 | Q30: =E30/E$31 -> 0.18326468 | R30: =F30/F$31 -> 0.18285934 | S30: =G30/G$31 -> 0.18251828 | T30: =H30/H$31 -> 0.18246209 | U30: =I30/I$31 -> 0.18256987 | ... W30: =K30/K$31 -> 0.18279801 | Y30: =(P30-N30)/N30 -> 0.027291258 | Z30: =(Q30-P30)/P30 -> 0.1326774 | AA30: =(R30-Q30)/Q30 -> -0.0022117647 | AB30: =(S30-R30)/R30 -> -0.001865156 | AC30: =(T30-S30)/S30 -> -0.00030789497 | AD30: =(U30-T30)/T30 -> 0.00059071086 | AE30: =(V30-U30)/U30 -> 0.00079745416 | AF30: =(W30-V30)/V30 -> 0.00045181938
B31: =SUM(B13:B30) -> 200.00074 | C31: =SUM(C13:C30) -> 199.99518 | D31: =SUM(D13:D30) -> 200.00275 | E31: =SUM(E13:E30) -> 199.99999 | F31: =SUM(F13:F30) -> 200.00002 | G31: =SUM(G13:G30) -> 199.99999 | H31: =SUM(H13:H30) -> 200.00002 | I31: =SUM(I13:I30) -> 200 | ... K31: =SUM(K13:K30) -> 199.99999 | N31: =SUM(N13:N30) -> 1 | O31: =SUM(O13:O30) -> 1 | P31: =SUM(P13:P30) -> 1 | Q31: =SUM(Q13:Q30) -> 1 | R31: =SUM(R13:R30) -> 1 | S31: =SUM(S13:S30) -> 1 | T31: =SUM(T13:T30) -> 1 | U31: =SUM(U13:U30) -> 1 | ... W31: =SUM(W13:W30) -> 1
A32: 1/ Conversion factor used to convert U.S. Environmental Protection Agency (EPA) rated efficiency to "on road" miles per gallon.
A33: 2/ Environmental Protection Agency rated miles per gallon. | N33: *2010 | O33: *2011 | P33: 2015 | Q33: 2020 | R33: 2025 | S33: 2030 | T33: 2035 | U33: 2040 | V33: 2045 | W33: 2050
A34: Sources: 2019 and projections: U.S. Energy Information Administration (EIA), AEO2020 National Energy Modeling System run ref2020.d112119a. | M34: minicompact | N34: =N13 -> 0.0044418486 | O34: =O13 -> 0.005312743 | P34: =P13 -> 0.0037032241 | Q34: =Q13 -> 0.0022523201 | R34: =R13 -> 0.0024329247 | S34: =S13 -> 0.0025302052 | T34: =T13 -> 0.0025189098 | U34: =U13 -> 0.0025375801 | ... W34: =W13 -> 0.0025803901
M35: compact | N35: =N14+N15+N18 -> 0.24504459 | O35: =O14+O15+O18 -> 0.27113067 | P35: =P14+P15+P18 -> 0.1392435 | Q35: =Q14+Q15+Q18 -> 0.1011984 | R35: =R14+R15+R18 -> 0.10018794 | S35: =S14+S15+S18 -> 0.099390052 | T35: =T14+T15+T18 -> 0.097472633 | U35: =U14+U15+U18 -> 0.096600497 | ... W35: =W14+W15+W18 -> 0.095881175
M36: full | N36: =N16+N17 -> 0.2505117 | O36: =O16+O17 -> 0.2235687 | P36: =P16+P17 -> 0.22454823 | Q36: =Q16+Q17 -> 0.25272452 | R36: =R16+R17 -> 0.23586579 | S36: =S16+S17 -> 0.22991933 | T36: =T16+T17 -> 0.22894443 | U36: =U16+U17 -> 0.22708365 | ... W36: =W16+W17 -> 0.22308546
M37: pickup | N37: =N23+N24 -> 0.13710454 | O37: =O23+O24 -> 0.13540301 | P37: =P23+P24 -> 0.13620283 | Q37: =Q23+Q24 -> 0.11718366 | R37: =R23+R24 -> 0.12063044 | S37: =S23+S24 -> 0.12175382 | T37: =T23+T24 -> 0.12267055 | U37: =U23+U24 -> 0.12317966 | ... W37: =W23+W24 -> 0.12384849
M38: van | N38: =N25+N26 -> 0.04859848 | O38: =O25+O26 -> 0.049977299 | P38: =P25+P26 -> 0.043508447 | Q38: =Q25+Q26 -> 0.038774947 | R38: =R25+R26 -> 0.03925344 | S38: =S25+S26 -> 0.039487478 | T38: =T25+T26 -> 0.039250187 | U38: =U25+U26 -> 0.039056571 | ... W38: =W25+W26 -> 0.038954937
M39: small suv | N39: =N27 -> 0.025799905 | O39: =O27 -> 0.025000602 | P39: =P27 -> 0.02399967 | Q39: =Q27 -> 0.023687676 | R39: =R27 -> 0.021713868 | S39: =S27 -> 0.020867636 | T39: =T27 -> 0.020394603 | U39: =U27 -> 0.020051995 | ... W39: =W27 -> 0.019519931
M40: large suv | N40: =N28 -> 0.025999904 | O40: =O28 -> 0.025500614 | P40: =P28 -> 0.024499663 | Q40: =Q28 -> 0.024109501 | R40: =R28 -> 0.023028607 | S40: =S28 -> 0.022477817 | T40: =T28 -> 0.022144423 | U40: =U28 -> 0.02191252 | ... W40: =W28 -> 0.021581506
M41: cco | N41: =N19+N20 -> 0 | O41: =O19+O20 -> 0 | P41: =P19+P20 -> 0.13249818 | Q41: =Q19+Q20 -> 0.14382473 | R41: =R19+R20 -> 0.16151343 | S41: =S19+S20 -> 0.16816042 | T41: =T19+T20 -> 0.17106402 | U41: =U19+U20 -> 0.17377825 | ... W41: =W19+W20 -> 0.17845298
M42: tco | N42: =N29+N30 -> 0.26249903 | O42: =O29+O30 -> 0.26410636 | P42: =P29+P30 -> 0.27179626 | Q42: =Q29+Q30 -> 0.29624425 | R42: =R29+R30 -> 0.29537356 | S42: =S29+S30 -> 0.29541325 | T42: =T29+T30 -> 0.29554024 | U42: =U29+U30 -> 0.29579928 | ... W42: =W29+W30 -> 0.29609513
N43: =SUM(N34:N42) -> 1 | O43: =SUM(O34:O42) -> 1 | P43: =SUM(P34:P42) -> 1 | Q43: =SUM(Q34:Q42) -> 1 | R43: =SUM(R34:R42) -> 1 | S43: =SUM(S34:S42) -> 1 | T43: =SUM(T34:T42) -> 1 | U43: =SUM(U34:U42) -> 1 | ... W43: =SUM(W34:W42) -> 1
M45: minicompact | P45: =(P34-N34)/N34 -> -0.16628764 | Q45: =(Q34-P34)/P34 -> -0.39179481 | R45: =(R34-Q34)/Q34 -> 0.080186041
M46: compacct | P46: =(P35-N35)/N35 -> -0.43176259 | Q46: =(Q35-P35)/P35 -> -0.27322715 | R46: =(R35-Q35)/Q35 -> -0.0099849462
M47: full | P47: =(P36-N36)/N36 -> -0.10364175 | Q47: =(Q36-P36)/P36 -> 0.1254799 | R47: =(R36-Q36)/Q36 -> -0.066707922
...

Sheet AEOT41
A1: 41. Light-Duty Vehicle Miles Traveled by Technology Type
A2: (billion miles, unless otherwise noted)
A4: Technology Type | B4: 2010 | C4: 2011 | D4: 2015 | E4: 2020 | F4: 2025 | G4: 2030 | H4: 2035 | I4: 2040 | J4: 2045 | K4: 2050 | M4: 2011 | N4: 2015 | O4: 2020
A5: Conventional Vehicles 1/
A6: Gasoline ICE Vehicles | B6: 2491.24 | C6: 2438.2559 | D6: 2439.2566 | E6: 2619.2202 | F6: 2678.8188 | G6: 2755.6814 | H6: 2793.9609 | I6: 2805.6086 | J6: 2824.7195 | K6: 2859.9473 | M6: =C6/C$24*0.95 -> 0.88093994 | N6: =D6/D$24*0.95 -> 0.8412098 | O6: =E6/E$24*0.95 -> 0.83787767
A7: TDI Diesel ICE | B7: 9.431239 | C7: 16.446852 | D7: 15.09309 | E7: 15.833532 | F7: 20.85504 | G7: 24.29698 | H7: 26.775667 | I7: 28.416264 | J7: 29.459896 | K7: 30.198006 | M7: =C7/C$24*0.95 -> 0.0059422348 | N7: =D7/D$24*0.95 -> 0.0052050511 | O7: =E7/E$24*0.95 -> 0.0050650812
A9: Alternative-Fuel Vehicles 1/
A10: Ethanol-Flex Fuel ICE | B10: 117.1096 | C10: 135.36729 | D10: 241.70822 | E10: 244.64951 | F10: 218.93741 | G10: 190.45348 | H10: 170.01115 | I10: 159.57793 | J10: 155.20985 | K10: 153.49451 | M10: =C10/C$24*0.95 -> 0.048908098 | N10: =D10/D$24*0.95 -> 0.083356267 | O10: =E10/E$24*0.95 -> 0.078262361
A11: 100 Mile Electric Vehicle | B11: 0.263333 | C11: 0.276059 | D11: 2.745044 | E11: 2.449263 | F11: 2.094198 | G11: 1.675519 | H11: 1.433428 | I11: 1.565928 | J11: 1.862501 | K11: 2.147963 | M11: =C11/C$24*0.95 -> 9.9739901e-05 | N11: =D11/D$24*0.95 -> 0.00094666461 | O11: =E11/E$24*0.95 -> 0.00078350907
A12: 200 Mile Electric Vehicle | B12: 0 | C12: 0 | D12: 1.359417 | E12: 4.532279 | F12: 12.438354 | G12: 27.82465 | H12: 47.76144 | I12: 74.628311 | J12: 103.13279 | K12: 131.34914 | N12: =D12/D$24*0.95 -> 0.00046881288 | O12: =E12/E$24*0.95 -> 0.0014498572
A13: 300 Mile Electric Vehicle | E13: 9.5408 | F13: 33.471264 | G13: 55.339535 | H13: 83.749908 | I13: 114.39914 | J13: 143.8271 | K13: 173.43198 | O13: =E13/E$24*0.95 -> 0.0030520623
A14: Plug-in 10 Gasoline Hybrid | B14: 0 | C14: 0 | D14: 1.955248 | E14: 4.136904 | F14: 3.621751 | G14: 3.249222 | H14: 2.994675 | I14: 3.35659 | J14: 4.440414 | K14: 6.674379 | N14: =D14/D$24*0.95 -> 0.00067429305 | O14: =E14/E$24*0.95 -> 0.0013233784
A15: Plug-in 40 Gasoline Hybrid | B15: 0 | C15: 0.051477 | D15: 1.623688 | E15: 5.618971 | F15: 8.653733 | G15: 13.703238 | H15: 19.139738 | I15: 24.444071 | J15: 29.06357 | K15: 32.746845 | N15: =D15/D$24*0.95 -> 0.00055995021 | O15: =E15/E$24*0.95 -> 0.0017974855
A16: Electric-Diesel Hybrid | B16: 0 | C16: 0 | D16: 0 | E16: 0 | F16: 0 | G16: 0.027628 | H16: 1.51349 | I16: 3.267112 | J16: 4.83323 | K16: 5.974064
A17: Electric-Gasoline Hybrid | B17: 25.707821 | C17: 28.393736 | D17: 44.660255 | E17: 61.238773 | F17: 76.295631 | G17: 92.83506 | H17: 110.65475 | I17: 129.67389 | J17: 148.02522 | K17: 166.1572 | M17: =C17/C$24*0.95 -> 0.010258635 | N17: =D17/D$24*0.95 -> 0.015401678 | O17: =E17/E$24*0.95 -> 0.019590029
A18: Natural Gas ICE | B18: 1.231625 | C18: 1.300262 | D18: 1.723101 | E18: 0.391595 | F18: 0.290712 | G18: 0.243757 | H18: 0.226109 | I18: 0.222108 | J18: 0.227075 | K18: 0.235807 | M18: =C18/C$24*0.95 -> 0.00046978364 | N18: =D18/D$24*0.95 -> 0.0005942341 | O18: =E18/E$24*0.95 -> 0.00012526961
A19: Natural Gas Bi-fuel | B19: 2.06937 | C19: 2.148796 | D19: 1.708403 | E19: 0.981212 | F19: 0.870276 | G19: 0.782469 | H19: 0.746479 | I19: 0.740544 | J19: 0.754363 | K19: 0.775036 | M19: =C19/C$24*0.95 -> 0.00077635832 | N19: =D19/D$24*0.95 -> 0.0005891653 | O19: =E19/E$24*0.95 -> 0.00031388565
A20: Propane ICE | B20: 1.541919 | C20: 1.588658 | D20: 0.51921 | E20: 0.230872 | F20: 0.22131 | G20: 0.223722 | H20: 0.233546 | I20: 0.248793 | J20: 0.271471 | K20: 0.303419 | M20: =C20/C$24*0.95 -> 0.00057398089 | N20: =D20/D$24*0.95 -> 0.00017905641 | O20: =E20/E$24*0.95 -> 7.3854994e-05
A21: Propane Bi-fuel | B21: 5.517705 | C21: 5.57055 | D21: 2.295468 | E21: 0.797479 | F21: 0.559042 | G21: 0.408211 | H21: 0.333277 | I21: 0.307229 | J21: 0.307984 | K21: 0.312475 | M21: =C21/C$24*0.95 -> 0.0020126354 | N21: =D21/D$24*0.95 -> 0.0007916224 | O21: =E21/E$24*0.95 -> 0.00025511022
A22: Fuel Cell Methanol | B22: 0 | C22: 0 | D22: 0 | E22: 0 | F22: 0 | G22: 0 | H22: 0 | I22: 0 | J22: 0 | K22: 0
A23: Fuel Cell Hydrogen | B23: 0 | C23: 0 | D23: 0.067882 | E23: 0.095158 | F23: 0.101934 | G23: 0.124517 | H23: 0.167003 | I23: 0.233468 | J23: 0.317333 | K23: 0.409345
B24: =SUM(B6:B23) -> 2654.1126 | C24: =SUM(C6:C23) -> 2629.3995 | D24: =SUM(D6:D23) -> 2754.7156 | E24: =SUM(E6:E23) -> 2969.7166 | F24: =SUM(F6:F23) -> 3057.2295 | G24: =SUM(G6:G23) -> 3166.8694 | H24: =SUM(H6:H23) -> 3259.7016 | I24: =SUM(I6:I23) -> 3346.69 | ... K24: =SUM(K6:K23) -> 3564.1574 | M24: =SUM(M6:M23) -> 0.9499814 | N24: =SUM(N6:N23) -> 0.94997659 | O24: =SUM(O6:O23) -> 0.94996956

Sheet initial results
A1: * Filtered for Commodity = TL and Var_Fout
C4: Page Fields:
C5: Table Name: Transportation Summary
C6: Active Unit:
C7: Scenario | D7: Attribute | E7: ProcessSet | F7: Process | G7: Region | H7: Commodity\Period | I7: 2010 | J7: 2011 | K7: 2015 | L7: 2020 | N7: TLECCNG | O7: =SUMIFS(I:I,F:F,$N7)/SUMIFS(I:I,H:H,"TL") -> 0.00011901873
A8: =LEFT(F8,4) -> TLCC | C8: 9rT_Ref_V1_1_1201_0212 | D8: VAR_FOut | E8: TL-CNG | F8: TLCCNGX | G8: R1 | H8: TL | K8: 0.040708762 | L8: 0.040708762 | N8: TLECCNGX | O8: =SUMIFS(I:I,F:F,$N8)/SUMIFS(I:I,H:H,"TL") -> 0.00050127795
A9: =LEFT(F9,4) -> TLCC | C9: 9rT_Ref_V1_1_1201_0212 | D9: VAR_FOut | E9: TL-CNG | F9: TLCCNGX | G9: R2 | H9: TL | K9: 0.11348086 | L9: 0.11348086 | N9: TLECCONV | O9: =SUMIFS(I:I,F:F,$N9)/SUMIFS(I:I,H:H,"TL") -> 0.24276402
A10: =LEFT(F10,4) -> TLCC | C10: 9rT_Ref_V1_1_1201_0212 | D10: VAR_FOut | E10: TL-CNG | F10: TLCCNGX | G10: R3 | H10: TL | K10: 0.12376562 | L10: 0.12376562 | N10: TLECDSL | O10: =SUMIFS(I:I,F:F,$N10)/SUMIFS(I:I,H:H,"TL") -> 0.0016328531
A11: =LEFT(F11,4) -> TLCC | C11: 9rT_Ref_V1_1_1201_0212 | D11: VAR_FOut | E11: TL-CNG | F11: TLCCNGX | G11: R4 | H11: TL | K11: 0.059690218 | L11: 0.059690218 | N11: TLECELC100 | O11: =SUMIFS(I:I,F:F,$N11)/SUMIFS(I:I,H:H,"TL") -> 3.4271628e-05
A12: =LEFT(F12,4) -> TLCC | C12: 9rT_Ref_V1_1_1201_0212 | D12: VAR_FOut | E12: TL-CNG | F12: TLCCNGX | G12: R5 | H12: TL | K12: 0.18097365 | L12: 0.18097365 | N12: TLECETHX | O12: =SUMIFS(I:I,F:F,$N12)/SUMIFS(I:I,H:H,"TL") -> 0.0045206957
A13: =LEFT(F13,4) -> TLCC | C13: 9rT_Ref_V1_1_1201_0212 | D13: VAR_FOut | E13: TL-CNG | F13: TLCCNGX | G13: R6 | H13: TL | K13: 0.050868825 | L13: 0.050868825 | N13: TLECHEV | O13: =SUMIFS(I:I,F:F,$N13)/SUMIFS(I:I,H:H,"TL") -> 0.0041376545
A14: =LEFT(F14,4) -> TLCC | C14: 9rT_Ref_V1_1_1201_0212 | D14: VAR_FOut | E14: TL-CNG | F14: TLCCNGX | G14: R7 | H14: TL | K14: 0.11541044 | L14: 0.11541044 | N14: TLECLPGX | O14: =SUMIFS(I:I,F:F,$N14)/SUMIFS(I:I,H:H,"TL") -> 0.00050127795
A15: =LEFT(F15,4) -> TLCC | C15: 9rT_Ref_V1_1_1201_0212 | D15: VAR_FOut | E15: TL-CNG | F15: TLCCNGX | G15: R8 | H15: TL | K15: 0.066266715 | L15: 0.066266715 | N15: TLEFCNG | O15: =SUMIFS(I:I,F:F,$N15)/SUMIFS(I:I,H:H,"TL") -> 0.00012312075
A16: =LEFT(F16,4) -> TLCC | C16: 9rT_Ref_V1_1_1201_0212 | D16: VAR_FOut | E16: TL-CNG | F16: TLCCNGX | G16: R9 | H16: TL | K16: 0.14613777 | L16: 0.14613777 | N16: TLEFCNGX | O16: =SUMIFS(I:I,F:F,$N16)/SUMIFS(I:I,H:H,"TL") -> 0.00051855465
A17: =LEFT(F17,4) -> TLEC | C17: 9rT_Ref_V1_1_1201_0212 | D17: VAR_FOut | E17: TL-CNG | F17: TLECCNG | G17: R1 | H17: TL | I17: 0.015920458 | J17: 0.0053374056 | K17: 0.0032696039 | L17: 0.002323563 | N17: TLEFCONV | O17: =SUMIFS(I:I,F:F,$N17)/SUMIFS(I:I,H:H,"TL") -> 0.25113095
A18: =LEFT(F18,4) -> TLEC | C18: 9rT_Ref_V1_1_1201_0212 | D18: VAR_FOut | E18: TL-CNG | F18: TLECCNG | G18: R2 | H18: TL | I18: 0.047175753 | J18: 0.017283724 | K18: 0.0086946069 | L18: 0.0058944006 | N18: TLEFDSL | O18: =SUMIFS(I:I,F:F,$N18)/SUMIFS(I:I,H:H,"TL") -> 0.0016891299
A19: =LEFT(F19,4) -> TLEC | C19: 9rT_Ref_V1_1_1201_0212 | D19: VAR_FOut | E19: TL-CNG | F19: TLECCNG | G19: R3 | H19: TL | J19: 0.022178721 | K19: 0.010487354 | L19: 0.0073598548 | N19: TLEFETHX | O19: =SUMIFS(I:I,F:F,$N19)/SUMIFS(I:I,H:H,"TL") -> 0.0046765029
A20: =LEFT(F20,4) -> TLEC | C20: 9rT_Ref_V1_1_1201_0212 | D20: VAR_FOut | E20: TL-CNG | F20: TLECCNG | G20: R4 | H20: TL | I20: 0.024772278 | J20: 0.0088515679 | K20: 0.005210665 | L20: 0.0037467288 | N20: TLEFHEV | O20: =SUMIFS(I:I,F:F,$N20)/SUMIFS(I:I,H:H,"TL") -> 0.0042802601
A21: =LEFT(F21,4) -> TLEC | C21: 9rT_Ref_V1_1_1201_0212 | D21: VAR_FOut | E21: TL-CNG | F21: TLECCNG | G21: R5 | H21: TL | I21: 0.06760151 | J21: 0.027483522 | K21: 0.014507305 | L21: 0.010383474 | N21: TLEFLPGX | O21: =SUMIFS(I:I,F:F,$N21)/SUMIFS(I:I,H:H,"TL") -> 0.00051855465
A22: =LEFT(F22,4) -> TLEC | C22: 9rT_Ref_V1_1_1201_0212 | D22: VAR_FOut | E22: TL-CNG | F22: TLECCNG | G22: R6 | H22: TL | I22: 0.022579104 | J22: 0.0083420053 | K22: 0.0045707644 | L22: 0.0034369699 | N22: TLELSCONV | O22: =SUMIFS(I:I,F:F,$N22)/SUMIFS(I:I,H:H,"TL") -> 0.022789
A23: =LEFT(F23,4) -> TLEC | C23: 9rT_Ref_V1_1_1201_0212 | D23: VAR_FOut | E23: TL-CNG | F23: TLECCNG | G23: R7 | H23: TL | I23: 0.045800485 | J23: 0.019114 | K23: 0.0089416225 | L23: 0.0064028997 | N23: TLELSDSL | O23: =SUMIFS(I:I,F:F,$N23)/SUMIFS(I:I,H:H,"TL") -> 0.00069397281
A24: =LEFT(F24,4) -> TLEC | C24: 9rT_Ref_V1_1_1201_0212 | D24: VAR_FOut | E24: TL-CNG | F24: TLECCNG | G24: R8 | H24: TL | I24: 0.028840244 | J24: 0.013046374 | K24: 0.0058157166 | L24: 0.0041703766 | N24: TLELSETHX | O24: =SUMIFS(I:I,F:F,$N24)/SUMIFS(I:I,H:H,"TL") -> 0.00079498233
A25: =LEFT(F25,4) -> TLEC | C25: 9rT_Ref_V1_1_1201_0212 | D25: VAR_FOut | E25: TL-CNG | F25: TLECCNG | G25: R9 | H25: TL | I25: 0.063199311 | J25: 0.028642065 | K25: 0.012285446 | L25: 0.0083731963 | N25: TLELSHEV | O25: =SUMIFS(I:I,F:F,$N25)/SUMIFS(I:I,H:H,"TL") -> 0.00010399886
A26: =LEFT(F26,4) -> TLEC | C26: 9rT_Ref_V1_1_1201_0212 | D26: VAR_FOut | E26: TL-CNG | F26: TLECCNGX | G26: R1 | H26: TL | I26: 0.063439145 | J26: 0.059722211 | K26: 0.014371257 | L26: 0.0051646195 | N26: TLEMCCONV | O26: =SUMIFS(I:I,F:F,$N26)/SUMIFS(I:I,H:H,"TL") -> 0.0073391452
A27: =LEFT(F27,4) -> TLEC | C27: 9rT_Ref_V1_1_1201_0212 | D27: VAR_FOut | E27: TL-CNG | F27: TLECCNGX | G27: R2 | H27: TL | I27: 0.17751448 | J27: 0.16656414 | K27: 0.040041031 | L27: 0.013579649 | N27: TLEPCNG | O27: =SUMIFS(I:I,F:F,$N27)/SUMIFS(I:I,H:H,"TL") -> 6.6015882e-05
A28: =LEFT(F28,4) -> TLEC | C28: 9rT_Ref_V1_1_1201_0212 | D28: VAR_FOut | E28: TL-CNG | F28: TLECCNGX | G28: R3 | H28: TL | I28: 0.1972047 | J28: 0.18523952 | K28: 0.044954074 | L28: 0.016716246 | N28: TLEPCNGX | O28: =SUMIFS(I:I,F:F,$N28)/SUMIFS(I:I,H:H,"TL") -> 0.00035345319
A29: =LEFT(F29,4) -> TLEC | C29: 9rT_Ref_V1_1_1201_0212 | D29: VAR_FOut | E29: TL-CNG | F29: TLECCNGX | G29: R4 | H29: TL | I29: 0.094539062 | J29: 0.088466043 | K29: 0.021226904 | L29: 0.007979424 | N29: TLEPCONV | O29: =SUMIFS(I:I,F:F,$N29)/SUMIFS(I:I,H:H,"TL") -> 0.1120341
A30: =LEFT(F30,4) -> TLEC | C30: 9rT_Ref_V1_1_1201_0212 | D30: VAR_FOut | E30: TL-CNG | F30: TLECCNGX | G30: R5 | H30: TL | I30: 0.24451094 | J30: 0.22991453 | K30: 0.058609618 | L30: 0.022097001 | N30: TLEPDSL | O30: =SUMIFS(I:I,F:F,$N30)/SUMIFS(I:I,H:H,"TL") -> 0.0043107334
A31: =LEFT(F31,4) -> TLEC | C31: 9rT_Ref_V1_1_1201_0212 | D31: VAR_FOut | E31: TL-CNG | F31: TLECCNGX | G31: R6 | H31: TL | I31: 0.082618897 | J31: 0.07775987 | K31: 0.01800677 | L31: 0.0070107548 | N31: TLEPETHX | O31: =SUMIFS(I:I,F:F,$N31)/SUMIFS(I:I,H:H,"TL") -> 0.004939477
... A36: =LEFT(F36,4) -> TLEF | C36: 9rT_Ref_V1_1_1201_0212 | D36: VAR_FOut | E36: TL-CNG | F36: TLEFCNG | G36: R2 | H36: TL | I36: 0.048801679 | J36: 0.017879413 | K36: 0.0089942692 | L36: 0.0060975529 | N36: TLESSELC100 | O36: =SUMIFS(I:I,F:F,$N36)/SUMIFS(I:I,H:H,"TL") -> 1.6396336e-05
A37: =LEFT(F37,4) -> TLEF | C37: 9rT_Ref_V1_1_1201_0212 | D37: VAR_FOut | E37: TL-CNG | F37: TLEFCNG | G37: R3 | H37: TL | K37: 0.010848804 | L37: 0.0076135144 | N37: TLESSETHX | O37: =SUMIFS(I:I,F:F,$N37)/SUMIFS(I:I,H:H,"TL") -> 0.0037828299
A38: =LEFT(F38,4) -> TLEF | C38: 9rT_Ref_V1_1_1201_0212 | D38: VAR_FOut | E38: TL-CNG | F38: TLEFCNG | G38: R4 | H38: TL | I38: 0.025626062 | J38: 0.0091566399 | K38: 0.0053902521 | L38: 0.0038758609 | N38: TLETCOCONV | O38: =SUMIFS(I:I,F:F,$N38)/SUMIFS(I:I,H:H,"TL") -> 0.16590175
A39: =LEFT(F39,4) -> TLEF | C39: 9rT_Ref_V1_1_1201_0212 | D39: VAR_FOut | E39: TL-CNG | F39: TLEFCNG | G39: R5 | H39: TL | I39: 0.069931417 | J39: 0.02843075 | K39: 0.015007303 | L39: 0.010741344 | N39: TLETCODSL | O39: =SUMIFS(I:I,F:F,$N39)/SUMIFS(I:I,H:H,"TL") -> 0.0070064563
A40: =LEFT(F40,4) -> TLEF | C40: 9rT_Ref_V1_1_1201_0212 | D40: VAR_FOut | E40: TL-CNG | F40: TLEFCNG | G40: R6 | H40: TL | I40: 0.023357299 | J40: 0.0086295151 | K40: 0.0047282972 | L40: 0.0035554262 | N40: TLETCOETHX | O40: =SUMIFS(I:I,F:F,$N40)/SUMIFS(I:I,H:H,"TL") -> 0.0094570748
A41: =LEFT(F41,4) -> TLEF | C41: 9rT_Ref_V1_1_1201_0212 | D41: VAR_FOut | E41: TL-CNG | F41: TLEFCNG | G41: R7 | H41: TL | I41: 0.047379012 | J41: 0.01977277 | K41: 0.0092497983 | L41: 0.0066235776 | N41: TLETCOHEV | O41: =SUMIFS(I:I,F:F,$N41)/SUMIFS(I:I,H:H,"TL") -> 0.0010499884
A42: =LEFT(F42,4) -> TLEF | C42: 9rT_Ref_V1_1_1201_0212 | D42: VAR_FOut | E42: TL-CNG | F42: TLEFCNG | G42: R8 | H42: TL | I42: 0.029834232 | J42: 0.013496021 | K42: 0.006016157 | L42: 0.0043141099 | N42: TLEVCNG | O42: =SUMIFS(I:I,F:F,$N42)/SUMIFS(I:I,H:H,"TL") -> 2.3400184e-05
A43: =LEFT(F43,4) -> TLEF | C43: 9rT_Ref_V1_1_1201_0212 | D43: VAR_FOut | E43: TL-CNG | F43: TLEFCNG | G43: R9 | H43: TL | I43: 0.065377495 | J43: 0.029629222 | K43: 0.012708867 | L43: 0.008661781 | N43: TLEVCNGX | O43: =SUMIFS(I:I,F:F,$N43)/SUMIFS(I:I,H:H,"TL") -> 0.00012528606
