Workbook

Sheet onSets
B1: ~UC_Sets: R_E: R1,R2,R3,R4,R5,R6,R7,R8,R9
B2: ~UC_Sets: T_E:
H4: ~UC_T:UC_RHSRT
C5: UC_N | D5: PSET_SET | E5: PSET_CO | F5: CSET_CN | G5: Year | H5: LimType | I5: UC_FLO | J5: R1 | K5: R2 | L5: R3 | M5: R4 | N5: R5 | O5: R6 | P5: R7 | Q5: R8 | R5: R9 | S5: UC_RHSRT~0 | T5: UC_Desc
C6: ELC_COAL | D6: ELC-COAL | E6: ELC | F6: ELC | G6: 2010 | H6: LO | I6: 1 | J6: =NetGenbyRegion!$H26*0.9 -> 45.4248 | K6: =NetGenbyRegion!$H27*0.95 -> 441.009 | L6: =NetGenbyRegion!$H28*0.95 -> 1455.7333 | M6: =NetGenbyRegion!$H29*0.95 -> 782.2908 | N6: =NetGenbyRegion!$H30*0.95 -> 1263.9533 | O6: =NetGenbyRegion!$H31*0.95 -> 716.68494 | P6: =NetGenbyRegion!$H32*0.95 -> 786.1896 | Q6: =NetGenbyRegion!$H33*0.95 -> 701.46252 | R6: =NetGenbyRegion!$H34*0.95 -> 55.58868 | S6: 1 | T6: Coal Use in ELC Production
C7: ELC_COAL | D7: ELC-COAL | E7: ELC | F7: ELC | G7: 2010 | H7: UP | I7: 1 | J7: =NetGenbyRegion!$H26*1.1 -> 55.5192 | K7: =NetGenbyRegion!$H27*1.1 -> 510.642 | L7: =NetGenbyRegion!$H28*1.1 -> 1685.5859 | M7: =NetGenbyRegion!$H29*1.1 -> 905.8104 | N7: =NetGenbyRegion!$H30*1.1 -> 1463.5249 | O7: =NetGenbyRegion!$H31*1.1 -> 829.84572 | P7: =NetGenbyRegion!$H32*1.1 -> 910.3248 | Q7: =NetGenbyRegion!$H33*1.1 -> 812.21976 | R7: =NetGenbyRegion!$H34*1.7 -> 99.47448 | S7: 1 | T7: Coal Use in ELC Production
C8: ELC_COAL | D8: ELC-COAL | E8: ELC | F8: ELC | G8: 2011 | H8: LO | I8: 1 | J8: =NetGenbyRegion!$I26*0.95 -> 23.25942 | K8: =NetGenbyRegion!$I27*0.95 -> 386.38476 | L8: =NetGenbyRegion!$I28*0.95 -> 1349.5081 | M8: =NetGenbyRegion!$I29*0.95 -> 782.0685 | N8: =NetGenbyRegion!$I30*0.95 -> 1099.4548 | O8: =NetGenbyRegion!$I31*0.95 -> 675.12852 | P8: =NetGenbyRegion!$I32*0.95 -> 840.98484 | Q8: =NetGenbyRegion!$I33*0.95 -> 677.68326 | R8: =NetGenbyRegion!$I34*0.95 -> 40.71852 | S8: 1 | T8: Coal Use in ELC Production
C9: ELC_COAL | D9: ELC-COAL | E9: ELC | F9: ELC | G9: 2011 | H9: UP | I9: 1 | J9: =NetGenbyRegion!$I26*1.1 -> 26.93196 | K9: =NetGenbyRegion!$I27*1.1 -> 447.39288 | L9: =NetGenbyRegion!$I28*1.1 -> 1562.5883 | M9: =NetGenbyRegion!$I29*1.1 -> 905.553 | N9: =NetGenbyRegion!$I30*1.1 -> 1273.0529 | O9: =NetGenbyRegion!$I31*1.1 -> 781.72776 | P9: =NetGenbyRegion!$I32*1.1 -> 973.77192 | Q9: =NetGenbyRegion!$I33*1.1 -> 784.68588 | R9: =NetGenbyRegion!$I34*1.1 -> 47.14776 | S9: 1 | T9: Coal Use in ELC Production
C10: ELC_COAL | D10: ELC-COAL | E10: ELC | F10: ELC | G10: 2015 | H10: LO | I10: 1 | J10: =NetGenbyRegion!$J26*0.95 -> 13.12596 | K10: =NetGenbyRegion!$J27*0.95 -> 232.5258 | L10: =NetGenbyRegion!$J28*0.95 -> 1063.6132 | M10: =NetGenbyRegion!$J29*0.95 -> 666.08604 | N10: =NetGenbyRegion!$J30*0.95 -> 822.96144 | O10: =NetGenbyRegion!$J31*0.95 -> 512.7093 | P10: =NetGenbyRegion!$J32*0.95 -> 625.50432 | Q10: =NetGenbyRegion!$J33*0.95 -> 618.02136 | R10: =NetGenbyRegion!$J34*0.95 -> 31.6521 | S10: 1 | T10: Coal Use in ELC Production
C11: ELC_COAL | D11: ELC-COAL | E11: ELC | F11: ELC | G11: 2015 | H11: UP | I11: 1 | J11: =NetGenbyRegion!$J26*1.02 -> 14.093136 | K11: =NetGenbyRegion!$J27*1.02 -> 249.65928 | L11: =NetGenbyRegion!$J28*1.02 -> 1141.9847 | M11: =NetGenbyRegion!$J29*1.02 -> 715.16606 | N11: =NetGenbyRegion!$J30*1.02 -> 883.6007 | O11: =NetGenbyRegion!$J31*1.02 -> 550.48788 | P11: =NetGenbyRegion!$J32*1.02 -> 671.59411 | Q11: =NetGenbyRegion!$J33*1.02 -> 663.55978 | R11: =NetGenbyRegion!$J34*1.02 -> 33.98436 | S11: 1 | T11: Coal Use in ELC Production
C12: ELC_COAL | D12: ELC-COAL | E12: ELC | F12: ELC | G12: 2020 | H12: LO | I12: 1 | J12: =NetGenbyRegion!$K26*0.95 -> 1.56294 | K12: =NetGenbyRegion!$K27*0.95 -> 137.25486 | L12: =NetGenbyRegion!$K28*0.95 -> 745.94988 | M12: =NetGenbyRegion!$K29*0.95 -> 544.37166 | N12: =NetGenbyRegion!$K30*0.95 -> 543.7116 | O12: =NetGenbyRegion!$K31*0.95 -> 345.33792 | P12: =NetGenbyRegion!$K32*0.95 -> 445.3695 | Q12: =NetGenbyRegion!$K33*0.95 -> 478.2699 | R12: =NetGenbyRegion!$K34*0.95 -> 39.6891 | S12: 1 | T12: Coal Use in ELC Production
C13: ELC_NGA | D13: ELC-NGA | E13: ELC | F13: ELC | G13: 2010 | H13: LO | I13: 1 | J13: =NetGenbyRegion!$L26*0.95 -> 188.4933 | K13: =NetGenbyRegion!$L27*0.95 -> 360.70398 | L13: =NetGenbyRegion!$L28*0.95 -> 120.49002 | M13: =NetGenbyRegion!$L29*0.95 -> 44.24796 | N13: =NetGenbyRegion!$L30*0.95 -> 658.5039 | O13: =NetGenbyRegion!$L31*0.95 -> 244.09566 | P13: =NetGenbyRegion!$L32*0.95 -> 771.88716 | Q13: =NetGenbyRegion!$L33*0.95 -> 275.57676 | R13: =NetGenbyRegion!$L34*0.95 -> 418.75506 | S13: 1 | T13: NG Use in ELC Production
C14: ELC_NGA | D14: ELC-NGA | E14: ELC | F14: ELC | G14: 2010 | H14: UP | I14: 1 | J14: =NetGenbyRegion!$L26*1.1 -> 218.2554 | K14: =NetGenbyRegion!$L27*1.1 -> 417.65724 | L14: =NetGenbyRegion!$L28*1.1 -> 139.51476 | M14: =NetGenbyRegion!$L29*1.1 -> 51.23448 | N14: =NetGenbyRegion!$L30*1.1 -> 762.4782 | O14: =NetGenbyRegion!$L31*1.1 -> 282.63708 | P14: =NetGenbyRegion!$L32*1.1 -> 893.76408 | Q14: =NetGenbyRegion!$L33*1.1 -> 319.08888 | R14: =NetGenbyRegion!$L34*1.7 -> 749.35116 | S14: 1 | T14: NG Use in ELC Production
C15: ELC_NGA | D15: ELC-NGA | E15: ELC | F15: ELC | G15: 2011 | H15: LO | I15: 1 | J15: =NetGenbyRegion!$M26*0.95 -> 205.61382 | K15: =NetGenbyRegion!$M27*0.95 -> 395.61876 | L15: =NetGenbyRegion!$M28*0.95 -> 155.31588 | M15: =NetGenbyRegion!$M29*0.95 -> 40.06188 | N15: =NetGenbyRegion!$M30*0.95 -> 718.71984 | O15: =NetGenbyRegion!$M31*0.95 -> 276.59592 | P15: =NetGenbyRegion!$M32*0.95 -> 822.29454 | Q15: =NetGenbyRegion!$M33*0.95 -> 239.48892 | R15: =NetGenbyRegion!$M34*0.95 -> 314.19882 | S15: 1 | T15: NG Use in ELC Production
C16: ELC_NGA | D16: ELC-NGA | E16: ELC | F16: ELC | G16: 2011 | H16: UP | I16: 1 | J16: =NetGenbyRegion!$M26*1.1 -> 238.07916 | K16: =NetGenbyRegion!$M27*1.1 -> 458.08488 | L16: =NetGenbyRegion!$M28*1.1 -> 179.83944 | M16: =NetGenbyRegion!$M29*1.1 -> 46.38744 | N16: =NetGenbyRegion!$M30*1.1 -> 832.20192 | O16: =NetGenbyRegion!$M31*1.1 -> 320.26896 | P16: =NetGenbyRegion!$M32*1.1 -> 952.13052 | Q16: =NetGenbyRegion!$M33*1.1 -> 277.30296 | R16: =NetGenbyRegion!$M34*1.1 -> 363.80916 | S16: 1 | T16: NG Use in ELC Production
C17: ELC_NGA | D17: ELC-NGA | E17: ELC | F17: ELC | G17: 2015 | H17: LO | I17: 1 | J17: =NetGenbyRegion!$N26*0.95 -> 177.64164 | K17: =NetGenbyRegion!$N27*0.95 -> 514.47744 | L17: =NetGenbyRegion!$N28*0.95 -> 292.79304 | M17: =NetGenbyRegion!$N29*0.95 -> 57.65094 | N17: =NetGenbyRegion!$N30*0.95 -> 1029.2627 | O17: =NetGenbyRegion!$N31*0.95 -> 390.46824 | P17: =NetGenbyRegion!$N32*0.95 -> 983.60226 | Q17: =NetGenbyRegion!$N33*0.95 -> 325.57032 | R17: =NetGenbyRegion!$N34*0.95 -> 461.31696 | S17: 1 | T17: NG Use in ELC Production
C18: ELC_NGA | D18: ELC-NGA | E18: ELC | F18: ELC | G18: 2015 | H18: UP | I18: 1 | J18: =NetGenbyRegion!$N26*1.01 -> 188.86111 | K18: =NetGenbyRegion!$N27*1.01 -> 546.97075 | L18: =NetGenbyRegion!$N28*1.01 -> 311.28523 | M18: =NetGenbyRegion!$N29*1.01 -> 61.292052 | N18: =NetGenbyRegion!$N30*1.01 -> 1094.2687 | O18: =NetGenbyRegion!$N31*1.01 -> 415.12939 | P18: =NetGenbyRegion!$N32*1.01 -> 1045.7245 | Q18: =NetGenbyRegion!$N33*1.01 -> 346.13266 | R18: =NetGenbyRegion!$N34*1.01 -> 490.45277 | S18: 1 | T18: NG Use in ELC Production
C19: ELC_NGA | D19: ELC-NGA | E19: ELC | F19: ELC | G19: 2020 | H19: LO | I19: 1 | J19: =NetGenbyRegion!$O26*0.95 -> 160.40142 | K19: =NetGenbyRegion!$O27*0.95 -> 631.27044 | L19: =NetGenbyRegion!$O28*0.95 -> 521.6355 | M19: =NetGenbyRegion!$O29*0.95 -> 110.13426 | N19: =NetGenbyRegion!$O30*0.95 -> 1298.468 | O19: =NetGenbyRegion!$O31*0.95 -> 460.6911 | P19: =NetGenbyRegion!$O32*0.95 -> 1092.3172 | Q19: =NetGenbyRegion!$O33*0.95 -> 388.37178 | R19: =NetGenbyRegion!$O34*0.95 -> 380.30058 | S19: 1 | T19: NG Use in ELC Production
C20: ELC_PET | D20: ELC-PET | E20: ELC | F20: ELC | G20: 2010 | H20: LO | I20: 1 | J20: =NetGenbyRegion!$X26*0.99 -> 3.17196 | K20: =NetGenbyRegion!$X27*0.99 -> 7.71606 | L20: =NetGenbyRegion!$X28*0.99 -> 2.680128 | M20: =NetGenbyRegion!$X29*0.99 -> 1.215324 | N20: =NetGenbyRegion!$X30*0.99 -> 29.659608 | O20: =NetGenbyRegion!$X31*0.99 -> 1.8711 | P20: =NetGenbyRegion!$X32*0.99 -> 0.905256 | Q20: =NetGenbyRegion!$X33*0.99 -> 0.930204 | R20: =NetGenbyRegion!$X34*0.99 -> 31.59486 | S20: 1 | T20: PET Use in ELC Production
C21: ELC_PET | D21: ELC-PET | E21: ELC | F21: ELC | G21: 2010 | H21: UP | I21: 1 | J21: =NetGenbyRegion!$X26*1.1 -> 3.5244 | K21: =NetGenbyRegion!$X27*1.1 -> 8.5734 | L21: =NetGenbyRegion!$X28*1.1 -> 2.97792 | M21: =NetGenbyRegion!$X29*1.1 -> 1.35036 | N21: =NetGenbyRegion!$X30*1.1 -> 32.95512 | O21: =NetGenbyRegion!$X31*1.1 -> 2.079 | P21: =NetGenbyRegion!$X32*1.1 -> 1.00584 | Q21: =NetGenbyRegion!$X33*1.1 -> 1.03356 | R21: =NetGenbyRegion!$X34*1.1 -> 35.1054 | S21: 1 | T21: PET Use in ELC Production
C22: ELC_PET | D22: ELC-PET | E22: ELC | F22: ELC | G22: 2011 | H22: LO | I22: 1 | J22: =NetGenbyRegion!$Y26*0.99 -> 1.760616 | K22: =NetGenbyRegion!$Y27*0.99 -> 4.772196 | L22: =NetGenbyRegion!$Y28*0.99 -> 2.70864 | M22: =NetGenbyRegion!$Y29*0.99 -> 1.08702 | N22: =NetGenbyRegion!$Y30*0.99 -> 9.804564 | O22: =NetGenbyRegion!$Y31*0.99 -> 1.660824 | P22: =NetGenbyRegion!$Y32*0.99 -> 0.866052 | Q22: =NetGenbyRegion!$Y33*0.99 -> 0.901692 | R22: =NetGenbyRegion!$Y34*0.99 -> 31.124412 | S22: 1 | T22: PET Use in ELC Production
C23: ELC_PET | D23: ELC-PET | E23: ELC | F23: ELC | G23: 2011 | H23: UP | I23: 1 | J23: =NetGenbyRegion!$Y26*1.1 -> 1.95624 | K23: =NetGenbyRegion!$Y27*1.1 -> 5.30244 | L23: =NetGenbyRegion!$Y28*1.1 -> 3.0096 | M23: =NetGenbyRegion!$Y29*1.1 -> 1.2078 | N23: =NetGenbyRegion!$Y30*1.1 -> 10.89396 | O23: =NetGenbyRegion!$Y31*1.1 -> 1.84536 | P23: =NetGenbyRegion!$Y32*1.1 -> 0.96228 | Q23: =NetGenbyRegion!$Y33*1.1 -> 1.00188 | R23: =NetGenbyRegion!$Y34*1.1 -> 34.58268 | S23: 1 | T23: PET Use in ELC Production
C24: ELC_PET | D24: ELC-PET | E24: ELC | F24: ELC | G24: 2015 | H24: LO | I24: 1 | J24: =NetGenbyRegion!$Z26*0.99 -> 6.871392 | K24: =NetGenbyRegion!$Z27*0.99 -> 9.369756 | L24: =NetGenbyRegion!$Z28*0.99 -> 1.928124 | M24: =NetGenbyRegion!$Z29*0.99 -> 1.022868 | N24: =NetGenbyRegion!$Z30*0.99 -> 10.253628 | O24: =NetGenbyRegion!$Z31*0.99 -> 1.147608 | P24: =NetGenbyRegion!$Z32*0.99 -> 0.869616 | Q24: =NetGenbyRegion!$Z33*0.99 -> 0.755568 | R24: =NetGenbyRegion!$Z34*0.99 -> 27.036504 | S24: 5 | T24: PET Use in ELC Production
C25: ELC_PET | D25: ELC-PET | E25: ELC | F25: ELC | G25: 2015 | H25: UP | I25: 1 | J25: =NetGenbyRegion!$Z26*1.1 -> 7.63488 | K25: =NetGenbyRegion!$Z27*1.1 -> 10.41084 | L25: =NetGenbyRegion!$Z28*1.1 -> 2.14236 | M25: =NetGenbyRegion!$Z29*1.1 -> 1.13652 | N25: =NetGenbyRegion!$Z30*1.1 -> 11.39292 | O25: =NetGenbyRegion!$Z31*1.1 -> 1.27512 | P25: =NetGenbyRegion!$Z32*1.1 -> 0.96624 | Q25: =NetGenbyRegion!$Z33*1.1 -> 0.83952 | R25: =NetGenbyRegion!$Z34*1.1 -> 30.04056 | S25: 5 | T25: PET Use in ELC Production
C26: ELC_PET | D26: ELC-PET | E26: ELC | F26: ELC | G26: 2020 | H26: LO | I26: 1 | J26: =NetGenbyRegion!$AA26*0.95 -> 0.8037 | K26: =NetGenbyRegion!$AA27*0.95 -> 2.44188 | L26: =NetGenbyRegion!$AA28*0.95 -> 1.56978 | M26: =NetGenbyRegion!$AA29*0.95 -> 1.08756 | N26: =NetGenbyRegion!$AA30*0.95 -> 4.03902 | O26: =NetGenbyRegion!$AA31*0.95 -> 0.77976 | P26: =NetGenbyRegion!$AA32*0.95 -> 0.4275 | Q26: =NetGenbyRegion!$AA33*0.95 -> 0.74898 | R26: =NetGenbyRegion!$AA34*0.95 -> 25.80048 | S26: 5 | T26: PET Use in ELC Production
C27: ELC_WND | D27: ELC-WND | E27: ELC | F27: ELC | G27: 2010 | H27: LO | I27: 1 | J27: =NetGenbyRegion!$D$39*0.98 -> 2.159136 | K27: =NetGenbyRegion!$D$40*0.98*1 -> 15.745464 | L27: =NetGenbyRegion!$D$41*0.98*1 -> 31.212216 | M27: =NetGenbyRegion!$D$42*0.98*1 -> 85.27176 | N27: =NetGenbyRegion!$D$43*0.98*1 -> 3.326904 | O27: =NetGenbyRegion!$D$44*0.98*1 -> 0.144648 | P27: =NetGenbyRegion!$D$45*0.98*1 -> 106.04815 | Q27: =NetGenbyRegion!$D$46*0.98*1 -> 36.987552 | R27: =NetGenbyRegion!$D$47*0.98*1 -> 52.013304 | S27: 1 | T27: Wind Use in ELC Production
C28: ELC_WND | D28: ELC-WND | E28: ELC | F28: ELC | G28: 2010 | H28: UP | I28: 1 | J28: =NetGenbyRegion!$D$39*1.02 -> 2.247264 | K28: =NetGenbyRegion!$D$40*1.02*1 -> 16.388136 | L28: =NetGenbyRegion!$D$41*1.02*1 -> 32.486184 | M28: =NetGenbyRegion!$D$42*1.02*1 -> 88.75224 | N28: =NetGenbyRegion!$D$43*1.02*1 -> 3.462696 | O28: =NetGenbyRegion!$D$44*1.02*1 -> 0.150552 | P28: =NetGenbyRegion!$D$45*1.02*1 -> 110.37665 | Q28: =NetGenbyRegion!$D$46*1.02*1 -> 38.497248 | R28: =NetGenbyRegion!$D$47*1.02*1 -> 54.136296 | S28: 1 | T28: Wind Use in ELC Production
C29: ELC_WND | D29: ELC-WND | E29: ELC | F29: ELC | G29: 2011 | H29: LO | I29: 1 | J29: =NetGenbyRegion!$E$39*0.98 -> 3.037608 | K29: =NetGenbyRegion!$E$40*0.98*1 -> 16.345224 | L29: =NetGenbyRegion!$E$41*0.98*1 -> 40.000464 | M29: =NetGenbyRegion!$E$42*0.98*1 -> 110.28881 | N29: =NetGenbyRegion!$E$43*0.98*1 -> 4.843944 | O29: =NetGenbyRegion!$E$44*0.98*1 -> 0.186984 | P29: =NetGenbyRegion!$E$45*0.98*1 -> 127.54778 | Q29: =NetGenbyRegion!$E$46*0.98*1 -> 53.99604 | R29: =NetGenbyRegion!$E$47*0.98*1 -> 66.29112 | S29: 1 | T29: Wind Use in ELC Production
C30: ELC_WND | D30: ELC-WND | E30: ELC | F30: ELC | G30: 2011 | H30: UP | I30: 1 | J30: =NetGenbyRegion!$E$39*1.02 -> 3.161592 | K30: =NetGenbyRegion!$E$40*1.02*1 -> 17.012376 | L30: =NetGenbyRegion!$E$41*1.02*1 -> 41.633136 | M30: =NetGenbyRegion!$E$42*1.02*1 -> 114.79039 | N30: =NetGenbyRegion!$E$43*1.02*1 -> 5.041656 | O30: =NetGenbyRegion!$E$44*1.02*1 -> 0.194616 | P30: =NetGenbyRegion!$E$45*1.02*1 -> 132.75382 | Q30: =NetGenbyRegion!$E$46*1.02*1 -> 56.19996 | R30: =NetGenbyRegion!$E$47*1.02*1 -> 68.99688 | S30: 1 | T30: Wind Use in ELC Production
C31: ELC_WND | D31: ELC-WND | E31: ELC | F31: ELC | G31: 2015 | H31: LO | I31: 1 | J31: =NetGenbyRegion!$F$39*0.95*1 -> 7.64028 | K31: =NetGenbyRegion!$F$40*0.95*1 -> 25.13358 | L31: =NetGenbyRegion!$F$41*0.95*1 -> 77.98968 | M31: =NetGenbyRegion!$F$42*0.95*1 -> 177.2757 | N31: =NetGenbyRegion!$F$43*0.95*1 -> 6.19362 | O31: =NetGenbyRegion!$F$44*0.95*1 -> 0.15732 | P31: =NetGenbyRegion!$F$45*0.95*1 -> 201.21228 | Q31: =NetGenbyRegion!$F$46*0.95*1 -> 64.7577 | R31: =NetGenbyRegion!$F$47*0.95*1 -> 88.67034 | S31: 1 | T31: Wind Use in ELC Production
C32: ELC_WND | D32: ELC-WND | E32: ELC | F32: ELC | G32: 2015 | H32: UP | I32: 1 | J32: =NetGenbyRegion!$F$39*1.05*1 -> 8.44452 | K32: =NetGenbyRegion!$F$40*1.05*1 -> 27.77922 | L32: =NetGenbyRegion!$F$41*1.05*1 -> 86.19912 | M32: =NetGenbyRegion!$F$42*1.05*1 -> 195.9363 | N32: =NetGenbyRegion!$F$43*1.05*1 -> 6.84558 | O32: =NetGenbyRegion!$F$44*1.05*1 -> 0.17388 | P32: =NetGenbyRegion!$F$45*1.05*1 -> 222.39252 | Q32: =NetGenbyRegion!$F$46*1.05*1 -> 71.5743 | R32: =NetGenbyRegion!$F$47*1.05*1 -> 98.00406 | S32: 1 | T32: Wind Use in ELC Production
C33: ELC_WND | D33: ELC-WND | E33: ELC | F33: ELC | G33: 2020 | H33: LO | I33: 1 | J33: =NetGenbyRegion!$G$39*0.95*1 -> 12.40434 | K33: =NetGenbyRegion!$G$40*0.95*1 -> 28.77246 | L33: =NetGenbyRegion!$G$41*0.95*1 -> 100.62324 | M33: =NetGenbyRegion!$G$42*0.95*1 -> 284.22594 | N33: =NetGenbyRegion!$G$43*0.95*1 -> 9.70596 | O33: =NetGenbyRegion!$G$44*0.95*1 -> 0.14022 | P33: =NetGenbyRegion!$G$45*0.95*1 -> 387.30132 | Q33: =NetGenbyRegion!$G$46*0.95*1 -> 97.43238 | R33: =NetGenbyRegion!$G$47*0.95*1 -> 102.09384 | S33: 1 | T33: Wind Use in ELC Production
C34: ELC_SOL | D34: ELC-SOL | E34: ELC | F34: ELC | G34: 2010 | H34: LO | I34: 1 | J34: 0 | K34: =NetGenbyRegion!$H$40*0.98*1 -> 0.098784 | L34: 0 | M34: =NetGenbyRegion!$H$42*0.98*1 -> 0 | N34: 0 | O34: =NetGenbyRegion!$H$44*0.98*1 -> 0 | P34: 0 | Q34: =NetGenbyRegion!$H$46*0.98*1 -> 0.994896 | R34: =NetGenbyRegion!$H$47*0.98*1 -> 2.69892 | S34: 1 | T34: Solar Use in ELC Production
C35: ELC_SOL | D35: ELC-SOL | E35: ELC | F35: ELC | G35: 2010 | H35: UP | I35: 1 | J35: =NetGenbyRegion!$H$39*1.02*1 -> 0.003672 | K35: =NetGenbyRegion!$H$40*1.02*1 -> 0.102816 | L35: =NetGenbyRegion!$H$41*1.02*1 -> 0.099144 | M35: =NetGenbyRegion!$H$42*1.02*1 -> 0 | N35: =NetGenbyRegion!$H$43*1.02*1 -> 0.337824 | O35: =NetGenbyRegion!$H$44*1.02*1 -> 0 | P35: =NetGenbyRegion!$H$45*1.02*1 -> 0.029376 | Q35: =NetGenbyRegion!$H$46*1.02*1 -> 1.035504 | R35: =NetGenbyRegion!$H$47*1.02*1 -> 2.80908 | S35: 1 | T35: Solar Use in ELC Production
C36: ELC_SOL | D36: ELC-SOL | E36: ELC | F36: ELC | G36: 2011 | H36: LO | I36: 1 | J36: =NetGenbyRegion!$I$39*0.98*1 -> 0.021168 | K36: =NetGenbyRegion!$I$40*0.98*1 -> 0.29988 | L36: =NetGenbyRegion!$I$41*0.98*1 -> 0.10584 | M36: =NetGenbyRegion!$I$42*0.98*1 -> 0 | N36: =NetGenbyRegion!$I$43*0.98*1 -> 0.543312 | O36: =NetGenbyRegion!$I$44*0.98*1 -> 0 | P36: =NetGenbyRegion!$I$45*0.98*1 -> 0.102312 | Q36: =NetGenbyRegion!$I$46*0.98*1 -> 1.972152 | R36: =NetGenbyRegion!$I$47*0.98*1 -> 3.041136 | S36: 1 | T36: Solar Use in ELC Production
C37: ELC_SOL | D37: ELC-SOL | E37: ELC | F37: ELC | G37: 2011 | H37: UP | I37: 1 | J37: =NetGenbyRegion!$I$39*1.02*1 -> 0.022032 | K37: =NetGenbyRegion!$I$40*1.02*1 -> 0.31212 | L37: =NetGenbyRegion!$I$41*1.02*1 -> 0.11016 | M37: =NetGenbyRegion!$I$42*1.02*1 -> 0 | N37: =NetGenbyRegion!$I$43*1.02*1 -> 0.565488 | O37: =NetGenbyRegion!$I$44*1.02*1 -> 0 | P37: =NetGenbyRegion!$I$45*1.02*1 -> 0.106488 | Q37: =NetGenbyRegion!$I$46*1.02*1 -> 2.052648 | R37: =NetGenbyRegion!$I$47*1.02*1 -> 3.165264 | S37: 1 | T37: Solar Use in ELC Production
C38: ELC_SOL | D38: ELC-SOL | E38: ELC | F38: ELC | G38: 2015 | H38: LO | I38: 1 | J38: =NetGenbyRegion!$J$39*0.98*1 -> 1.862784 | K38: =NetGenbyRegion!$J$40*0.98*1 -> 2.272032 | L38: =NetGenbyRegion!$J$41*0.98*1 -> 0.913752 | M38: =NetGenbyRegion!$J$42*0.98*1 -> 0.074088 | N38: =NetGenbyRegion!$J$43*0.98*1 -> 6.378624 | O38: =NetGenbyRegion!$J$44*0.98*1 -> 0.257544 | P38: =NetGenbyRegion!$J$45*0.98*1 -> 1.414728 | Q38: =NetGenbyRegion!$J$46*0.98*1 -> 20.92104 | R38: =NetGenbyRegion!$J$47*0.98*1 -> 51.988608 | S38: 1 | T38: Solar Use in ELC Production
C39: ELC_SOL | D39: ELC-SOL | E39: ELC | F39: ELC | G39: 2015 | H39: UP | I39: 1 | J39: =NetGenbyRegion!$J$39*1.02*1 -> 1.938816 | K39: =NetGenbyRegion!$J$40*1.02*1 -> 2.364768 | L39: =NetGenbyRegion!$J$41*1.02*1 -> 0.951048 | M39: =NetGenbyRegion!$J$42*1.02*1 -> 0.077112 | N39: =NetGenbyRegion!$J$43*1.02*1 -> 6.638976 | O39: =NetGenbyRegion!$J$44*1.02*1 -> 0.268056 | P39: =NetGenbyRegion!$J$45*1.02*1 -> 1.472472 | Q39: =NetGenbyRegion!$J$46*1.02*1 -> 21.77496 | R39: =NetGenbyRegion!$J$47*1.02*1 -> 54.110592 | S39: 1 | T39: Solar Use in ELC Production
C40: ELC_SOL | D40: ELC-SOL | E40: ELC | F40: ELC | G40: 2020 | H40: LO | I40: 1 | J40: =NetGenbyRegion!$K$39*0.98*1.4 -> 7.8928416 | K40: =NetGenbyRegion!$K$40*0.98*1.4 -> 8.76708 | L40: =NetGenbyRegion!$K$41*0.98*1.4 -> 3.7142784 | M40: =NetGenbyRegion!$K$42*0.98*1.4 -> 8.3274912 | N40: =NetGenbyRegion!$K$43*0.98*1.4 -> 75.747571 | O40: =NetGenbyRegion!$K$44*0.98*1.4 -> 5.2997616 | P40: =NetGenbyRegion!$K$45*0.98*1.4 -> 22.621536 | Q40: =NetGenbyRegion!$K$46*0.98*1.4 -> 75.796963 | R40: =NetGenbyRegion!$K$47*0.98*1.4 -> 143.89865 | S40: 1 | T40: Solar Use in ELC Production
C41: ELC_BIO | D41: ELC-BIO | E41: ELC | F41: ELC | G41: 2010 | H41: LO | I41: 1 | J41: 0 | K41: =NetGenbyRegion!$L$40*0.98 -> 15.177456 | L41: =NetGenbyRegion!$L$41*0.98 -> 12.584376 | M41: =NetGenbyRegion!$L$42*0.5 -> 2.9106 | N41: =NetGenbyRegion!$L$43*0.98 -> 18.747792 | O41: =NetGenbyRegion!$L$44*0.98 -> 1.319472 | P41: =NetGenbyRegion!$L$45*0.98 -> 1.933344 | Q41: =NetGenbyRegion!$L$46*0.98 -> 1.365336 | R41: 0 | S41: 1 | T41: Wind Use in ELC Production
...

Sheet onTechs
B1: ~UC_Sets: R_E: R1,R2,R3,R4,R5,R6,R7,R8,R9
B2: ~UC_Sets: T_E:
G4: ~UC_T:UC_RHSRT
C5: UC_N | D5: PSET_SET | E5: PSET_PN | F5: Year | G5: LimType | H5: UC_ACT | I5: R1 | J5: R2 | K5: R3 | L5: R4 | M5: R5 | N5: R6 | O5: R7 | P5: R8 | Q5: R9 | R5: UC_RHSRT~0 | S5: UC_Desc
C6: ELC_NUK | D6: ELE | E6: EURNALWRO, EURNALWRR | F6: 2010 | G6: LO | H6: 1 | I6: =NetGenbyRegion!$P$26*0.98 -> 135.33761 | J6: =NetGenbyRegion!$P$27*0.98 -> 537.91063 | K6: =NetGenbyRegion!$P$28*0.98 -> 546.4872 | L6: =NetGenbyRegion!$P$29*0.98 -> 167.70348 | M6: =NetGenbyRegion!$P$30*0.98 -> 672.93425 | N6: =NetGenbyRegion!$P$31*0.98 -> 265.73954 | O6: =NetGenbyRegion!$P$32*0.98 -> 264.58942 | P6: =NetGenbyRegion!$P$33*0.98 -> 110.0736 | Q6: =NetGenbyRegion!$P$34*0.98 -> 146.20738 | R6: 5 | S6: Nuclear use in ELC production
C7: ELC_NUK | D7: ELE | E7: EURNALWRO, EURNALWRR | F7: 2010 | G7: UP | H7: 1 | I7: =NetGenbyRegion!$P$26*1.02 -> 140.86159 | J7: =NetGenbyRegion!$P$27*1.02 -> 559.86617 | K7: =NetGenbyRegion!$P$28*1.02 -> 568.7928 | L7: =NetGenbyRegion!$P$29*1.02 -> 174.54852 | M7: =NetGenbyRegion!$P$30*1.02 -> 700.40095 | N7: =NetGenbyRegion!$P$31*1.02 -> 276.58606 | O7: =NetGenbyRegion!$P$32*1.02 -> 275.38898 | P7: =NetGenbyRegion!$P$33*1.02 -> 114.5664 | Q7: =NetGenbyRegion!$P$34*1.02 -> 152.17502 | R7: 5 | S7: Nuclear use in ELC production
C8: ELC_NUK | D8: ELE | E8: EURNALWRO, EURNALWRR | F8: 2011 | G8: LO | H8: 1 | I8: =NetGenbyRegion!$Q$26*0.98 -> 120.95042 | J8: =NetGenbyRegion!$Q$27*0.98 -> 537.83654 | K8: =NetGenbyRegion!$Q$28*0.98 -> 547.41154 | L8: =NetGenbyRegion!$Q$29*0.98 -> 143.93182 | M8: =NetGenbyRegion!$Q$30*0.98 -> 662.19149 | N8: =NetGenbyRegion!$Q$31*0.98 -> 270.28714 | O8: =NetGenbyRegion!$Q$32*0.98 -> 248.57582 | P8: =NetGenbyRegion!$Q$33*0.98 -> 110.34878 | Q8: =NetGenbyRegion!$Q$34*0.98 -> 146.30616 | R8: 5 | S8: Nuclear use in ELC production
C9: ELC_NUK | D9: ELE | E9: EURNALWRO, EURNALWRR | F9: 2011 | G9: UP | H9: 1 | I9: =NetGenbyRegion!$Q$26*1.02 -> 125.88718 | J9: =NetGenbyRegion!$Q$27*1.02 -> 559.78906 | K9: =NetGenbyRegion!$Q$28*1.02 -> 569.75486 | L9: =NetGenbyRegion!$Q$29*1.02 -> 149.80658 | M9: =NetGenbyRegion!$Q$30*1.02 -> 689.21971 | N9: =NetGenbyRegion!$Q$31*1.02 -> 281.31926 | O9: =NetGenbyRegion!$Q$32*1.02 -> 258.72178 | P9: =NetGenbyRegion!$Q$33*1.02 -> 114.85282 | Q9: =NetGenbyRegion!$Q$34*1.02 -> 152.27784 | R9: 5 | S9: Nuclear use in ELC production
C10: ELC_NUK | D10: ELE | E10: EURNALWRO, EURNALWRR | F10: 2015 | G10: LO | H10: 1 | I10: =NetGenbyRegion!$R$26*0.98 -> 112.50792 | J10: =NetGenbyRegion!$R$27*0.98 -> 558.76817 | K10: =NetGenbyRegion!$R$28*0.98 -> 543.31553 | L10: =NetGenbyRegion!$R$29*0.98 -> 164.67646 | M10: =NetGenbyRegion!$R$30*0.98 -> 705.30718 | N10: =NetGenbyRegion!$R$31*0.98 -> 277.39253 | O10: =NetGenbyRegion!$R$32*0.98 -> 241.6433 | P10: =NetGenbyRegion!$R$33*0.98 -> 114.75173 | Q10: =NetGenbyRegion!$R$34*0.98 -> 94.077648 | R10: 5 | S10: Nuclear use in ELC production
C11: ELC_NUK | D11: ELE | E11: EURNALWRO, EURNALWRR | F11: 2015 | G11: UP | H11: 1 | I11: =NetGenbyRegion!$R$26*1.02 -> 117.10008 | J11: =NetGenbyRegion!$R$27*1.02 -> 581.57503 | K11: =NetGenbyRegion!$R$28*1.02 -> 565.49167 | L11: =NetGenbyRegion!$R$29*1.02 -> 171.39794 | M11: =NetGenbyRegion!$R$30*1.02 -> 734.09522 | N11: =NetGenbyRegion!$R$31*1.02 -> 288.71467 | O11: =NetGenbyRegion!$R$32*1.02 -> 251.5063 | P11: =NetGenbyRegion!$R$33*1.02 -> 119.43547 | Q11: =NetGenbyRegion!$R$34*1.02 -> 97.917552 | R11: 5 | S11: Nuclear use in ELC production
C12: ELC_NUK | D12: ELE | E12: EURNALWRO, EURNALWRR | F12: 2020 | G12: LO | H12: 1 | I12: =I10*0.75 -> 84.38094 | J12: =J10*0.75 -> 419.07613 | K12: =K10*0.75 -> 407.48665 | L12: =L10*0.75 -> 123.50734 | M12: =M10*0.75 -> 528.98038 | N12: =N10*0.75 -> 208.0444 | O12: =O10*0.75 -> 181.23248 | P12: =P10*0.75 -> 86.063796 | Q12: =Q10*0.75 -> 70.558236 | R12: 5 | S12: Nuclear use in ELC production
C13: ELC_NUK | D13: ELE | E13: EURNALWRO, EURNALWRR | F13: 2020 | G13: UP | H13: 1 | I13: =I11 -> 117.10008 | J13: =J11 -> 581.57503 | K13: =K11 -> 565.49167 | L13: =L11 -> 171.39794 | M13: =M11 -> 734.09522 | N13: =N11 -> 288.71467 | O13: =O11 -> 251.5063 | P13: =P11 -> 119.43547 | Q13: =Q11 -> 97.917552 | R13: 5 | S13: Nuclear use in ELC production
C14: ELC_NUK | D14: ELE | E14: EURNALWRO, EURNALWRR | F14: 2030 | G14: UP | H14: 1 | I14: =I13*0.85 -> 99.535068 | J14: =J13*0.85 -> 494.33878 | K14: =K13*0.85 -> 480.66792 | L14: =L13*0.85 -> 145.68825 | M14: =M13*0.85 -> 623.98094 | N14: =N13*0.85 -> 245.40747 | O14: =O13*0.85 -> 213.78035 | P14: =P13*0.85 -> 101.52015 | Q14: =Q13*0.85 -> 83.229919 | R14: 5 | S14: Nuclear use in ELC production
C15: ELC_NUK | D15: ELE | E15: EURNALWRO, EURNALWRR | F15: 2055 | G15: UP | H15: 1 | I15: =I14 -> 99.535068 | J15: =J14 -> 494.33878 | K15: =K14 -> 480.66792 | L15: =L14 -> 145.68825 | M15: =M14 -> 623.98094 | N15: =N14 -> 245.40747 | O15: =O14 -> 213.78035 | P15: =P14 -> 101.52015 | Q15: =Q14 -> 83.229919 | R15: 5 | S15: Nuclear use in ELC production
C16: ELC_HYD | D16: ELE | E16: EHYDCONR | F16: 2010 | G16: LO | H16: 1 | I16: =NetGenbyRegion!$T$26*0.8 -> 20.9664 | J16: =NetGenbyRegion!$T$27*0.8 -> 79.95168 | K16: =NetGenbyRegion!$T$28*0.8 -> 12.096 | L16: =NetGenbyRegion!$T$29*0.8 -> 34.00992 | M16: =NetGenbyRegion!$T$30*0.8 -> 42.1056 | N16: =NetGenbyRegion!$T$31*0.8 -> 55.93536 | O16: =NetGenbyRegion!$T$32*0.8 -> 25.45344 | P16: =NetGenbyRegion!$T$33*0.8 -> 88.88544 | Q16: =NetGenbyRegion!$T$34*0.8 -> 384.94368 | R16: 5 | S16: Hydropower use in ELC production
C17: ELC_HYD | D17: ELE | E17: EHYDCONR | F17: 2010 | G17: UP | H17: 1 | I17: =NetGenbyRegion!$T$26*1 -> 26.208 | J17: =NetGenbyRegion!$T$27*1 -> 99.9396 | K17: =NetGenbyRegion!$T$28*1 -> 15.12 | L17: =NetGenbyRegion!$T$29*1 -> 42.5124 | M17: =NetGenbyRegion!$T$30*1 -> 52.632 | N17: =NetGenbyRegion!$T$31*1 -> 69.9192 | O17: =NetGenbyRegion!$T$32*1 -> 31.8168 | P17: =NetGenbyRegion!$T$33*1 -> 111.1068 | Q17: =NetGenbyRegion!$T$34*1 -> 481.1796 | R17: 5 | S17: Hydropower use in ELC production
C18: ELC_HYD | D18: ELE | E18: EHYDCONR | F18: 2011 | G18: LO | H18: 1 | I18: =NetGenbyRegion!$U$26*0.8 -> 22.87584 | J18: =NetGenbyRegion!$U$27*0.8 -> 89.73792 | K18: =NetGenbyRegion!$U$28*0.8 -> 12.25152 | L18: =NetGenbyRegion!$U$29*0.8 -> 39.0528 | M18: =NetGenbyRegion!$U$30*0.8 -> 37.28448 | N18: =NetGenbyRegion!$U$31*0.8 -> 61.71552 | O18: =NetGenbyRegion!$U$32*0.8 -> 17.48736 | P18: =NetGenbyRegion!$U$33*0.8 -> 121.23936 | Q18: =NetGenbyRegion!$U$34*0.8 -> 358.99114 | R18: 5 | S18: Hydropower use in ELC production
C19: ELC_HYD | D19: ELE | E19: EHYDCONR | F19: 2011 | G19: UP | H19: 1 | I19: =NetGenbyRegion!$U$26*1 -> 28.5948 | J19: =NetGenbyRegion!$U$27*1 -> 112.1724 | K19: =NetGenbyRegion!$U$28*1 -> 15.3144 | L19: =NetGenbyRegion!$U$29*1 -> 48.816 | M19: =NetGenbyRegion!$U$30*1 -> 46.6056 | N19: =NetGenbyRegion!$U$31*1 -> 77.1444 | O19: =NetGenbyRegion!$U$32*1 -> 21.8592 | P19: =NetGenbyRegion!$U$33*1 -> 151.5492 | Q19: =NetGenbyRegion!$U$34*1 -> 448.73892 | R19: 5 | S19: Hydropower use in ELC production
C20: ELC_HYD | D20: ELE | E20: EHYDCONR | F20: 2015 | G20: LO | H20: 1 | I20: =NetGenbyRegion!$V$26*0.9 -> 21.06972 | J20: =NetGenbyRegion!$V$27*0.9 -> 92.53764 | K20: =NetGenbyRegion!$V$28*0.9 -> 14.92992 | L20: =NetGenbyRegion!$V$29*0.9 -> 38.67912 | M20: =NetGenbyRegion!$V$30*0.9 -> 45.68724 | N20: =NetGenbyRegion!$V$31*0.9 -> 74.02428 | O20: =NetGenbyRegion!$V$32*0.9 -> 26.53236 | P20: =NetGenbyRegion!$V$33*0.9 -> 99.77256 | Q20: =NetGenbyRegion!$V$34*0.9 -> 389.11104 | R20: 5 | S20: Hydropower use in ELC production
C21: ELC_HYD | D21: ELE | E21: EHYDCONR | F21: 2015 | G21: UP | H21: 1 | I21: =NetGenbyRegion!$V$26*1 -> 23.4108 | J21: =NetGenbyRegion!$V$27*1 -> 102.8196 | K21: =NetGenbyRegion!$V$28*1 -> 16.5888 | L21: =NetGenbyRegion!$V$29*1 -> 42.9768 | M21: =NetGenbyRegion!$V$30*1 -> 50.7636 | N21: =NetGenbyRegion!$V$31*1 -> 82.2492 | O21: =NetGenbyRegion!$V$32*1 -> 29.4804 | P21: =NetGenbyRegion!$V$33*1 -> 110.8584 | Q21: =NetGenbyRegion!$V$34*1 -> 432.3456 | R21: 5 | S21: Hydropower use in ELC production
C22: ELC_HYD | D22: ELE | E22: EHYDCONR | F22: 2020 | G22: UP | H22: 1 | I22: =I21 -> 23.4108 | J22: =J21 -> 102.8196 | K22: =K21 -> 16.5888 | L22: =L21 -> 42.9768 | M22: =M21 -> 50.7636 | N22: =N21 -> 82.2492 | O22: =O21 -> 29.4804 | P22: =P21 -> 110.8584 | Q22: =Q21 -> 432.3456 | R22: 5 | S22: Hydropower use in ELC production
C23: ELC_HYD | D23: ELE | E23: EHYDCONR | F23: 2055 | G23: UP | H23: 1 | I23: =I22 -> 23.4108 | J23: =J22 -> 102.8196 | K23: =K22 -> 16.5888 | L23: =L22 -> 42.9768 | M23: =M22 -> 50.7636 | N23: =N22 -> 82.2492 | O23: =O22 -> 29.4804 | P23: =P22 -> 110.8584 | Q23: =Q22 -> 432.3456 | R23: 5 | S23: Hydropower use in ELC production

Sheet cofire data
B1: ~UC_Sets: R_E: R1,R2,R3,R4,R5,R6,R7,R8,R9
B2: ~UC_Sets: T_E:
G4: ~UC_T:UC_RHSRT~UP
D5: UC_N | E5: PSET_SET | F5: PSET_PN | G5: Year | H5: UC_ACT | I5: UC_RHSRT | J5: UC_RHSRT~0 | K5: UC_Desc
D6: ELCBICFBHO | F6: SECSTBHFGO | G6: 2010 | H6: -0.1 | I6: 0 | J6: 5 | K6: Limit on biomass co-firing E input to resid BH coal steam over 100 MW
F7: SEELCBIBHO | H7: 0.9
D8: ELCBICFBHU | F8: SECSTBHFGU | G8: 2010 | H8: -0.1 | I8: 0 | J8: 5 | K8: Limit on biomass co-firing E input to resid BH coal steam under 100 MW
F9: SEELCBIBHU | H9: 0.9
D10: ELCBICFBMO | F10: SECSTBMFGO | G10: 2010 | H10: -0.1 | I10: 0 | J10: 5 | K10: Limit on biomass co-firing E input to resid BM coal steam over 100 MW
F11: SEELCBIBMO | H11: 0.9
D12: ELCBICFBMU | F12: SECSTBMFGU | G12: 2010 | H12: -0.1 | I12: 0 | J12: 5 | K12: Limit on biomass co-firing E input to resid BM coal steam under 100 MW
F13: SEELCBIBMU | H13: 0.9
D14: ELCBICFBLO | F14: SECSTBLFGO | G14: 2010 | H14: -0.1 | I14: 0 | J14: 5 | K14: Limit on biomass co-firing E input to resid BL coal steam over 100 MW
F15: SEELCBIBLO | H15: 0.9
D16: ELCBICFBLU | F16: SECSTBLFGU | G16: 2010 | H16: -0.1 | I16: 0 | J16: 5 | K16: Limit on biomass co-firing E input to resid BL coal steam under 100 MW
F17: SEELCBIBLU | H17: 0.9
D18: ELCBICFLHO | F18: SECSTLHFGO | G18: 2010 | H18: -0.1 | I18: 0 | J18: 5 | K18: Limit on biomass co-firing E input to resid LH coal steam over 100 MW
F19: SEELCBILHO | H19: 0.9
D20: ELCBICFLHU | F20: SECSTLHFGU | G20: 2010 | H20: -0.1 | I20: 0 | J20: 5 | K20: Limit on biomass co-firing E input to resid LH coal steam under 100 MW
F21: SEELCBILHU | H21: 0.9
D22: ELCBICFLMO | F22: SECSTLMFGO | G22: 2010 | H22: -0.1 | I22: 0 | J22: 5 | K22: Limit on biomass co-firing E input to resid LM coal steam over 100 MW
F23: SEELCBILMO | H23: 0.9
D24: ELCBICFLMU | F24: SECSTLMFGU | G24: 2010 | H24: -0.1 | I24: 0 | J24: 5 | K24: Limit on biomass co-firing E input to resid LM coal steam under 100 MW
F25: SEELCBILMU | H25: 0.9
D26: ELCBICFSMO | F26: SECSTSMFGO | G26: 2010 | H26: -0.1 | I26: 0 | J26: 5 | K26: Limit on biomass co-firing E input to resid SM coal steam over 100 MW
F27: SEELCBISMO | H27: 0.9
D28: ELCBICFSMU | F28: SECSTSMFGU | G28: 2010 | H28: -0.1 | I28: 0 | J28: 5 | K28: Limit on biomass co-firing E input to resid SM coal steam under 100 MW
F29: SEELCBISMU | H29: 0.9
D30: ELCBICFSLO | F30: SECSTSLFGO | G30: 2010 | H30: -0.1 | I30: 0 | J30: 5 | K30: Limit on biomass co-firing E input to resid SL coal steam over 100 MW
F31: SEELCBISLO | H31: 0.9
D32: ELCBICFSLU | F32: SECSTSLFGU | G32: 2010 | H32: -0.1 | I32: 0 | J32: 5 | K32: Limit on biomass co-firing E input to resid SL coal steam under 100 MW
F33: SEELCBISLU | H33: 0.9
D34: ELCBIOCFN | F34: SECSTMBH | G34: 2010 | H34: -0.1 | I34: 0 | J34: 5 | K34: Limit on biomass co-firing E input to new coal steam
F35: SECSTMBM | H35: -0.1
F36: SECSTMBL | H36: -0.1
F37: SECSTMLH | H37: -0.1
F38: SECSTMLM | H38: -0.1
F39: SECSTMSM | H39: -0.1
F40: SECSTMSL | H40: -0.1
F41: SEELCBION | H41: 0.9

Sheet NetGenbyRegion
A1: http://www.eia.gov/electricity/data/browser/
A2: 42248
A3: Source: U.S. Energy Information Administration
A5: Electricity production (historic) from EIA | C5: kMWh
B6: thousand megawatthours | C6: all | G6: Coal | K6: gas | O6: nuke | S6: hydro | W6: oil | AA6: Wind | AE6: Solar | AI6: Biomass | AM6: Geothermal
B7: thousand megawatthours | C7: 2010 | D7: 2011 | E7: 2015 | F7: 2019 | G7: 2010 | H7: 2011 | I7: 2015 | J7: 2019 | K7: 2010 | L7: 2011 | M7: 2015 | N7: 2019 | O7: 2010 | P7: 2011 | Q7: 2015 | R7: 2019 | S7: 2010 | T7: 2011 | U7: 2015 | V7: 2019 | W7: 2010 | X7: 2011 | Y7: 2015 | Z7: 2019 | AA7: 2010 | AB7: 2011 | AC7: 2015 | AD7: 2019 | AE7: 2010 | AF7: 2011 | AG7: 2015 | AH7: 2019 | AI7: 2010 | AJ7: 2011 | AK7: 2015 | AL7: 2019 | AM7: 2010 | AN7: 2011 | AO7: 2015 | AP7: 2019
A8: Electric Power : United States | B8: thousand megawatthours | C8: 3972386 | D8: 3948186 | E8: 3919294 | F8: 3955781 | G8: 1827738 | H8: 1717891 | I8: 1340993 | J8: 959507 | K8: 901389 | L8: 926290 | M8: 1237656 | N8: 1474734 | O8: 806968 | P8: 790204 | Q8: 797178 | R8: 809409 | S8: 258455 | T8: 317531 | U8: 247636 | V8: 272377 | W8: 22375 | X8: 15343 | Y8: 16626 | Z8: 11024 | AA8: 94636 | AB8: 120121 | AC8: 190547 | AD8: 299785 | AE8: 1206 | AF8: 1727 | AG8: 24456 | AH8: 71547 | AI8: 27822 | AJ8: 26722 | AK8: 32386 | AL8: 28753 | AM8: 15219 | AN8: 15316 | AO8: 15918 | AP8: 15569
A9: Electric Power : New England | B9: thousand megawatthours | C9: 123441 | D9: 117021 | E9: 106031 | F9: 96052 | G9: 14020 | H9: 6801 | I9: 3838 | J9: 457 | K9: 55115 | L9: 60121 | M9: 51942 | N9: 46901 | O9: 38361 | P9: 34283 | Q9: 31890 | R9: 29818 | S9: 7280 | T9: 7943 | U9: 6503 | V9: 7039 | W9: 890 | X9: 494 | Y9: 1928 | Z9: 235 | AA9: 612 | AB9: 861 | AC9: 2234 | AD9: 3627 | AE9: 1 | AF9: 6 | AG9: 528 | AH9: 1598 | AI9: 5729 | AJ9: 5059 | AK9: 6029 | AL9: 5095 | AM9: 0 | AN9: 0 | AO9: 0 | AP9: 0
A10: Electric Power : Middle Atlantic | B10: thousand megawatthours | C10: 426598 | D10: 423543 | E10: 421071 | F10: 428483 | G10: 128950 | H10: 112978 | I10: 67990 | J10: 40133 | K10: 105469 | L10: 115678 | M10: 150432 | N10: 184582 | O10: 152469 | P10: 152448 | Q10: 158381 | R10: 154732 | S10: 27761 | T10: 31159 | U10: 28561 | V10: 33540 | W10: 2165 | X10: 1339 | Y10: 2629 | Z10: 714 | AA10: 4463 | AB10: 4633 | AC10: 7349 | AD10: 8413 | AE10: 28 | AF10: 85 | AG10: 644 | AH10: 1775 | AI10: 4302 | AJ10: 4067 | AK10: 4297 | AL10: 3677 | AM10: 0 | AN10: 0 | AO10: 0 | AP10: 0
A11: Electric Power : East North Central | B11: thousand megawatthours | C11: 634383 | D11: 617796 | E11: 587365 | F11: 570550 | G11: 425653 | H11: 394593 | I11: 310998 | J11: 218114 | K11: 35231 | L11: 45414 | M11: 85612 | N11: 152525 | O11: 154900 | P11: 155162 | Q11: 154001 | R11: 158686 | S11: 4200 | T11: 4254 | U11: 4608 | V11: 3739 | W11: 752 | X11: 760 | Y11: 541 | Z11: 459 | AA11: 8847 | AB11: 11338 | AC11: 22804 | AD11: 29422 | AE11: 27 | AF11: 30 | AG11: 259 | AH11: 752 | AI11: 3567 | AJ11: 3876 | AK11: 3929 | AL11: 3637 | AM11: 0 | AN11: 0 | AO11: 0 | AP11: 0
A12: Electric Power : West North Central | B12: thousand megawatthours | C12: 328467 | D12: 328311 | E12: 324703 | F12: 334750 | G12: 228740 | H12: 228675 | I12: 194762 | J12: 159173 | K12: 12938 | L12: 11714 | M12: 16857 | N12: 32203 | O12: 47535 | P12: 40797 | Q12: 46677 | R12: 44729 | S12: 11809 | T12: 13560 | U12: 11938 | V12: 11904 | W12: 341 | X12: 305 | Y12: 287 | Z12: 318 | AA12: 24170 | AB12: 31261 | AC12: 51835 | AD12: 83107 | AE12: 0 | AF12: 0 | AG12: 21 | AH12: 1686 | AI12: 1617 | AJ12: 1434 | AK12: 1574 | AL12: 961 | AM12: 0 | AN12: 0 | AO12: 0 | AP12: 0
A13: Electric Power : South Atlantic | B13: thousand megawatthours | C13: 784712 | D13: 743048 | E13: 771534 | F13: 790488 | G13: 369577 | H13: 321478 | I13: 240632 | J13: 158980 | K13: 192545 | L13: 210152 | M13: 300954 | N13: 379669 | O13: 190741 | P13: 187696 | Q13: 199917 | R13: 205228 | S13: 14620 | T13: 12946 | U13: 14101 | V13: 17564 | W13: 8322 | X13: 2751 | Y13: 2877 | Z13: 1181 | AA13: 943 | AB13: 1373 | AC13: 1811 | AD13: 2838 | AE13: 92 | AF13: 154 | AG13: 1808 | AH13: 15336 | AI13: 5314 | AJ13: 5508 | AK13: 8288 | AL13: 8390 | AM13: 0 | AN13: 0 | AO13: 0 | AP13: 0
A14: Electric Power : East South Central | B14: thousand megawatthours | C14: 378075 | D14: 378141 | E14: 366924 | F14: 351884 | G14: 209557 | H14: 197406 | I14: 149915 | J14: 100976 | K14: 71373 | L14: 80876 | M14: 114172 | N14: 134705 | O14: 75323 | P14: 76612 | Q14: 78626 | R14: 90410 | S14: 19422 | T14: 21429 | U14: 22847 | V14: 24703 | W14: 525 | X14: 466 | Y14: 322 | Z14: 228 | AA14: 41 | AB14: 53 | AC14: 46 | AD14: 41 | AE14: 0 | AF14: 0 | AG14: 73 | AH14: 1073 | AI14: 374 | AJ14: 355 | AK14: 437 | AL14: 316 | AM14: 0 | AN14: 0 | AO14: 0 | AP14: 0
A15: Electric Power : West South Central | B15: thousand megawatthours | C15: 575326 | D15: 607117 | E15: 613032 | F15: 648613 | G15: 229880 | H15: 245902 | I15: 182896 | J15: 130225 | K15: 225698 | L15: 240437 | M15: 287603 | N15: 319391 | O15: 74997 | P15: 70458 | Q15: 68493 | R15: 68854 | S15: 8838 | T15: 6072 | U15: 8189 | V15: 6686 | W15: 254 | X15: 243 | Y15: 244 | Z15: 125 | AA15: 30059 | AB15: 36153 | AC15: 58834 | AD15: 113246 | AE15: 8 | AF15: 29 | AG15: 401 | AH15: 4580 | AI15: 548 | AJ15: 688 | AK15: 1050 | AL15: 623 | AM15: 0 | AN15: 0 | AO15: 0 | AP15: 0
A16: Electric Power : Mountain | B16: thousand megawatthours | C16: 362393 | D16: 361361 | E16: 369184 | F16: 364762 | G16: 205106 | H16: 198153 | I16: 180708 | J16: 139845 | K16: 80578 | L16: 70026 | M16: 95196 | N16: 113559 | O16: 31200 | P16: 31278 | Q16: 32526 | R16: 31920 | S16: 30863 | T16: 42097 | U16: 30794 | V16: 30177 | W16: 261 | X16: 253 | Y16: 212 | Z16: 219 | AA16: 10484 | AB16: 15305 | AC16: 18935 | AD16: 28489 | AE16: 282 | AF16: 559 | AG16: 5930 | AH16: 15346 | AI16: 387 | AJ16: 417 | AK16: 638 | AL16: 651 | AM16: 2419 | AN16: 2540 | AO16: 3625 | AP16: 3902
A17: Electric Power : Pacific Contiguous | B17: thousand megawatthours | C17: 342459 | D17: 355353 | E17: 344133 | F17: 355048 | G17: 14364 | H17: 10142 | I17: 7393 | J17: 9715 | K17: 118758 | L17: 88025 | M17: 131869 | N17: 108104 | O17: 41442 | P17: 41470 | Q17: 26666 | R17: 25032 | S17: 132199 | T17: 176682 | U17: 118464 | V17: 135743 | W17: 74 | X17: 67 | Y17: 76 | Z17: 59 | AA17: 14743 | AB17: 18790 | AC17: 25927 | AD17: 29852 | AE17: 765 | AF17: 862 | AG17: 14736 | AH17: 29134 | AI17: 5981 | AJ17: 5279 | AK17: 6090 | AL17: 5296 | AM17: 12600 | AN17: 12552 | AO17: 12062 | AP17: 11559
A18: Electric Power : Pacific Noncontiguous | B18: thousand megawatthours | C18: 16532 | D18: 16496 | E18: 15317 | F18: 15151 | G18: 1890 | H18: 1764 | I18: 1862 | J18: 1890 | K18: 3685 | L18: 3846 | M18: 3019 | N18: 3095 | O18: 0 | P18: 0 | Q18: 0 | R18: 0 | S18: 1462 | T18: 1389 | U18: 1632 | V18: 1282 | W18: 8791 | X18: 8666 | Y18: 7510 | Z18: 7485 | AA18: 274 | AB18: 353 | AC18: 772 | AD18: 749 | AE18: 2 | AF18: 4 | AG18: 54 | AH18: 268 | AI18: 2 | AJ18: 39 | AK18: 52 | AL18: 107 | AM18: 201 | AN18: 224 | AO18: 230 | AP18: 108
A22: Converted to PJ for MARKAL | D22: PJ
D23: All | H23: Coal | L23: Gas | P23: Nuke | T23: Hydro | X23: Oil
D24: 2010 | E24: 2011 | F24: 2015 | G24: 2019 | H24: 2010 | I24: 2011 | J24: 2015 | K24: 2019 | L24: 2010 | M24: 2011 | N24: 2015 | O24: 2019 | P24: 2010 | Q24: 2011 | R24: 2015 | S24: 2019 | T24: 2010 | U24: 2011 | V24: 2015 | W24: 2019 | X24: 2010 | Y24: 2011 | Z24: 2015 | AA24: 2019
A25: National | C25: all | D25: =C8/1000*3.6 -> 14300.59 | E25: =D8/1000*3.6 -> 14213.47 | F25: =E8/1000*3.6 -> 14109.458 | G25: =F8/1000*3.6 -> 14240.812 | H25: =G8/1000*3.6 -> 6579.8568 | I25: =H8/1000*3.6 -> 6184.4076 | J25: =I8/1000*3.6 -> 4827.5748 | K25: =J8/1000*3.6 -> 3454.2252 | ... AA25: =Z8/1000*3.6 -> 39.6864
A26: R1 | C26: 1 | D26: =C9/1000*3.6 -> 444.3876 | E26: =D9/1000*3.6 -> 421.2756 | F26: =E9/1000*3.6 -> 381.7116 | G26: =F9/1000*3.6 -> 345.7872 | H26: =G9/1000*3.6 -> 50.472 | I26: =H9/1000*3.6 -> 24.4836 | J26: =I9/1000*3.6 -> 13.8168 | K26: =J9/1000*3.6 -> 1.6452 | ... AA26: =Z9/1000*3.6 -> 0.846
A27: R2 | C27: 2 | D27: =C10/1000*3.6 -> 1535.7528 | E27: =D10/1000*3.6 -> 1524.7548 | F27: =E10/1000*3.6 -> 1515.8556 | G27: =F10/1000*3.6 -> 1542.5388 | H27: =G10/1000*3.6 -> 464.22 | I27: =H10/1000*3.6 -> 406.7208 | J27: =I10/1000*3.6 -> 244.764 | K27: =J10/1000*3.6 -> 144.4788 | ... AA27: =Z10/1000*3.6 -> 2.5704
A28: R3 | C28: 3 | D28: =C11/1000*3.6 -> 2283.7788 | E28: =D11/1000*3.6 -> 2224.0656 | F28: =E11/1000*3.6 -> 2114.514 | G28: =F11/1000*3.6 -> 2053.98 | H28: =G11/1000*3.6 -> 1532.3508 | I28: =H11/1000*3.6 -> 1420.5348 | J28: =I11/1000*3.6 -> 1119.5928 | K28: =J11/1000*3.6 -> 785.2104 | ... AA28: =Z11/1000*3.6 -> 1.6524
A29: R4 | C29: 4 | D29: =C12/1000*3.6 -> 1182.4812 | E29: =D12/1000*3.6 -> 1181.9196 | F29: =E12/1000*3.6 -> 1168.9308 | G29: =F12/1000*3.6 -> 1205.1 | H29: =G12/1000*3.6 -> 823.464 | I29: =H12/1000*3.6 -> 823.23 | J29: =I12/1000*3.6 -> 701.1432 | K29: =J12/1000*3.6 -> 573.0228 | ... AA29: =Z12/1000*3.6 -> 1.1448
A30: R5 | C30: 5 | D30: =C13/1000*3.6 -> 2824.9632 | E30: =D13/1000*3.6 -> 2674.9728 | F30: =E13/1000*3.6 -> 2777.5224 | G30: =F13/1000*3.6 -> 2845.7568 | H30: =G13/1000*3.6 -> 1330.4772 | I30: =H13/1000*3.6 -> 1157.3208 | J30: =I13/1000*3.6 -> 866.2752 | K30: =J13/1000*3.6 -> 572.328 | ... AA30: =Z13/1000*3.6 -> 4.2516
A31: R6 | C31: 6 | D31: =C14/1000*3.6 -> 1361.07 | E31: =D14/1000*3.6 -> 1361.3076 | F31: =E14/1000*3.6 -> 1320.9264 | G31: =F14/1000*3.6 -> 1266.7824 | H31: =G14/1000*3.6 -> 754.4052 | I31: =H14/1000*3.6 -> 710.6616 | J31: =I14/1000*3.6 -> 539.694 | K31: =J14/1000*3.6 -> 363.5136 | ... AA31: =Z14/1000*3.6 -> 0.8208
A32: R7 | C32: 7 | D32: =C15/1000*3.6 -> 2071.1736 | E32: =D15/1000*3.6 -> 2185.6212 | F32: =E15/1000*3.6 -> 2206.9152 | G32: =F15/1000*3.6 -> 2335.0068 | H32: =G15/1000*3.6 -> 827.568 | I32: =H15/1000*3.6 -> 885.2472 | J32: =I15/1000*3.6 -> 658.4256 | K32: =J15/1000*3.6 -> 468.81 | ... AA32: =Z15/1000*3.6 -> 0.45
A33: R8 | C33: 8 | D33: =C16/1000*3.6 -> 1304.6148 | E33: =D16/1000*3.6 -> 1300.8996 | F33: =E16/1000*3.6 -> 1329.0624 | G33: =F16/1000*3.6 -> 1313.1432 | H33: =G16/1000*3.6 -> 738.3816 | I33: =H16/1000*3.6 -> 713.3508 | J33: =I16/1000*3.6 -> 650.5488 | K33: =J16/1000*3.6 -> 503.442 | ... AA33: =Z16/1000*3.6 -> 0.7884
A34: R9 | C34: 9 | D34: =(C17+C18)/1000*3.6 -> 1292.3676 | E34: =(D17+D18)/1000*3.6 -> 1338.6564 | F34: =(E17+E18)/1000*3.6 -> 1294.02 | G34: =(F17+F18)/1000*3.6 -> 1332.7164 | H34: =(G17+G18)/1000*3.6 -> 58.5144 | I34: =(H17+H18)/1000*3.6 -> 42.8616 | J34: =(I17+I18)/1000*3.6 -> 33.318 | K34: =(J17+J18)/1000*3.6 -> 41.778 | ... T34: =(S17+S18)/1000*3.6 -> 481.1796 | U34: =(T17+T18)/1000*3.6*0.7 -> 448.73892 | V34: =(U17+U18)/1000*3.6 -> 432.3456 | W34: =(V17+V18)/1000*3.6 -> 493.29 | X34: =(W17+W18)/1000*3.6 -> 31.914 | Y34: =(X17+X18)/1000*3.6 -> 31.4388 | Z34: =(Y17+Y18)/1000*3.6 -> 27.3096 | AA34: =(Z17+Z18)/1000*3.6 -> 27.1584
D36: Wind | H36: Solar | L36: Biomass | P36: Geothermal
D37: 2010 | E37: 2011 | F37: 2015 | G37: 2020 | H37: 2010 | I37: 2011 | J37: 2015 | K37: 2020 | L37: 2010 | M37: 2011 | N37: 2015 | O37: 2020 | P37: 2010 | Q37: 2011 | R37: 2015 | S37: 2020
A38: National | C38: all | D38: =AA8/1000*3.6 -> 340.6896 | E38: =AB8/1000*3.6 -> 432.4356 | F38: =AC8/1000*3.6 -> 685.9692 | G38: =AD8/1000*3.6 -> 1079.226 | H38: =AE8/1000*3.6 -> 4.3416 | I38: =AF8/1000*3.6 -> 6.2172 | J38: =AG8/1000*3.6 -> 88.0416 | K38: =AH8/1000*3.6 -> 257.5692 | ... S38: =AP8/1000*3.6 -> 56.0484
A39: R1 | C39: 1 | D39: =AA9/1000*3.6 -> 2.2032 | E39: =AB9/1000*3.6 -> 3.0996 | F39: =AC9/1000*3.6 -> 8.0424 | G39: =AD9/1000*3.6 -> 13.0572 | H39: =AE9/1000*3.6 -> 0.0036 | I39: =AF9/1000*3.6 -> 0.0216 | J39: =AG9/1000*3.6 -> 1.9008 | K39: =AH9/1000*3.6 -> 5.7528 | ... S39: =AP9/1000*3.6 -> 0
A40: R2 | C40: 2 | D40: =AA10/1000*3.6 -> 16.0668 | E40: =AB10/1000*3.6 -> 16.6788 | F40: =AC10/1000*3.6 -> 26.4564 | G40: =AD10/1000*3.6 -> 30.2868 | H40: =AE10/1000*3.6 -> 0.1008 | I40: =AF10/1000*3.6 -> 0.306 | J40: =AG10/1000*3.6 -> 2.3184 | K40: =AH10/1000*3.6 -> 6.39 | ... S40: =AP10/1000*3.6 -> 0
A41: R3 | C41: 3 | D41: =AA11/1000*3.6 -> 31.8492 | E41: =AB11/1000*3.6 -> 40.8168 | F41: =AC11/1000*3.6 -> 82.0944 | G41: =AD11/1000*3.6 -> 105.9192 | H41: =AE11/1000*3.6 -> 0.0972 | I41: =AF11/1000*3.6 -> 0.108 | J41: =AG11/1000*3.6 -> 0.9324 | K41: =AH11/1000*3.6 -> 2.7072 | ... S41: =AP11/1000*3.6 -> 0
A42: R4 | C42: 4 | D42: =AA12/1000*3.6 -> 87.012 | E42: =AB12/1000*3.6 -> 112.5396 | F42: =AC12/1000*3.6 -> 186.606 | G42: =AD12/1000*3.6 -> 299.1852 | H42: =AE12/1000*3.6 -> 0 | I42: =AF12/1000*3.6 -> 0 | J42: =AG12/1000*3.6 -> 0.0756 | K42: =AH12/1000*3.6 -> 6.0696 | ... S42: =AP12/1000*3.6 -> 0
A43: R5 | C43: 5 | D43: =AA13/1000*3.6 -> 3.3948 | E43: =AB13/1000*3.6 -> 4.9428 | F43: =AC13/1000*3.6 -> 6.5196 | G43: =AD13/1000*3.6 -> 10.2168 | H43: =AE13/1000*3.6 -> 0.3312 | I43: =AF13/1000*3.6 -> 0.5544 | J43: =AG13/1000*3.6 -> 6.5088 | K43: =AH13/1000*3.6 -> 55.2096 | ... S43: =AP13/1000*3.6 -> 0
A44: R6 | C44: 6 | D44: =AA14/1000*3.6 -> 0.1476 | E44: =AB14/1000*3.6 -> 0.1908 | F44: =AC14/1000*3.6 -> 0.1656 | G44: =AD14/1000*3.6 -> 0.1476 | H44: =AE14/1000*3.6 -> 0 | I44: =AF14/1000*3.6 -> 0 | J44: =AG14/1000*3.6 -> 0.2628 | K44: =AH14/1000*3.6 -> 3.8628 | ... S44: =AP14/1000*3.6 -> 0
A45: R7 | C45: 7 | D45: =AA15/1000*3.6 -> 108.2124 | E45: =AB15/1000*3.6 -> 130.1508 | F45: =AC15/1000*3.6 -> 211.8024 | G45: =AD15/1000*3.6 -> 407.6856 | H45: =AE15/1000*3.6 -> 0.0288 | I45: =AF15/1000*3.6 -> 0.1044 | J45: =AG15/1000*3.6 -> 1.4436 | K45: =AH15/1000*3.6 -> 16.488 | ... S45: =AP15/1000*3.6 -> 0
...

Sheet NetGenRawData
B1: Net generation for electric power
B2: https://www.eia.gov/electricity/data/browser/#/topic/0?agg=2,0,1&fuel=vvt9u&geo=vvg&sec=008&freq=A&start=2001&end=2019&ctype=linechart&ltype=pin&rtype=s&pin=&rse=0&maptype=0
B3: Fri Jun 26 2020 08:42:54 GMT-0400 (Eastern Daylight Time)
B4: Source: U.S. Energy Information Administration
B5: description | C5: units | D5: source key | E5: 2010 | F5: 2011 | G5: 2015 | H5: 2019
B6: Net generation for electric power | C6: thousand megawatthours
B7: United States | D7: ELEC.GEN..A
B8: United States : all fuels (utility-scale) | C8: thousand megawatthours | D8: ELEC.GEN.ALL-US-98.A | E8: 3972386 | F8: 3948186 | G8: 3919294 | H8: 3955781
B9: New England : all fuels (utility-scale) | C9: thousand megawatthours | D9: ELEC.GEN.ALL-NEW-98.A | E9: 123441 | F9: 117021 | G9: 106031 | H9: 96052
B10: Middle Atlantic : all fuels (utility-scale) | C10: thousand megawatthours | D10: ELEC.GEN.ALL-MAT-98.A | E10: 426598 | F10: 423543 | G10: 421071 | H10: 428483
B11: East North Central : all fuels (utility-scale) | C11: thousand megawatthours | D11: ELEC.GEN.ALL-ENC-98.A | E11: 634383 | F11: 617796 | G11: 587365 | H11: 570550
B12: West North Central : all fuels (utility-scale) | C12: thousand megawatthours | D12: ELEC.GEN.ALL-WNC-98.A | E12: 328467 | F12: 328311 | G12: 324703 | H12: 334750
B13: South Atlantic : all fuels (utility-scale) | C13: thousand megawatthours | D13: ELEC.GEN.ALL-SAT-98.A | E13: 784712 | F13: 743048 | G13: 771534 | H13: 790488
B14: East South Central : all fuels (utility-scale) | C14: thousand megawatthours | D14: ELEC.GEN.ALL-ESC-98.A | E14: 378075 | F14: 378141 | G14: 366924 | H14: 351884
B15: West South Central : all fuels (utility-scale) | C15: thousand megawatthours | D15: ELEC.GEN.ALL-WSC-98.A | E15: 575326 | F15: 607117 | G15: 613032 | H15: 648613
B16: Mountain : all fuels (utility-scale) | C16: thousand megawatthours | D16: ELEC.GEN.ALL-MTN-98.A | E16: 362393 | F16: 361361 | G16: 369184 | H16: 364762
B17: Pacific Contiguous : all fuels (utility-scale) | C17: thousand megawatthours | D17: ELEC.GEN.ALL-PCC-98.A | E17: 342459 | F17: 355353 | G17: 344133 | H17: 355048
B18: Pacific Noncontiguous : all fuels (utility-scale) | C18: thousand megawatthours | D18: ELEC.GEN.ALL-PCN-98.A | E18: 16532 | F18: 16496 | G18: 15317 | H18: 15151
B19: United States : coal | C19: thousand megawatthours | D19: ELEC.GEN.COW-US-98.A | E19: 1827738 | F19: 1717891 | G19: 1340993 | H19: 959507
... B41: United States : other gases | C41: thousand megawatthours | D41: ELEC.GEN.OOG-US-98.A | E41: 2967 | F41: 2939 | G41: 3715 | H41: 4306
B42: New England : other gases | C42: thousand megawatthours | D42: ELEC.GEN.OOG-NEW-98.A | E42: 14 | F42: -- | G42: -- | H42: --
B43: Middle Atlantic : other gases | C43: thousand megawatthours | D43: ELEC.GEN.OOG-MAT-98.A | E43: 54 | F43: 41 | G43: 0 | H43: 0
B44: East North Central : other gases | C44: thousand megawatthours | D44: ELEC.GEN.OOG-ENC-98.A | E44: 405 | F44: 386 | G44: 1983 | H44: 2274
B45: West North Central : other gases | C45: thousand megawatthours | D45: ELEC.GEN.OOG-WNC-98.A | E45: 7 | F45: 0 | G45: -- | H45: --
B46: South Atlantic : other gases | C46: thousand megawatthours | D46: ELEC.GEN.OOG-SAT-98.A | E46: 215 | F46: -- | G46: -- | H46: --
B47: East South Central : other gases | C47: thousand megawatthours | D47: ELEC.GEN.OOG-ESC-98.A | E47: 3 | F47: -- | G47: -- | H47: --
B48: West South Central : other gases | C48: thousand megawatthours | D48: ELEC.GEN.OOG-WSC-98.A | E48: 1929 | F48: 2180 | G48: 1314 | H48: 1699
B49: Mountain : other gases | C49: thousand megawatthours | D49: ELEC.GEN.OOG-MTN-98.A | E49: 6 | F49: 7 | G49: 23 | H49: 10
B50: Pacific Contiguous : other gases | C50: thousand megawatthours | D50: ELEC.GEN.OOG-PCC-98.A | E50: 334 | F50: 326 | G50: 395 | H50: 322
B51: Pacific Noncontiguous : other gases | C51: thousand megawatthours | D51: ELEC.GEN.OOG-PCN-98.A | E51: -- | F51: -- | G51: -- | H51: --
B52: United States : petroleum coke | C52: thousand megawatthours | D52: ELEC.GEN.PC-US-98.A | E52: 12304 | F52: 12859 | G52: 9879 | H52: 6324
B53: New England : petroleum coke | C53: thousand megawatthours | D53: ELEC.GEN.PC-NEW-98.A | E53: -- | F53: -- | G53: -- | H53: --
B54: Middle Atlantic : petroleum coke | C54: thousand megawatthours | D54: ELEC.GEN.PC-MAT-98.A | E54: 515 | F54: 263 | G54: 0 | H54: 0
B55: East North Central : petroleum coke | C55: thousand megawatthours | D55: ELEC.GEN.PC-ENC-98.A | E55: 1595 | F55: 2632 | G55: 2908 | H55: 1525
B56: West North Central : petroleum coke | C56: thousand megawatthours | D56: ELEC.GEN.PC-WNC-98.A | E56: 135 | F56: 88 | G56: 0 | H56: --
B57: South Atlantic : petroleum coke | C57: thousand megawatthours | D57: ELEC.GEN.PC-SAT-98.A | E57: 3228 | F57: 1898 | G57: 1568 | H57: 1201
B58: East South Central : petroleum coke | C58: thousand megawatthours | D58: ELEC.GEN.PC-ESC-98.A | E58: 2162 | F58: 1596 | G58: 964 | H58: 0
B59: West South Central : petroleum coke | C59: thousand megawatthours | D59: ELEC.GEN.PC-WSC-98.A | E59: 3268 | F59: 5075 | G59: 3957 | H59: 3149
B60: Mountain : petroleum coke | C60: thousand megawatthours | D60: ELEC.GEN.PC-MTN-98.A | E60: 395 | F60: 443 | G60: 483 | H60: 449
B61: Pacific Contiguous : petroleum coke | C61: thousand megawatthours | D61: ELEC.GEN.PC-PCC-98.A | E61: 1006 | F61: 864 | G61: 0 | H61: 0
...
