Workbook

Sheet IND
V2: Table 93. Fuel Relaxation Percentages
V3: General Industry Category | W3: Natural Gas | X3: Coal | Y3: NG | Z3: Coal
V4: Feedstocks | W4: 0.9
V5: Food | W5: 28 | X5: 20 | Y5: =1-(W5/100) -> 0.72 | Z5: =1-(X5/100) -> 0.8
V6: Paper | W6: 32 | X6: 23 | Y6: =1-(W6/100) -> 0.68 | Z6: =1-(X6/100) -> 0.77
V7: Chemicals | W7: 10 | X7: 36 | Y7: =1-(W7/100) -> 0.9 | Z7: =1-(X7/100) -> 0.64
V8: Nonmetallic Mineral Products | W8: 29 | X8: 51 | Y8: =1-(W8/100) -> 0.71 | Z8: =1-(X8/100) -> 0.49
V9: Primary Metals | W9: 12 | X9: 3 | Y9: =1-(W9/100) -> 0.88 | Z9: =1-(X9/100) -> 0.97
V10: Other | W10: 20 | X10: 20 | Y10: =1-(W10/100) -> 0.8 | Z10: =1-(X10/100) -> 0.8
V11: Source: 2007 OPEI Report
V12: epa.gov/sectors/pdf/energy/report.pdf
B13: ~UC_Sets: R_E: R1,R2,R3,R4,R5,R6,R7,R8,R9
B14: ~UC_Sets: T_E:
F16: ~UC_T: UC_COMPRD~2011 | Y16: ~UC_T: UC_COMPRD~2055
C17: UC_N | D17: PSET_SET | E17: CSET_CN | F17: LimType | G17: UC_FLO | H17: R1 | I17: R2 | J17: R3 | K17: R4 | L17: R5 | M17: R6 | N17: R7 | O17: R8 | P17: R9 | Q17: UC_RHSRT | R17: UC_RHSRT~0 | S17: UC_Desc | V17: UC_N | W17: PSET_SET | X17: CSET_CN | Y17: LimType | Z17: UC_FLO | AA17: R1 | AB17: R2 | AC17: R3 | AD17: R4 | AE17: R5 | AF17: R6 | AG17: R7 | AH17: R8 | AI17: R9 | AJ17: UC_Desc
C18: S_IFDFSNGA | D18: IFDFS_NGA | E18: IFDFEED | F18: LO | G18: 1 | H18: =IF(SUMIFS('Industrial Summary'!$G:$G,'Industrial Summary'!$F:$F,H$17,'Industrial Summary'!$D:$D,$E18)>0,(-SUMIFS('Industrial Summary'!$G:$G,'Industrial Summary'!$F:$F,H$17,'Industrial Summary'!$D:$D,$E18,'Industrial Summary'!$A:$A,"NGA")/SUMIFS('Industrial Summary'!$G:$G,'Industrial Summary'!$F:$F,H$17,'Industrial Summary'!$D:$D,$E18)),0)*0.98 -> 0 | I18: =IF(SUMIFS('Industrial Summary'!$G:$G,'Industrial Summary'!$F:$F,I$17,'Industrial Summary'!$D:$D,$E18)>0,(-SUMIFS('Industrial Summary'!$G:$G,'Industrial Summary'!$F:$F,I$17,'Industrial Summary'!$D:$D,$E18,'Industrial Summary'!$A:$A,"NGA")/SUMIFS('Industrial Summary'!$G:$G,'Industrial Summary'!$F:$F,I$17,'Industrial Summary'!$D:$D,$E18)),0)*0.98 -> 0 | J18: =IF(SUMIFS('Industrial Summary'!$G:$G,'Industrial Summary'!$F:$F,J$17,'Industrial Summary'!$D:$D,$E18)>0,(-SUMIFS('Industrial Summary'!$G:$G,'Industrial Summary'!$F:$F,J$17,'Industrial Summary'!$D:$D,$E18,'Industrial Summary'!$A:$A,"NGA")/SUMIFS('Industrial Summary'!$G:$G,'Industrial Summary'!$F:$F,J$17,'Industrial Summary'!$D:$D,$E18)),0)*0.98 -> -0.67515689 | K18: =IF(SUMIFS('Industrial Summary'!$G:$G,'Industrial Summary'!$F:$F,K$17,'Industrial Summary'!$D:$D,$E18)>0,(-SUMIFS('Industrial Summary'!$G:$G,'Industrial Summary'!$F:$F,K$17,'Industrial Summary'!$D:$D,$E18,'Industrial Summary'!$A:$A,"NGA")/SUMIFS('Industrial Summary'!$G:$G,'Industrial Summary'!$F:$F,K$17,'Industrial Summary'!$D:$D,$E18)),0)*0.98 -> -0.7181206 | L18: =IF(SUMIFS('Industrial Summary'!$G:$G,'Industrial Summary'!$F:$F,L$17,'Industrial Summary'!$D:$D,$E18)>0,(-SUMIFS('Industrial Summary'!$G:$G,'Industrial Summary'!$F:$F,L$17,'Industrial Summary'!$D:$D,$E18,'Industrial Summary'!$A:$A,"NGA")/SUMIFS('Industrial Summary'!$G:$G,'Industrial Summary'!$F:$F,L$17,'Industrial Summary'!$D:$D,$E18)),0)*0.98 -> 0 | M18: =IF(SUMIFS('Industrial Summary'!$G:$G,'Industrial Summary'!$F:$F,M$17,'Industrial Summary'!$D:$D,$E18)>0,(-SUMIFS('Industrial Summary'!$G:$G,'Industrial Summary'!$F:$F,M$17,'Industrial Summary'!$D:$D,$E18,'Industrial Summary'!$A:$A,"NGA")/SUMIFS('Industrial Summary'!$G:$G,'Industrial Summary'!$F:$F,M$17,'Industrial Summary'!$D:$D,$E18)),0)*0.98 -> 0 | N18: =IF(SUMIFS('Industrial Summary'!$G:$G,'Industrial Summary'!$F:$F,N$17,'Industrial Summary'!$D:$D,$E18)>0,(-SUMIFS('Industrial Summary'!$G:$G,'Industrial Summary'!$F:$F,N$17,'Industrial Summary'!$D:$D,$E18,'Industrial Summary'!$A:$A,"NGA")/SUMIFS('Industrial Summary'!$G:$G,'Industrial Summary'!$F:$F,N$17,'Industrial Summary'!$D:$D,$E18)),0)*0.98 -> 0 | O18: =IF(SUMIFS('Industrial Summary'!$G:$G,'Industrial Summary'!$F:$F,O$17,'Industrial Summary'!$D:$D,$E18)>0,(-SUMIFS('Industrial Summary'!$G:$G,'Industrial Summary'!$F:$F,O$17,'Industrial Summary'!$D:$D,$E18,'Industrial Summary'!$A:$A,"NGA")/SUMIFS('Industrial Summary'!$G:$G,'Industrial Summary'!$F:$F,O$17,'Industrial Summary'!$D:$D,$E18)),0)*0.98 -> -0.98 | P18: =IF(SUMIFS('Industrial Summary'!$G:$G,'Industrial Summary'!$F:$F,P$17,'Industrial Summary'!$D:$D,$E18)>0,(-SUMIFS('Industrial Summary'!$G:$G,'Industrial Summary'!$F:$F,P$17,'Industrial Summary'!$D:$D,$E18,'Industrial Summary'!$A:$A,"NGA")/SUMIFS('Industrial Summary'!$G:$G,'Industrial Summary'!$F:$F,P$17,'Industrial Summary'!$D:$D,$E18)),0)*0.98 -> -0.98 | Q18: 0 | R18: 15 | S18: =_xlfn.CONCAT("UC_",D18) -> UC_IFDFS_NGA | V18: =C18 -> S_IFDFSNGA | W18: =D18 -> IFDFS_NGA | X18: =E18 -> IFDFEED | Y18: =F18 -> LO | Z18: 1 | AA18: =H18*$AM18 -> 0 | AB18: =I18*$AM18 -> 0 | AC18: =J18*$AM18 -> -0.48611296 | AD18: =K18*$AM18 -> -0.51704683 | AE18: =L18*$AM18 -> 0 | AF18: =M18*$AM18 -> 0 | AG18: =N18*$AM18 -> 0 | AH18: =O18*$AM18 -> -0.7056 | AI18: =P18*$AM18 -> -0.7056 | AL18: =RIGHT(W18,3) -> NGA | AM18: =Y5 -> 0.72
C19: S_IFDFSLPG | D19: IFDFS_LPG | E19: IFDFEED | F19: LO | G19: 1 | H19: =IF(SUMIFS('Industrial Summary'!$G:$G,'Industrial Summary'!$F:$F,H$17,'Industrial Summary'!$D:$D,$E19)>0,(-SUMIFS('Industrial Summary'!$G:$G,'Industrial Summary'!$F:$F,H$17,'Industrial Summary'!$D:$D,$E19,'Industrial Summary'!$A:$A,"LPG")/SUMIFS('Industrial Summary'!$G:$G,'Industrial Summary'!$F:$F,H$17,'Industrial Summary'!$D:$D,$E19)),0)*0.98 -> 0 | I19: =IF(SUMIFS('Industrial Summary'!$G:$G,'Industrial Summary'!$F:$F,I$17,'Industrial Summary'!$D:$D,$E19)>0,(-SUMIFS('Industrial Summary'!$G:$G,'Industrial Summary'!$F:$F,I$17,'Industrial Summary'!$D:$D,$E19,'Industrial Summary'!$A:$A,"LPG")/SUMIFS('Industrial Summary'!$G:$G,'Industrial Summary'!$F:$F,I$17,'Industrial Summary'!$D:$D,$E19)),0)*0.98 -> 0 | J19: =IF(SUMIFS('Industrial Summary'!$G:$G,'Industrial Summary'!$F:$F,J$17,'Industrial Summary'!$D:$D,$E19)>0,(-SUMIFS('Industrial Summary'!$G:$G,'Industrial Summary'!$F:$F,J$17,'Industrial Summary'!$D:$D,$E19,'Industrial Summary'!$A:$A,"LPG")/SUMIFS('Industrial Summary'!$G:$G,'Industrial Summary'!$F:$F,J$17,'Industrial Summary'!$D:$D,$E19)),0)*0.98 -> -0.029486178 | K19: =IF(SUMIFS('Industrial Summary'!$G:$G,'Industrial Summary'!$F:$F,K$17,'Industrial Summary'!$D:$D,$E19)>0,(-SUMIFS('Industrial Summary'!$G:$G,'Industrial Summary'!$F:$F,K$17,'Industrial Summary'!$D:$D,$E19,'Industrial Summary'!$A:$A,"LPG")/SUMIFS('Industrial Summary'!$G:$G,'Industrial Summary'!$F:$F,K$17,'Industrial Summary'!$D:$D,$E19)),0)*0.98 -> 0 | L19: =IF(SUMIFS('Industrial Summary'!$G:$G,'Industrial Summary'!$F:$F,L$17,'Industrial Summary'!$D:$D,$E19)>0,(-SUMIFS('Industrial Summary'!$G:$G,'Industrial Summary'!$F:$F,L$17,'Industrial Summary'!$D:$D,$E19,'Industrial Summary'!$A:$A,"LPG")/SUMIFS('Industrial Summary'!$G:$G,'Industrial Summary'!$F:$F,L$17,'Industrial Summary'!$D:$D,$E19)),0)*0.98 -> 0 | M19: =IF(SUMIFS('Industrial Summary'!$G:$G,'Industrial Summary'!$F:$F,M$17,'Industrial Summary'!$D:$D,$E19)>0,(-SUMIFS('Industrial Summary'!$G:$G,'Industrial Summary'!$F:$F,M$17,'Industrial Summary'!$D:$D,$E19,'Industrial Summary'!$A:$A,"LPG")/SUMIFS('Industrial Summary'!$G:$G,'Industrial Summary'!$F:$F,M$17,'Industrial Summary'!$D:$D,$E19)),0)*0.98 -> 0 | N19: =IF(SUMIFS('Industrial Summary'!$G:$G,'Industrial Summary'!$F:$F,N$17,'Industrial Summary'!$D:$D,$E19)>0,(-SUMIFS('Industrial Summary'!$G:$G,'Industrial Summary'!$F:$F,N$17,'Industrial Summary'!$D:$D,$E19,'Industrial Summary'!$A:$A,"LPG")/SUMIFS('Industrial Summary'!$G:$G,'Industrial Summary'!$F:$F,N$17,'Industrial Summary'!$D:$D,$E19)),0)*0.98 -> 0 | O19: =IF(SUMIFS('Industrial Summary'!$G:$G,'Industrial Summary'!$F:$F,O$17,'Industrial Summary'!$D:$D,$E19)>0,(-SUMIFS('Industrial Summary'!$G:$G,'Industrial Summary'!$F:$F,O$17,'Industrial Summary'!$D:$D,$E19,'Industrial Summary'!$A:$A,"LPG")/SUMIFS('Industrial Summary'!$G:$G,'Industrial Summary'!$F:$F,O$17,'Industrial Summary'!$D:$D,$E19)),0)*0.98 -> 0 | P19: =IF(SUMIFS('Industrial Summary'!$G:$G,'Industrial Summary'!$F:$F,P$17,'Industrial Summary'!$D:$D,$E19)>0,(-SUMIFS('Industrial Summary'!$G:$G,'Industrial Summary'!$F:$F,P$17,'Industrial Summary'!$D:$D,$E19,'Industrial Summary'!$A:$A,"LPG")/SUMIFS('Industrial Summary'!$G:$G,'Industrial Summary'!$F:$F,P$17,'Industrial Summary'!$D:$D,$E19)),0)*0.98 -> 0 | Q19: 0 | R19: 15 | S19: =_xlfn.CONCAT("UC_",D19) -> UC_IFDFS_LPG | V19: =C19 -> S_IFDFSLPG | W19: =D19 -> IFDFS_LPG | X19: =E19 -> IFDFEED | Y19: =F19 -> LO | Z19: 1 | AA19: =H19*$AM19 -> 0 | AB19: =I19*$AM19 -> 0 | AC19: =J19*$AM19 -> -0.021230048 | AD19: =K19*$AM19 -> 0 | AE19: =L19*$AM19 -> 0 | AF19: =M19*$AM19 -> 0 | AG19: =N19*$AM19 -> 0 | AH19: =O19*$AM19 -> 0 | AI19: =P19*$AM19 -> 0 | AL19: =RIGHT(W19,3) -> LPG | AM19: =Y5 -> 0.72
C20: S_IFDFSBIO | D20: IFDFS_BIO | E20: IFDFEED | F20: LO | G20: 1 | H20: =IF(SUMIFS('Industrial Summary'!$G:$G,'Industrial Summary'!$F:$F,H$17,'Industrial Summary'!$D:$D,$E20)>0,(-SUMIFS('Industrial Summary'!$G:$G,'Industrial Summary'!$F:$F,H$17,'Industrial Summary'!$D:$D,$E20,'Industrial Summary'!$A:$A,"BIO")/SUMIFS('Industrial Summary'!$G:$G,'Industrial Summary'!$F:$F,H$17,'Industrial Summary'!$D:$D,$E20)),0)*0.98 -> 0 | I20: =IF(SUMIFS('Industrial Summary'!$G:$G,'Industrial Summary'!$F:$F,I$17,'Industrial Summary'!$D:$D,$E20)>0,(-SUMIFS('Industrial Summary'!$G:$G,'Industrial Summary'!$F:$F,I$17,'Industrial Summary'!$D:$D,$E20,'Industrial Summary'!$A:$A,"BIO")/SUMIFS('Industrial Summary'!$G:$G,'Industrial Summary'!$F:$F,I$17,'Industrial Summary'!$D:$D,$E20)),0)*0.98 -> 0 | J20: =IF(SUMIFS('Industrial Summary'!$G:$G,'Industrial Summary'!$F:$F,J$17,'Industrial Summary'!$D:$D,$E20)>0,(-SUMIFS('Industrial Summary'!$G:$G,'Industrial Summary'!$F:$F,J$17,'Industrial Summary'!$D:$D,$E20,'Industrial Summary'!$A:$A,"BIO")/SUMIFS('Industrial Summary'!$G:$G,'Industrial Summary'!$F:$F,J$17,'Industrial Summary'!$D:$D,$E20)),0)*0.98 -> -0.27535693 | K20: =IF(SUMIFS('Industrial Summary'!$G:$G,'Industrial Summary'!$F:$F,K$17,'Industrial Summary'!$D:$D,$E20)>0,(-SUMIFS('Industrial Summary'!$G:$G,'Industrial Summary'!$F:$F,K$17,'Industrial Summary'!$D:$D,$E20,'Industrial Summary'!$A:$A,"BIO")/SUMIFS('Industrial Summary'!$G:$G,'Industrial Summary'!$F:$F,K$17,'Industrial Summary'!$D:$D,$E20)),0)*0.98 -> -0.2618794 | L20: =IF(SUMIFS('Industrial Summary'!$G:$G,'Industrial Summary'!$F:$F,L$17,'Industrial Summary'!$D:$D,$E20)>0,(-SUMIFS('Industrial Summary'!$G:$G,'Industrial Summary'!$F:$F,L$17,'Industrial Summary'!$D:$D,$E20,'Industrial Summary'!$A:$A,"BIO")/SUMIFS('Industrial Summary'!$G:$G,'Industrial Summary'!$F:$F,L$17,'Industrial Summary'!$D:$D,$E20)),0)*0.98 -> 0 | M20: =IF(SUMIFS('Industrial Summary'!$G:$G,'Industrial Summary'!$F:$F,M$17,'Industrial Summary'!$D:$D,$E20)>0,(-SUMIFS('Industrial Summary'!$G:$G,'Industrial Summary'!$F:$F,M$17,'Industrial Summary'!$D:$D,$E20,'Industrial Summary'!$A:$A,"BIO")/SUMIFS('Industrial Summary'!$G:$G,'Industrial Summary'!$F:$F,M$17,'Industrial Summary'!$D:$D,$E20)),0)*0.98 -> 0 | N20: =IF(SUMIFS('Industrial Summary'!$G:$G,'Industrial Summary'!$F:$F,N$17,'Industrial Summary'!$D:$D,$E20)>0,(-SUMIFS('Industrial Summary'!$G:$G,'Industrial Summary'!$F:$F,N$17,'Industrial Summary'!$D:$D,$E20,'Industrial Summary'!$A:$A,"BIO")/SUMIFS('Industrial Summary'!$G:$G,'Industrial Summary'!$F:$F,N$17,'Industrial Summary'!$D:$D,$E20)),0)*0.98 -> 0 | O20: =IF(SUMIFS('Industrial Summary'!$G:$G,'Industrial Summary'!$F:$F,O$17,'Industrial Summary'!$D:$D,$E20)>0,(-SUMIFS('Industrial Summary'!$G:$G,'Industrial Summary'!$F:$F,O$17,'Industrial Summary'!$D:$D,$E20,'Industrial Summary'!$A:$A,"BIO")/SUMIFS('Industrial Summary'!$G:$G,'Industrial Summary'!$F:$F,O$17,'Industrial Summary'!$D:$D,$E20)),0)*0.98 -> 0 | P20: =IF(SUMIFS('Industrial Summary'!$G:$G,'Industrial Summary'!$F:$F,P$17,'Industrial Summary'!$D:$D,$E20)>0,(-SUMIFS('Industrial Summary'!$G:$G,'Industrial Summary'!$F:$F,P$17,'Industrial Summary'!$D:$D,$E20,'Industrial Summary'!$A:$A,"BIO")/SUMIFS('Industrial Summary'!$G:$G,'Industrial Summary'!$F:$F,P$17,'Industrial Summary'!$D:$D,$E20)),0)*0.98 -> 0 | Q20: 0 | R20: 15 | S20: =_xlfn.CONCAT("UC_",D20) -> UC_IFDFS_BIO | V20: =C20 -> S_IFDFSBIO | W20: =D20 -> IFDFS_BIO | X20: =E20 -> IFDFEED | Y20: =F20 -> LO | Z20: 1 | AA20: =H20*$AM20 -> 0 | AB20: =I20*$AM20 -> 0 | AC20: =J20*$AM20 -> -0.27535693 | AD20: =K20*$AM20 -> -0.2618794 | AE20: =L20*$AM20 -> 0 | AF20: =M20*$AM20 -> 0 | AG20: =N20*$AM20 -> 0 | AH20: =O20*$AM20 -> 0 | AI20: =P20*$AM20 -> 0 | AL20: =RIGHT(W20,3) -> BIO | AM20: =1 -> 1
C21: S_IFDSTELC | D21: IFDST_ELC | E21: IFDSTM | F21: LO | G21: 1 | H21: =(IF(SUMIFS('Industrial Summary'!$G:$G,'Industrial Summary'!$F:$F,H$17,'Industrial Summary'!$D:$D,$E21)>0,((-SUMIFS('Industrial Summary'!$G:$G,'Industrial Summary'!$F:$F,H$17,'Industrial Summary'!$D:$D,$E21,'Industrial Summary'!$A:$A,"ELC")+-SUMIFS('Industrial Summary'!$G:$G,'Industrial Summary'!$F:$F,H$17,'Industrial Summary'!$D:$D,"IFDFSTM",'Industrial Summary'!$A:$A,"ELC"))/SUMIFS('Industrial Summary'!$G:$G,'Industrial Summary'!$F:$F,H$17,'Industrial Summary'!$D:$D,$E21)),0))*0.98 -> -0.049360046 | I21: =(IF(SUMIFS('Industrial Summary'!$G:$G,'Industrial Summary'!$F:$F,I$17,'Industrial Summary'!$D:$D,$E21)>0,((-SUMIFS('Industrial Summary'!$G:$G,'Industrial Summary'!$F:$F,I$17,'Industrial Summary'!$D:$D,$E21,'Industrial Summary'!$A:$A,"ELC")+-SUMIFS('Industrial Summary'!$G:$G,'Industrial Summary'!$F:$F,I$17,'Industrial Summary'!$D:$D,"IFDFSTM",'Industrial Summary'!$A:$A,"ELC"))/SUMIFS('Industrial Summary'!$G:$G,'Industrial Summary'!$F:$F,I$17,'Industrial Summary'!$D:$D,$E21)),0))*0.98 -> -0.05534842 | J21: =(IF(SUMIFS('Industrial Summary'!$G:$G,'Industrial Summary'!$F:$F,J$17,'Industrial Summary'!$D:$D,$E21)>0,((-SUMIFS('Industrial Summary'!$G:$G,'Industrial Summary'!$F:$F,J$17,'Industrial Summary'!$D:$D,$E21,'Industrial Summary'!$A:$A,"ELC")+-SUMIFS('Industrial Summary'!$G:$G,'Industrial Summary'!$F:$F,J$17,'Industrial Summary'!$D:$D,"IFDFSTM",'Industrial Summary'!$A:$A,"ELC"))/SUMIFS('Industrial Summary'!$G:$G,'Industrial Summary'!$F:$F,J$17,'Industrial Summary'!$D:$D,$E21)),0))*0.98 -> -0.024687584 | K21: =(IF(SUMIFS('Industrial Summary'!$G:$G,'Industrial Summary'!$F:$F,K$17,'Industrial Summary'!$D:$D,$E21)>0,((-SUMIFS('Industrial Summary'!$G:$G,'Industrial Summary'!$F:$F,K$17,'Industrial Summary'!$D:$D,$E21,'Industrial Summary'!$A:$A,"ELC")+-SUMIFS('Industrial Summary'!$G:$G,'Industrial Summary'!$F:$F,K$17,'Industrial Summary'!$D:$D,"IFDFSTM",'Industrial Summary'!$A:$A,"ELC"))/SUMIFS('Industrial Summary'!$G:$G,'Industrial Summary'!$F:$F,K$17,'Industrial Summary'!$D:$D,$E21)),0))*0.98 -> -0.01162323 | L21: =(IF(SUMIFS('Industrial Summary'!$G:$G,'Industrial Summary'!$F:$F,L$17,'Industrial Summary'!$D:$D,$E21)>0,((-SUMIFS('Industrial Summary'!$G:$G,'Industrial Summary'!$F:$F,L$17,'Industrial Summary'!$D:$D,$E21,'Industrial Summary'!$A:$A,"ELC")+-SUMIFS('Industrial Summary'!$G:$G,'Industrial Summary'!$F:$F,L$17,'Industrial Summary'!$D:$D,"IFDFSTM",'Industrial Summary'!$A:$A,"ELC"))/SUMIFS('Industrial Summary'!$G:$G,'Industrial Summary'!$F:$F,L$17,'Industrial Summary'!$D:$D,$E21)),0))*0.98 -> -0.010565124 | M21: =(IF(SUMIFS('Industrial Summary'!$G:$G,'Industrial Summary'!$F:$F,M$17,'Industrial Summary'!$D:$D,$E21)>0,((-SUMIFS('Industrial Summary'!$G:$G,'Industrial Summary'!$F:$F,M$17,'Industrial Summary'!$D:$D,$E21,'Industrial Summary'!$A:$A,"ELC")+-SUMIFS('Industrial Summary'!$G:$G,'Industrial Summary'!$F:$F,M$17,'Industrial Summary'!$D:$D,"IFDFSTM",'Industrial Summary'!$A:$A,"ELC"))/SUMIFS('Industrial Summary'!$G:$G,'Industrial Summary'!$F:$F,M$17,'Industrial Summary'!$D:$D,$E21)),0))*0.98 -> -0.022965711 | N21: =(IF(SUMIFS('Industrial Summary'!$G:$G,'Industrial Summary'!$F:$F,N$17,'Industrial Summary'!$D:$D,$E21)>0,((-SUMIFS('Industrial Summary'!$G:$G,'Industrial Summary'!$F:$F,N$17,'Industrial Summary'!$D:$D,$E21,'Industrial Summary'!$A:$A,"ELC")+-SUMIFS('Industrial Summary'!$G:$G,'Industrial Summary'!$F:$F,N$17,'Industrial Summary'!$D:$D,"IFDFSTM",'Industrial Summary'!$A:$A,"ELC"))/SUMIFS('Industrial Summary'!$G:$G,'Industrial Summary'!$F:$F,N$17,'Industrial Summary'!$D:$D,$E21)),0))*0.98 -> -0.22216612 | O21: =(IF(SUMIFS('Industrial Summary'!$G:$G,'Industrial Summary'!$F:$F,O$17,'Industrial Summary'!$D:$D,$E21)>0,((-SUMIFS('Industrial Summary'!$G:$G,'Industrial Summary'!$F:$F,O$17,'Industrial Summary'!$D:$D,$E21,'Industrial Summary'!$A:$A,"ELC")+-SUMIFS('Industrial Summary'!$G:$G,'Industrial Summary'!$F:$F,O$17,'Industrial Summary'!$D:$D,"IFDFSTM",'Industrial Summary'!$A:$A,"ELC"))/SUMIFS('Industrial Summary'!$G:$G,'Industrial Summary'!$F:$F,O$17,'Industrial Summary'!$D:$D,$E21)),0))*0.98 -> -0.065067147 | P21: =(IF(SUMIFS('Industrial Summary'!$G:$G,'Industrial Summary'!$F:$F,P$17,'Industrial Summary'!$D:$D,$E21)>0,((-SUMIFS('Industrial Summary'!$G:$G,'Industrial Summary'!$F:$F,P$17,'Industrial Summary'!$D:$D,$E21,'Industrial Summary'!$A:$A,"ELC")+-SUMIFS('Industrial Summary'!$G:$G,'Industrial Summary'!$F:$F,P$17,'Industrial Summary'!$D:$D,"IFDFSTM",'Industrial Summary'!$A:$A,"ELC"))/SUMIFS('Industrial Summary'!$G:$G,'Industrial Summary'!$F:$F,P$17,'Industrial Summary'!$D:$D,$E21)),0))*0.98 -> -0.010304792 | Q21: 0 | R21: 15 | S21: =_xlfn.CONCAT("UC_",D21) -> UC_IFDST_ELC | V21: =C21 -> S_IFDSTELC | W21: =D21 -> IFDST_ELC | X21: =E21 -> IFDSTM | Y21: =F21 -> LO | Z21: 1 | AA21: =H21*$AM21 -> -0.049360046 | AB21: =I21*$AM21 -> -0.05534842 | AC21: =J21*$AM21 -> -0.024687584 | AD21: =K21*$AM21 -> -0.01162323 | AE21: =L21*$AM21 -> -0.010565124 | AF21: =M21*$AM21 -> -0.022965711 | AG21: =N21*$AM21 -> -0.22216612 | AH21: =O21*$AM21 -> -0.065067147 | AI21: =P21*$AM21 -> -0.010304792 | AL21: =RIGHT(W21,3) -> ELC | AM21: =1 -> 1
C22: S_IFDSTRFL | D22: IFDST_RFL | E22: IFDSTM | F22: LO | G22: 1 | H22: =(IF(SUMIFS('Industrial Summary'!$G:$G,'Industrial Summary'!$F:$F,H$17,'Industrial Summary'!$D:$D,$E22)>0,((-SUMIFS('Industrial Summary'!$G:$G,'Industrial Summary'!$F:$F,H$17,'Industrial Summary'!$D:$D,$E22,'Industrial Summary'!$A:$A,"RFL")+-SUMIFS('Industrial Summary'!$G:$G,'Industrial Summary'!$F:$F,H$17,'Industrial Summary'!$D:$D,"IFDFSTM",'Industrial Summary'!$A:$A,"RFL"))/SUMIFS('Industrial Summary'!$G:$G,'Industrial Summary'!$F:$F,H$17,'Industrial Summary'!$D:$D,$E22)),0))*0.98 -> -0.067499057 | I22: =(IF(SUMIFS('Industrial Summary'!$G:$G,'Industrial Summary'!$F:$F,I$17,'Industrial Summary'!$D:$D,$E22)>0,((-SUMIFS('Industrial Summary'!$G:$G,'Industrial Summary'!$F:$F,I$17,'Industrial Summary'!$D:$D,$E22,'Industrial Summary'!$A:$A,"RFL")+-SUMIFS('Industrial Summary'!$G:$G,'Industrial Summary'!$F:$F,I$17,'Industrial Summary'!$D:$D,"IFDFSTM",'Industrial Summary'!$A:$A,"RFL"))/SUMIFS('Industrial Summary'!$G:$G,'Industrial Summary'!$F:$F,I$17,'Industrial Summary'!$D:$D,$E22)),0))*0.98 -> 0 | J22: =(IF(SUMIFS('Industrial Summary'!$G:$G,'Industrial Summary'!$F:$F,J$17,'Industrial Summary'!$D:$D,$E22)>0,((-SUMIFS('Industrial Summary'!$G:$G,'Industrial Summary'!$F:$F,J$17,'Industrial Summary'!$D:$D,$E22,'Industrial Summary'!$A:$A,"RFL")+-SUMIFS('Industrial Summary'!$G:$G,'Industrial Summary'!$F:$F,J$17,'Industrial Summary'!$D:$D,"IFDFSTM",'Industrial Summary'!$A:$A,"RFL"))/SUMIFS('Industrial Summary'!$G:$G,'Industrial Summary'!$F:$F,J$17,'Industrial Summary'!$D:$D,$E22)),0))*0.98 -> 0 | K22: =(IF(SUMIFS('Industrial Summary'!$G:$G,'Industrial Summary'!$F:$F,K$17,'Industrial Summary'!$D:$D,$E22)>0,((-SUMIFS('Industrial Summary'!$G:$G,'Industrial Summary'!$F:$F,K$17,'Industrial Summary'!$D:$D,$E22,'Industrial Summary'!$A:$A,"RFL")+-SUMIFS('Industrial Summary'!$G:$G,'Industrial Summary'!$F:$F,K$17,'Industrial Summary'!$D:$D,"IFDFSTM",'Industrial Summary'!$A:$A,"RFL"))/SUMIFS('Industrial Summary'!$G:$G,'Industrial Summary'!$F:$F,K$17,'Industrial Summary'!$D:$D,$E22)),0))*0.98 -> 0 | L22: =(IF(SUMIFS('Industrial Summary'!$G:$G,'Industrial Summary'!$F:$F,L$17,'Industrial Summary'!$D:$D,$E22)>0,((-SUMIFS('Industrial Summary'!$G:$G,'Industrial Summary'!$F:$F,L$17,'Industrial Summary'!$D:$D,$E22,'Industrial Summary'!$A:$A,"RFL")+-SUMIFS('Industrial Summary'!$G:$G,'Industrial Summary'!$F:$F,L$17,'Industrial Summary'!$D:$D,"IFDFSTM",'Industrial Summary'!$A:$A,"RFL"))/SUMIFS('Industrial Summary'!$G:$G,'Industrial Summary'!$F:$F,L$17,'Industrial Summary'!$D:$D,$E22)),0))*0.98 -> 0 | M22: =(IF(SUMIFS('Industrial Summary'!$G:$G,'Industrial Summary'!$F:$F,M$17,'Industrial Summary'!$D:$D,$E22)>0,((-SUMIFS('Industrial Summary'!$G:$G,'Industrial Summary'!$F:$F,M$17,'Industrial Summary'!$D:$D,$E22,'Industrial Summary'!$A:$A,"RFL")+-SUMIFS('Industrial Summary'!$G:$G,'Industrial Summary'!$F:$F,M$17,'Industrial Summary'!$D:$D,"IFDFSTM",'Industrial Summary'!$A:$A,"RFL"))/SUMIFS('Industrial Summary'!$G:$G,'Industrial Summary'!$F:$F,M$17,'Industrial Summary'!$D:$D,$E22)),0))*0.98 -> 0 | N22: =(IF(SUMIFS('Industrial Summary'!$G:$G,'Industrial Summary'!$F:$F,N$17,'Industrial Summary'!$D:$D,$E22)>0,((-SUMIFS('Industrial Summary'!$G:$G,'Industrial Summary'!$F:$F,N$17,'Industrial Summary'!$D:$D,$E22,'Industrial Summary'!$A:$A,"RFL")+-SUMIFS('Industrial Summary'!$G:$G,'Industrial Summary'!$F:$F,N$17,'Industrial Summary'!$D:$D,"IFDFSTM",'Industrial Summary'!$A:$A,"RFL"))/SUMIFS('Industrial Summary'!$G:$G,'Industrial Summary'!$F:$F,N$17,'Industrial Summary'!$D:$D,$E22)),0))*0.98 -> 0 | O22: =(IF(SUMIFS('Industrial Summary'!$G:$G,'Industrial Summary'!$F:$F,O$17,'Industrial Summary'!$D:$D,$E22)>0,((-SUMIFS('Industrial Summary'!$G:$G,'Industrial Summary'!$F:$F,O$17,'Industrial Summary'!$D:$D,$E22,'Industrial Summary'!$A:$A,"RFL")+-SUMIFS('Industrial Summary'!$G:$G,'Industrial Summary'!$F:$F,O$17,'Industrial Summary'!$D:$D,"IFDFSTM",'Industrial Summary'!$A:$A,"RFL"))/SUMIFS('Industrial Summary'!$G:$G,'Industrial Summary'!$F:$F,O$17,'Industrial Summary'!$D:$D,$E22)),0))*0.98 -> 0 | P22: =(IF(SUMIFS('Industrial Summary'!$G:$G,'Industrial Summary'!$F:$F,P$17,'Industrial Summary'!$D:$D,$E22)>0,((-SUMIFS('Industrial Summary'!$G:$G,'Industrial Summary'!$F:$F,P$17,'Industrial Summary'!$D:$D,$E22,'Industrial Summary'!$A:$A,"RFL")+-SUMIFS('Industrial Summary'!$G:$G,'Industrial Summary'!$F:$F,P$17,'Industrial Summary'!$D:$D,"IFDFSTM",'Industrial Summary'!$A:$A,"RFL"))/SUMIFS('Industrial Summary'!$G:$G,'Industrial Summary'!$F:$F,P$17,'Industrial Summary'!$D:$D,$E22)),0))*0.98 -> 0 | Q22: 0 | R22: 15 | S22: =_xlfn.CONCAT("UC_",D22) -> UC_IFDST_RFL | V22: =C22 -> S_IFDSTRFL | W22: =D22 -> IFDST_RFL | X22: =E22 -> IFDSTM | Y22: =F22 -> LO | Z22: 1 | AA22: =H22*$AM22 -> -0.067499057 | AB22: =I22*$AM22 -> 0 | AC22: =J22*$AM22 -> 0 | AD22: =K22*$AM22 -> 0 | AE22: =L22*$AM22 -> 0 | AF22: =M22*$AM22 -> 0 | AG22: =N22*$AM22 -> 0 | AH22: =O22*$AM22 -> 0 | AI22: =P22*$AM22 -> 0 | AL22: =RIGHT(W22,3) -> RFL | AM22: =1 -> 1
C23: S_IFDSTDST | D23: IFDST_DST | E23: IFDSTM | F23: LO | G23: 1 | H23: =(IF(SUMIFS('Industrial Summary'!$G:$G,'Industrial Summary'!$F:$F,H$17,'Industrial Summary'!$D:$D,$E23)>0,((-SUMIFS('Industrial Summary'!$G:$G,'Industrial Summary'!$F:$F,H$17,'Industrial Summary'!$D:$D,$E23,'Industrial Summary'!$A:$A,"DST")+-SUMIFS('Industrial Summary'!$G:$G,'Industrial Summary'!$F:$F,H$17,'Industrial Summary'!$D:$D,"IFDFSTM",'Industrial Summary'!$A:$A,"DST"))/SUMIFS('Industrial Summary'!$G:$G,'Industrial Summary'!$F:$F,H$17,'Industrial Summary'!$D:$D,$E23)),0))*0.98 -> -0.083222866 | I23: =(IF(SUMIFS('Industrial Summary'!$G:$G,'Industrial Summary'!$F:$F,I$17,'Industrial Summary'!$D:$D,$E23)>0,((-SUMIFS('Industrial Summary'!$G:$G,'Industrial Summary'!$F:$F,I$17,'Industrial Summary'!$D:$D,$E23,'Industrial Summary'!$A:$A,"DST")+-SUMIFS('Industrial Summary'!$G:$G,'Industrial Summary'!$F:$F,I$17,'Industrial Summary'!$D:$D,"IFDFSTM",'Industrial Summary'!$A:$A,"DST"))/SUMIFS('Industrial Summary'!$G:$G,'Industrial Summary'!$F:$F,I$17,'Industrial Summary'!$D:$D,$E23)),0))*0.98 -> 0 | J23: =(IF(SUMIFS('Industrial Summary'!$G:$G,'Industrial Summary'!$F:$F,J$17,'Industrial Summary'!$D:$D,$E23)>0,((-SUMIFS('Industrial Summary'!$G:$G,'Industrial Summary'!$F:$F,J$17,'Industrial Summary'!$D:$D,$E23,'Industrial Summary'!$A:$A,"DST")+-SUMIFS('Industrial Summary'!$G:$G,'Industrial Summary'!$F:$F,J$17,'Industrial Summary'!$D:$D,"IFDFSTM",'Industrial Summary'!$A:$A,"DST"))/SUMIFS('Industrial Summary'!$G:$G,'Industrial Summary'!$F:$F,J$17,'Industrial Summary'!$D:$D,$E23)),0))*0.98 -> 0 | K23: =(IF(SUMIFS('Industrial Summary'!$G:$G,'Industrial Summary'!$F:$F,K$17,'Industrial Summary'!$D:$D,$E23)>0,((-SUMIFS('Industrial Summary'!$G:$G,'Industrial Summary'!$F:$F,K$17,'Industrial Summary'!$D:$D,$E23,'Industrial Summary'!$A:$A,"DST")+-SUMIFS('Industrial Summary'!$G:$G,'Industrial Summary'!$F:$F,K$17,'Industrial Summary'!$D:$D,"IFDFSTM",'Industrial Summary'!$A:$A,"DST"))/SUMIFS('Industrial Summary'!$G:$G,'Industrial Summary'!$F:$F,K$17,'Industrial Summary'!$D:$D,$E23)),0))*0.98 -> 0 | L23: =(IF(SUMIFS('Industrial Summary'!$G:$G,'Industrial Summary'!$F:$F,L$17,'Industrial Summary'!$D:$D,$E23)>0,((-SUMIFS('Industrial Summary'!$G:$G,'Industrial Summary'!$F:$F,L$17,'Industrial Summary'!$D:$D,$E23,'Industrial Summary'!$A:$A,"DST")+-SUMIFS('Industrial Summary'!$G:$G,'Industrial Summary'!$F:$F,L$17,'Industrial Summary'!$D:$D,"IFDFSTM",'Industrial Summary'!$A:$A,"DST"))/SUMIFS('Industrial Summary'!$G:$G,'Industrial Summary'!$F:$F,L$17,'Industrial Summary'!$D:$D,$E23)),0))*0.98 -> 0 | M23: =(IF(SUMIFS('Industrial Summary'!$G:$G,'Industrial Summary'!$F:$F,M$17,'Industrial Summary'!$D:$D,$E23)>0,((-SUMIFS('Industrial Summary'!$G:$G,'Industrial Summary'!$F:$F,M$17,'Industrial Summary'!$D:$D,$E23,'Industrial Summary'!$A:$A,"DST")+-SUMIFS('Industrial Summary'!$G:$G,'Industrial Summary'!$F:$F,M$17,'Industrial Summary'!$D:$D,"IFDFSTM",'Industrial Summary'!$A:$A,"DST"))/SUMIFS('Industrial Summary'!$G:$G,'Industrial Summary'!$F:$F,M$17,'Industrial Summary'!$D:$D,$E23)),0))*0.98 -> 0 | N23: =(IF(SUMIFS('Industrial Summary'!$G:$G,'Industrial Summary'!$F:$F,N$17,'Industrial Summary'!$D:$D,$E23)>0,((-SUMIFS('Industrial Summary'!$G:$G,'Industrial Summary'!$F:$F,N$17,'Industrial Summary'!$D:$D,$E23,'Industrial Summary'!$A:$A,"DST")+-SUMIFS('Industrial Summary'!$G:$G,'Industrial Summary'!$F:$F,N$17,'Industrial Summary'!$D:$D,"IFDFSTM",'Industrial Summary'!$A:$A,"DST"))/SUMIFS('Industrial Summary'!$G:$G,'Industrial Summary'!$F:$F,N$17,'Industrial Summary'!$D:$D,$E23)),0))*0.98 -> 0 | O23: =(IF(SUMIFS('Industrial Summary'!$G:$G,'Industrial Summary'!$F:$F,O$17,'Industrial Summary'!$D:$D,$E23)>0,((-SUMIFS('Industrial Summary'!$G:$G,'Industrial Summary'!$F:$F,O$17,'Industrial Summary'!$D:$D,$E23,'Industrial Summary'!$A:$A,"DST")+-SUMIFS('Industrial Summary'!$G:$G,'Industrial Summary'!$F:$F,O$17,'Industrial Summary'!$D:$D,"IFDFSTM",'Industrial Summary'!$A:$A,"DST"))/SUMIFS('Industrial Summary'!$G:$G,'Industrial Summary'!$F:$F,O$17,'Industrial Summary'!$D:$D,$E23)),0))*0.98 -> 0 | P23: =(IF(SUMIFS('Industrial Summary'!$G:$G,'Industrial Summary'!$F:$F,P$17,'Industrial Summary'!$D:$D,$E23)>0,((-SUMIFS('Industrial Summary'!$G:$G,'Industrial Summary'!$F:$F,P$17,'Industrial Summary'!$D:$D,$E23,'Industrial Summary'!$A:$A,"DST")+-SUMIFS('Industrial Summary'!$G:$G,'Industrial Summary'!$F:$F,P$17,'Industrial Summary'!$D:$D,"IFDFSTM",'Industrial Summary'!$A:$A,"DST"))/SUMIFS('Industrial Summary'!$G:$G,'Industrial Summary'!$F:$F,P$17,'Industrial Summary'!$D:$D,$E23)),0))*0.98 -> 0 | Q23: 0 | R23: 15 | S23: =_xlfn.CONCAT("UC_",D23) -> UC_IFDST_DST | V23: =C23 -> S_IFDSTDST | W23: =D23 -> IFDST_DST | X23: =E23 -> IFDSTM | Y23: =F23 -> LO | Z23: 1 | AA23: =H23*$AM23 -> -0.083222866 | AB23: =I23*$AM23 -> 0 | AC23: =J23*$AM23 -> 0 | AD23: =K23*$AM23 -> 0 | AE23: =L23*$AM23 -> 0 | AF23: =M23*$AM23 -> 0 | AG23: =N23*$AM23 -> 0 | AH23: =O23*$AM23 -> 0 | AI23: =P23*$AM23 -> 0 | AL23: =RIGHT(W23,3) -> DST | AM23: =1 -> 1
C24: S_IFDSTNGA | D24: IFDST_NGA | E24: IFDSTM | F24: LO | G24: 1 | H24: =(IF(SUMIFS('Industrial Summary'!$G:$G,'Industrial Summary'!$F:$F,H$17,'Industrial Summary'!$D:$D,$E24)>0,((-SUMIFS('Industrial Summary'!$G:$G,'Industrial Summary'!$F:$F,H$17,'Industrial Summary'!$D:$D,$E24,'Industrial Summary'!$A:$A,"NGA")+-SUMIFS('Industrial Summary'!$G:$G,'Industrial Summary'!$F:$F,H$17,'Industrial Summary'!$D:$D,"IFDFSTM",'Industrial Summary'!$A:$A,"NGA"))/SUMIFS('Industrial Summary'!$G:$G,'Industrial Summary'!$F:$F,H$17,'Industrial Summary'!$D:$D,$E24)),0))*0.98 -> -0.77715739 | I24: =(IF(SUMIFS('Industrial Summary'!$G:$G,'Industrial Summary'!$F:$F,I$17,'Industrial Summary'!$D:$D,$E24)>0,((-SUMIFS('Industrial Summary'!$G:$G,'Industrial Summary'!$F:$F,I$17,'Industrial Summary'!$D:$D,$E24,'Industrial Summary'!$A:$A,"NGA")+-SUMIFS('Industrial Summary'!$G:$G,'Industrial Summary'!$F:$F,I$17,'Industrial Summary'!$D:$D,"IFDFSTM",'Industrial Summary'!$A:$A,"NGA"))/SUMIFS('Industrial Summary'!$G:$G,'Industrial Summary'!$F:$F,I$17,'Industrial Summary'!$D:$D,$E24)),0))*0.98 -> -0.87736154 | J24: =(IF(SUMIFS('Industrial Summary'!$G:$G,'Industrial Summary'!$F:$F,J$17,'Industrial Summary'!$D:$D,$E24)>0,((-SUMIFS('Industrial Summary'!$G:$G,'Industrial Summary'!$F:$F,J$17,'Industrial Summary'!$D:$D,$E24,'Industrial Summary'!$A:$A,"NGA")+-SUMIFS('Industrial Summary'!$G:$G,'Industrial Summary'!$F:$F,J$17,'Industrial Summary'!$D:$D,"IFDFSTM",'Industrial Summary'!$A:$A,"NGA"))/SUMIFS('Industrial Summary'!$G:$G,'Industrial Summary'!$F:$F,J$17,'Industrial Summary'!$D:$D,$E24)),0))*0.98 -> -0.58836465 | K24: =(IF(SUMIFS('Industrial Summary'!$G:$G,'Industrial Summary'!$F:$F,K$17,'Industrial Summary'!$D:$D,$E24)>0,((-SUMIFS('Industrial Summary'!$G:$G,'Industrial Summary'!$F:$F,K$17,'Industrial Summary'!$D:$D,$E24,'Industrial Summary'!$A:$A,"NGA")+-SUMIFS('Industrial Summary'!$G:$G,'Industrial Summary'!$F:$F,K$17,'Industrial Summary'!$D:$D,"IFDFSTM",'Industrial Summary'!$A:$A,"NGA"))/SUMIFS('Industrial Summary'!$G:$G,'Industrial Summary'!$F:$F,K$17,'Industrial Summary'!$D:$D,$E24)),0))*0.98 -> -0.73966074 | L24: =(IF(SUMIFS('Industrial Summary'!$G:$G,'Industrial Summary'!$F:$F,L$17,'Industrial Summary'!$D:$D,$E24)>0,((-SUMIFS('Industrial Summary'!$G:$G,'Industrial Summary'!$F:$F,L$17,'Industrial Summary'!$D:$D,$E24,'Industrial Summary'!$A:$A,"NGA")+-SUMIFS('Industrial Summary'!$G:$G,'Industrial Summary'!$F:$F,L$17,'Industrial Summary'!$D:$D,"IFDFSTM",'Industrial Summary'!$A:$A,"NGA"))/SUMIFS('Industrial Summary'!$G:$G,'Industrial Summary'!$F:$F,L$17,'Industrial Summary'!$D:$D,$E24)),0))*0.98 -> -0.32791352 | M24: =(IF(SUMIFS('Industrial Summary'!$G:$G,'Industrial Summary'!$F:$F,M$17,'Industrial Summary'!$D:$D,$E24)>0,((-SUMIFS('Industrial Summary'!$G:$G,'Industrial Summary'!$F:$F,M$17,'Industrial Summary'!$D:$D,$E24,'Industrial Summary'!$A:$A,"NGA")+-SUMIFS('Industrial Summary'!$G:$G,'Industrial Summary'!$F:$F,M$17,'Industrial Summary'!$D:$D,"IFDFSTM",'Industrial Summary'!$A:$A,"NGA"))/SUMIFS('Industrial Summary'!$G:$G,'Industrial Summary'!$F:$F,M$17,'Industrial Summary'!$D:$D,$E24)),0))*0.98 -> -0.88655923 | N24: =(IF(SUMIFS('Industrial Summary'!$G:$G,'Industrial Summary'!$F:$F,N$17,'Industrial Summary'!$D:$D,$E24)>0,((-SUMIFS('Industrial Summary'!$G:$G,'Industrial Summary'!$F:$F,N$17,'Industrial Summary'!$D:$D,$E24,'Industrial Summary'!$A:$A,"NGA")+-SUMIFS('Industrial Summary'!$G:$G,'Industrial Summary'!$F:$F,N$17,'Industrial Summary'!$D:$D,"IFDFSTM",'Industrial Summary'!$A:$A,"NGA"))/SUMIFS('Industrial Summary'!$G:$G,'Industrial Summary'!$F:$F,N$17,'Industrial Summary'!$D:$D,$E24)),0))*0.98 -> -0.75783388 | O24: =(IF(SUMIFS('Industrial Summary'!$G:$G,'Industrial Summary'!$F:$F,O$17,'Industrial Summary'!$D:$D,$E24)>0,((-SUMIFS('Industrial Summary'!$G:$G,'Industrial Summary'!$F:$F,O$17,'Industrial Summary'!$D:$D,$E24,'Industrial Summary'!$A:$A,"NGA")+-SUMIFS('Industrial Summary'!$G:$G,'Industrial Summary'!$F:$F,O$17,'Industrial Summary'!$D:$D,"IFDFSTM",'Industrial Summary'!$A:$A,"NGA"))/SUMIFS('Industrial Summary'!$G:$G,'Industrial Summary'!$F:$F,O$17,'Industrial Summary'!$D:$D,$E24)),0))*0.98 -> -0.53593576 | P24: =(IF(SUMIFS('Industrial Summary'!$G:$G,'Industrial Summary'!$F:$F,P$17,'Industrial Summary'!$D:$D,$E24)>0,((-SUMIFS('Industrial Summary'!$G:$G,'Industrial Summary'!$F:$F,P$17,'Industrial Summary'!$D:$D,$E24,'Industrial Summary'!$A:$A,"NGA")+-SUMIFS('Industrial Summary'!$G:$G,'Industrial Summary'!$F:$F,P$17,'Industrial Summary'!$D:$D,"IFDFSTM",'Industrial Summary'!$A:$A,"NGA"))/SUMIFS('Industrial Summary'!$G:$G,'Industrial Summary'!$F:$F,P$17,'Industrial Summary'!$D:$D,$E24)),0))*0.98 -> -0.84170957 | Q24: 0 | R24: 15 | S24: =_xlfn.CONCAT("UC_",D24) -> UC_IFDST_NGA | V24: =C24 -> S_IFDSTNGA | W24: =D24 -> IFDST_NGA | X24: =E24 -> IFDSTM | Y24: =F24 -> LO | Z24: 1 | AA24: =H24*$AM24 -> -0.55955332 | AB24: =I24*$AM24 -> -0.63170031 | AC24: =J24*$AM24 -> -0.42362255 | AD24: =K24*$AM24 -> -0.53255573 | AE24: =L24*$AM24 -> -0.23609773 | AF24: =M24*$AM24 -> -0.63832265 | AG24: =N24*$AM24 -> -0.5456404 | AH24: =O24*$AM24 -> -0.38587375 | AI24: =P24*$AM24 -> -0.60603089 | AL24: =RIGHT(W24,3) -> NGA | AM24: =Y5 -> 0.72
C25: S_IFDSTCOA | D25: IFDST_COA | E25: IFDSTM | F25: UP | G25: 1 | H25: =(IF(SUMIFS('Industrial Summary'!$G:$G,'Industrial Summary'!$F:$F,H$17,'Industrial Summary'!$D:$D,$E25)>0,((-SUMIFS('Industrial Summary'!$G:$G,'Industrial Summary'!$F:$F,H$17,'Industrial Summary'!$D:$D,$E25,'Industrial Summary'!$A:$A,"COA")+-SUMIFS('Industrial Summary'!$G:$G,'Industrial Summary'!$F:$F,H$17,'Industrial Summary'!$D:$D,"IFDFSTM",'Industrial Summary'!$A:$A,"COA"))/SUMIFS('Industrial Summary'!$G:$G,'Industrial Summary'!$F:$F,H$17,'Industrial Summary'!$D:$D,$E25)),0))*0.98 -> 0 | I25: =(IF(SUMIFS('Industrial Summary'!$G:$G,'Industrial Summary'!$F:$F,I$17,'Industrial Summary'!$D:$D,$E25)>0,((-SUMIFS('Industrial Summary'!$G:$G,'Industrial Summary'!$F:$F,I$17,'Industrial Summary'!$D:$D,$E25,'Industrial Summary'!$A:$A,"COA")+-SUMIFS('Industrial Summary'!$G:$G,'Industrial Summary'!$F:$F,I$17,'Industrial Summary'!$D:$D,"IFDFSTM",'Industrial Summary'!$A:$A,"COA"))/SUMIFS('Industrial Summary'!$G:$G,'Industrial Summary'!$F:$F,I$17,'Industrial Summary'!$D:$D,$E25)),0))*0.98 -> -0.047290041 | J25: =(IF(SUMIFS('Industrial Summary'!$G:$G,'Industrial Summary'!$F:$F,J$17,'Industrial Summary'!$D:$D,$E25)>0,((-SUMIFS('Industrial Summary'!$G:$G,'Industrial Summary'!$F:$F,J$17,'Industrial Summary'!$D:$D,$E25,'Industrial Summary'!$A:$A,"COA")+-SUMIFS('Industrial Summary'!$G:$G,'Industrial Summary'!$F:$F,J$17,'Industrial Summary'!$D:$D,"IFDFSTM",'Industrial Summary'!$A:$A,"COA"))/SUMIFS('Industrial Summary'!$G:$G,'Industrial Summary'!$F:$F,J$17,'Industrial Summary'!$D:$D,$E25)),0))*0.98 -> -0.36694777 | K25: =(IF(SUMIFS('Industrial Summary'!$G:$G,'Industrial Summary'!$F:$F,K$17,'Industrial Summary'!$D:$D,$E25)>0,((-SUMIFS('Industrial Summary'!$G:$G,'Industrial Summary'!$F:$F,K$17,'Industrial Summary'!$D:$D,$E25,'Industrial Summary'!$A:$A,"COA")+-SUMIFS('Industrial Summary'!$G:$G,'Industrial Summary'!$F:$F,K$17,'Industrial Summary'!$D:$D,"IFDFSTM",'Industrial Summary'!$A:$A,"COA"))/SUMIFS('Industrial Summary'!$G:$G,'Industrial Summary'!$F:$F,K$17,'Industrial Summary'!$D:$D,$E25)),0))*0.98 -> -0.22871603 | L25: =(IF(SUMIFS('Industrial Summary'!$G:$G,'Industrial Summary'!$F:$F,L$17,'Industrial Summary'!$D:$D,$E25)>0,((-SUMIFS('Industrial Summary'!$G:$G,'Industrial Summary'!$F:$F,L$17,'Industrial Summary'!$D:$D,$E25,'Industrial Summary'!$A:$A,"COA")+-SUMIFS('Industrial Summary'!$G:$G,'Industrial Summary'!$F:$F,L$17,'Industrial Summary'!$D:$D,"IFDFSTM",'Industrial Summary'!$A:$A,"COA"))/SUMIFS('Industrial Summary'!$G:$G,'Industrial Summary'!$F:$F,L$17,'Industrial Summary'!$D:$D,$E25)),0))*0.98 -> -0.64152136 | M25: =(IF(SUMIFS('Industrial Summary'!$G:$G,'Industrial Summary'!$F:$F,M$17,'Industrial Summary'!$D:$D,$E25)>0,((-SUMIFS('Industrial Summary'!$G:$G,'Industrial Summary'!$F:$F,M$17,'Industrial Summary'!$D:$D,$E25,'Industrial Summary'!$A:$A,"COA")+-SUMIFS('Industrial Summary'!$G:$G,'Industrial Summary'!$F:$F,M$17,'Industrial Summary'!$D:$D,"IFDFSTM",'Industrial Summary'!$A:$A,"COA"))/SUMIFS('Industrial Summary'!$G:$G,'Industrial Summary'!$F:$F,M$17,'Industrial Summary'!$D:$D,$E25)),0))*0.98 -> -0.070475055 | N25: =(IF(SUMIFS('Industrial Summary'!$G:$G,'Industrial Summary'!$F:$F,N$17,'Industrial Summary'!$D:$D,$E25)>0,((-SUMIFS('Industrial Summary'!$G:$G,'Industrial Summary'!$F:$F,N$17,'Industrial Summary'!$D:$D,$E25,'Industrial Summary'!$A:$A,"COA")+-SUMIFS('Industrial Summary'!$G:$G,'Industrial Summary'!$F:$F,N$17,'Industrial Summary'!$D:$D,"IFDFSTM",'Industrial Summary'!$A:$A,"COA"))/SUMIFS('Industrial Summary'!$G:$G,'Industrial Summary'!$F:$F,N$17,'Industrial Summary'!$D:$D,$E25)),0))*0.98 -> 0 | O25: =(IF(SUMIFS('Industrial Summary'!$G:$G,'Industrial Summary'!$F:$F,O$17,'Industrial Summary'!$D:$D,$E25)>0,((-SUMIFS('Industrial Summary'!$G:$G,'Industrial Summary'!$F:$F,O$17,'Industrial Summary'!$D:$D,$E25,'Industrial Summary'!$A:$A,"COA")+-SUMIFS('Industrial Summary'!$G:$G,'Industrial Summary'!$F:$F,O$17,'Industrial Summary'!$D:$D,"IFDFSTM",'Industrial Summary'!$A:$A,"COA"))/SUMIFS('Industrial Summary'!$G:$G,'Industrial Summary'!$F:$F,O$17,'Industrial Summary'!$D:$D,$E25)),0))*0.98 -> -0.3789971 | P25: =(IF(SUMIFS('Industrial Summary'!$G:$G,'Industrial Summary'!$F:$F,P$17,'Industrial Summary'!$D:$D,$E25)>0,((-SUMIFS('Industrial Summary'!$G:$G,'Industrial Summary'!$F:$F,P$17,'Industrial Summary'!$D:$D,$E25,'Industrial Summary'!$A:$A,"COA")+-SUMIFS('Industrial Summary'!$G:$G,'Industrial Summary'!$F:$F,P$17,'Industrial Summary'!$D:$D,"IFDFSTM",'Industrial Summary'!$A:$A,"COA"))/SUMIFS('Industrial Summary'!$G:$G,'Industrial Summary'!$F:$F,P$17,'Industrial Summary'!$D:$D,$E25)),0))*0.98 -> -0.12798563 | Q25: 0 | R25: 15 | S25: =_xlfn.CONCAT("UC_",D25) -> UC_IFDST_COA | V25: =C25 -> S_IFDSTCOA | W25: =D25 -> IFDST_COA | X25: =E25 -> IFDSTM | Y25: =F25 -> UP | Z25: 1 | AA25: =H25*$AM25 -> 0 | AB25: =I25*$AM25 -> -0.037832032 | AC25: =J25*$AM25 -> -0.29355821 | AD25: =K25*$AM25 -> -0.18297282 | AE25: =L25*$AM25 -> -0.51321709 | AF25: =M25*$AM25 -> -0.056380044 | AG25: =N25*$AM25 -> 0 | AH25: =O25*$AM25 -> -0.30319768 | AI25: =P25*$AM25 -> -0.10238851 | AL25: =RIGHT(W25,3) -> COA | AM25: =Z5 -> 0.8
C26: S_IFDPHELC | D26: IFDPH_ELC | E26: IFDPRH | F26: LO | G26: 1 | H26: =IF(SUMIFS('Industrial Summary'!$G:$G,'Industrial Summary'!$F:$F,H$17,'Industrial Summary'!$D:$D,$E26)>0,(-SUMIFS('Industrial Summary'!$G:$G,'Industrial Summary'!$F:$F,H$17,'Industrial Summary'!$D:$D,$E26,'Industrial Summary'!$A:$A,"ELC")/SUMIFS('Industrial Summary'!$G:$G,'Industrial Summary'!$F:$F,H$17,'Industrial Summary'!$D:$D,$E26)),0)*0.98 -> -0.089657252 | I26: =IF(SUMIFS('Industrial Summary'!$G:$G,'Industrial Summary'!$F:$F,I$17,'Industrial Summary'!$D:$D,$E26)>0,(-SUMIFS('Industrial Summary'!$G:$G,'Industrial Summary'!$F:$F,I$17,'Industrial Summary'!$D:$D,$E26,'Industrial Summary'!$A:$A,"ELC")/SUMIFS('Industrial Summary'!$G:$G,'Industrial Summary'!$F:$F,I$17,'Industrial Summary'!$D:$D,$E26)),0)*0.98 -> -0.089657252 | J26: =IF(SUMIFS('Industrial Summary'!$G:$G,'Industrial Summary'!$F:$F,J$17,'Industrial Summary'!$D:$D,$E26)>0,(-SUMIFS('Industrial Summary'!$G:$G,'Industrial Summary'!$F:$F,J$17,'Industrial Summary'!$D:$D,$E26,'Industrial Summary'!$A:$A,"ELC")/SUMIFS('Industrial Summary'!$G:$G,'Industrial Summary'!$F:$F,J$17,'Industrial Summary'!$D:$D,$E26)),0)*0.98 -> -0.10030697 | K26: =IF(SUMIFS('Industrial Summary'!$G:$G,'Industrial Summary'!$F:$F,K$17,'Industrial Summary'!$D:$D,$E26)>0,(-SUMIFS('Industrial Summary'!$G:$G,'Industrial Summary'!$F:$F,K$17,'Industrial Summary'!$D:$D,$E26,'Industrial Summary'!$A:$A,"ELC")/SUMIFS('Industrial Summary'!$G:$G,'Industrial Summary'!$F:$F,K$17,'Industrial Summary'!$D:$D,$E26)),0)*0.98 -> -0.10669002 | L26: =IF(SUMIFS('Industrial Summary'!$G:$G,'Industrial Summary'!$F:$F,L$17,'Industrial Summary'!$D:$D,$E26)>0,(-SUMIFS('Industrial Summary'!$G:$G,'Industrial Summary'!$F:$F,L$17,'Industrial Summary'!$D:$D,$E26,'Industrial Summary'!$A:$A,"ELC")/SUMIFS('Industrial Summary'!$G:$G,'Industrial Summary'!$F:$F,L$17,'Industrial Summary'!$D:$D,$E26)),0)*0.98 -> -0.1354569 | M26: =IF(SUMIFS('Industrial Summary'!$G:$G,'Industrial Summary'!$F:$F,M$17,'Industrial Summary'!$D:$D,$E26)>0,(-SUMIFS('Industrial Summary'!$G:$G,'Industrial Summary'!$F:$F,M$17,'Industrial Summary'!$D:$D,$E26,'Industrial Summary'!$A:$A,"ELC")/SUMIFS('Industrial Summary'!$G:$G,'Industrial Summary'!$F:$F,M$17,'Industrial Summary'!$D:$D,$E26)),0)*0.98 -> -0.10836552 | N26: =IF(SUMIFS('Industrial Summary'!$G:$G,'Industrial Summary'!$F:$F,N$17,'Industrial Summary'!$D:$D,$E26)>0,(-SUMIFS('Industrial Summary'!$G:$G,'Industrial Summary'!$F:$F,N$17,'Industrial Summary'!$D:$D,$E26,'Industrial Summary'!$A:$A,"ELC")/SUMIFS('Industrial Summary'!$G:$G,'Industrial Summary'!$F:$F,N$17,'Industrial Summary'!$D:$D,$E26)),0)*0.98 -> -0.10836552 | O26: =IF(SUMIFS('Industrial Summary'!$G:$G,'Industrial Summary'!$F:$F,O$17,'Industrial Summary'!$D:$D,$E26)>0,(-SUMIFS('Industrial Summary'!$G:$G,'Industrial Summary'!$F:$F,O$17,'Industrial Summary'!$D:$D,$E26,'Industrial Summary'!$A:$A,"ELC")/SUMIFS('Industrial Summary'!$G:$G,'Industrial Summary'!$F:$F,O$17,'Industrial Summary'!$D:$D,$E26)),0)*0.98 -> -0.067582227 | P26: =IF(SUMIFS('Industrial Summary'!$G:$G,'Industrial Summary'!$F:$F,P$17,'Industrial Summary'!$D:$D,$E26)>0,(-SUMIFS('Industrial Summary'!$G:$G,'Industrial Summary'!$F:$F,P$17,'Industrial Summary'!$D:$D,$E26,'Industrial Summary'!$A:$A,"ELC")/SUMIFS('Industrial Summary'!$G:$G,'Industrial Summary'!$F:$F,P$17,'Industrial Summary'!$D:$D,$E26)),0)*0.98 -> -0.079508502 | Q26: 0 | R26: 15 | S26: =_xlfn.CONCAT("UC_",D26) -> UC_IFDPH_ELC | V26: =C26 -> S_IFDPHELC | W26: =D26 -> IFDPH_ELC | X26: =E26 -> IFDPRH | Y26: =F26 -> LO | Z26: 1 | AA26: =H26*$AM26 -> -0.089657252 | AB26: =I26*$AM26 -> -0.089657252 | AC26: =J26*$AM26 -> -0.10030697 | AD26: =K26*$AM26 -> -0.10669002 | AE26: =L26*$AM26 -> -0.1354569 | AF26: =M26*$AM26 -> -0.10836552 | AG26: =N26*$AM26 -> -0.10836552 | AH26: =O26*$AM26 -> -0.067582227 | AI26: =P26*$AM26 -> -0.079508502 | AL26: =RIGHT(W26,3) -> ELC | AM26: =1 -> 1
C27: S_IFDPHRFL | D27: IFDPH_RFL | E27: IFDPRH | F27: LO | G27: 1 | H27: =IF(SUMIFS('Industrial Summary'!$G:$G,'Industrial Summary'!$F:$F,H$17,'Industrial Summary'!$D:$D,$E27)>0,(-SUMIFS('Industrial Summary'!$G:$G,'Industrial Summary'!$F:$F,H$17,'Industrial Summary'!$D:$D,$E27,'Industrial Summary'!$A:$A,"RFL")/SUMIFS('Industrial Summary'!$G:$G,'Industrial Summary'!$F:$F,H$17,'Industrial Summary'!$D:$D,$E27)),0)*0.98 -> -0.0040003546 | I27: =IF(SUMIFS('Industrial Summary'!$G:$G,'Industrial Summary'!$F:$F,I$17,'Industrial Summary'!$D:$D,$E27)>0,(-SUMIFS('Industrial Summary'!$G:$G,'Industrial Summary'!$F:$F,I$17,'Industrial Summary'!$D:$D,$E27,'Industrial Summary'!$A:$A,"RFL")/SUMIFS('Industrial Summary'!$G:$G,'Industrial Summary'!$F:$F,I$17,'Industrial Summary'!$D:$D,$E27)),0)*0.98 -> -0.0040003546 | J27: =IF(SUMIFS('Industrial Summary'!$G:$G,'Industrial Summary'!$F:$F,J$17,'Industrial Summary'!$D:$D,$E27)>0,(-SUMIFS('Industrial Summary'!$G:$G,'Industrial Summary'!$F:$F,J$17,'Industrial Summary'!$D:$D,$E27,'Industrial Summary'!$A:$A,"RFL")/SUMIFS('Industrial Summary'!$G:$G,'Industrial Summary'!$F:$F,J$17,'Industrial Summary'!$D:$D,$E27)),0)*0.98 -> 0 | K27: =IF(SUMIFS('Industrial Summary'!$G:$G,'Industrial Summary'!$F:$F,K$17,'Industrial Summary'!$D:$D,$E27)>0,(-SUMIFS('Industrial Summary'!$G:$G,'Industrial Summary'!$F:$F,K$17,'Industrial Summary'!$D:$D,$E27,'Industrial Summary'!$A:$A,"RFL")/SUMIFS('Industrial Summary'!$G:$G,'Industrial Summary'!$F:$F,K$17,'Industrial Summary'!$D:$D,$E27)),0)*0.98 -> 0 | L27: =IF(SUMIFS('Industrial Summary'!$G:$G,'Industrial Summary'!$F:$F,L$17,'Industrial Summary'!$D:$D,$E27)>0,(-SUMIFS('Industrial Summary'!$G:$G,'Industrial Summary'!$F:$F,L$17,'Industrial Summary'!$D:$D,$E27,'Industrial Summary'!$A:$A,"RFL")/SUMIFS('Industrial Summary'!$G:$G,'Industrial Summary'!$F:$F,L$17,'Industrial Summary'!$D:$D,$E27)),0)*0.98 -> 0 | M27: =IF(SUMIFS('Industrial Summary'!$G:$G,'Industrial Summary'!$F:$F,M$17,'Industrial Summary'!$D:$D,$E27)>0,(-SUMIFS('Industrial Summary'!$G:$G,'Industrial Summary'!$F:$F,M$17,'Industrial Summary'!$D:$D,$E27,'Industrial Summary'!$A:$A,"RFL")/SUMIFS('Industrial Summary'!$G:$G,'Industrial Summary'!$F:$F,M$17,'Industrial Summary'!$D:$D,$E27)),0)*0.98 -> -0.0029377736 | N27: =IF(SUMIFS('Industrial Summary'!$G:$G,'Industrial Summary'!$F:$F,N$17,'Industrial Summary'!$D:$D,$E27)>0,(-SUMIFS('Industrial Summary'!$G:$G,'Industrial Summary'!$F:$F,N$17,'Industrial Summary'!$D:$D,$E27,'Industrial Summary'!$A:$A,"RFL")/SUMIFS('Industrial Summary'!$G:$G,'Industrial Summary'!$F:$F,N$17,'Industrial Summary'!$D:$D,$E27)),0)*0.98 -> -0.0029377736 | O27: =IF(SUMIFS('Industrial Summary'!$G:$G,'Industrial Summary'!$F:$F,O$17,'Industrial Summary'!$D:$D,$E27)>0,(-SUMIFS('Industrial Summary'!$G:$G,'Industrial Summary'!$F:$F,O$17,'Industrial Summary'!$D:$D,$E27,'Industrial Summary'!$A:$A,"RFL")/SUMIFS('Industrial Summary'!$G:$G,'Industrial Summary'!$F:$F,O$17,'Industrial Summary'!$D:$D,$E27)),0)*0.98 -> 0 | P27: =IF(SUMIFS('Industrial Summary'!$G:$G,'Industrial Summary'!$F:$F,P$17,'Industrial Summary'!$D:$D,$E27)>0,(-SUMIFS('Industrial Summary'!$G:$G,'Industrial Summary'!$F:$F,P$17,'Industrial Summary'!$D:$D,$E27,'Industrial Summary'!$A:$A,"RFL")/SUMIFS('Industrial Summary'!$G:$G,'Industrial Summary'!$F:$F,P$17,'Industrial Summary'!$D:$D,$E27)),0)*0.98 -> 0 | Q27: 0 | R27: 15 | S27: =_xlfn.CONCAT("UC_",D27) -> UC_IFDPH_RFL | V27: =C27 -> S_IFDPHRFL | W27: =D27 -> IFDPH_RFL | X27: =E27 -> IFDPRH | Y27: =F27 -> LO | Z27: 1 | AA27: =H27*$AM27 -> -0.0040003546 | AB27: =I27*$AM27 -> -0.0040003546 | AC27: =J27*$AM27 -> 0 | AD27: =K27*$AM27 -> 0 | AE27: =L27*$AM27 -> 0 | AF27: =M27*$AM27 -> -0.0029377736 | AG27: =N27*$AM27 -> -0.0029377736 | AH27: =O27*$AM27 -> 0 | AI27: =P27*$AM27 -> 0 | AL27: =RIGHT(W27,3) -> RFL | AM27: =1 -> 1
C28: S_IFDPHDST | D28: IFDPH_DST | E28: IFDPRH | F28: LO | G28: 1 | H28: =IF(SUMIFS('Industrial Summary'!$G:$G,'Industrial Summary'!$F:$F,H$17,'Industrial Summary'!$D:$D,$E28)>0,(-SUMIFS('Industrial Summary'!$G:$G,'Industrial Summary'!$F:$F,H$17,'Industrial Summary'!$D:$D,$E28,'Industrial Summary'!$A:$A,"DST")/SUMIFS('Industrial Summary'!$G:$G,'Industrial Summary'!$F:$F,H$17,'Industrial Summary'!$D:$D,$E28)),0)*0.98 -> -0.011013887 | I28: =IF(SUMIFS('Industrial Summary'!$G:$G,'Industrial Summary'!$F:$F,I$17,'Industrial Summary'!$D:$D,$E28)>0,(-SUMIFS('Industrial Summary'!$G:$G,'Industrial Summary'!$F:$F,I$17,'Industrial Summary'!$D:$D,$E28,'Industrial Summary'!$A:$A,"DST")/SUMIFS('Industrial Summary'!$G:$G,'Industrial Summary'!$F:$F,I$17,'Industrial Summary'!$D:$D,$E28)),0)*0.98 -> -0.011013887 | J28: =IF(SUMIFS('Industrial Summary'!$G:$G,'Industrial Summary'!$F:$F,J$17,'Industrial Summary'!$D:$D,$E28)>0,(-SUMIFS('Industrial Summary'!$G:$G,'Industrial Summary'!$F:$F,J$17,'Industrial Summary'!$D:$D,$E28,'Industrial Summary'!$A:$A,"DST")/SUMIFS('Industrial Summary'!$G:$G,'Industrial Summary'!$F:$F,J$17,'Industrial Summary'!$D:$D,$E28)),0)*0.98 -> 0 | K28: =IF(SUMIFS('Industrial Summary'!$G:$G,'Industrial Summary'!$F:$F,K$17,'Industrial Summary'!$D:$D,$E28)>0,(-SUMIFS('Industrial Summary'!$G:$G,'Industrial Summary'!$F:$F,K$17,'Industrial Summary'!$D:$D,$E28,'Industrial Summary'!$A:$A,"DST")/SUMIFS('Industrial Summary'!$G:$G,'Industrial Summary'!$F:$F,K$17,'Industrial Summary'!$D:$D,$E28)),0)*0.98 -> 0 | L28: =IF(SUMIFS('Industrial Summary'!$G:$G,'Industrial Summary'!$F:$F,L$17,'Industrial Summary'!$D:$D,$E28)>0,(-SUMIFS('Industrial Summary'!$G:$G,'Industrial Summary'!$F:$F,L$17,'Industrial Summary'!$D:$D,$E28,'Industrial Summary'!$A:$A,"DST")/SUMIFS('Industrial Summary'!$G:$G,'Industrial Summary'!$F:$F,L$17,'Industrial Summary'!$D:$D,$E28)),0)*0.98 -> 0 | M28: =IF(SUMIFS('Industrial Summary'!$G:$G,'Industrial Summary'!$F:$F,M$17,'Industrial Summary'!$D:$D,$E28)>0,(-SUMIFS('Industrial Summary'!$G:$G,'Industrial Summary'!$F:$F,M$17,'Industrial Summary'!$D:$D,$E28,'Industrial Summary'!$A:$A,"DST")/SUMIFS('Industrial Summary'!$G:$G,'Industrial Summary'!$F:$F,M$17,'Industrial Summary'!$D:$D,$E28)),0)*0.98 -> -0.0080883598 | N28: =IF(SUMIFS('Industrial Summary'!$G:$G,'Industrial Summary'!$F:$F,N$17,'Industrial Summary'!$D:$D,$E28)>0,(-SUMIFS('Industrial Summary'!$G:$G,'Industrial Summary'!$F:$F,N$17,'Industrial Summary'!$D:$D,$E28,'Industrial Summary'!$A:$A,"DST")/SUMIFS('Industrial Summary'!$G:$G,'Industrial Summary'!$F:$F,N$17,'Industrial Summary'!$D:$D,$E28)),0)*0.98 -> -0.0080883598 | O28: =IF(SUMIFS('Industrial Summary'!$G:$G,'Industrial Summary'!$F:$F,O$17,'Industrial Summary'!$D:$D,$E28)>0,(-SUMIFS('Industrial Summary'!$G:$G,'Industrial Summary'!$F:$F,O$17,'Industrial Summary'!$D:$D,$E28,'Industrial Summary'!$A:$A,"DST")/SUMIFS('Industrial Summary'!$G:$G,'Industrial Summary'!$F:$F,O$17,'Industrial Summary'!$D:$D,$E28)),0)*0.98 -> -0.017819131 | P28: =IF(SUMIFS('Industrial Summary'!$G:$G,'Industrial Summary'!$F:$F,P$17,'Industrial Summary'!$D:$D,$E28)>0,(-SUMIFS('Industrial Summary'!$G:$G,'Industrial Summary'!$F:$F,P$17,'Industrial Summary'!$D:$D,$E28,'Industrial Summary'!$A:$A,"DST")/SUMIFS('Industrial Summary'!$G:$G,'Industrial Summary'!$F:$F,P$17,'Industrial Summary'!$D:$D,$E28)),0)*0.98 -> 0 | Q28: 0 | R28: 15 | S28: =_xlfn.CONCAT("UC_",D28) -> UC_IFDPH_DST | V28: =C28 -> S_IFDPHDST | W28: =D28 -> IFDPH_DST | X28: =E28 -> IFDPRH | Y28: =F28 -> LO | Z28: 1 | AA28: =H28*$AM28 -> -0.011013887 | AB28: =I28*$AM28 -> -0.011013887 | AC28: =J28*$AM28 -> 0 | AD28: =K28*$AM28 -> 0 | AE28: =L28*$AM28 -> 0 | AF28: =M28*$AM28 -> -0.0080883598 | AG28: =N28*$AM28 -> -0.0080883598 | AH28: =O28*$AM28 -> -0.017819131 | AI28: =P28*$AM28 -> 0 | AL28: =RIGHT(W28,3) -> DST | AM28: =1 -> 1
C29: S_IFDPHNGA | D29: IFDPH_NGA | E29: IFDPRH | F29: LO | G29: 1 | H29: =IF(SUMIFS('Industrial Summary'!$G:$G,'Industrial Summary'!$F:$F,H$17,'Industrial Summary'!$D:$D,$E29)>0,(-SUMIFS('Industrial Summary'!$G:$G,'Industrial Summary'!$F:$F,H$17,'Industrial Summary'!$D:$D,$E29,'Industrial Summary'!$A:$A,"NGA")/SUMIFS('Industrial Summary'!$G:$G,'Industrial Summary'!$F:$F,H$17,'Industrial Summary'!$D:$D,$E29)),0)*0.98 -> -0.86412736 | I29: =IF(SUMIFS('Industrial Summary'!$G:$G,'Industrial Summary'!$F:$F,I$17,'Industrial Summary'!$D:$D,$E29)>0,(-SUMIFS('Industrial Summary'!$G:$G,'Industrial Summary'!$F:$F,I$17,'Industrial Summary'!$D:$D,$E29,'Industrial Summary'!$A:$A,"NGA")/SUMIFS('Industrial Summary'!$G:$G,'Industrial Summary'!$F:$F,I$17,'Industrial Summary'!$D:$D,$E29)),0)*0.98 -> -0.86412736 | J29: =IF(SUMIFS('Industrial Summary'!$G:$G,'Industrial Summary'!$F:$F,J$17,'Industrial Summary'!$D:$D,$E29)>0,(-SUMIFS('Industrial Summary'!$G:$G,'Industrial Summary'!$F:$F,J$17,'Industrial Summary'!$D:$D,$E29,'Industrial Summary'!$A:$A,"NGA")/SUMIFS('Industrial Summary'!$G:$G,'Industrial Summary'!$F:$F,J$17,'Industrial Summary'!$D:$D,$E29)),0)*0.98 -> -0.74916612 | K29: =IF(SUMIFS('Industrial Summary'!$G:$G,'Industrial Summary'!$F:$F,K$17,'Industrial Summary'!$D:$D,$E29)>0,(-SUMIFS('Industrial Summary'!$G:$G,'Industrial Summary'!$F:$F,K$17,'Industrial Summary'!$D:$D,$E29,'Industrial Summary'!$A:$A,"NGA")/SUMIFS('Industrial Summary'!$G:$G,'Industrial Summary'!$F:$F,K$17,'Industrial Summary'!$D:$D,$E29)),0)*0.98 -> -0.73447698 | L29: =IF(SUMIFS('Industrial Summary'!$G:$G,'Industrial Summary'!$F:$F,L$17,'Industrial Summary'!$D:$D,$E29)>0,(-SUMIFS('Industrial Summary'!$G:$G,'Industrial Summary'!$F:$F,L$17,'Industrial Summary'!$D:$D,$E29,'Industrial Summary'!$A:$A,"NGA")/SUMIFS('Industrial Summary'!$G:$G,'Industrial Summary'!$F:$F,L$17,'Industrial Summary'!$D:$D,$E29)),0)*0.98 -> -0.81672206 | M29: =IF(SUMIFS('Industrial Summary'!$G:$G,'Industrial Summary'!$F:$F,M$17,'Industrial Summary'!$D:$D,$E29)>0,(-SUMIFS('Industrial Summary'!$G:$G,'Industrial Summary'!$F:$F,M$17,'Industrial Summary'!$D:$D,$E29,'Industrial Summary'!$A:$A,"NGA")/SUMIFS('Industrial Summary'!$G:$G,'Industrial Summary'!$F:$F,M$17,'Industrial Summary'!$D:$D,$E29)),0)*0.98 -> -0.83290774 | N29: =IF(SUMIFS('Industrial Summary'!$G:$G,'Industrial Summary'!$F:$F,N$17,'Industrial Summary'!$D:$D,$E29)>0,(-SUMIFS('Industrial Summary'!$G:$G,'Industrial Summary'!$F:$F,N$17,'Industrial Summary'!$D:$D,$E29,'Industrial Summary'!$A:$A,"NGA")/SUMIFS('Industrial Summary'!$G:$G,'Industrial Summary'!$F:$F,N$17,'Industrial Summary'!$D:$D,$E29)),0)*0.98 -> -0.83290774 | O29: =IF(SUMIFS('Industrial Summary'!$G:$G,'Industrial Summary'!$F:$F,O$17,'Industrial Summary'!$D:$D,$E29)>0,(-SUMIFS('Industrial Summary'!$G:$G,'Industrial Summary'!$F:$F,O$17,'Industrial Summary'!$D:$D,$E29,'Industrial Summary'!$A:$A,"NGA")/SUMIFS('Industrial Summary'!$G:$G,'Industrial Summary'!$F:$F,O$17,'Industrial Summary'!$D:$D,$E29)),0)*0.98 -> -0.85789617 | P29: =IF(SUMIFS('Industrial Summary'!$G:$G,'Industrial Summary'!$F:$F,P$17,'Industrial Summary'!$D:$D,$E29)>0,(-SUMIFS('Industrial Summary'!$G:$G,'Industrial Summary'!$F:$F,P$17,'Industrial Summary'!$D:$D,$E29,'Industrial Summary'!$A:$A,"NGA")/SUMIFS('Industrial Summary'!$G:$G,'Industrial Summary'!$F:$F,P$17,'Industrial Summary'!$D:$D,$E29)),0)*0.98 -> -0.86116013 | Q29: 0 | R29: 15 | S29: =_xlfn.CONCAT("UC_",D29) -> UC_IFDPH_NGA | V29: =C29 -> S_IFDPHNGA | W29: =D29 -> IFDPH_NGA | X29: =E29 -> IFDPRH | Y29: =F29 -> LO | Z29: 1 | AA29: =H29*$AM29 -> -0.6221717 | AB29: =I29*$AM29 -> -0.6221717 | AC29: =J29*$AM29 -> -0.53939961 | AD29: =K29*$AM29 -> -0.52882342 | AE29: =L29*$AM29 -> -0.58803988 | AF29: =M29*$AM29 -> -0.59969357 | AG29: =N29*$AM29 -> -0.59969357 | AH29: =O29*$AM29 -> -0.61768524 | AI29: =P29*$AM29 -> -0.62003529 | AL29: =RIGHT(W29,3) -> NGA | AM29: =Y5 -> 0.72
C30: S_IFDPHLPG | D30: IFDPH_LPG | E30: IFDPRH | F30: LO | G30: 1 | H30: =IF(SUMIFS('Industrial Summary'!$G:$G,'Industrial Summary'!$F:$F,H$17,'Industrial Summary'!$D:$D,$E30)>0,(-SUMIFS('Industrial Summary'!$G:$G,'Industrial Summary'!$F:$F,H$17,'Industrial Summary'!$D:$D,$E30,'Industrial Summary'!$A:$A,"LPG")/SUMIFS('Industrial Summary'!$G:$G,'Industrial Summary'!$F:$F,H$17,'Industrial Summary'!$D:$D,$E30)),0)*0.98 -> -0.0074127708 | I30: =IF(SUMIFS('Industrial Summary'!$G:$G,'Industrial Summary'!$F:$F,I$17,'Industrial Summary'!$D:$D,$E30)>0,(-SUMIFS('Industrial Summary'!$G:$G,'Industrial Summary'!$F:$F,I$17,'Industrial Summary'!$D:$D,$E30,'Industrial Summary'!$A:$A,"LPG")/SUMIFS('Industrial Summary'!$G:$G,'Industrial Summary'!$F:$F,I$17,'Industrial Summary'!$D:$D,$E30)),0)*0.98 -> -0.0074127708 | J30: =IF(SUMIFS('Industrial Summary'!$G:$G,'Industrial Summary'!$F:$F,J$17,'Industrial Summary'!$D:$D,$E30)>0,(-SUMIFS('Industrial Summary'!$G:$G,'Industrial Summary'!$F:$F,J$17,'Industrial Summary'!$D:$D,$E30,'Industrial Summary'!$A:$A,"LPG")/SUMIFS('Industrial Summary'!$G:$G,'Industrial Summary'!$F:$F,J$17,'Industrial Summary'!$D:$D,$E30)),0)*0.98 -> 0 | K30: =IF(SUMIFS('Industrial Summary'!$G:$G,'Industrial Summary'!$F:$F,K$17,'Industrial Summary'!$D:$D,$E30)>0,(-SUMIFS('Industrial Summary'!$G:$G,'Industrial Summary'!$F:$F,K$17,'Industrial Summary'!$D:$D,$E30,'Industrial Summary'!$A:$A,"LPG")/SUMIFS('Industrial Summary'!$G:$G,'Industrial Summary'!$F:$F,K$17,'Industrial Summary'!$D:$D,$E30)),0)*0.98 -> 0 | L30: =IF(SUMIFS('Industrial Summary'!$G:$G,'Industrial Summary'!$F:$F,L$17,'Industrial Summary'!$D:$D,$E30)>0,(-SUMIFS('Industrial Summary'!$G:$G,'Industrial Summary'!$F:$F,L$17,'Industrial Summary'!$D:$D,$E30,'Industrial Summary'!$A:$A,"LPG")/SUMIFS('Industrial Summary'!$G:$G,'Industrial Summary'!$F:$F,L$17,'Industrial Summary'!$D:$D,$E30)),0)*0.98 -> 0 | M30: =IF(SUMIFS('Industrial Summary'!$G:$G,'Industrial Summary'!$F:$F,M$17,'Industrial Summary'!$D:$D,$E30)>0,(-SUMIFS('Industrial Summary'!$G:$G,'Industrial Summary'!$F:$F,M$17,'Industrial Summary'!$D:$D,$E30,'Industrial Summary'!$A:$A,"LPG")/SUMIFS('Industrial Summary'!$G:$G,'Industrial Summary'!$F:$F,M$17,'Industrial Summary'!$D:$D,$E30)),0)*0.98 -> -0.0054437779 | N30: =IF(SUMIFS('Industrial Summary'!$G:$G,'Industrial Summary'!$F:$F,N$17,'Industrial Summary'!$D:$D,$E30)>0,(-SUMIFS('Industrial Summary'!$G:$G,'Industrial Summary'!$F:$F,N$17,'Industrial Summary'!$D:$D,$E30,'Industrial Summary'!$A:$A,"LPG")/SUMIFS('Industrial Summary'!$G:$G,'Industrial Summary'!$F:$F,N$17,'Industrial Summary'!$D:$D,$E30)),0)*0.98 -> -0.0054437779 | O30: =IF(SUMIFS('Industrial Summary'!$G:$G,'Industrial Summary'!$F:$F,O$17,'Industrial Summary'!$D:$D,$E30)>0,(-SUMIFS('Industrial Summary'!$G:$G,'Industrial Summary'!$F:$F,O$17,'Industrial Summary'!$D:$D,$E30,'Industrial Summary'!$A:$A,"LPG")/SUMIFS('Industrial Summary'!$G:$G,'Industrial Summary'!$F:$F,O$17,'Industrial Summary'!$D:$D,$E30)),0)*0.98 -> -0.0032708078 | P30: =IF(SUMIFS('Industrial Summary'!$G:$G,'Industrial Summary'!$F:$F,P$17,'Industrial Summary'!$D:$D,$E30)>0,(-SUMIFS('Industrial Summary'!$G:$G,'Industrial Summary'!$F:$F,P$17,'Industrial Summary'!$D:$D,$E30,'Industrial Summary'!$A:$A,"LPG")/SUMIFS('Industrial Summary'!$G:$G,'Industrial Summary'!$F:$F,P$17,'Industrial Summary'!$D:$D,$E30)),0)*0.98 -> 0 | Q30: 0 | R30: 15 | S30: =_xlfn.CONCAT("UC_",D30) -> UC_IFDPH_LPG | V30: =C30 -> S_IFDPHLPG | W30: =D30 -> IFDPH_LPG | X30: =E30 -> IFDPRH | Y30: =F30 -> LO | Z30: 1 | AA30: =H30*$AM30 -> -0.005337195 | AB30: =I30*$AM30 -> -0.005337195 | AC30: =J30*$AM30 -> 0 | AD30: =K30*$AM30 -> 0 | AE30: =L30*$AM30 -> 0 | AF30: =M30*$AM30 -> -0.0039195201 | AG30: =N30*$AM30 -> -0.0039195201 | AH30: =O30*$AM30 -> -0.0023549816 | AI30: =P30*$AM30 -> 0 | AL30: =RIGHT(W30,3) -> LPG | AM30: =Y5 -> 0.72
