Workbook
Name _1_2007_InternetDataFile_ExistGenUnits: #REF!
Name AnswerData: #REF!
Name bprint: #REF!
Name cprint: #REF!
Name exch_rate: #REF!
Name fitfile: [1]MODEL!$D$38
Name INF: [1]MODEL!$H$14
Name PPP: [1]MODEL!$D$12
Name PPPEX: [1]MODEL!$D$13
Name rail_coal: #REF!

Sheet ANSv6.0-Technologies
A1: ANSWER-Technologies
B7: TechName | C7: TechDesc | D7: TACTUnit | E7: TCAPUnit | F7: Set Memberships | G7: Comment

Sheet ANSv6.0-Commodities
A1: ANSWER-Commodities
B7: CommName | C7: CommDesc | D7: CommUnit | E7: Set Memberships | F7: Comment

Sheet ANSv6.1-Commodities
A1: ANSWER-Commodities
B7: CommName | C7: CommDesc | D7: CommUnit | E7: Set Memberships | F7: Comment

Sheet ANSv6.1-Technologies
A1: ANSWER-Technologies
B7: TechName | C7: TechDesc | D7: TACTUnit | E7: TCAPUnit | F7: Set Memberships | G7: Comment

Sheet ANSv6.1-Constraints
A1: ANSWER-Constraints
B7: ConstrName | C7: ConstrDesc | D7: Units | E7: Set Memberships | F7: Comment

Sheet ANSv6.1-CommData
A1: ANSWER-CommData
B7: CommName | C7: CommDesc | D7: Units

Sheet ANSv6.1-TechData
A1: ANSWER-TechData
B7: TechName | C7: TechDesc | D7: Units | E7: CommIN | F7: CommOUT

Sheet ANSv6.1-ConstrData
A1: ANSWER-ConstrData
B7: ConstrName | C7: ConstrDesc | D7: Units | E7: TechName

Sheet CSAPR_TOT
A1: UC - All Regions/Each Period
B2: ~UC_Sets: R_S: AllRegions
B5: UC_N | C5: Pset_Set | D5: Cset_CN | E5: Year | F5: LimType | G5: UC_COMNET | H5: UC_RHSTS | I5: UC_RHSTS~0 | J5: UC_Desc
B6: CSAPR_NOX_AllRegions | D6: ELCNOX | E6: 2025 | F6: UP | G6: 1 | H6: =IPMSummary!D28*0.907185+(AKandHI!$L$21+AKandHI!$L$10)/1000 -> 1390.2968 | I6: 5 | J6: CSAPR_NOX upper bound on the total emissions of All Regions
B7: CSAPR_NOX_AllRegions | D7: ELCNOX | E7: 2030 | F7: UP | G7: 1 | H7: =IPMSummary!E28*0.907185+(AKandHI!$L$21+AKandHI!$L$10)/1000 -> 1341.3669 | I7: 5 | J7: CSAPR_NOX upper bound on the total emissions of All Regions
B8: CSAPR_NOX_AllRegions | D8: ELCNOX | E8: 2035 | F8: UP | G8: 1 | H8: =(CSAPR_TOT!H7+CSAPR_TOT!H9)/2 -> 1331.6144 | I8: 5 | J8: CSAPR_NOX upper bound on the total emissions of All Regions
B9: CSAPR_NOX_AllRegions | D9: ELCNOX | E9: 2040 | F9: UP | G9: 1 | H9: =IPMSummary!F28*0.907185+(AKandHI!$L$21+AKandHI!$L$10)/1000 -> 1321.8618 | I9: 5 | J9: CSAPR_NOX upper bound on the total emissions of All Regions
B10: CSAPR_NOX_AllRegions | D10: ELCNOX | E10: 2045 | F10: UP | G10: 1 | H10: =(CSAPR_TOT!H9+CSAPR_TOT!H11)/2 -> 1344.3992 | I10: 5 | J10: CSAPR_NOX upper bound on the total emissions of All Regions
B11: CSAPR_NOX_AllRegions | D11: ELCNOX | E11: 2050 | F11: UP | G11: 1 | H11: =IPMSummary!G28*0.907185+(AKandHI!$L$21+AKandHI!$L$10)/1000 -> 1366.9365 | I11: 5 | J11: CSAPR_NOX upper bound on the total emissions of All Regions
B12: CSAPR_NOX_AllRegions | D12: ELCNOX | E12: 2055 | F12: UP | G12: 1 | H12: =H11 -> 1366.9365 | I12: 5 | J12: CSAPR_NOX upper bound on the total emissions of All Regions
B13: CSAPR_SO2_AllRegions | D13: ELCSO2 | E13: 2025 | F13: UP | G13: 1 | H13: =IPMSummary!D14*0.907185+(AKandHI!$L$15+AKandHI!$L$26)/1000 -> 1363.502 | I13: 5 | J13: CSAPR_SO2 upper bound on the total emissions of All Regions
B14: CSAPR_SO2_AllRegions | D14: ELCSO2 | E14: 2030 | F14: UP | G14: 1 | H14: =IPMSummary!E14*0.907185+(AKandHI!$L$15+AKandHI!$L$26)/1000 -> 1342.2587 | I14: 5 | J14: CSAPR_SO2 upper bound on the total emissions of All Regions
B15: CSAPR_SO2_AllRegions | D15: ELCSO2 | E15: 2035 | F15: UP | G15: 1 | H15: =(CSAPR_TOT!H14+CSAPR_TOT!H16)/2 -> 1320.7728 | I15: 5 | J15: CSAPR_SO2 upper bound on the total emissions of All Regions
B16: CSAPR_SO2_AllRegions | D16: ELCSO2 | E16: 2040 | F16: UP | G16: 1 | H16: =IPMSummary!F14*0.907185+(AKandHI!$L$15+AKandHI!$L$26)/1000 -> 1299.2869 | I16: 5 | J16: CSAPR_SO2 upper bound on the total emissions of All Regions
B17: CSAPR_SO2_AllRegions | D17: ELCSO2 | E17: 2045 | F17: UP | G17: 1 | H17: =(CSAPR_TOT!H16+CSAPR_TOT!H18)/2 -> 1308.9874 | I17: 5 | J17: CSAPR_SO2 upper bound on the total emissions of All Regions
B18: CSAPR_SO2_AllRegions | D18: ELCSO2 | E18: 2050 | F18: UP | G18: 1 | H18: =IPMSummary!G14*0.907185+(AKandHI!$L$15+AKandHI!$L$26)/1000 -> 1318.688 | I18: 5 | J18: CSAPR_SO2 upper bound on the total emissions of All Regions
B19: CSAPR_SO2_AllRegions | D19: ELCSO2 | E19: 2055 | F19: UP | G19: 1 | H19: =H18 -> 1318.688 | I19: 5 | J19: CSAPR_SO2 upper bound on the total emissions of All Regions

Sheet CSAPR_REG
A1: Trans - Insert
B2: ~TFM_INS
B3: TimeSlice | C3: LimType | D3: Attribute | E3: Year | F3: AllRegions | G3: R1 | H3: R2 | I3: R3 | J3: R4 | K3: R5 | L3: R6 | M3: R7 | N3: R8 | O3: R9 | P3: Pset_Set | Q3: Pset_PN | R3: Pset_PD | S3: Pset_CI | T3: Pset_CO | U3: Cset_Set | V3: Cset_CN | W3: Cset_CD
C4: UP | D4: COM_BNDNET | E4: 2010 | G4: =HistoricData!P8-5/6*(HistoricData!P8-'NEI11v1 Summary'!C8) -> 16.138806 | H4: =HistoricData!P9-5/6*(HistoricData!P9-'NEI11v1 Summary'!D8) -> 171.07596 | I4: =HistoricData!P10-5/6*(HistoricData!P10-'NEI11v1 Summary'!E8) -> 424.75509 | J4: =HistoricData!P11-5/6*(HistoricData!P11-'NEI11v1 Summary'!F8) -> 291.20197 | K4: =HistoricData!P12-5/6*(HistoricData!P12-'NEI11v1 Summary'!G8) -> 348.39327 | L4: =HistoricData!P13-5/6*(HistoricData!P13-'NEI11v1 Summary'!H8) -> 224.59036 | M4: =HistoricData!P14-5/6*(HistoricData!P14-'NEI11v1 Summary'!I8) -> 285.31053 | N4: =HistoricData!P15-5/6*(HistoricData!P15-'NEI11v1 Summary'!J8) -> 235.37513 | O4: =HistoricData!P16-5/6*(HistoricData!P16-'NEI11v1 Summary'!K8) -> 61.829637 | V4: ELCNOX
C5: UP | D5: COM_BNDNET | E5: 2012 | G5: =AVERAGE(G6,G4) -> 14.317966 | H5: =AVERAGE(H6,H4) -> 151.64519 | I5: =AVERAGE(I6,I4) -> 345.42628 | J5: =AVERAGE(J6,J4) -> 230.01298 | K5: =AVERAGE(K6,K4) -> 285.19535 | L5: =AVERAGE(L6,L4) -> 171.68908 | M5: =AVERAGE(M6,M4) -> 252.76631 | N5: =AVERAGE(N6,N4) -> 243.81432 | O5: =AVERAGE(O6,O4) -> 54.916879 | V5: ELCNOX
C6: UP | D6: COM_BNDNET | E6: 2015 | G6: =IPMSummary!B19*0.907185 -> 12.497126 | H6: =IPMSummary!B20*0.907185 -> 132.21441 | I6: =IPMSummary!B21*0.907185 -> 266.09748 | J6: =IPMSummary!B22*0.907185 -> 168.82399 | K6: =IPMSummary!B23*0.907185 -> 221.99743 | L6: =IPMSummary!B24*0.907185 -> 118.78781 | M6: =IPMSummary!B25*0.907185 -> 220.22208 | N6: =IPMSummary!B26*0.907185 -> 252.2535 | O6: =IPMSummary!B27*0.907185+(AKandHI!L21+AKandHI!L10)/1000 -> 48.004121 | V6: ELCNOX
C7: UP | D7: COM_BNDNET | E7: 2020 | G7: =IPMSummary!C19*0.907185 -> 12.123572 | H7: =IPMSummary!C20*0.907185 -> 133.38528 | I7: =IPMSummary!C21*0.907185 -> 266.55031 | J7: =IPMSummary!C22*0.907185 -> 151.99132 | K7: =IPMSummary!C23*0.907185 -> 223.98673 | L7: =IPMSummary!C24*0.907185 -> 116.42259 | M7: =IPMSummary!C25*0.907185 -> 203.88706 | N7: =IPMSummary!C26*0.907185 -> 198.54908 | O7: =IPMSummary!C27*0.907185+(AKandHI!L21+AKandHI!L10)/1000 -> 48.554838 | V7: ELCNOX
C8: UP | D8: COM_BNDNET | E8: 2025 | H8: =IPMSummary!D20*0.907185 -> 135.89506 | I8: =IPMSummary!D21*0.907185 -> 268.7271 | J8: =IPMSummary!D22*0.907185 -> 156.81486 | K8: =IPMSummary!D23*0.907185 -> 240.36531 | V8: ELCNOX
C9: UP | D9: COM_BNDNET | E9: 0 | H9: 5 | I9: 5 | J9: 5 | K9: 5 | V9: ELCNOX
C10: UP | D10: COM_BNDNET | E10: 2010 | G10: =HistoricData!N8-5/6*(HistoricData!N8-'NEI11v1 Summary'!C29) -> 58.952352 | H10: =HistoricData!N9-5/6*(HistoricData!N9-'NEI11v1 Summary'!D29) -> 468.25199 | I10: =HistoricData!N10-5/6*(HistoricData!N10-'NEI11v1 Summary'!E29) -> 1549.5512 | J10: =HistoricData!N11-5/6*(HistoricData!N11-'NEI11v1 Summary'!F29) -> 554.13493 | K10: =HistoricData!N12-5/6*(HistoricData!N12-'NEI11v1 Summary'!G29) -> 901.19478 | L10: =HistoricData!N13-5/6*(HistoricData!N13-'NEI11v1 Summary'!H29) -> 643.2241 | M10: =HistoricData!N14-5/6*(HistoricData!N14-'NEI11v1 Summary'!I29) -> 632.92334 | N10: =HistoricData!N15-5/6*(HistoricData!N15-'NEI11v1 Summary'!J29) -> 164.97932 | O10: =HistoricData!N16-5/6*(HistoricData!N16-'NEI11v1 Summary'!K29) -> 33.312086 | V10: ELCSO2
C11: UP | D11: COM_BNDNET | E11: 2012 | G11: =AVERAGE(G12,G10) -> 31.172288 | H11: =AVERAGE(H12,H10) -> 266.88874 | I11: =AVERAGE(I12,I10) -> 944.70817 | J11: =AVERAGE(J12,J10) -> 339.44605 | K11: =AVERAGE(K12,K10) -> 560.89709 | L11: =AVERAGE(L12,L10) -> 403.3084 | M11: =AVERAGE(M12,M10) -> 410.05762 | N11: =AVERAGE(N12,N10) -> 145.33533 | O11: =AVERAGE(O12,O10) -> 22.58407 | V11: ELCSO2
C12: UP | D12: COM_BNDNET | E12: 2015 | G12: =IPMSummary!B5*0.907185 -> 3.3922245 | H12: =IPMSummary!B6*0.907185 -> 65.5255 | I12: =IPMSummary!B7*0.907185 -> 339.86512 | J12: =IPMSummary!B8*0.907185 -> 124.75716 | K12: =IPMSummary!B9*0.907185 -> 220.59941 | L12: =IPMSummary!B10*0.907185 -> 163.39271 | M12: =IPMSummary!B11*0.907185 -> 187.1919 | N12: =IPMSummary!B12*0.907185 -> 125.69134 | O12: =IPMSummary!B13*0.907185+(AKandHI!L15+AKandHI!L26)/1000 -> 11.856054 | V12: ELCSO2
C13: UP | D13: COM_BNDNET | E13: 2020 | G13: =IPMSummary!C5*0.907185 -> 2.7983306 | H13: =IPMSummary!C6*0.907185 -> 66.453016 | I13: =IPMSummary!C7*0.907185 -> 359.19685 | J13: =IPMSummary!C8*0.907185 -> 132.99866 | K13: =IPMSummary!C9*0.907185 -> 229.15477 | L13: =IPMSummary!C10*0.907185 -> 161.46819 | M13: =IPMSummary!C11*0.907185 -> 186.50266 | N13: =IPMSummary!C12*0.907185 -> 128.60282 | O13: =IPMSummary!C13*0.907185+(AKandHI!L15+AKandHI!L26)/1000 -> 12.019539 | V13: ELCSO2
C14: UP | D14: COM_BNDNET | E14: 2025 | H14: =IPMSummary!D6*0.907185 -> 72.40337 | I14: =IPMSummary!D7*0.907185 -> 376.92814 | J14: =IPMSummary!D8*0.907185 -> 138.72896 | K14: =IPMSummary!D9*0.907185 -> 247.18359 | V14: ELCSO2
C15: UP | D15: COM_BNDNET | E15: 0 | H15: 5 | I15: 5 | J15: 5 | K15: 5 | V15: ELCSO2
C16: UP | D16: COM_BNDNET | E16: 2010 | G16: =8.77-5/6*(8.77-'NEI11v1 Summary'!C15) -> 2.8428718 | H16: =88.79-5/6*(88.79-'NEI11v1 Summary'!D15) -> 26.937088 | I16: =144.69-5/6*(144.69-'NEI11v1 Summary'!E15) -> 77.516688 | J16: =43.85-5/6*(43.85-'NEI11v1 Summary'!F15) -> 29.640487 | K16: =168.81-5/6*(168.81-'NEI11v1 Summary'!G15) -> 74.177872 | L16: =67.96-5/6*(67.96-'NEI11v1 Summary'!H15) -> 32.89163 | M16: =48.23-5/6*(48.23-'NEI11v1 Summary'!I15) -> 34.307348 | N16: =46.04-5/6*(46.04-'NEI11v1 Summary'!J15) -> 19.092652 | O16: =9.87-5/6*(9.87-'NEI11v1 Summary'!K15) -> 6.5515939 | V16: ELCPM10
C17: UP | D17: COM_BNDNET | E17: 0 | G17: 1 | H17: 1 | I17: 1 | J17: 1 | K17: 1 | L17: 1 | M17: 1 | N17: 1 | O17: 1 | V17: ELCPM10
B21: * R9 values from DataSummaryCAIR sheet.
B22: *National PM10 totals determined from EPA's Emission Trends reporting. Allocation to regions was done via state-level PM2.5 estimates in the National Emission Inventory.

Sheet ANSv6.0-ConstrData
A1: ANSWER-ConstrData
B7: ConstrName | C7: ConstrDesc | D7: Units | E7: TechName

Sheet ANSv6.0-TechData
A1: ANSWER-TechData
B7: TechName | C7: TechDesc | D7: Units | E7: CommIN | F7: CommOUT

Sheet ANSv6.0-CommData
A1: ANSWER-CommData
B7: CommName | C7: CommDesc | D7: Units

Sheet ANSv6.0-Constraints
A1: ANSWER-Constraints
B7: ConstrName | C7: ConstrDesc | D7: Units | E7: Set Memberships | F7: Comment

Sheet NEI11v1 Summary
B1: Summary from the EPA's NEI 2011v1, converted to kTonnes
B3: Sum of EMISSIONS_TON | C3: Column Labels
B4: Row Labels | C4: 1 | D4: 2 | E4: 3 | F4: 4 | G4: 5 | H4: 6 | I4: 7 | J4: 8 | K4: 9
B5: Ammonia | C5: 10.028138 | D5: 19.339892 | E5: 37.613579 | F5: 18.409868 | G5: 34.825881 | H5: 12.474636 | I5: 25.632468 | J5: 13.054067 | K5: 34.489351
B6: Carbon Monoxide | C6: 1864.747 | D6: 4387.2527 | E6: 7711.2298 | F6: 3931.9587 | G6: 8596.244 | H6: 2799.5862 | I6: 4869.2729 | J6: 3175.8732 | K6: 4687.9416
B7: Nitrogen Oxides | C7: 314.14618 | D7: 1004.8314 | E7: 2013.8349 | F7: 1440.4476 | G7: 2007.6621 | H7: 960.76723 | I7: 2084.7107 | J7: 1097.4751 | K7: 1166.2924
B8: FUEL COMB. ELEC. UTIL. | C8: 12.519603 | D8: 159.63851 | E8: 370.03077 | F8: 257.13934 | G8: 278.08343 | H8: 189.07867 | I8: 276.86048 | J8: 199.21576 | K8: 62.138128
B9: FUEL COMB. INDUSTRIAL | C9: 25.821599 | D9: 59.979075 | E9: 176.67891 | F9: 106.97555 | G9: 143.23124 | H9: 115.26306 | I9: 333.60444 | J9: 113.15105 | K9: 98.703195
B10: FUEL COMB. OTHER | C10: 40.63704 | D10: 100.73329 | E10: 118.76509 | F10: 46.655304 | G10: 59.48034 | H10: 20.134605 | I10: 33.156481 | J10: 35.178864 | K10: 50.813137
B11: HIGHWAY VEHICLES | C11: 154.17139 | D11: 439.64084 | E11: 839.78465 | F11: 525.70897 | G11: 1065.9696 | H11: 430.59746 | I11: 689.22573 | J11: 412.79634 | K11: 614.02708
B12: OFF-HIGHWAY | C12: 80.872051 | D12: 204.84595 | E12: 476.22668 | F12: 445.00739 | G12: 423.61238 | H12: 168.08743 | I12: 440.89776 | J12: 238.3066 | K12: 335.15825
B13: PETROLEUM & RELATED INDUSTRIES | C13: 0.12449214 | D13: 39.993777 | E13: 32.348834 | F13: 58.961055 | G13: 37.285051 | H13: 37.606007 | I13: 310.96582 | J13: 98.826471 | K13: 5.4526349
B14: PM10 Primary (Filt + Cond) | C14: 61.634132 | D14: 139.83595 | E14: 274.47963 | F14: 155.52416 | G14: 243.27413 | H14: 102.40978 | I14: 165.68981 | J14: 89.025089 | K14: 132.68371
B15: FUEL COMB. ELEC. UTIL. | C15: 1.6574462 | D15: 14.566506 | E15: 64.082025 | F15: 26.798584 | G15: 55.251447 | H15: 25.877956 | I15: 31.522817 | J15: 13.703183 | K15: 5.8879127
... B42: Grand Total | C42: 2638.0115 | D42: 6665.8718 | E42: 12793.968 | F42: 6911.1712 | G42: 12818.74 | H42: 5010.3834 | I42: 9747.2038 | J42: 5513.4082 | K42: 6898.6561

Sheet HistoricData
A1: Data source: U.S. EPA Clean Air Markets Division’s “Data and Maps” web page (http://camddataandmaps.epa.gov/gdm/index.cfm)
A2: Units: thousand short tons
A4: State | B4: Year | C4: SO2 (tons) | D4: NOx (tons) | E4: CO2 (tons) | F4: Heat Input (MMBtu) | G4: Gross Load (MW-h) | H4: Region | I4: SO2(kt) | J4: NOx(kt) | K4: CO2(Mt) | M4: Summary
A5: AL | B5: 2005 | C5: 460071.65 | D5: 133474.62 | E5: 91471965 | F5: 9.3689031e+08 | G5: 96216414 | H5: 6 | I5: 417.3701 | J5: 121.08617 | K5: 82.981994 | N5: Column Labels
A6: AL | B6: 2010 | C6: 204189.47 | D6: 63289.848 | E6: 85171207 | F6: 9.4634166e+08 | G6: 1.0571874e+08 | H6: 6 | I6: 185.23763 | J6: 57.415601 | K6: 77.266041 | N6: Sum of SO2(kt) | P6: Sum of NOx(kt)
A7: AR | B7: 2005 | C7: 66189.718 | D7: 35332.801 | E7: 29180670 | F7: 3.0590969e+08 | G7: 29957254 | H7: 7 | I7: 60.046319 | J7: 32.053387 | K7: 26.472267 | M7: Row Labels | N7: 2005 | O7: 2010 | P7: 2005 | Q7: 2010
A8: AR | B8: 2010 | C8: 67083.708 | D8: 37784.683 | E8: 36254482 | F8: 3.8911395e+08 | G8: 42106075 | H8: 7 | I8: 60.857334 | J8: 34.277698 | K8: 32.889522 | M8: 1 | N8: 131.26698 | O8: 69.41843 | P8: 34.234823 | Q8: 14.624808
A9: AZ | B9: 2005 | C9: 52761.521 | D9: 80790.027 | E9: 58265191 | F9: 6.5718374e+08 | G9: 69203662 | H9: 8 | I9: 47.86446 | J9: 73.291501 | K9: 52.857307 | M9: 2 | N9: 1103.9633 | O9: 410.95822 | P9: 228.26325 | Q9: 141.18809
A10: AZ | B10: 2010 | C10: 36445.121 | D10: 60523.702 | E10: 60713242 | F10: 6.8133097e+08 | G10: 77832826 | H10: 8 | I10: 33.062467 | J10: 54.906195 | K10: 55.078143 | M10: 3 | N10: 2544.3111 | O10: 1413.9785 | P10: 698.37672 | Q10: 373.29058
A11: CA | B11: 2005 | C11: 172.398 | D11: 4356.617 | E11: 31660158 | F11: 5.3058019e+08 | G11: 62785114 | H11: 9 | I11: 0.15639688 | J11: 3.9522576 | K11: 28.721621 | M11: 4 | N11: 778.32564 | O11: 570.2205 | P11: 461.51517 | Q11: 260.83452
A12: CA | B12: 2010 | C12: 227.268 | D12: 4501.843 | E12: 37086792 | F12: 6.22375e+08 | G12: 80496693 | H12: 9 | I12: 0.20617412 | J12: 4.0840044 | K12: 33.644582 | M12: 5 | N12: 2483.7764 | O12: 735.10964 | P12: 699.94249 | Q12: 288.14835
A13: CO | B13: 2005 | C13: 59337.064 | D13: 67635.398 | E13: 46127713 | F13: 4.8487559e+08 | G13: 48498319 | H13: 8 | I13: 53.829694 | J13: 61.357819 | K13: 41.846369 | M13: 6 | N13: 1179.7666 | O13: 589.14244 | P13: 402.14877 | Q13: 195.91637
A14: CO | B14: 2010 | C14: 45861.528 | D14: 54876.308 | E14: 45099380 | F14: 4.7272089e+08 | G14: 48765504 | H14: 8 | I14: 41.60489 | J14: 49.782963 | K14: 40.913481 | M14: 7 | N14: 733.83793 | O14: 646.1154 | P14: 327.5608 | Q14: 272.53636
A15: CT | B15: 2005 | C15: 7522.651 | D15: 5859.34 | E15: 9645877.4 | F15: 1.2762656e+08 | G15: 12557834 | H15: 1 | I15: 6.8244361 | J15: 5.3155054 | K15: 8.7505953 | M15: 8 | N15: 304.42649 | O15: 193.33164 | P15: 416.17199 | Q15: 299.94048
A16: CT | B16: 2010 | C16: 1954.963 | D16: 2052.707 | E16: 6645391.5 | F16: 99888242 | G16: 10536197 | H16: 1 | I16: 1.7735131 | J16: 1.862185 | K16: 6.0285995 | M16: 9 | N16: =14.150248950375+(AKandHI!L15+AKandHI!L26)/1000 -> 21.472291 | O16: =16.859442647565+(AKandHI!L15+AKandHI!L26)/1000 -> 24.181485 | P16: =27.909810515835+(AKandHI!L10+AKandHI!L21)/1000 -> 60.287184 | Q16: =23.778582558705+(AKandHI!L10+AKandHI!L21)/1000 -> 56.155956
A17: DC | B17: 2005 | C17: 834.254 | D17: 275.916 | E17: 187206.13 | F17: 2312926.3 | G17: 182829.68 | H17: 5 | I17: 0.75682271 | J17: 0.25030686 | K17: 0.1698306 | M17: Grand Total | N17: 9273.8248 | O17: 4645.1342 | P17: 3296.1238 | Q17: 1870.2581
A18: DC | B18: 2010 | C18: 873.751 | D18: 373.155 | E18: 220765.06 | F18: 2720688.3 | G18: 218078.09 | H18: 5 | I18: 0.7926538 | J18: 0.33852062 | K18: 0.20027475
A19: DE | B19: 2005 | C19: 30580.158 | D19: 11345.497 | E19: 6688310.3 | F19: 71722558 | G19: 6864585.6 | H19: 5 | I19: 27.741861 | J19: 10.292465 | K19: 6.0675347
A20: DE | B20: 2010 | C20: 14491.681 | D20: 4131.278 | E20: 3939746.8 | F20: 47168305 | G20: 4538807.9 | H20: 5 | I20: 13.146636 | J20: 3.7478334 | K20: 3.5740792
A21: FL | B21: 2005 | C21: 415405.8 | D21: 212004.54 | E21: 1.3649713e+08 | F21: 1.637437e+09 | G21: 1.5885861e+08 | H21: 5 | I21: 376.84991 | J21: 192.32734 | K21: 123.82815
A22: FL | B22: 2010 | C22: 138345.33 | D22: 73147.901 | E22: 1.3113698e+08 | F22: 1.692645e+09 | G22: 1.7328583e+08 | H22: 5 | I22: 125.50481 | J22: 66.358679 | K22: 118.9655
A23: GA | B23: 2005 | C23: 616169.37 | D23: 111365.1 | E23: 94101017 | F23: 9.4944021e+08 | G23: 98804932 | H23: 5 | I23: 558.97961 | J23: 101.02875 | K23: 85.367031
A24: GA | B24: 2010 | C24: 218836.11 | D24: 60521.903 | E24: 87577540 | F24: 9.2802048e+08 | G24: 1.0019643e+08 | H24: 5 | I24: 198.52484 | J24: 54.904563 | K24: 79.44903
A25: IA | B25: 2005 | C25: 126778.98 | D25: 71502.102 | E25: 40411329 | F25: 4.0134318e+08 | G25: 35416052 | H25: 4 | I25: 115.01199 | J25: 64.865634 | K25: 36.660552
A26: IA | B26: 2010 | C26: 104649.8 | D26: 44442.842 | E26: 45401248 | F26: 4.3651366e+08 | G26: 42162208 | H26: 4 | I26: 94.936729 | J26: 40.31788 | K26: 41.187331
A27: ID | B27: 2005 | C27: 2.898 | D27: 88.696 | E27: 574923.68 | F27: 9661652.4 | G27: 1403939 | H27: 8 | I27: 0.0026290221 | J27: 0.080463681 | K27: 0.52156213
A28: ID | B28: 2010 | C28: 3.498 | D28: 112.566 | E28: 693068.54 | F28: 11662220 | G28: 1611779.6 | H28: 8 | I28: 0.0031733331 | J28: 0.10211819 | K28: 0.62874138
A29: IL | B29: 2005 | C29: 326632.04 | D29: 126047.71 | E29: 1.0610452e+08 | F29: 1.055344e+09 | G29: 1.0289217e+08 | H29: 3 | I29: 296.31568 | J29: 114.34859 | K29: 96.256425
... A102: WY | B102: 2010 | C102: 64848.778 | D102: 60902.066 | E102: 49382465 | F102: 4.7101406e+08 | G102: 45813963 | H102: 8 | I102: 58.829839 | J102: 55.249441 | K102: 44.799031

Sheet AKandHI
E1: 2005 NOx and SO2 emissions for Hawaii and Alaska were extracted from EPA's Tier-2, state-level summaries:
E2: These are added into the CSAPR2005 and CSAPR2014 R9 totals
E3: http://www.epa.gov/ttn/chief/net/2005inventory.html#inventorydata
L4: Metric units
B5: State FIPS | C5: State Abbreviation | D5: Tier1 Code | E5: Tier1 Description | F5: Tier2 Code | G5: Tier2 Description | H5: Tier12 | I5: Pollutant_Code | J5: Pollutant Code Description | K5: Annual Emissions
B6: 15 | C6: HI | D6: 01 | E6: FUEL COMB. ELEC. UTIL. | F6: 05 | G6: Internal Combustion | H6: 0105 | I6: NOX | J6: Nitrogen Oxides | K6: 6217.2621
B7: 15 | C7: HI | D7: 01 | E7: FUEL COMB. ELEC. UTIL. | F7: 04 | G7: Other | H7: 0104 | I7: NOX | J7: Nitrogen Oxides | K7: 0.382404
B8: 15 | C8: HI | D8: 01 | E8: FUEL COMB. ELEC. UTIL. | F8: 02 | G8: Oil | H8: 0102 | I8: NOX | J8: Nitrogen Oxides | K8: 15.30692
B9: 15 | C9: HI | D9: 01 | E9: FUEL COMB. ELEC. UTIL. | F9: 01 | G9: Coal | H9: 0101 | I9: NOX | J9: Nitrogen Oxides | K9: 422.7231
K10: =SUM(K6:K9) -> 6655.6746 | L10: =1/1.10231131*K10 -> 6037.9264
B11: 15 | C11: HI | D11: 01 | E11: FUEL COMB. ELEC. UTIL. | F11: 05 | G11: Internal Combustion | H11: 0105 | I11: SO2 | J11: Sulfur Dioxide | K11: 1427.8198
B12: 15 | C12: HI | D12: 01 | E12: FUEL COMB. ELEC. UTIL. | F12: 04 | G12: Other | H12: 0104 | I12: SO2 | J12: Sulfur Dioxide | K12: 1.5592838
B13: 15 | C13: HI | D13: 01 | E13: FUEL COMB. ELEC. UTIL. | F13: 02 | G13: Oil | H13: 0102 | I13: SO2 | J13: Sulfur Dioxide | K13: 7.2595991
B14: 15 | C14: HI | D14: 01 | E14: FUEL COMB. ELEC. UTIL. | F14: 01 | G14: Coal | H14: 0101 | I14: SO2 | J14: Sulfur Dioxide | K14: 639.76102
K15: =SUM(K11:K14) -> 2076.3997 | L15: =1/1.10231131*K15 -> 1883.6782
B16: State FIPS | C16: State Abbreviation | D16: Tier1 Code | E16: Tier1 Description | F16: Tier2 Code | G16: Tier2 Description | H16: Tier12 | I16: Pollutant_Code | J16: Pollutant Code Description | K16: Annual Emissions
B17: 02 | C17: AK | D17: 01 | E17: FUEL COMB. ELEC. UTIL. | F17: 05 | G17: Internal Combustion | H17: 0105 | I17: NOX | J17: Nitrogen Oxides | K17: 25646.5
B18: 02 | C18: AK | D18: 01 | E18: FUEL COMB. ELEC. UTIL. | F18: 03 | G18: Gas | H18: 0103 | I18: NOX | J18: Nitrogen Oxides | K18: 135.13
B19: 02 | C19: AK | D19: 01 | E19: FUEL COMB. ELEC. UTIL. | F19: 02 | G19: Oil | H19: 0102 | I19: NOX | J19: Nitrogen Oxides | K19: 815.03
B20: 02 | C20: AK | D20: 01 | E20: FUEL COMB. ELEC. UTIL. | F20: 01 | G20: Coal | H20: 0101 | I20: NOX | J20: Nitrogen Oxides | K20: 2437.61
K21: =SUM(K17:K20) -> 29034.27 | L21: =1/1.10231131*K21 -> 26339.447
B22: 02 | C22: AK | D22: 01 | E22: FUEL COMB. ELEC. UTIL. | F22: 05 | G22: Internal Combustion | H22: 0105 | I22: SO2 | J22: Sulfur Dioxide | K22: 3957.21
B23: 02 | C23: AK | D23: 01 | E23: FUEL COMB. ELEC. UTIL. | F23: 03 | G23: Gas | H23: 0103 | I23: SO2 | J23: Sulfur Dioxide | K23: 0.38
B24: 02 | C24: AK | D24: 01 | E24: FUEL COMB. ELEC. UTIL. | F24: 02 | G24: Oil | H24: 0102 | I24: SO2 | J24: Sulfur Dioxide | K24: 139.2
B25: 02 | C25: AK | D25: 01 | E25: FUEL COMB. ELEC. UTIL. | F25: 01 | G25: Coal | H25: 0101 | I25: SO2 | J25: Sulfur Dioxide | K25: 1897.98
K26: =SUM(K22:K25) -> 5994.77 | L26: =1/1.10231131*K26 -> 5438.3639

Sheet IPMSummary
A2: SO2 emissions (thousand tons)
B3: Values
A4: Row Labels | B4: Sum of 2016 | C4: Sum of 2020 | D4: Sum of 2025 | E4: Sum of 2030 | F4: Sum of 2040 | G4: Sum of 2050
A5: 1 | B5: 3.7392864 | C5: 3.0846306 | D5: 3.1190737 | E5: 3.122495 | F5: 3.1287516 | G5: 3.1866257
A6: 2 | B6: 72.229479 | C6: 73.25189 | D6: 79.811031 | E6: 76.313716 | F6: 83.706738 | G6: 82.107347
A7: 3 | B7: 374.63706 | C7: 395.94664 | D7: 415.49203 | E7: 399.2196 | F7: 389.1371 | G7: 396.87011
A8: 4 | B8: 137.52119 | C8: 146.60588 | D8: 152.92246 | E8: 171.21639 | F8: 176.88534 | G8: 186.86135
A9: 5 | B9: 243.16915 | C9: 252.59982 | D9: 272.47318 | E9: 257.98426 | F9: 239.51716 | G9: 235.19422
A10: 6 | B10: 180.10958 | C10: 177.98817 | D10: 197.34222 | E10: 194.75651 | F10: 188.85874 | G10: 185.43778
A11: 7 | B11: 206.34369 | C11: 205.58393 | D11: 226.69002 | E11: 215.75448 | F11: 192.09031 | G11: 195.27168
A12: 8 | B12: 138.55095 | C12: 141.7603 | D12: 141.79606 | E12: 147.32116 | F12: 144.93527 | G12: 154.6432
A13: 9 | B13: 4.9978908 | C13: 5.1781022 | D13: 5.2860136 | E13: 5.8267139 | F13: 5.8876326 | G13: 5.960818
A14: Grand Total | B14: 1361.2983 | C14: 1401.9994 | D14: 1494.9321 | E14: 1471.5153 | F14: 1424.147 | G14: 1445.5331
A16: NOx emissions (thousand tons)
B17: Values
A18: Row Labels | B18: Sum of 2016 | C18: Sum of 2020 | D18: Sum of 2025 | E18: Sum of 2030 | F18: Sum of 2040 | G18: Sum of 2050
A19: 1 | B19: 13.775719 | C19: 13.363947 | D19: 13.387022 | E19: 13.41182 | F19: 13.682398 | G19: 13.905182
A20: 2 | B20: 145.74139 | C20: 147.03206 | D20: 149.79862 | E20: 146.20613 | F20: 147.00794 | G20: 150.739
A21: 3 | B21: 293.32217 | C21: 293.82134 | D21: 296.22084 | E21: 278.69064 | F21: 280.55269 | G21: 287.89974
A22: 4 | B22: 186.09654 | C22: 167.5417 | D22: 172.85874 | E22: 174.16331 | F22: 175.77656 | G22: 177.32944
A23: 5 | B23: 244.7102 | C23: 246.90304 | D23: 264.95733 | E23: 254.85823 | F23: 247.00689 | G23: 265.70302
A24: 6 | B24: 130.9411 | C24: 128.3339 | D24: 135.2757 | E24: 131.50348 | F24: 133.17023 | G24: 139.84631
A25: 7 | B25: 242.75322 | C25: 224.74695 | D25: 232.46025 | E25: 221.6476 | F25: 202.62823 | G25: 208.08984
A26: 8 | B26: 278.0618 | C26: 218.86284 | D26: 212.41236 | E26: 199.57153 | F26: 198.23588 | G26: 202.91612
A27: 9 | B27: 17.225536 | C27: 17.832597 | D27: 19.478646 | E27: 22.860797 | F27: 23.352099 | G27: 24.670583
A28: Grand Total | B28: 1552.6277 | C28: 1458.4384 | D28: 1496.8495 | E28: 1442.9135 | F28: 1421.4129 | G28: 1471.0992

Sheet IPMProjections
B1: EPA 5-14_Base_Case - State Emissions Projections - All Emissions
C3: Power Generation Emissions
A5: MARKAL | C5: SO2 (thousand tons) | K5: Ozone Season NOx (thousand tons) | R5: MARKAL | S5: Annual NOx (thousand tons) | Z5: Hg (tons) | AG5: HCL (thousand tons) | AN5: CO2 (million short tons)
A6: Region | B6: State | C6: 2016 | D6: 2018 | E6: 2020 | F6: 2025 | G6: 2030 | H6: 2040 | I6: 2050 | J6: =A6 -> Region | K6: 2016 | L6: 2018 | M6: 2020 | N6: 2025 | O6: 2030 | P6: 2040 | Q6: 2050 | R6: Region | S6: 2016 | T6: 2018 | U6: 2020 | V6: 2025 | W6: 2030 | X6: 2040 | Y6: 2050 | Z6: 2016 | AA6: 2018 | AB6: 2020 | AC6: 2025 | AD6: 2030 | AE6: 2040 | AF6: 2050 | AG6: 2016 | AH6: 2018 | AI6: 2020 | AJ6: 2025 | AK6: 2030 | AL6: 2040 | AM6: 2050 | AN6: 2016 | AO6: 2018 | AP6: 2020 | AQ6: 2025 | AR6: 2030 | AS6: 2040 | AT6: 2050
A7: =INDEX(RegXWalk!A:A,MATCH(B7,RegXWalk!B:B,0)) -> 6 | B7: Alabama | C7: 37.485753 | D7: 40.660595 | E7: 42.16077 | F7: 43.031783 | G7: 43.031783 | H7: 36.910077 | I7: 28.912373 | J7: =A7 -> 6 | K7: 13.009219 | L7: 12.151178 | M7: 12.012894 | N7: 12.678728 | O7: 12.321334 | P7: 13.096234 | Q7: 13.741016 | R7: =A7 -> 6 | S7: 27.648796 | T7: 27.646363 | U7: 27.416575 | V7: 28.781504 | W7: 28.15836 | X7: 30.168393 | Y7: 31.889296 | Z7: 0.12692404 | AA7: 0.13615962 | AB7: 0.13699855 | AC7: 0.13922163 | AD7: 0.13921752 | AE7: 0.13441378 | AF7: 0.12687008 | AG7: 0.071800523 | AH7: 0.078184569 | AI7: 0.077380715 | AJ7: 0.079073001 | AK7: 0.079073001 | AL7: 0.069266139 | AM7: 0.052980226 | AN7: 62.402009 | AO7: 61.428719 | AP7: 63.367186 | AQ7: 63.626303 | AR7: 60.190196 | AS7: 83.734159 | AT7: 101.99536
A8: =INDEX(RegXWalk!A:A,MATCH(B8,RegXWalk!B:B,0)) -> 8 | B8: Arizona | C8: 26.840523 | D8: 27.53687 | E8: 27.312911 | F8: 27.53687 | G8: 27.475351 | H8: 26.809663 | I8: 27.095531 | J8: =A8 -> 8 | K8: 19.724554 | L8: 15.616412 | M8: 15.375088 | N8: 16.016787 | O8: 12.030654 | P8: 11.991451 | Q8: 12.629357 | R8: =A8 -> 8 | S8: 46.747521 | T8: 36.900046 | U8: 37.148375 | V8: 38.218887 | W8: 26.596132 | X8: 25.337538 | Y8: 27.705324 | Z8: 0.14865955 | AA8: 0.14887352 | AB8: 0.14845291 | AC8: 0.14888028 | AD8: 0.1487632 | AE8: 0.14715821 | AF8: 0.14603224 | AG8: 0.089974612 | AH8: 0.093742704 | AI8: 0.09299229 | AJ8: 0.093742704 | AK8: 0.093530177 | AL8: 0.090637718 | AM8: 0.095210582 | AN8: 58.520679 | AO8: 58.537643 | AP8: 59.950372 | AQ8: 64.194707 | AR8: 54.634179 | AS8: 55.101149 | AT8: 65.836682
A9: =INDEX(RegXWalk!A:A,MATCH(B9,RegXWalk!B:B,0)) -> 7 | B9: Arkansas | C9: 22.171535 | D9: 25.427143 | E9: 22.685498 | F9: 25.168164 | G9: 25.168164 | H9: 25.170018 | I9: 26.825889 | J9: =A9 -> 7 | K9: 16.71653 | L9: 11.839827 | M9: 11.287551 | N9: 12.050703 | O9: 11.960328 | P9: 12.206508 | Q9: 12.573909 | R9: =A9 -> 7 | S9: 37.078791 | T9: 26.06317 | U9: 24.148651 | V9: 26.785489 | W9: 26.686633 | X9: 26.361987 | Y9: 27.497885 | Z9: 0.089863804 | AA9: 0.10186766 | AB9: 0.092705952 | AC9: 0.10102847 | AD9: 0.10102854 | AE9: 0.10249273 | AF9: 0.10808925 | AG9: 0.037019458 | AH9: 0.041757221 | AI9: 0.038629394 | AJ9: 0.042072488 | AK9: 0.042072488 | AL9: 0.041997544 | AM9: 0.044044532 | AN9: 44.073822 | AO9: 48.580054 | AP9: 45.978536 | AQ9: 50.492036 | AR9: 50.551023 | AS9: 51.829263 | AT9: 56.227119
A10: =INDEX(RegXWalk!A:A,MATCH(B10,RegXWalk!B:B,0)) -> 9 | B10: California | C10: 3.4464546 | D10: 3.7091557 | E10: 3.6238173 | F10: 3.6584059 | G10: 4.1990913 | H10: 4.26001 | I10: 4.3331954 | J10: =A10 -> 9 | K10: 3.6995339 | L10: 4.1208199 | M10: 3.9914276 | N10: 4.2707738 | O10: 6.5133668 | P10: 6.7305874 | Q10: 6.9139469 | R10: =A10 -> 9 | S10: 11.556253 | T10: 12.082553 | U10: 11.964044 | V10: 12.565398 | W10: 15.634274 | X10: 16.196297 | Y10: 16.956094 | Z10: 0.23324772 | AA10: 0.23512278 | AB10: 0.51426664 | AC10: 0.81354087 | AD10: 0.87841941 | AE10: 0.89709589 | AF10: 1.0444107 | AG10: 0.0093725863 | AH10: 0.0093725863 | AI10: 0.0093725863 | AJ10: 0.0093725863 | AK10: 0.0085214114 | AL10: 0.0085214113 | AM10: 0.0085214113 | AN10: 63.289669 | AO10: 66.70758 | AP10: 68.949459 | AQ10: 72.523238 | AR10: 84.29188 | AS10: 87.506835 | AT10: 90.972252
A11: =INDEX(RegXWalk!A:A,MATCH(B11,RegXWalk!B:B,0)) -> 8 | B11: Colorado | C11: 16.865655 | D11: 15.11537 | E11: 15.164062 | F11: 15.177894 | G11: 15.178412 | H11: 15.726053 | I11: 16.5415 | J11: =A11 -> 8 | K11: 14.87266 | L11: 12.210522 | M11: 12.363383 | N11: 11.690165 | O11: 11.733193 | P11: 11.627157 | Q11: 11.502857 | R11: =A11 -> 8 | S11: 34.35629 | T11: 27.699786 | U11: 27.852138 | V11: 25.831946 | W11: 26.019267 | X11: 25.838663 | Y11: 25.769365 | Z11: 0.085579141 | AA11: 0.081445893 | AB11: 0.081276434 | AC11: 0.081684538 | AD11: 0.080984769 | AE11: 0.083413962 | AF11: 0.087002087 | AG11: 0.05028111 | AH11: 0.049612617 | AI11: 0.048817983 | AJ11: 0.06179949 | AK11: 0.061650448 | AL11: 0.060236741 | AM11: 0.059186346 | AN11: 42.832599 | AO11: 39.905899 | AP11: 40.259049 | AQ11: 41.995434 | AR11: 43.741328 | AS11: 46.30621 | AT11: 48.11436
A12: =INDEX(RegXWalk!A:A,MATCH(B12,RegXWalk!B:B,0)) -> 1 | B12: Connecticut | C12: 0.67689105 | D12: 0.64718634 | E12: 0.64843323 | F12: 0.66127087 | G12: 0.66139082 | H12: 0.66638012 | I12: 0.68019523 | J12: =A12 -> 1 | K12: 1.6437202 | L12: 1.5874724 | M12: 1.5410241 | N12: 1.5531337 | O12: 1.5309402 | P12: 1.6297533 | Q12: 1.7618752 | R12: =A12 -> 1 | S12: 3.7051096 | T12: 3.5587259 | U12: 3.5238287 | V12: 3.5342062 | W12: 3.5194136 | X12: 3.7335277 | Y12: 3.9685305 | Z12: 0.047117632 | AA12: 0.047076222 | AB12: 0.047085224 | AC12: 0.047176709 | AD12: 0.047177763 | AE12: 0.047216534 | AF12: 0.047318123 | AG12: 0.056270054 | AH12: 0.056270054 | AI12: 0.056270054 | AJ12: 0.056270054 | AK12: 0.056270054 | AL12: 0.056270054 | AM12: 0.056270054 | AN12: 8.8066221 | AO12: 7.8805246 | AP12: 7.981582 | AQ12: 8.0273286 | AR12: 8.1944992 | AS12: 10.901297 | AT12: 13.574365
A13: =INDEX(RegXWalk!A:A,MATCH(B13,RegXWalk!B:B,0)) -> 5 | B13: Delaware | C13: 0.12657735 | D13: 0.12657735 | E13: 0.12657735 | F13: 0.12657735 | G13: 0.12657735 | H13: 0.12657735 | I13: 0.12657735 | J13: =A13 -> 5 | K13: 0.39753977 | L13: 0.38811979 | M13: 0.40387731 | N13: 0.40387731 | O13: 0.40387731 | P13: 0.30604017 | Q13: 0.30604017 | R13: =A13 -> 5 | S13: 0.78434672 | T13: 0.76137199 | U13: 0.79141538 | V13: 0.77712951 | W13: 0.75528736 | X13: 0.62064472 | Y13: 0.50317821 | Z13: 1.702816e-06 | AA13: 1.6618342e-06 | AB13: 1.7118021e-06 | AC13: 1.6844162e-06 | AD13: 1.6425394e-06 | AE13: 1.1569975e-06 | AF13: 8.2809125e-07 | AG13: 0 | AH13: 0 | AI13: 0 | AJ13: 0 | AK13: 0 | AL13: 0 | AM13: 0 | AN13: 1.9724409 | AO13: 1.9381684 | AP13: 1.9799559 | AQ13: 1.9570534 | AR13: 1.9220324 | AS13: 1.5159807 | AT13: 1.2409211
A14: =INDEX(RegXWalk!A:A,MATCH(B14,RegXWalk!B:B,0)) -> 5 | B14: District of Columbia | C14: 0 | D14: 0 | E14: 0 | F14: 0 | G14: 0 | H14: 0 | I14: 0.13080204 | J14: =A14 -> 5 | K14: 0 | L14: 0 | M14: 0 | N14: 0 | O14: 0 | P14: 0 | Q14: 0.013707337 | R14: =A14 -> 5 | S14: 0 | T14: 0 | U14: 0 | V14: 0 | W14: 0 | X14: 0 | Y14: 0.03270051 | Z14: 0 | AA14: 0 | AB14: 0 | AC14: 0 | AD14: 0 | AE14: 0 | AF14: 0.00093196454 | AG14: 0 | AH14: 0 | AI14: 0 | AJ14: 0 | AK14: 0 | AL14: 0 | AM14: 0 | AN14: 0 | AO14: 0 | AP14: 0 | AQ14: 0 | AR14: 0 | AS14: 0 | AT14: 0.31882997
A15: =INDEX(RegXWalk!A:A,MATCH(B15,RegXWalk!B:B,0)) -> 5 | B15: Florida | C15: 77.313031 | D15: 81.773971 | E15: 81.178855 | F15: 80.92161 | G15: 72.583875 | H15: 61.397966 | I15: 44.627736 | J15: =A15 -> 5 | K15: 29.374548 | L15: 33.178503 | M15: 33.384964 | N15: 35.119027 | O15: 32.881557 | P15: 31.318419 | Q15: 32.490303 | R15: =A15 -> 5 | S15: 62.960905 | T15: 71.339624 | U15: 67.71036 | V15: 73.253079 | W15: 70.308347 | X15: 68.082423 | Y15: 70.603687 | Z15: 0.26445215 | AA15: 0.28641855 | AB15: 0.28415244 | AC15: 0.29251651 | AD15: 0.28348879 | AE15: 0.27701904 | AF15: 0.24467724 | AG15: 0.18560781 | AH15: 0.28996895 | AI15: 0.21577757 | AJ15: 0.30429709 | AK15: 0.28429629 | AL15: 0.18824146 | AM15: 0.12717751 | AN15: 123.70087 | AO15: 132.09843 | AP15: 130.28036 | AQ15: 140.40175 | AR15: 153.75762 | AS15: 168.81657 | AT15: 184.41864
A16: =INDEX(RegXWalk!A:A,MATCH(B16,RegXWalk!B:B,0)) -> 5 | B16: Georgia | C16: 23.348217 | D16: 26.635538 | E16: 27.10055 | F16: 29.035321 | G16: 29.193565 | H16: 27.814411 | I16: 30.436344 | J16: =A16 -> 5 | K16: 10.339826 | L16: 9.5353692 | M16: 9.7268056 | N16: 12.694493 | O16: 10.753946 | P16: 10.425308 | Q16: 11.316738 | R16: =A16 -> 5 | S16: 24.814507 | T16: 25.170025 | U16: 25.387122 | V16: 29.623232 | W16: 26.929193 | X16: 24.81632 | Y16: 28.833889 | Z16: 0.14366577 | AA16: 0.1551769 | AB16: 0.15764305 | AC16: 0.16889855 | AD16: 0.1764258 | AE16: 0.17222315 | AF16: 0.19588348 | AG16: 0.066664983 | AH16: 0.16815294 | AI16: 0.16435863 | AJ16: 0.20822652 | AK16: 0.17854254 | AL16: 0.17835188 | AM16: 0.20296341 | AN16: 65.722584 | AO16: 66.811153 | AP16: 69.320733 | AQ16: 77.90633 | AR16: 74.510485 | AS16: 69.082662 | AT16: 81.968768
A17: =INDEX(RegXWalk!A:A,MATCH(B17,RegXWalk!B:B,0)) -> 8 | B17: Idaho | C17: 0.15471038 | D17: 0.17556361 | E17: 0.17556361 | F17: 0.18711093 | G17: 0.18711093 | H17: 0.18711093 | I17: 0.18711093 | J17: =A17 -> 8 | K17: 0.19953982 | L17: 0.20629751 | M17: 0.20629751 | N17: 0.32054495 | O17: 0.32054495 | P17: 0.63459186 | Q17: 1.1356279 | R17: =A17 -> 8 | S17: 0.55573346 | T17: 0.61642224 | U17: 0.61642224 | V17: 0.95721376 | W17: 0.95721376 | X17: 1.6414578 | Y17: 2.8146881 | Z17: 0.0023575417 | AA17: 0.0025061238 | AB17: 0.0025061238 | AC17: 0.0025895096 | AD17: 0.0025895096 | AE17: 0.0025977306 | AF17: 0.0026125937 | AG17: 0 | AH17: 0 | AI17: 0 | AJ17: 0 | AK17: 0 | AL17: 0 | AM17: 0 | AN17: 0.93367971 | AO17: 0.98683829 | AP17: 0.98683829 | AQ17: 1.9442546 | AR17: 1.9442546 | AS17: 8.8193585 | AT17: 21.249151
A18: =INDEX(RegXWalk!A:A,MATCH(B18,RegXWalk!B:B,0)) -> 3 | B18: Illinois | C18: 48.997314 | D18: 51.705424 | E18: 51.989816 | F18: 53.211046 | G18: 55.139831 | H18: 55.406704 | I18: 55.444979 | J18: =A18 -> 3 | K18: 15.411115 | L18: 15.809515 | M18: 16.049391 | N18: 16.479718 | O18: 16.406247 | P18: 16.446299 | Q18: 17.148248 | R18: =A18 -> 3 | S18: 35.079459 | T18: 35.573484 | U18: 35.718488 | V18: 36.237723 | W18: 36.133967 | X18: 36.198698 | Y18: 37.721383 | Z18: 0.22193838 | AA18: 0.23235153 | AB18: 0.22713983 | AC18: 0.22694221 | AD18: 0.23030739 | AE18: 0.23425885 | AF18: 0.2348357 | AG18: 0.19377619 | AH18: 0.20242405 | AI18: 0.48676491 | AJ18: 0.48570669 | AK18: 0.48654809 | AL18: 0.48645241 | AM18: 0.4865481 | AN18: 92.665541 | AO18: 94.228221 | AP18: 93.743659 | AQ18: 94.442643 | AR18: 94.333117 | AS18: 95.862133 | AT18: 112.12412
... A55: =INDEX(RegXWalk!A:A,MATCH(B55,RegXWalk!B:B,0)) -> 8 | B55: Wyoming | C55: 22.752424 | D55: 23.80054 | E55: 23.714276 | F55: 27.295945 | G55: 27.764506 | H55: 25.985233 | I55: 25.411174 | J55: =A55 -> 8 | K55: 14.130398 | L55: 9.8398935 | M55: 9.6483046 | N55: 8.9778214 | O55: 8.985269 | P55: 8.9799513 | Q55: 8.9799513 | R55: =A55 -> 8 | S55: 33.482176 | T55: 22.57128 | U55: 22.369951 | V55: 20.530663 | W55: 20.554691 | X55: 20.58462 | Y55: 20.536243 | Z55: 0.29684839 | AA55: 0.30088777 | AB55: 0.30044543 | AC55: 0.31073622 | AD55: 0.31262969 | AE55: 0.32404598 | AF55: 0.32706432 | AG55: 0.03460678 | AH55: 0.035539662 | AI55: 0.035414105 | AJ55: 0.035562799 | AK55: 0.035562799 | AL55: 0.035562799 | AM55: 0.035564268 | AN55: 43.213929 | AO55: 45.216825 | AP55: 44.999913 | AQ55: 45.26772 | AR55: 45.323984 | AS55: 45.394067 | AT55: 45.276049
B56: Nationwide | C56: =SUM(C7:C55) -> 1361.2983 | D56: =SUM(D7:D55) -> 1414.776 | E56: =SUM(E7:E55) -> 1401.9994 | F56: =SUM(F7:F55) -> 1494.9321 | G56: =SUM(G7:G55) -> 1471.5153 | H56: =SUM(H7:H55) -> 1424.147 | I56: =SUM(I7:I55) -> 1445.5331 | K56: =SUM(K7:K55) -> 693.20212 | L56: =SUM(L7:L55) -> 662.33683 | M56: =SUM(M7:M55) -> 650.71477 | N56: =SUM(N7:N55) -> 669.97036 | O56: =SUM(O7:O55) -> 647.90721 | P56: =SUM(P7:P55) -> 638.72562 | Q56: =SUM(Q7:Q55) -> 655.17864 | S56: =SUM(S7:S55) -> 1552.6277 | T56: =SUM(T7:T55) -> 1492.3604 | U56: =SUM(U7:U55) -> 1458.4384 | V56: =SUM(V7:V55) -> 1496.8495 | W56: =SUM(W7:W55) -> 1442.9135 | X56: =SUM(X7:X55) -> 1421.4129 | Y56: =SUM(Y7:Y55) -> 1471.0992 | Z56: =SUM(Z7:Z55) -> 6.7154623 | ... AT56: =SUM(AT7:AT55) -> 2921.9587
B58: Note: The post-processed results in the parsed file and the flat file for any given year will show slightly different state-level tallies due to how the post-processing is conducted.

Sheet DataSummaryMATS
A2: National totals derivied from EPA's IPM analysis of the MATS rule
A3: http://www.epa.gov/airmarkt/progsregs/epa-ipm/proposed-toxics.html
A5: File | B5: ToxR_Policy_Case.xls
B6: Ktons | E6: kTonnes
A7: EMISSION Results | B7: 2015 | C7: 2020 | D7: 2030 | E7: 2015 | F7: 2020 | G7: 2030
A8: SO2 (1000 tons) | B8: 2079.859 | C8: 2104.153 | D8: 2141.03 | E8: =B8/1.10231131 -> 1886.8163 | F8: =C8/1.10231131 -> 1908.8555 | G8: =D8/1.10231131 -> 1942.3097
A9: NOx (1000 tons) | B9: 1900.256 | C9: 1933.393 | D9: 1974.231 | E9: =B9/1.10231131 -> 1723.8832 | F9: =C9/1.10231131 -> 1753.9446 | G9: =D9/1.10231131 -> 1790.9922
A10: CO2 (million metric tons) | B10: 2215.392 | C10: 2296.5773 | D10: 2449.2664

Sheet RegXWalk
A1: Region | B1: State
A2: 6 | B2: Alabama
A3: 8 | B3: Arizona
A4: 7 | B4: Arkansas
A5: 9 | B5: California
A6: 8 | B6: Colorado
A7: 1 | B7: Connecticut
A8: 5 | B8: Delaware
A9: 5 | B9: District of Columbia
A10: 5 | B10: Florida
A11: 5 | B11: Georgia
A12: 8 | B12: Idaho
A13: 3 | B13: Illinois
... A50: 8 | B50: Wyoming

Sheet Conversions
A1: Heating Values (LHV) | E1: Standard Conversions
A2: Heat capacity | B2: KJ/kg | C2: Mbtu/ton | E2: from | F2: to | G2: multiply by
A3: Coal equivalent | B3: 29260 | E3: Mtce | F3: PJ | G3: 29.26
A4: Chinese coal | B4: 20908 | E4: Btu | F4: J | G4: 1055
A5: Petroleum | B5: 41800 | E5: kcal | F5: kJ | G5: 4.1868
A6: Natural gas | B6: 35500 | E6: kWh | F6: MJ | G6: 3.6
A7: Wood and wood waste | B7: 16051 | C7: =B7/$F$21/$F$17*2000/1000 -> 13.799744 | E7: ft3 | F7: m3 | G7: 0.0283
A8: Ag residues | B8: 14423 | C8: =B8/$F$21/$F$17*2000/1000 -> 12.400082 | E8: Trillion Btu | F8: PJ | G8: 1.055
A9: Switchgrass | B9: 14423 | C9: =B9/$F$21/$F$17*2000/1000 -> 12.400082
A10: LPG | B10: 47310 | C10: =B10/B3 -> 1.6168831
A11: DME | B11: 28500 | C11: =B11/B3 -> 0.97402597
A12: Methane Emission Parameters
A13: 1 Gg CH4 = | B13: =B14*B15/10^3 -> 0.0548392 | C13: PJ
A14: 1 Tg = | B14: 52 | C14: Bcf
A15: 1 Bcf = | B15: 1.0546 | C15: PJ | E15: 1 kg CH4= | F15: =B14*G7 -> 1.4716 | G15: m3
A16: 1 Tg = | B16: 5.7273 | C16: MMTCE | E16: 1scf NG= | F16: 928 | G16: Btu | H16: Lower heat value
A17: 1 MMT MSW = | B17: 11 | C17: PJ | E17: 1 Btu = | F17: 1055 | G17: J
A18: 1 m3 CH4 = | B18: 37 | C18: MJ | E18: 1scf NG= | F18: =F16*F17 -> 979040 | G18: J
A19: 1 $/TCE = | B19: =B16/B14/B15 -> 0.10443807 | C19: m$/PJ | E19: 1 m3 NG = | F19: =F18/G7/10^6 -> 34.595053 | G19: MJ
A20: 1 kg CH4 = | B20: 21 | C20: kg CO2 eq. | E20: 1 gal gasoline = | F20: 121.9 | G20: MJ
A21: Model Monetary Units | C21: 1995$US M | E21: 1 kg = | F21: 2.205 | G21: lb
A22: 1 short ton coal = | B22: 20 | C22: Million Btu
A23: 1 million short ton coal = | B23: =B22*1055*10^-3 -> 21.1 | C23: PJ
A24: ft3 CH4/short ton coal = | B24: =1/(B14*B23) -> 0.00091141086 | C24: kt/PJ
A25: 1 m3 CH4 = | B25: 0.662 | C25: kg CH4
A26: 1 GW = | B26: 31.536 | C26: PJa
A27: 1 million barrels oil = | B27: 5.8 | C27: PJ
A29: Emission Factors
A30: 1 PJ CH4 released = | B30: =1/Conversions!B13 -> 18.235131 | C30: kt CH4
A31: 1 PJ CH4 burned = | B31: =15.3*0.001 -> 0.0153 | C31: mt CO2 (carbon)
A32: 1 PJ MSW burned = | B32: =20*0.001 -> 0.02 | C32: mt CO2 (carbon)
A33: 1 kt CH4 burned = | B33: =12/16 -> 0.75 | C33: kt CO2 (carbon)
A35: GDP Deflators (Conversion to US$2005)
A36: Year | B36: Deflator | C36: Multiply By (for $2005)
A37: 1983 | B37: 57.603 | C37: =$B$59/B37 -> 1.7360207
A38: 1984 | B38: 59.766 | C38: =$B$59/B38 -> 1.6731921
A39: 1985 | B39: 61.576 | C39: =$B$59/B39 -> 1.6240094
A40: 1986 | B40: 62.937 | C40: =$B$59/B40 -> 1.5888905
A41: 1987 | B41: 64.764 | C41: =$B$59/B41 -> 1.5440677
A42: 1988 | B42: 66.988 | C42: =$B$59/B42 -> 1.4928047
...
