Workbook

Sheet COM
B2: ~UC_Sets: R_E: R1,R2,R3,R4,R5,R6,R7,R8,R9
B3: ~UC_Sets: T_E:
F5: ~UC_T: UC_COMPRD~2011~LO | Y5: ~UC_T: UC_COMPRD~2055~LO
C6: UC_N | D6: PSET_SET | E6: CSET_CN | F6: CSET_SET | G6: UC_FLO | H6: R1 | I6: R2 | J6: R3 | K6: R4 | L6: R5 | M6: R6 | N6: R7 | O6: R8 | P6: R9 | Q6: UC_RHSRT | R6: UC_RHSRT~0 | S6: UC_Desc | V6: UC_N | W6: PSET_SET | X6: CSET_CN | Y6: CSET_SET | Z6: UC_FLO | AA6: R1 | AB6: R2 | AC6: R3 | AD6: R4 | AE6: R5 | AF6: R6 | AG6: R7 | AH6: R8 | AI6: R9 | AJ6: UC_Desc
C7: S_CSCELC | D7: CSC-ELC | E7: =LEFT(D7,3) -> CSC | F7: DEM | G7: 1 | H7: =-ComConstr!C3*0.99 -> -0.96226162 | I7: =-ComConstr!D3*0.99 -> -0.97057033 | J7: =-ComConstr!E3*0.99 -> -0.96498334 | K7: =-ComConstr!F3*0.99 -> -0.98893959 | L7: =-ComConstr!G3*0.99 -> -0.98610353 | M7: =-ComConstr!H3*0.99 -> -0.98194617 | N7: =-ComConstr!I3*0.99 -> -0.98875461 | O7: =-ComConstr!J3*0.99 -> -0.97452371 | P7: =-ComConstr!K3*0.99 -> -0.98568987 | Q7: 0 | R7: 15 | S7: Commercial Space Cooling - ELC | V7: S_CSCELC | W7: CSC-ELC | X7: =LEFT(W7,3) -> CSC | Y7: DEM | Z7: 1 | AA7: =H7*0.76 -> -0.73131883 | AB7: =I7*0.76 -> -0.73763345 | AC7: =J7*0.76 -> -0.73338734 | AD7: =K7*0.76 -> -0.75159409 | AE7: =L7*0.76 -> -0.74943869 | AF7: =M7*0.76 -> -0.74627909 | AG7: =N7*0.76 -> -0.7514535 | AH7: =O7*0.76 -> -0.74063802 | AI7: =P7*0.76 -> -0.7491243 | AJ7: Commercial Space Cooling - ELC
C8: S_CSCNG | D8: CSC-NG | E8: =LEFT(D8,3) -> CSC | F8: DEM | G8: 1 | H8: =-ComConstr!C4*0.99 -> -0.027738376 | I8: =-ComConstr!D4*0.99 -> -0.019429671 | J8: =-ComConstr!E4*0.99 -> -0.025016663 | K8: =-ComConstr!F4*0.99 -> -0.0010604062 | L8: =-ComConstr!G4*0.99 -> -0.0038964662 | M8: =-ComConstr!H4*0.99 -> -0.008053826 | N8: =-ComConstr!I4*0.99 -> -0.0012453904 | O8: =-ComConstr!J4*0.99 -> -0.015476287 | P8: =-ComConstr!K4*0.99 -> -0.0043101258 | Q8: 0 | R8: 15 | S8: Commercial Space Cooling - NG | V8: S_CSCNG | W8: CSC-NG | X8: =LEFT(W8,3) -> CSC | Y8: DEM | Z8: 1 | AA8: =H8*0.76 -> -0.021081166 | AB8: =I8*0.76 -> -0.01476655 | AC8: =J8*0.76 -> -0.019012664 | AD8: =K8*0.76 -> -0.00080590869 | AE8: =L8*0.76 -> -0.0029613143 | AF8: =M8*0.76 -> -0.0061209078 | AG8: =N8*0.76 -> -0.00094649674 | AH8: =O8*0.76 -> -0.011761978 | AI8: =P8*0.76 -> -0.0032756956 | AJ8: Commercial Space Cooling - NG
C9: S_CSCRF | D9: CSC-RF | E9: =LEFT(D9,3) -> CSC | F9: DEM | G9: 1 | H9: =-ComConstr!C5*0.99 -> -0.4495977 | I9: =-ComConstr!D5*0.99 -> -0.49222652 | J9: =-ComConstr!E5*0.99 -> -0.44647597 | K9: =-ComConstr!F5*0.99 -> -0.48911949 | L9: =-ComConstr!G5*0.99 -> -0.40085749 | M9: =-ComConstr!H5*0.99 -> -0.47483535 | N9: =-ComConstr!I5*0.99 -> -0.47050675 | O9: =-ComConstr!J5*0.99 -> -0.42627258 | P9: =-ComConstr!K5*0.99 -> -0.50953848 | Q9: 0 | R9: 15 | S9: Commercial Space Cooling - Rooftop | V9: S_CSCRF | W9: CSC-RF | X9: =LEFT(W9,3) -> CSC | Y9: DEM | Z9: 1 | AA9: =H9*0.85 -> -0.38215805 | AB9: =I9*0.85 -> -0.41839254 | AC9: =J9*0.85 -> -0.37950457 | AD9: =K9*0.85 -> -0.41575157 | AE9: =L9*0.85 -> -0.34072886 | AF9: =M9*0.85 -> -0.40361004 | AG9: =N9*0.85 -> -0.39993074 | AH9: =O9*0.85 -> -0.3623317 | AI9: =P9*0.85 -> -0.43310771 | AJ9: Commercial Space Cooling - Rooftop
C10: S_CSCCEN | D10: CSC-CEN | E10: =LEFT(D10,3) -> CSC | F10: DEM | G10: 1 | H10: =-ComConstr!C6*0.99 -> -0.090731993 | I10: =-ComConstr!D6*0.99 -> -0.081271617 | J10: =-ComConstr!E6*0.99 -> -0.17320523 | K10: =-ComConstr!F6*0.99 -> -0.21479186 | L10: =-ComConstr!G6*0.99 -> -0.10169059 | M10: =-ComConstr!H6*0.99 -> -0.1459498 | N10: =-ComConstr!I6*0.99 -> -0.19860544 | O10: =-ComConstr!J6*0.99 -> -0.12133101 | P10: =-ComConstr!K6*0.99 -> -0.12323201 | Q10: 0 | R10: 15 | S10: Commercial Space Cooling - Central | V10: S_CSCCEN | W10: CSC-CEN | X10: =LEFT(W10,3) -> CSC | Y10: DEM | Z10: 1 | AA10: =H10*0.85 -> -0.077122194 | AB10: =I10*0.85 -> -0.069080874 | AC10: =J10*0.85 -> -0.14722444 | AD10: =K10*0.85 -> -0.18257308 | AE10: =L10*0.85 -> -0.086437005 | AF10: =M10*0.85 -> -0.12405733 | AG10: =N10*0.85 -> -0.16881463 | AH10: =O10*0.85 -> -0.10313136 | AI10: =P10*0.85 -> -0.10474721 | AJ10: Commercial Space Cooling - Central
C11: S_CSCWWL | D11: CSC-WW | E11: =LEFT(D11,3) -> CSC | F11: DEM | G11: 1 | H11: =-ComConstr!C7*0.99 -> -0.12254018 | I11: =-ComConstr!D7*0.99 -> -0.10491886 | J11: =-ComConstr!E7*0.99 -> -0.043794447 | K11: =-ComConstr!F7*0.99 -> -0.042357563 | L11: =-ComConstr!G7*0.99 -> -0.058145827 | M11: =-ComConstr!H7*0.99 -> -0.076556215 | N11: =-ComConstr!I7*0.99 -> -0.051770986 | O11: =-ComConstr!J7*0.99 -> -0.12778806 | P11: =-ComConstr!K7*0.99 -> -0.073596795 | Q11: 0 | R11: 15 | S11: Commercial Space Cooling - Wall/Wiindow low | V11: S_CSCWWL | W11: CSC-WW | X11: =LEFT(W11,3) -> CSC | Y11: DEM | Z11: 1 | AA11: =H11*0.85 -> -0.10415915 | AB11: =I11*0.85 -> -0.089181027 | AC11: =J11*0.85 -> -0.03722528 | AD11: =K11*0.85 -> -0.036003928 | AE11: =L11*0.85 -> -0.049423953 | AF11: =M11*0.85 -> -0.065072783 | AG11: =N11*0.85 -> -0.044005338 | AH11: =O11*0.85 -> -0.10861985 | AI11: =P11*0.85 -> -0.062557276 | AJ11: Commercial Space Cooling - Wall/Wiindow low
C12: S_CSCGHP | D12: CSC-GHP | E12: =LEFT(D12,3) -> CSC | F12: DEM | G12: 1 | H12: =-ComConstr!C8*0.99 -> -0.018623292 | I12: =-ComConstr!D8*0.99 -> -0.016251135 | J12: =-ComConstr!E8*0.99 -> -0.0081882884 | K12: =-ComConstr!F8*0.99 -> -0.013802886 | L12: =-ComConstr!G8*0.99 -> -0.054111229 | M12: =-ComConstr!H8*0.99 -> -0.039295946 | N12: =-ComConstr!I8*0.99 -> -0.021935054 | O12: =-ComConstr!J8*0.99 -> -0.026153462 | P12: =-ComConstr!K8*0.99 -> -0.036361696 | Q12: 0 | R12: 15 | S12: Commercial Space Cooling - GHP | V12: S_CSCGHP | W12: CSC-GHP | X12: =LEFT(W12,3) -> CSC | Y12: DEM | Z12: 1 | AA12: =H12*0.85 -> -0.015829798 | AB12: =I12*0.85 -> -0.013813465 | AC12: =J12*0.85 -> -0.0069600451 | AD12: =K12*0.85 -> -0.011732453 | AE12: =L12*0.85 -> -0.045994544 | AF12: =M12*0.85 -> -0.033401554 | AG12: =N12*0.85 -> -0.018644796 | AH12: =O12*0.85 -> -0.022230443 | AI12: =P12*0.85 -> -0.030907441 | AJ12: Commercial Space Cooling - GHP
C13: S_CSCAHP | D13: CSC-AHP | E13: =LEFT(D13,3) -> CSC | F13: DEM | G13: 1 | H13: =-ComConstr!C9*0.99 -> -0.047888464 | I13: =-ComConstr!D9*0.99 -> -0.041788633 | J13: =-ComConstr!E9*0.99 -> -0.021055599 | K13: =-ComConstr!F9*0.99 -> -0.035493136 | L13: =-ComConstr!G9*0.99 -> -0.13914316 | M13: =-ComConstr!H9*0.99 -> -0.10104672 | N13: =-ComConstr!I9*0.99 -> -0.056404423 | O13: =-ComConstr!J9*0.99 -> -0.06725176 | P13: =-ComConstr!K9*0.99 -> -0.093501503 | Q13: 0 | R13: 15 | S13: Commercial Space Cooling - AHP | V13: S_CSCAHP | W13: CSC-AHP | X13: =LEFT(W13,3) -> CSC | Y13: DEM | Z13: 1 | AA13: =H13*0.85 -> -0.040705194 | AB13: =I13*0.85 -> -0.035520338 | AC13: =J13*0.85 -> -0.017897259 | AD13: =K13*0.85 -> -0.030169166 | AE13: =L13*0.85 -> -0.11827169 | AF13: =M13*0.85 -> -0.08588971 | AG13: =N13*0.85 -> -0.04794376 | AH13: =O13*0.85 -> -0.057163996 | AI13: =P13*0.85 -> -0.079476278 | AJ13: Commercial Space Cooling - AHP
C14: S_CSCCC | D14: CSC-CC | E14: =LEFT(D14,3) -> CSC | F14: DEM | G14: 1 | H14: =-ComConstr!C10*0.99 -> -0.052920915 | I14: =-ComConstr!D10*0.99 -> -0.052736318 | J14: =-ComConstr!E10*0.99 -> -0.06172195 | K14: =-ComConstr!F10*0.99 -> -0.042542424 | L14: =-ComConstr!G10*0.99 -> -0.051162028 | M14: =-ComConstr!H10*0.99 -> -0.031737672 | N14: =-ComConstr!I10*0.99 -> -0.041710076 | O14: =-ComConstr!J10*0.99 -> -0.046094935 | P14: =-ComConstr!K10*0.99 -> -0.033338307 | Q14: 0 | R14: 15 | S14: Commercial Space Cooling - Centr. Chiller | V14: S_CSCCC | W14: CSC-CC | X14: =LEFT(W14,3) -> CSC | Y14: DEM | Z14: 1 | AA14: =H14*0.76 -> -0.040219896 | AB14: =I14*0.76 -> -0.040079602 | AC14: =J14*0.76 -> -0.046908682 | AD14: =K14*0.76 -> -0.032332243 | AE14: =L14*0.76 -> -0.038883141 | AF14: =M14*0.76 -> -0.024120631 | AG14: =N14*0.76 -> -0.031699658 | AH14: =O14*0.76 -> -0.03503215 | AI14: =P14*0.76 -> -0.025337114 | AJ14: Commercial Space Cooling - Centr. Chiller
C15: S_CSCRC | D15: CSC-RC | E15: =LEFT(D15,3) -> CSC | F15: DEM | G15: 1 | H15: =-ComConstr!C11*0.99 -> -0.1876287 | I15: =-ComConstr!D11*0.99 -> -0.18697422 | J15: =-ComConstr!E11*0.99 -> -0.21883237 | K15: =-ComConstr!F11*0.99 -> -0.15083223 | L15: =-ComConstr!G11*0.99 -> -0.18139264 | M15: =-ComConstr!H11*0.99 -> -0.11252448 | N15: =-ComConstr!I11*0.99 -> -0.14788118 | O15: =-ComConstr!J11*0.99 -> -0.1634275 | P15: =-ComConstr!K11*0.99 -> -0.11819945 | Q15: 0 | R15: 15 | S15: Commercial Space Cooling - Reciprocating Chiller | V15: S_CSCRC | W15: CSC-RC | X15: =LEFT(W15,3) -> CSC | Y15: DEM | Z15: 1 | AA15: =H15*0.76 -> -0.14259781 | AB15: =I15*0.76 -> -0.14210041 | AC15: =J15*0.76 -> -0.1663126 | AD15: =K15*0.76 -> -0.1146325 | AE15: =L15*0.76 -> -0.13785841 | AF15: =M15*0.76 -> -0.085518601 | AG15: =N15*0.76 -> -0.1123897 | AH15: =O15*0.76 -> -0.1242049 | AI15: =P15*0.76 -> -0.089831585 | AJ15: Commercial Space Cooling - Reciprocating Chiller
C16: S_CCKELC | D16: CCK-ELC | E16: =LEFT(D16,3) -> CCK | F16: DEM | G16: 1 | H16: =-ComConstr!C12*0.99 -> -0.36079473 | I16: =-ComConstr!D12*0.99 -> -0.33189077 | J16: =-ComConstr!E12*0.99 -> -0.36787955 | K16: =-ComConstr!F12*0.99 -> -0.44002557 | L16: =-ComConstr!G12*0.99 -> -0.41043373 | M16: =-ComConstr!H12*0.99 -> -0.37812763 | N16: =-ComConstr!I12*0.99 -> -0.38144646 | O16: =-ComConstr!J12*0.99 -> -0.35888943 | P16: =-ComConstr!K12*0.99 -> -0.26752941 | Q16: 0 | R16: 15 | S16: Commercial Cooking - ELC | V16: S_CCKELC | W16: CCK-ELC | X16: =LEFT(W16,3) -> CCK | Y16: DEM | Z16: 1 | AA16: =H16*0.76 -> -0.274204 | AB16: =I16*0.76 -> -0.25223699 | AC16: =J16*0.76 -> -0.27958846 | AD16: =K16*0.76 -> -0.33441943 | AE16: =L16*0.76 -> -0.31192964 | AF16: =M16*0.76 -> -0.287377 | AG16: =N16*0.76 -> -0.28989931 | AH16: =O16*0.76 -> -0.27275597 | AI16: =P16*0.76 -> -0.20332236 | AJ16: Commercial Cooking - ELC
C17: S_CCKNG | D17: CCK-NG | E17: =LEFT(D17,3) -> CCK | F17: DEM | G17: 1 | H17: =-ComConstr!C13*0.99 -> -0.62920527 | I17: =-ComConstr!D13*0.99 -> -0.65810923 | J17: =-ComConstr!E13*0.99 -> -0.62212045 | K17: =-ComConstr!F13*0.99 -> -0.54997443 | L17: =-ComConstr!G13*0.99 -> -0.57956627 | M17: =-ComConstr!H13*0.99 -> -0.61187237 | N17: =-ComConstr!I13*0.99 -> -0.60855354 | O17: =-ComConstr!J13*0.99 -> -0.63111057 | P17: =-ComConstr!K13*0.99 -> -0.72247059 | Q17: 0 | R17: 15 | S17: Commercial Cooking - NG | V17: S_CCKNG | W17: CCK-NG | X17: =LEFT(W17,3) -> CCK | Y17: DEM | Z17: 1 | AA17: =H17*0.76 -> -0.478196 | AB17: =I17*0.76 -> -0.50016301 | AC17: =J17*0.76 -> -0.47281154 | AD17: =K17*0.76 -> -0.41798057 | AE17: =L17*0.76 -> -0.44047036 | AF17: =M17*0.76 -> -0.465023 | AG17: =N17*0.76 -> -0.46250069 | AH17: =O17*0.76 -> -0.47964403 | AI17: =P17*0.76 -> -0.54907764 | AJ17: Commercial Cooking - NG
C18: S_CSHELC | D18: CSH-ELC | E18: =LEFT(D18,3) -> CSH | F18: DEM | G18: 1 | H18: =-ComConstr!C14*0.99 -> -0.1118828 | I18: =-ComConstr!D14*0.99 -> -0.096993398 | J18: =-ComConstr!E14*0.99 -> -0.069090817 | K18: =-ComConstr!F14*0.99 -> -0.10128474 | L18: =-ComConstr!G14*0.99 -> -0.27727514 | M18: =-ComConstr!H14*0.99 -> -0.21229547 | N18: =-ComConstr!I14*0.99 -> -0.16121274 | O18: =-ComConstr!J14*0.99 -> -0.097071128 | P18: =-ComConstr!K14*0.99 -> -0.16379207 | Q18: 0 | R18: 15 | S18: Commercial Space Heatng - ELC | V18: S_CSHELC | W18: CSH-ELC | X18: =LEFT(W18,3) -> CSH | Y18: DEM | Z18: 1 | AA18: =H18*0.76 -> -0.085030928 | AB18: =I18*0.76 -> -0.073714983 | AC18: =J18*0.76 -> -0.052509021 | AD18: =K18*0.76 -> -0.076976399 | AE18: =L18*0.76 -> -0.2107291 | AF18: =M18*0.76 -> -0.16134456 | AG18: =N18*0.76 -> -0.12252168 | AH18: =O18*0.76 -> -0.073774057 | AI18: =P18*0.76 -> -0.12448197 | AJ18: Commercial Space Heatng - ELC
C19: S_CSHNG | D19: CSH-NG | E19: =LEFT(D19,3) -> CSH | F19: DEM | G19: 1 | H19: =-ComConstr!C15*0.99 -> -0.49777188 | I19: =-ComConstr!D15*0.99 -> -0.66624125 | J19: =-ComConstr!E15*0.99 -> -0.90989786 | K19: =-ComConstr!F15*0.99 -> -0.88871526 | L19: =-ComConstr!G15*0.99 -> -0.65422887 | M19: =-ComConstr!H15*0.99 -> -0.775911 | N19: =-ComConstr!I15*0.99 -> -0.8269493 | O19: =-ComConstr!J15*0.99 -> -0.88907193 | P19: =-ComConstr!K15*0.99 -> -0.82565288 | Q19: 0 | R19: 15 | S19: Commercial Space Heatng - NG | V19: S_CSHNG | W19: CSH-NG | X19: =LEFT(W19,3) -> CSH | Y19: DEM | Z19: 1 | AA19: =H19*0.76 -> -0.37830663 | AB19: =I19*0.76 -> -0.50634335 | AC19: =J19*0.76 -> -0.69152238 | AD19: =K19*0.76 -> -0.6754236 | AE19: =L19*0.76 -> -0.49721394 | AF19: =M19*0.76 -> -0.58969236 | AG19: =N19*0.76 -> -0.62848146 | AH19: =O19*0.76 -> -0.67569467 | AI19: =P19*0.76 -> -0.62749619 | AJ19: Commercial Space Heatng - NG
C20: S_CSHDSL | D20: CSH-DSL | E20: =LEFT(D20,3) -> CSH | F20: DEM | G20: 1 | H20: =-ComConstr!C16*0.99 -> -0.38034532 | I20: =-ComConstr!D16*0.99 -> -0.22676535 | J20: =-ComConstr!E16*0.99 -> -0.011011319 | K20: =-ComConstr!F16*0.99 -> 0 | L20: =-ComConstr!G16*0.99 -> -0.05849599 | M20: =-ComConstr!H16*0.99 -> -0.0017935331 | N20: =-ComConstr!I16*0.99 -> -0.0018379683 | O20: =-ComConstr!J16*0.99 -> -0.0038569445 | P20: =-ComConstr!K16*0.99 -> -0.00055505522 | Q20: 0 | R20: 15 | S20: Commercial Space Heating - DSL | V20: S_CSHDSL | W20: CSH-DSL | X20: =LEFT(W20,3) -> CSH | Y20: DEM | Z20: 1 | AA20: =H20*0.76 -> -0.28906244 | AB20: =I20*0.76 -> -0.17234166 | AC20: =J20*0.76 -> -0.0083686022 | AD20: =K20*0.76 -> 0 | AE20: =L20*0.76 -> -0.044456952 | AF20: =M20*0.76 -> -0.0013630852 | AG20: =N20*0.76 -> -0.0013968559 | AH20: =O20*0.76 -> -0.0029312778 | AI20: =P20*0.76 -> -0.00042184197 | AJ20: Commercial Space Heating - DSL
C21: S_CSHBLR | D21: CSH-BLR | E21: =LEFT(D21,3) -> CSH | F21: DEM | G21: 1 | H21: =-ComConstr!C17*0.98 -> -0.57372387 | I21: =-ComConstr!D17*0.98 -> -0.56173358 | J21: =-ComConstr!E17*0.98 -> -0.40277857 | K21: =-ComConstr!F17*0.98 -> -0.31760496 | L21: =-ComConstr!G17*0.98 -> -0.30882116 | M21: =-ComConstr!H17*0.98 -> -0.26888846 | N21: =-ComConstr!I17*0.98 -> -0.23028039 | O21: =-ComConstr!J17*0.98 -> -0.28598435 | P21: =-ComConstr!K17*0.98 -> -0.23888647 | Q21: 0 | R21: 15 | S21: Commercial Space Heating - Boilers | V21: S_CSHBLR | W21: CSH-BLR | X21: =LEFT(W21,3) -> CSH | Y21: DEM | Z21: 1 | AA21: =H21*0.85 -> -0.48766529 | AB21: =I21*0.85 -> -0.47747354 | AC21: =J21*0.85 -> -0.34236179 | AD21: =K21*0.85 -> -0.26996422 | AE21: =L21*0.85 -> -0.26249799 | AF21: =M21*0.85 -> -0.22855519 | AG21: =N21*0.85 -> -0.19573833 | AH21: =O21*0.85 -> -0.2430867 | AI21: =P21*0.85 -> -0.2030535 | AJ21: Commercial Space Heating - Boilers
C22: S_CSHFUR | D22: CSH-FUR | E22: =LEFT(D22,3) -> CSH | F22: DEM | G22: 1 | H22: =-ComConstr!C18*0.98 -> -0.29755482 | I22: =-ComConstr!D18*0.98 -> -0.32281547 | J22: =-ComConstr!E18*0.98 -> -0.53029777 | K22: =-ComConstr!F18*0.98 -> -0.56710788 | L22: =-ComConstr!G18*0.98 -> -0.399304 | M22: =-ComConstr!H18*0.98 -> -0.5338998 | N22: =-ComConstr!I18*0.98 -> -0.59490186 | O22: =-ComConstr!J18*0.98 -> -0.59897592 | P22: =-ComConstr!K18*0.98 -> -0.5884606 | Q22: 0 | R22: 15 | S22: Commercial Space Heating - Furnace | V22: S_CSHFUR | W22: CSH-FUR | X22: =LEFT(W22,3) -> CSH | Y22: DEM | Z22: 1 | AA22: =H22*0.85 -> -0.2529216 | AB22: =I22*0.85 -> -0.27439315 | AC22: =J22*0.85 -> -0.45075311 | AD22: =K22*0.85 -> -0.4820417 | AE22: =L22*0.85 -> -0.3394084 | AF22: =M22*0.85 -> -0.45381483 | AG22: =N22*0.85 -> -0.50566658 | AH22: =O22*0.85 -> -0.50912953 | AI22: =P22*0.85 -> -0.50019151 | AJ22: Commercial Space Heating - Furnace
C23: S_CSHELO | D23: CSH-ELO | E23: =LEFT(D23,3) -> CSH | F23: DEM | G23: 1 | H23: =-ComConstr!C19*0.99 -> -0.062523329 | I23: =-ComConstr!D19*0.99 -> -0.051795281 | J23: =-ComConstr!E19*0.99 -> -0.028660312 | K23: =-ComConstr!F19*0.99 -> -0.058534323 | L23: =-ComConstr!G19*0.99 -> -0.048439141 | M23: =-ComConstr!H19*0.99 -> -0.048105183 | N23: =-ComConstr!I19*0.99 -> -0.061154843 | O23: =-ComConstr!J19*0.99 -> -0.045959399 | P23: =-ComConstr!K19*0.99 -> -0.044348828 | Q23: 0 | R23: 15 | S23: Commercial Space Heating - ELO | V23: S_CSHELO | W23: CSH-ELO | X23: =LEFT(W23,3) -> CSH | Y23: DEM | Z23: 1 | AA23: =H23*0.76 -> -0.04751773 | AB23: =I23*0.76 -> -0.039364413 | AC23: =J23*0.76 -> -0.021781837 | AD23: =K23*0.76 -> -0.044486085 | AE23: =L23*0.76 -> -0.036813747 | AF23: =M23*0.76 -> -0.036559939 | AG23: =N23*0.76 -> -0.04647768 | AH23: =O23*0.76 -> -0.034929143 | AI23: =P23*0.76 -> -0.033705109 | AJ23: Commercial Space Heating - ELO
C24: S_CWHELC | D24: CWH-ELC | E24: =LEFT(D24,3) -> CWH | F24: DEM | G24: 1 | H24: =-ComConstr!C20*0.99 -> -0.041902452 | I24: =-ComConstr!D20*0.99 -> -0.044528537 | J24: =-ComConstr!E20*0.99 -> -0.056927999 | K24: =-ComConstr!F20*0.99 -> -0.081365565 | L24: =-ComConstr!G20*0.99 -> -0.23085428 | M24: =-ComConstr!H20*0.99 -> -0.17309898 | N24: =-ComConstr!I20*0.99 -> -0.11039193 | O24: =-ComConstr!J20*0.99 -> -0.082003411 | P24: =-ComConstr!K20*0.99 -> -0.025377386 | Q24: 0 | R24: 15 | S24: Commercial Water Heating - ELC | V24: S_CWHELC | W24: CWH-ELC | X24: =LEFT(W24,3) -> CWH | Y24: DEM | Z24: 1 | AA24: =H24*0.76 -> -0.031845863 | AB24: =I24*0.76 -> -0.033841688 | AC24: =J24*0.76 -> -0.043265279 | AD24: =K24*0.76 -> -0.06183783 | AE24: =L24*0.76 -> -0.17544925 | AF24: =M24*0.76 -> -0.13155522 | AG24: =N24*0.76 -> -0.08389787 | AH24: =O24*0.76 -> -0.062322593 | AI24: =P24*0.76 -> -0.019286813 | AJ24: Commercial Water Heating - ELC
C25: S_CWHNG | D25: CWH-NG | E25: =LEFT(D25,3) -> CWH | F25: DEM | G25: 1 | H25: =-ComConstr!C21*0.99 -> -0.78576552 | I25: =-ComConstr!D21*0.99 -> -0.94547146 | J25: =-ComConstr!E21*0.99 -> -0.933072 | K25: =-ComConstr!F21*0.99 -> -0.90863443 | L25: =-ComConstr!G21*0.99 -> -0.75151294 | M25: =-ComConstr!H21*0.99 -> -0.81690102 | N25: =-ComConstr!I21*0.99 -> -0.87960807 | O25: =-ComConstr!J21*0.99 -> -0.90799659 | P25: =-ComConstr!K21*0.99 -> -0.96462261 | Q25: 0 | R25: 15 | S25: Commercial Water Heating - NG | V25: S_CWHNG | W25: CWH-NG | X25: =LEFT(W25,3) -> CWH | Y25: DEM | Z25: 1 | AA25: =H25*0.76 -> -0.5971818 | AB25: =I25*0.76 -> -0.71855831 | AC25: =J25*0.76 -> -0.70913472 | AD25: =K25*0.76 -> -0.69056217 | AE25: =L25*0.76 -> -0.57114984 | AF25: =M25*0.76 -> -0.62084478 | AG25: =N25*0.76 -> -0.66850213 | AH25: =O25*0.76 -> -0.69007741 | AI25: =P25*0.76 -> -0.73311319 | AJ25: Commercial Water Heating - NG
C26: S_CWHDSL | D26: CWH-DSL | E26: =LEFT(D26,3) -> CWH | F26: DEM | G26: 1 | H26: =-ComConstr!C22*0.99 -> -0.16233203 | I26: =-ComConstr!D22*0.99 -> 0 | J26: =-ComConstr!E22*0.99 -> 0 | K26: =-ComConstr!F22*0.99 -> 0 | L26: =-ComConstr!G22*0.99 -> -0.0076327725 | M26: =-ComConstr!H22*0.99 -> 0 | N26: =-ComConstr!I22*0.99 -> 0 | O26: =-ComConstr!J22*0.99 -> 0 | P26: =-ComConstr!K22*0.99 -> 0 | Q26: 0 | R26: 15 | S26: Commercial Water Heating - DSL | V26: S_CWHDSL | W26: CWH-DSL | X26: =LEFT(W26,3) -> CWH | Y26: DEM | Z26: 1 | AA26: =H26*0.76 -> -0.12337234 | AB26: =I26*0.76 -> 0 | AC26: =J26*0.76 -> 0 | AD26: =K26*0.76 -> 0 | AE26: =L26*0.76 -> -0.0058009071 | AF26: =M26*0.76 -> 0 | AG26: =N26*0.76 -> 0 | AH26: =O26*0.76 -> 0 | AI26: =P26*0.76 -> 0 | AJ26: Commercial Water Heating - DSL
G33: ~UC_T: UC_COMPRD~2011~LO
C34: UC_N | D34: PSET_SET | E34: CSET_CN | F34: CSET_SET | G34: LimType | H34: UC_FLO | I34: 2011 | J34: 2020 | K34: 2025 | L34: 2055 | M34: UC_RHSRT | N34: UC_RHSRT~0 | O34: UC_DESC
C35: S_CVTCAV | D35: CVT-CAV | E35: =LEFT(D35,3) -> CVT | F35: DEM | H35: 1 | I35: =-ComConstr!C28*0.99 -> -0.64027788 | L35: =I35 -> -0.64027788 | M35: 0 | N35: 15 | O35: Commercial Ventilation - CAV
C36: S_CVTVAV | D36: CVT-VAV | E36: =LEFT(D36,3) -> CVT | F36: DEM | H36: 1 | I36: =-ComConstr!C29*0.99 -> -0.34972212 | L36: =I36 -> -0.34972212 | M36: 0 | N36: 15 | O36: Commercial Ventilation - VAV
C37: S_CRFCR | D37: CRF-CEN | E37: =LEFT(D37,3) -> CRF | F37: DEM | H37: 1 | I37: =-ComConstr!C30*0.99 -> -0.070373033 | L37: =I37 -> -0.070373033 | M37: 0 | N37: 15 | O37: Commercial Refrigeration - Central
C38: S_CRFWIC | D38: CRF-WIC | E38: =LEFT(D38,3) -> CRF | F38: DEM | H38: 1 | I38: =-ComConstr!C31*0.99 -> -0.22415106 | L38: =I38 -> -0.22415106 | M38: 0 | N38: 15 | O38: Commercial Refrigeration - Walk-In Cooler
C39: S_CRFWIF | D39: CRF-WIF | E39: =LEFT(D39,3) -> CRF | F39: DEM | H39: 1 | I39: =-ComConstr!C32*0.99 -> -0.083490712 | L39: =I39 -> -0.083490712 | M39: 0 | N39: 15 | O39: Commercial Refrigeration - Walk-In Freezer
C40: S_CRFRIR | D40: CRF-RIR | E40: =LEFT(D40,3) -> CRF | F40: DEM | H40: 1 | I40: =-ComConstr!C33*0.99 -> -0.091479588 | L40: =I40 -> -0.091479588 | M40: 0 | N40: 15 | O40: Commercial Refrigeration - Reach-In Cooler
C41: S_CRFRIF | D41: CRF-RIF | E41: =LEFT(D41,3) -> CRF | F41: DEM | H41: 1 | I41: =-ComConstr!C34*0.99 -> -0.31576145 | L41: =I41 -> -0.31576145 | M41: 0 | N41: 15 | O41: Commercial Refrigeration - Reach-In Freezer
C42: S_CRFICE | D42: CRF-ICM | E42: =LEFT(D42,3) -> CRF | F42: DEM | H42: 1 | I42: =-ComConstr!C35*0.99 -> -0.036769783 | L42: =I42 -> -0.036769783 | M42: 0 | N42: 15 | O42: Commercial Refrigeration - Ice Machine
C43: S_CRFBEV | D43: CRF-BEV | E43: =LEFT(D43,3) -> CRF | F43: DEM | H43: 1 | I43: =-ComConstr!C36*0.99 -> -0.12095141 | L43: =I43 -> -0.12095141 | M43: 0 | N43: 15 | O43: Commercial Refrigeration - Beverage Machine
C44: S_CRFRVM | D44: CRF-RVM | E44: =LEFT(D44,3) -> CRF | F44: DEM | H44: 1 | I44: =-ComConstr!C37*0.99 -> -0.047022969 | L44: =I44 -> -0.047022969 | M44: 0 | N44: 15 | O44: Commercial Refrigeration - Vending Machine
C45: S_CLTINC | D45: CLT-INC | E45: =LEFT(D45,3) -> CLT | F45: DEM | H45: 1 | I45: =-ComConstr!C38*0.99 -> -0.032377893 | L45: =I45*0.5 -> -0.016188946 | M45: 0 | N45: 15 | O45: Commercial Lighting - Incandescent
C46: S_CLTCFL | D46: CLT-CFL | E46: =LEFT(D46,3) -> CLT | F46: DEM | H46: 1 | I46: =-ComConstr!C39*0.99 -> -0.12728811 | L46: =I46*0.5 -> -0.063644053 | M46: 0 | N46: 15 | O46: Commercial Lighting - Compact Fluorescent
C47: S_CLTT8 | D47: CLT-T8 | E47: =LEFT(D47,3) -> CLT | F47: DEM | H47: 1 | I47: =-ComConstr!C40*0.99 -> -0.67439955 | L47: =I47*0.5 -> -0.33719977 | M47: 0 | N47: 15 | O47: Commercial Lighting - T8
C48: S_CLTHID | D48: CLT-HID | E48: =LEFT(D48,3) -> CLT | F48: DEM | H48: 1 | I48: =-ComConstr!C41*0.99 -> -0.069602558 | L48: =I48 -> -0.069602558 | M48: 0 | N48: 15 | O48: Commercial Lighting - HID
...

Sheet RES
B2: ~UC_Sets: R_E: R1,R2,R3,R4,R5,R6,R7,R8,R9
B3: ~UC_Sets: T_E:
F5: ~UC_T: UC_COMPRD~2020~LO
C6: UC_N | D6: PSET_SET | E6: CSET_CN | F6: CSET_SET | G6: UC_FLO | H6: R1 | I6: R2 | J6: R3 | K6: R4 | L6: R5 | M6: R6 | N6: R7 | O6: R8 | P6: R9 | Q6: UC_RHSRT | R6: UC_RHSRT~0 | S6: UC_Desc
C7: S_RLTINC | D7: RLT-INC | E7: RLT | F7: DEM | G7: 1 | H7: -0.25 | I7: -0.25 | J7: -0.25 | K7: -0.25 | L7: -0.25 | M7: -0.25 | N7: -0.25 | O7: -0.25 | P7: -0.25 | Q7: 0 | R7: 15
G10: ~UC_T: UC_COMPRD~2011~LO | AC10: ~UC_T: UC_COMPRD~2055~LO
C11: UC_N | D11: PSET_SET | E11: CSET_CN | F11: CSET_SET | G11: LimType | H11: UC_FLO | I11: R1 | J11: R2 | K11: R3 | L11: R4 | M11: R5 | N11: R6 | O11: R7 | P11: R8 | Q11: R9 | R11: UC_RHSRT | S11: UC_RHSRT~0 | T11: UC_Desc | Y11: UC_N | Z11: PSET_SET | AA11: CSET_CN | AB11: CSET_SET | AC11: LimType | AD11: UC_FLO | AE11: R1 | AF11: R2 | AG11: R3 | AH11: R4 | AI11: R5 | AJ11: R6 | AK11: R7 | AL11: R8 | AM11: R9 | AN11: UC_Desc
C12: S_RSHDSL | D12: RSH-DSL | E12: RSH | F12: DEM | H12: 1 | I12: -0.48 | J12: -0.26 | K12: -0.02 | L12: -0.02 | M12: -0.06 | Q12: -0.02 | R12: 0 | S12: 15 | T12: Residential Space Heating - DSL | Y12: S_RSHDSL | Z12: RSH-DSL | AA12: RSH | AB12: DEM | AD12: 1 | AE12: -0.24 | AF12: -0.13 | AG12: -0.01 | AH12: -0.01 | AI12: -0.03 | AM12: -0.01
C13: S_RSHELC | D13: RSH-ELC | E13: RSH | F13: DEM | H13: 1 | I13: -0.02 | J13: -0.04 | K13: -0.05 | L13: -0.08 | M13: -0.342 | N13: -0.2805 | O13: -0.18 | P13: -0.1 | Q13: -0.15 | R13: 0 | S13: 15 | T13: Residential Space Heating - ELC | Y13: S_RSHELC | Z13: RSH-ELC | AA13: RSH | AB13: DEM | AD13: 1 | AE13: -0.01 | AF13: -0.03 | AG13: -0.04 | AH13: -0.06 | AI13: -0.247 | AJ13: -0.204 | AK13: -0.135 | AL13: -0.07 | AM13: -0.11
C14: S_RSHLPG | D14: RSH-LPG | E14: RSH | F14: DEM | H14: 1 | I14: -0.02 | J14: -0.03 | K14: -0.06 | L14: -0.15 | M14: -0.04 | N14: -0.11 | O14: -0.06 | P14: -0.09 | Q14: -0.03 | R14: 0 | S14: 15 | T14: Residential Space Heating - LPG | Y14: S_RSHLPG | Z14: RSH-LPG | AA14: RSH | AB14: DEM | AD14: 1 | AE14: -0.01 | AF14: -0.02 | AG14: -0.03 | AH14: -0.08 | AI14: -0.02 | AJ14: -0.06 | AK14: -0.03 | AL14: -0.05 | AM14: -0.02
C15: S_RSHNG | D15: RSH-NG | E15: RSH | F15: DEM | H15: 1 | I15: -0.38 | J15: -0.6 | K15: -0.81 | L15: -0.65 | M15: -0.42 | N15: -0.43 | O15: -0.62 | P15: -0.73 | Q15: -0.66 | R15: 0 | S15: 15 | T15: Residential Space Heating - NG | Y15: S_RSHNG | Z15: RSH-NG | AA15: RSH | AB15: DEM | AD15: 1 | AE15: -0.28 | AF15: -0.44 | AG15: -0.59 | AH15: -0.47 | AI15: -0.31 | AJ15: -0.31 | AK15: -0.45 | AL15: -0.53 | AM15: -0.48
C16: S_RSHBIO | D16: RSH-BIO | E16: RSH | F16: DEM | G16: FX | H16: 1 | I16: -0.08 | J16: -0.04 | K16: -0.05 | L16: -0.08 | M16: -0.09 | N16: -0.12 | O16: -0.06 | P16: -0.06 | Q16: -0.13 | R16: 0 | S16: 15 | T16: Residential Space Heating - BIO | Y16: S_RSHBIO | Z16: RSH-BIO | AA16: RSH | AB16: DEM | AC16: FX | AD16: 1 | AE16: -0.06 | AF16: -0.03 | AG16: -0.04 | AH16: -0.06 | AI16: -0.07 | AJ16: -0.09 | AK16: -0.04 | AL16: -0.04 | AM16: -0.09
C17: S_RSHKER | D17: RSH-KER | E17: RSH | F17: DEM | H17: 1 | I17: -0.009 | J17: -0.011 | R17: 0 | S17: 15 | T17: Residential Space Heating - KER | Y17: S_RSHKER | Z17: RSH-KER | AA17: RSH | AB17: DEM | AD17: 1 | AE17: -0.005 | AF17: -0.006
C18: S_RSHFUR | D18: RSH-FUR | E18: RSH | F18: DEM | H18: 1 | I18: -0.37 | J18: -0.5 | K18: -0.8 | L18: -0.74 | M18: -0.45 | N18: -0.5 | O18: -0.57 | P18: -0.75 | Q18: -0.55 | R18: 0 | S18: 15 | T18: Residential Space Heating - Furnaces | Y18: S_RSHFUR | Z18: RSH-FUR | AA18: RSH | AB18: DEM | AD18: 1 | AE18: -0.27 | AF18: -0.37 | AG18: -0.58 | AH18: -0.54 | AI18: -0.33 | AJ18: -0.37 | AK18: -0.42 | AL18: -0.55 | AM18: -0.4
C19: S_RSHRD | D19: RSH-RD | E19: RSH | F19: DEM | H19: 1 | I19: -0.53 | J19: -0.42 | K19: -0.12 | L19: -0.14 | M19: -0.24 | N19: -0.21 | O19: -0.31 | P19: -0.12 | Q19: -0.28 | R19: 0 | S19: 15 | T19: Residential Space Heating - Radiant | Y19: S_RSHRD | Z19: RSH-RD | AA19: RSH | AB19: DEM | AD19: 1 | AE19: -0.39 | AF19: -0.31 | AG19: -0.09 | AH19: -0.1 | AI19: -0.18 | AJ19: -0.15 | AK19: -0.23 | AL19: -0.09 | AM19: -0.2
C20: S_RWHDSL | D20: RWH-DSL | E20: RWH | F20: DEM | H20: 1 | I20: -0.3 | J20: -0.11 | R20: 0 | S20: 15 | T20: Residential Water Heating - DSL | Y20: S_RWHDSL | Z20: RWH-DSL | AA20: RWH | AB20: DEM | AD20: 1 | AE20: -0.08 | AF20: -0.03
C21: S_RWHELC | D21: RWH-ELC | E21: RWH | F21: DEM | H21: 1 | I21: -0.16 | J21: -0.16 | K21: -0.19 | L21: -0.25 | M21: -0.59 | N21: -0.56 | O21: -0.38 | P21: -0.23 | Q21: -0.22 | R21: 0 | S21: 15 | T21: Residential Water Heating - ELC | Y21: S_RWHELC | Z21: RWH-ELC | AA21: RWH | AB21: DEM | AD21: 1 | AE21: -0.12 | AF21: -0.12 | AG21: -0.14 | AH21: -0.18 | AI21: -0.43 | AJ21: -0.41 | AK21: -0.28 | AL21: -0.17 | AM21: -0.16
C22: S_RWHLPG | D22: RWH-LPG | E22: RWH | F22: DEM | H22: 1 | I22: -0.03 | J22: -0.03 | K22: -0.05 | L22: -0.07 | M22: -0.03 | N22: -0.04 | O22: -0.05 | P22: -0.07 | Q22: -0.04 | R22: 0 | S22: 15 | T22: Residential Water Heating - LPG | Y22: S_RWHLPG | Z22: RWH-LPG | AA22: RWH | AB22: DEM | AD22: 1 | AE22: -0.02 | AF22: -0.02 | AG22: -0.03 | AH22: -0.04 | AI22: -0.02 | AJ22: -0.02 | AK22: -0.03 | AL22: -0.04 | AM22: -0.02
C23: S_RWHNG | D23: RWH-NG | E23: RWH | F23: DEM | H23: 1 | I23: -0.49 | J23: -0.67 | K23: -0.75 | L23: -0.66 | M23: -0.36 | N23: -0.38 | O23: -0.55 | P23: -0.68 | Q23: -0.72 | R23: 0 | S23: 15 | T23: Residential Water Heating - NG | Y23: S_RWHNG | Z23: RWH-NG | AA23: RWH | AB23: DEM | AD23: 1 | AE23: -0.36 | AF23: -0.49 | AG23: -0.55 | AH23: -0.48 | AI23: -0.26 | AJ23: -0.28 | AK23: -0.4 | AL23: -0.5 | AM23: -0.53
C24: S_RSCNG | D24: RSC-NG | E24: RSC | F24: DEM | H24: 1 | I24: 0 | J24: 0 | K24: 0 | L24: -0.01 | M24: -0.01 | N24: -0.01 | O24: 0 | P24: -0.01 | Q24: 0 | R24: 0 | S24: 15 | T24: Residential Space Cooling - Natural Gas | Y24: S_RSCNG | Z24: RSC-NG | AA24: RSC | AB24: DEM | AD24: 1 | AE24: 0 | AF24: 0 | AG24: 0 | AH24: -0.01 | AI24: -0.01 | AJ24: -0.01 | AK24: 0 | AL24: -0.01 | AM24: 0
C25: S_RSCHP | D25: RSC-HP | E25: RSC | F25: DEM | H25: 1 | I25: -0.01 | J25: -0.04 | K25: -0.03 | L25: -0.05 | M25: -0.29 | N25: -0.22 | O25: -0.05 | P25: -0.16 | Q25: -0.07 | R25: 0 | S25: 15 | T25: Residential Space Cooling - Central Heat Pump | Y25: S_RSCHP | Z25: RSC-HP | AA25: RSC | AB25: DEM | AD25: 1 | AE25: -0.01 | AF25: -0.03 | AG25: -0.02 | AH25: -0.04 | AI25: -0.21 | AJ25: -0.16 | AK25: -0.04 | AL25: -0.12 | AM25: -0.05
C26: S_RSCCAC | D26: RSC-CEN | E26: RSC | F26: DEM | H26: 1 | I26: -0.48 | J26: -0.63 | K26: -0.81 | L26: -0.87 | M26: -0.63 | N26: -0.7 | O26: -0.83 | P26: -0.79 | Q26: -0.78 | R26: 0 | S26: 15 | T26: Residential Space Cooling - Central AC | Y26: S_RSCCAC | Z26: RSC-CEN | AA26: RSC | AB26: DEM | AD26: 1 | AE26: -0.35 | AF26: -0.46 | AG26: -0.59 | AH26: -0.64 | AI26: -0.46 | AJ26: -0.51 | AK26: -0.61 | AL26: -0.58 | AM26: -0.57
C27: S_RSCRAC | D27: RSC-RAC | E27: RSC | F27: DEM | H27: 1 | I27: -0.5 | J27: -0.31 | K27: -0.14 | L27: -0.06 | M27: -0.06 | N27: -0.06 | O27: -0.1 | P27: -0.03 | Q27: -0.13 | R27: 0 | S27: 15 | T27: Residential Space Cooling - Room AC | Y27: S_RSCRAC | Z27: RSC-RAC | AA27: RSC | AB27: DEM | AD27: 1 | AE27: -0.37 | AF27: -0.23 | AG27: -0.1 | AH27: -0.04 | AI27: -0.04 | AJ27: -0.04 | AK27: -0.07 | AL27: -0.02 | AM27: -0.09
C28: S_RLTINC | D28: RLT-INC | E28: RLT | F28: DEM | H28: 1 | I28: -0.49 | J28: -0.49 | K28: -0.49 | L28: -0.49 | M28: -0.49 | N28: -0.49 | O28: -0.49 | P28: -0.49 | Q28: -0.49 | R28: 0 | S28: 15 | T28: Residential Lighting - Incandescent | Y28: S_RLTINC | Z28: RLT-INC | AA28: RLT | AB28: DEM | AD28: 1 | AE28: -0.05 | AF28: -0.05 | AG28: -0.05 | AH28: -0.05 | AI28: -0.05 | AJ28: -0.05 | AK28: -0.05 | AL28: -0.05 | AM28: -0.05
C29: S_RLTCFL | D29: RLT-CFL | E29: RLT | F29: DEM | H29: 1 | I29: -0.26 | J29: -0.26 | K29: -0.26 | L29: -0.26 | M29: -0.26 | N29: -0.26 | O29: -0.26 | P29: -0.26 | Q29: -0.26 | R29: 0 | S29: 15 | T29: Residential Lighting - Compact Fluorescent | Y29: S_RLTCFL | Z29: RLT-CFL | AA29: RLT | AB29: DEM | AD29: 1 | AE29: -0.19 | AF29: -0.19 | AG29: -0.19 | AH29: -0.19 | AI29: -0.19 | AJ29: -0.19 | AK29: -0.19 | AL29: -0.19 | AM29: -0.19
C30: S_RLTLFL | D30: RLT-LFL | E30: RLT | F30: DEM | H30: 1 | I30: -0.18 | J30: -0.18 | K30: -0.18 | L30: -0.18 | M30: -0.18 | N30: -0.18 | O30: -0.18 | P30: -0.18 | Q30: -0.18 | R30: 0 | S30: 15 | T30: Residential Lighting - Linear Fluorescent | Y30: S_RLTLFL | Z30: RLT-LFL | AA30: RLT | AB30: DEM | AD30: 1 | AE30: -0.13 | AF30: -0.13 | AG30: -0.13 | AH30: -0.13 | AI30: -0.13 | AJ30: -0.13 | AK30: -0.13 | AL30: -0.13 | AM30: -0.13
C31: S_RLTREF | D31: RLT-REF | E31: RLT | F31: DEM | H31: 1 | I31: -0.08 | J31: -0.08 | K31: -0.08 | L31: -0.08 | M31: -0.08 | N31: -0.08 | O31: -0.08 | P31: -0.08 | Q31: -0.08 | R31: 0 | S31: 15 | T31: Residential Lighting - Reflector | Y31: S_RLTREF | Z31: RLT-REF | AA31: RLT | AB31: DEM | AD31: 1 | AE31: -0.08 | AF31: -0.08 | AG31: -0.08 | AH31: -0.08 | AI31: -0.08 | AJ31: -0.08 | AK31: -0.08 | AL31: -0.08 | AM31: -0.08
C32: S_RLTEXT | D32: RLT-EXT | E32: RLT | F32: DEM | H32: 1 | I32: -0.04 | J32: -0.04 | K32: -0.04 | L32: -0.04 | M32: -0.04 | N32: -0.04 | O32: -0.04 | P32: -0.04 | Q32: -0.04 | R32: 0 | S32: 15 | T32: Residential Lighting - Exterior | Y32: S_RLTEXT | Z32: RLT-EXT | AA32: RLT | AB32: DEM | AD32: 1 | AE32: -0.04 | AF32: -0.04 | AG32: -0.04 | AH32: -0.04 | AI32: -0.04 | AJ32: -0.04 | AK32: -0.04 | AL32: -0.04 | AM32: -0.04
C33: S_RLTGSL | D33: RLT-GSL | E33: RLT | F33: DEM | H33: 1 | I33: -0.68 | J33: -0.68 | K33: -0.68 | L33: -0.68 | M33: -0.68 | N33: -0.68 | O33: -0.68 | P33: -0.68 | Q33: -0.68 | R33: 0 | S33: 15 | T33: Residential Lighting - General Services | Y33: S_RLTGSL | Z33: RLT-GSL | AA33: RLT | AB33: DEM | AD33: 1 | AE33: -0.68 | AF33: -0.68 | AG33: -0.68 | AH33: -0.68 | AI33: -0.68 | AJ33: -0.68 | AK33: -0.68 | AL33: -0.68 | AM33: -0.68

Sheet ComConstr
C1: =C16+C17+C18+C19 -> 1.336402 | D1: =D16+D17+D18+D19 -> 1.1839754 | E1: =E16+E17+E18+E19 -> 0.99219108 | F1: =F16+F17+F18+F19 -> 0.96189379 | G1: =G16+G17+G18+G19 -> 0.83059198 | H1: =H16+H17+H18+H19 -> 0.86957444 | I1: =I16+I17+I18+I19 -> 0.9056518 | J1: =J16+J17+J18+J19 -> 0.95334022 | K1: =K16+K17+K18+K19 -> 0.88958916
A2: UC_N | B2: PSET_SET | C2: R1 | D2: R2 | E2: R3 | F2: R4 | G2: R5 | H2: R6 | I2: R7 | J2: R8 | K2: R9 | N2: R1 | O2: R2 | P2: R3 | Q2: R4 | R2: R5 | S2: R6 | T2: R7 | U2: R8 | V2: R9
A3: S_CSCELC | B3: CSC-ELC | C3: =(SUMIFS('COM results'!$G:$G,'COM results'!$D:$D,"CSC",'COM results'!$F:$F,C$2,'COM results'!$A:$A,"AHP",'COM results'!$B:$B,"VAR_Fout")+SUMIFS('COM results'!$G:$G,'COM results'!$D:$D,"CSC",'COM results'!$F:$F,C$2,'COM results'!$A:$A,"GHP",'COM results'!$B:$B,"VAR_Fout")+SUMIFS('COM results'!$G:$G,'COM results'!$D:$D,"CSC",'COM results'!$F:$F,C$2,'COM results'!$A:$A,"CSC",'COM results'!$B:$B,"VAR_Fout")+SUMIFS('COM results'!$G:$G,'COM results'!$D:$D,"CSC",'COM results'!$F:$F,C$2,'COM results'!$A:$A,"CSW",'COM results'!$B:$B,"VAR_Fout")+SUMIFS('COM results'!$G:$G,'COM results'!$D:$D,"CSC",'COM results'!$F:$F,C$2,'COM results'!$A:$A,"CRC",'COM results'!$B:$B,"VAR_Fout")+SUMIFS('COM results'!$G:$G,'COM results'!$D:$D,"CSC",'COM results'!$F:$F,C$2,'COM results'!$A:$A,"CCC",'COM results'!$B:$B,"VAR_Fout")+SUMIFS('COM results'!$G:$G,'COM results'!$D:$D,"CSC",'COM results'!$F:$F,C$2,'COM results'!$A:$A,"RAC",'COM results'!$B:$B,"VAR_Fout")+SUMIFS('COM results'!$G:$G,'COM results'!$D:$D,"CSC",'COM results'!$F:$F,C$2,'COM results'!$A:$A,"WAC",'COM results'!$B:$B,"VAR_Fout")+SUMIFS('COM results'!$G:$G,'COM results'!$D:$D,"CSC",'COM results'!$F:$F,C$2,'COM results'!$A:$A,"CAC",'COM results'!$B:$B,"VAR_Fout"))/N3 -> 0.97198144 | D3: =(SUMIFS('COM results'!$G:$G,'COM results'!$D:$D,"CSC",'COM results'!$F:$F,D$2,'COM results'!$A:$A,"AHP",'COM results'!$B:$B,"VAR_Fout")+SUMIFS('COM results'!$G:$G,'COM results'!$D:$D,"CSC",'COM results'!$F:$F,D$2,'COM results'!$A:$A,"GHP",'COM results'!$B:$B,"VAR_Fout")+SUMIFS('COM results'!$G:$G,'COM results'!$D:$D,"CSC",'COM results'!$F:$F,D$2,'COM results'!$A:$A,"CSC",'COM results'!$B:$B,"VAR_Fout")+SUMIFS('COM results'!$G:$G,'COM results'!$D:$D,"CSC",'COM results'!$F:$F,D$2,'COM results'!$A:$A,"CSW",'COM results'!$B:$B,"VAR_Fout")+SUMIFS('COM results'!$G:$G,'COM results'!$D:$D,"CSC",'COM results'!$F:$F,D$2,'COM results'!$A:$A,"CRC",'COM results'!$B:$B,"VAR_Fout")+SUMIFS('COM results'!$G:$G,'COM results'!$D:$D,"CSC",'COM results'!$F:$F,D$2,'COM results'!$A:$A,"CCC",'COM results'!$B:$B,"VAR_Fout")+SUMIFS('COM results'!$G:$G,'COM results'!$D:$D,"CSC",'COM results'!$F:$F,D$2,'COM results'!$A:$A,"RAC",'COM results'!$B:$B,"VAR_Fout")+SUMIFS('COM results'!$G:$G,'COM results'!$D:$D,"CSC",'COM results'!$F:$F,D$2,'COM results'!$A:$A,"WAC",'COM results'!$B:$B,"VAR_Fout")+SUMIFS('COM results'!$G:$G,'COM results'!$D:$D,"CSC",'COM results'!$F:$F,D$2,'COM results'!$A:$A,"CAC",'COM results'!$B:$B,"VAR_Fout"))/O3 -> 0.98037407 | E3: =(SUMIFS('COM results'!$G:$G,'COM results'!$D:$D,"CSC",'COM results'!$F:$F,E$2,'COM results'!$A:$A,"AHP",'COM results'!$B:$B,"VAR_Fout")+SUMIFS('COM results'!$G:$G,'COM results'!$D:$D,"CSC",'COM results'!$F:$F,E$2,'COM results'!$A:$A,"GHP",'COM results'!$B:$B,"VAR_Fout")+SUMIFS('COM results'!$G:$G,'COM results'!$D:$D,"CSC",'COM results'!$F:$F,E$2,'COM results'!$A:$A,"CSC",'COM results'!$B:$B,"VAR_Fout")+SUMIFS('COM results'!$G:$G,'COM results'!$D:$D,"CSC",'COM results'!$F:$F,E$2,'COM results'!$A:$A,"CSW",'COM results'!$B:$B,"VAR_Fout")+SUMIFS('COM results'!$G:$G,'COM results'!$D:$D,"CSC",'COM results'!$F:$F,E$2,'COM results'!$A:$A,"CRC",'COM results'!$B:$B,"VAR_Fout")+SUMIFS('COM results'!$G:$G,'COM results'!$D:$D,"CSC",'COM results'!$F:$F,E$2,'COM results'!$A:$A,"CCC",'COM results'!$B:$B,"VAR_Fout")+SUMIFS('COM results'!$G:$G,'COM results'!$D:$D,"CSC",'COM results'!$F:$F,E$2,'COM results'!$A:$A,"RAC",'COM results'!$B:$B,"VAR_Fout")+SUMIFS('COM results'!$G:$G,'COM results'!$D:$D,"CSC",'COM results'!$F:$F,E$2,'COM results'!$A:$A,"WAC",'COM results'!$B:$B,"VAR_Fout")+SUMIFS('COM results'!$G:$G,'COM results'!$D:$D,"CSC",'COM results'!$F:$F,E$2,'COM results'!$A:$A,"CAC",'COM results'!$B:$B,"VAR_Fout"))/P3 -> 0.97473064 | F3: =(SUMIFS('COM results'!$G:$G,'COM results'!$D:$D,"CSC",'COM results'!$F:$F,F$2,'COM results'!$A:$A,"AHP",'COM results'!$B:$B,"VAR_Fout")+SUMIFS('COM results'!$G:$G,'COM results'!$D:$D,"CSC",'COM results'!$F:$F,F$2,'COM results'!$A:$A,"GHP",'COM results'!$B:$B,"VAR_Fout")+SUMIFS('COM results'!$G:$G,'COM results'!$D:$D,"CSC",'COM results'!$F:$F,F$2,'COM results'!$A:$A,"CSC",'COM results'!$B:$B,"VAR_Fout")+SUMIFS('COM results'!$G:$G,'COM results'!$D:$D,"CSC",'COM results'!$F:$F,F$2,'COM results'!$A:$A,"CSW",'COM results'!$B:$B,"VAR_Fout")+SUMIFS('COM results'!$G:$G,'COM results'!$D:$D,"CSC",'COM results'!$F:$F,F$2,'COM results'!$A:$A,"CRC",'COM results'!$B:$B,"VAR_Fout")+SUMIFS('COM results'!$G:$G,'COM results'!$D:$D,"CSC",'COM results'!$F:$F,F$2,'COM results'!$A:$A,"CCC",'COM results'!$B:$B,"VAR_Fout")+SUMIFS('COM results'!$G:$G,'COM results'!$D:$D,"CSC",'COM results'!$F:$F,F$2,'COM results'!$A:$A,"RAC",'COM results'!$B:$B,"VAR_Fout")+SUMIFS('COM results'!$G:$G,'COM results'!$D:$D,"CSC",'COM results'!$F:$F,F$2,'COM results'!$A:$A,"WAC",'COM results'!$B:$B,"VAR_Fout")+SUMIFS('COM results'!$G:$G,'COM results'!$D:$D,"CSC",'COM results'!$F:$F,F$2,'COM results'!$A:$A,"CAC",'COM results'!$B:$B,"VAR_Fout"))/Q3 -> 0.99892888 | G3: =(SUMIFS('COM results'!$G:$G,'COM results'!$D:$D,"CSC",'COM results'!$F:$F,G$2,'COM results'!$A:$A,"AHP",'COM results'!$B:$B,"VAR_Fout")+SUMIFS('COM results'!$G:$G,'COM results'!$D:$D,"CSC",'COM results'!$F:$F,G$2,'COM results'!$A:$A,"GHP",'COM results'!$B:$B,"VAR_Fout")+SUMIFS('COM results'!$G:$G,'COM results'!$D:$D,"CSC",'COM results'!$F:$F,G$2,'COM results'!$A:$A,"CSC",'COM results'!$B:$B,"VAR_Fout")+SUMIFS('COM results'!$G:$G,'COM results'!$D:$D,"CSC",'COM results'!$F:$F,G$2,'COM results'!$A:$A,"CSW",'COM results'!$B:$B,"VAR_Fout")+SUMIFS('COM results'!$G:$G,'COM results'!$D:$D,"CSC",'COM results'!$F:$F,G$2,'COM results'!$A:$A,"CRC",'COM results'!$B:$B,"VAR_Fout")+SUMIFS('COM results'!$G:$G,'COM results'!$D:$D,"CSC",'COM results'!$F:$F,G$2,'COM results'!$A:$A,"CCC",'COM results'!$B:$B,"VAR_Fout")+SUMIFS('COM results'!$G:$G,'COM results'!$D:$D,"CSC",'COM results'!$F:$F,G$2,'COM results'!$A:$A,"RAC",'COM results'!$B:$B,"VAR_Fout")+SUMIFS('COM results'!$G:$G,'COM results'!$D:$D,"CSC",'COM results'!$F:$F,G$2,'COM results'!$A:$A,"WAC",'COM results'!$B:$B,"VAR_Fout")+SUMIFS('COM results'!$G:$G,'COM results'!$D:$D,"CSC",'COM results'!$F:$F,G$2,'COM results'!$A:$A,"CAC",'COM results'!$B:$B,"VAR_Fout"))/R3 -> 0.99606418 | H3: =(SUMIFS('COM results'!$G:$G,'COM results'!$D:$D,"CSC",'COM results'!$F:$F,H$2,'COM results'!$A:$A,"AHP",'COM results'!$B:$B,"VAR_Fout")+SUMIFS('COM results'!$G:$G,'COM results'!$D:$D,"CSC",'COM results'!$F:$F,H$2,'COM results'!$A:$A,"GHP",'COM results'!$B:$B,"VAR_Fout")+SUMIFS('COM results'!$G:$G,'COM results'!$D:$D,"CSC",'COM results'!$F:$F,H$2,'COM results'!$A:$A,"CSC",'COM results'!$B:$B,"VAR_Fout")+SUMIFS('COM results'!$G:$G,'COM results'!$D:$D,"CSC",'COM results'!$F:$F,H$2,'COM results'!$A:$A,"CSW",'COM results'!$B:$B,"VAR_Fout")+SUMIFS('COM results'!$G:$G,'COM results'!$D:$D,"CSC",'COM results'!$F:$F,H$2,'COM results'!$A:$A,"CRC",'COM results'!$B:$B,"VAR_Fout")+SUMIFS('COM results'!$G:$G,'COM results'!$D:$D,"CSC",'COM results'!$F:$F,H$2,'COM results'!$A:$A,"CCC",'COM results'!$B:$B,"VAR_Fout")+SUMIFS('COM results'!$G:$G,'COM results'!$D:$D,"CSC",'COM results'!$F:$F,H$2,'COM results'!$A:$A,"RAC",'COM results'!$B:$B,"VAR_Fout")+SUMIFS('COM results'!$G:$G,'COM results'!$D:$D,"CSC",'COM results'!$F:$F,H$2,'COM results'!$A:$A,"WAC",'COM results'!$B:$B,"VAR_Fout")+SUMIFS('COM results'!$G:$G,'COM results'!$D:$D,"CSC",'COM results'!$F:$F,H$2,'COM results'!$A:$A,"CAC",'COM results'!$B:$B,"VAR_Fout"))/S3 -> 0.99186482 | I3: =(SUMIFS('COM results'!$G:$G,'COM results'!$D:$D,"CSC",'COM results'!$F:$F,I$2,'COM results'!$A:$A,"AHP",'COM results'!$B:$B,"VAR_Fout")+SUMIFS('COM results'!$G:$G,'COM results'!$D:$D,"CSC",'COM results'!$F:$F,I$2,'COM results'!$A:$A,"GHP",'COM results'!$B:$B,"VAR_Fout")+SUMIFS('COM results'!$G:$G,'COM results'!$D:$D,"CSC",'COM results'!$F:$F,I$2,'COM results'!$A:$A,"CSC",'COM results'!$B:$B,"VAR_Fout")+SUMIFS('COM results'!$G:$G,'COM results'!$D:$D,"CSC",'COM results'!$F:$F,I$2,'COM results'!$A:$A,"CSW",'COM results'!$B:$B,"VAR_Fout")+SUMIFS('COM results'!$G:$G,'COM results'!$D:$D,"CSC",'COM results'!$F:$F,I$2,'COM results'!$A:$A,"CRC",'COM results'!$B:$B,"VAR_Fout")+SUMIFS('COM results'!$G:$G,'COM results'!$D:$D,"CSC",'COM results'!$F:$F,I$2,'COM results'!$A:$A,"CCC",'COM results'!$B:$B,"VAR_Fout")+SUMIFS('COM results'!$G:$G,'COM results'!$D:$D,"CSC",'COM results'!$F:$F,I$2,'COM results'!$A:$A,"RAC",'COM results'!$B:$B,"VAR_Fout")+SUMIFS('COM results'!$G:$G,'COM results'!$D:$D,"CSC",'COM results'!$F:$F,I$2,'COM results'!$A:$A,"WAC",'COM results'!$B:$B,"VAR_Fout")+SUMIFS('COM results'!$G:$G,'COM results'!$D:$D,"CSC",'COM results'!$F:$F,I$2,'COM results'!$A:$A,"CAC",'COM results'!$B:$B,"VAR_Fout"))/T3 -> 0.99874203 | J3: =(SUMIFS('COM results'!$G:$G,'COM results'!$D:$D,"CSC",'COM results'!$F:$F,J$2,'COM results'!$A:$A,"AHP",'COM results'!$B:$B,"VAR_Fout")+SUMIFS('COM results'!$G:$G,'COM results'!$D:$D,"CSC",'COM results'!$F:$F,J$2,'COM results'!$A:$A,"GHP",'COM results'!$B:$B,"VAR_Fout")+SUMIFS('COM results'!$G:$G,'COM results'!$D:$D,"CSC",'COM results'!$F:$F,J$2,'COM results'!$A:$A,"CSC",'COM results'!$B:$B,"VAR_Fout")+SUMIFS('COM results'!$G:$G,'COM results'!$D:$D,"CSC",'COM results'!$F:$F,J$2,'COM results'!$A:$A,"CSW",'COM results'!$B:$B,"VAR_Fout")+SUMIFS('COM results'!$G:$G,'COM results'!$D:$D,"CSC",'COM results'!$F:$F,J$2,'COM results'!$A:$A,"CRC",'COM results'!$B:$B,"VAR_Fout")+SUMIFS('COM results'!$G:$G,'COM results'!$D:$D,"CSC",'COM results'!$F:$F,J$2,'COM results'!$A:$A,"CCC",'COM results'!$B:$B,"VAR_Fout")+SUMIFS('COM results'!$G:$G,'COM results'!$D:$D,"CSC",'COM results'!$F:$F,J$2,'COM results'!$A:$A,"RAC",'COM results'!$B:$B,"VAR_Fout")+SUMIFS('COM results'!$G:$G,'COM results'!$D:$D,"CSC",'COM results'!$F:$F,J$2,'COM results'!$A:$A,"WAC",'COM results'!$B:$B,"VAR_Fout")+SUMIFS('COM results'!$G:$G,'COM results'!$D:$D,"CSC",'COM results'!$F:$F,J$2,'COM results'!$A:$A,"CAC",'COM results'!$B:$B,"VAR_Fout"))/U3 -> 0.98436739 | K3: =(SUMIFS('COM results'!$G:$G,'COM results'!$D:$D,"CSC",'COM results'!$F:$F,K$2,'COM results'!$A:$A,"AHP",'COM results'!$B:$B,"VAR_Fout")+SUMIFS('COM results'!$G:$G,'COM results'!$D:$D,"CSC",'COM results'!$F:$F,K$2,'COM results'!$A:$A,"GHP",'COM results'!$B:$B,"VAR_Fout")+SUMIFS('COM results'!$G:$G,'COM results'!$D:$D,"CSC",'COM results'!$F:$F,K$2,'COM results'!$A:$A,"CSC",'COM results'!$B:$B,"VAR_Fout")+SUMIFS('COM results'!$G:$G,'COM results'!$D:$D,"CSC",'COM results'!$F:$F,K$2,'COM results'!$A:$A,"CSW",'COM results'!$B:$B,"VAR_Fout")+SUMIFS('COM results'!$G:$G,'COM results'!$D:$D,"CSC",'COM results'!$F:$F,K$2,'COM results'!$A:$A,"CRC",'COM results'!$B:$B,"VAR_Fout")+SUMIFS('COM results'!$G:$G,'COM results'!$D:$D,"CSC",'COM results'!$F:$F,K$2,'COM results'!$A:$A,"CCC",'COM results'!$B:$B,"VAR_Fout")+SUMIFS('COM results'!$G:$G,'COM results'!$D:$D,"CSC",'COM results'!$F:$F,K$2,'COM results'!$A:$A,"RAC",'COM results'!$B:$B,"VAR_Fout")+SUMIFS('COM results'!$G:$G,'COM results'!$D:$D,"CSC",'COM results'!$F:$F,K$2,'COM results'!$A:$A,"WAC",'COM results'!$B:$B,"VAR_Fout")+SUMIFS('COM results'!$G:$G,'COM results'!$D:$D,"CSC",'COM results'!$F:$F,K$2,'COM results'!$A:$A,"CAC",'COM results'!$B:$B,"VAR_Fout"))/V3 -> 0.99564634 | M3: CSC | N3: =SUMIFS('COM results'!$G:$G,'COM results'!$D:$D,$M3,'COM results'!$F:$F,N$2,'COM results'!$B:$B,"VAR_Fout") -> 34.718519 | O3: =SUMIFS('COM results'!$G:$G,'COM results'!$D:$D,$M3,'COM results'!$F:$F,O$2,'COM results'!$B:$B,"VAR_Fout") -> 164.33822 | P3: =SUMIFS('COM results'!$G:$G,'COM results'!$D:$D,$M3,'COM results'!$F:$F,P$2,'COM results'!$B:$B,"VAR_Fout") -> 175.94294 | Q3: =SUMIFS('COM results'!$G:$G,'COM results'!$D:$D,$M3,'COM results'!$F:$F,Q$2,'COM results'!$B:$B,"VAR_Fout") -> 95.974842 | R3: =SUMIFS('COM results'!$G:$G,'COM results'!$D:$D,$M3,'COM results'!$F:$F,R$2,'COM results'!$B:$B,"VAR_Fout") -> 640.49585 | S3: =SUMIFS('COM results'!$G:$G,'COM results'!$D:$D,$M3,'COM results'!$F:$F,S$2,'COM results'!$B:$B,"VAR_Fout") -> 151.86447 | T3: =SUMIFS('COM results'!$G:$G,'COM results'!$D:$D,$M3,'COM results'!$F:$F,T$2,'COM results'!$B:$B,"VAR_Fout") -> 446.54527 | U3: =SUMIFS('COM results'!$G:$G,'COM results'!$D:$D,$M3,'COM results'!$F:$F,U$2,'COM results'!$B:$B,"VAR_Fout") -> 110.09751 | V3: =SUMIFS('COM results'!$G:$G,'COM results'!$D:$D,$M3,'COM results'!$F:$F,V$2,'COM results'!$B:$B,"VAR_Fout") -> 136.21117
A4: S_CSCNG | B4: CSC-NG | C4: =(SUMIFS('COM results'!$G:$G,'COM results'!$D:$D,"CSC",'COM results'!$F:$F,C$2,'COM results'!$A:$A,"NHP",'COM results'!$B:$B,"VAR_Fout")+SUMIFS('COM results'!$G:$G,'COM results'!$D:$D,"CSC",'COM results'!$F:$F,C$2,'COM results'!$A:$A,"NRC",'COM results'!$B:$B,"VAR_Fout")+SUMIFS('COM results'!$G:$G,'COM results'!$D:$D,"CSC",'COM results'!$F:$F,C$2,'COM results'!$A:$A,"CHA",'COM results'!$B:$B,"VAR_Fout")+SUMIFS('COM results'!$G:$G,'COM results'!$D:$D,"CSC",'COM results'!$F:$F,C$2,'COM results'!$A:$A,"CHE",'COM results'!$B:$B,"VAR_Fout"))/N3 -> 0.028018562 | D4: =(SUMIFS('COM results'!$G:$G,'COM results'!$D:$D,"CSC",'COM results'!$F:$F,D$2,'COM results'!$A:$A,"NHP",'COM results'!$B:$B,"VAR_Fout")+SUMIFS('COM results'!$G:$G,'COM results'!$D:$D,"CSC",'COM results'!$F:$F,D$2,'COM results'!$A:$A,"NRC",'COM results'!$B:$B,"VAR_Fout")+SUMIFS('COM results'!$G:$G,'COM results'!$D:$D,"CSC",'COM results'!$F:$F,D$2,'COM results'!$A:$A,"CHA",'COM results'!$B:$B,"VAR_Fout")+SUMIFS('COM results'!$G:$G,'COM results'!$D:$D,"CSC",'COM results'!$F:$F,D$2,'COM results'!$A:$A,"CHE",'COM results'!$B:$B,"VAR_Fout"))/O3 -> 0.01962593 | E4: =(SUMIFS('COM results'!$G:$G,'COM results'!$D:$D,"CSC",'COM results'!$F:$F,E$2,'COM results'!$A:$A,"NHP",'COM results'!$B:$B,"VAR_Fout")+SUMIFS('COM results'!$G:$G,'COM results'!$D:$D,"CSC",'COM results'!$F:$F,E$2,'COM results'!$A:$A,"NRC",'COM results'!$B:$B,"VAR_Fout")+SUMIFS('COM results'!$G:$G,'COM results'!$D:$D,"CSC",'COM results'!$F:$F,E$2,'COM results'!$A:$A,"CHA",'COM results'!$B:$B,"VAR_Fout")+SUMIFS('COM results'!$G:$G,'COM results'!$D:$D,"CSC",'COM results'!$F:$F,E$2,'COM results'!$A:$A,"CHE",'COM results'!$B:$B,"VAR_Fout"))/P3 -> 0.025269357 | F4: =(SUMIFS('COM results'!$G:$G,'COM results'!$D:$D,"CSC",'COM results'!$F:$F,F$2,'COM results'!$A:$A,"NHP",'COM results'!$B:$B,"VAR_Fout")+SUMIFS('COM results'!$G:$G,'COM results'!$D:$D,"CSC",'COM results'!$F:$F,F$2,'COM results'!$A:$A,"NRC",'COM results'!$B:$B,"VAR_Fout")+SUMIFS('COM results'!$G:$G,'COM results'!$D:$D,"CSC",'COM results'!$F:$F,F$2,'COM results'!$A:$A,"CHA",'COM results'!$B:$B,"VAR_Fout")+SUMIFS('COM results'!$G:$G,'COM results'!$D:$D,"CSC",'COM results'!$F:$F,F$2,'COM results'!$A:$A,"CHE",'COM results'!$B:$B,"VAR_Fout"))/Q3 -> 0.0010711173 | G4: =(SUMIFS('COM results'!$G:$G,'COM results'!$D:$D,"CSC",'COM results'!$F:$F,G$2,'COM results'!$A:$A,"NHP",'COM results'!$B:$B,"VAR_Fout")+SUMIFS('COM results'!$G:$G,'COM results'!$D:$D,"CSC",'COM results'!$F:$F,G$2,'COM results'!$A:$A,"NRC",'COM results'!$B:$B,"VAR_Fout")+SUMIFS('COM results'!$G:$G,'COM results'!$D:$D,"CSC",'COM results'!$F:$F,G$2,'COM results'!$A:$A,"CHA",'COM results'!$B:$B,"VAR_Fout")+SUMIFS('COM results'!$G:$G,'COM results'!$D:$D,"CSC",'COM results'!$F:$F,G$2,'COM results'!$A:$A,"CHE",'COM results'!$B:$B,"VAR_Fout"))/R3 -> 0.0039358244 | H4: =(SUMIFS('COM results'!$G:$G,'COM results'!$D:$D,"CSC",'COM results'!$F:$F,H$2,'COM results'!$A:$A,"NHP",'COM results'!$B:$B,"VAR_Fout")+SUMIFS('COM results'!$G:$G,'COM results'!$D:$D,"CSC",'COM results'!$F:$F,H$2,'COM results'!$A:$A,"NRC",'COM results'!$B:$B,"VAR_Fout")+SUMIFS('COM results'!$G:$G,'COM results'!$D:$D,"CSC",'COM results'!$F:$F,H$2,'COM results'!$A:$A,"CHA",'COM results'!$B:$B,"VAR_Fout")+SUMIFS('COM results'!$G:$G,'COM results'!$D:$D,"CSC",'COM results'!$F:$F,H$2,'COM results'!$A:$A,"CHE",'COM results'!$B:$B,"VAR_Fout"))/S3 -> 0.0081351778 | I4: =(SUMIFS('COM results'!$G:$G,'COM results'!$D:$D,"CSC",'COM results'!$F:$F,I$2,'COM results'!$A:$A,"NHP",'COM results'!$B:$B,"VAR_Fout")+SUMIFS('COM results'!$G:$G,'COM results'!$D:$D,"CSC",'COM results'!$F:$F,I$2,'COM results'!$A:$A,"NRC",'COM results'!$B:$B,"VAR_Fout")+SUMIFS('COM results'!$G:$G,'COM results'!$D:$D,"CSC",'COM results'!$F:$F,I$2,'COM results'!$A:$A,"CHA",'COM results'!$B:$B,"VAR_Fout")+SUMIFS('COM results'!$G:$G,'COM results'!$D:$D,"CSC",'COM results'!$F:$F,I$2,'COM results'!$A:$A,"CHE",'COM results'!$B:$B,"VAR_Fout"))/T3 -> 0.0012579701 | J4: =(SUMIFS('COM results'!$G:$G,'COM results'!$D:$D,"CSC",'COM results'!$F:$F,J$2,'COM results'!$A:$A,"NHP",'COM results'!$B:$B,"VAR_Fout")+SUMIFS('COM results'!$G:$G,'COM results'!$D:$D,"CSC",'COM results'!$F:$F,J$2,'COM results'!$A:$A,"NRC",'COM results'!$B:$B,"VAR_Fout")+SUMIFS('COM results'!$G:$G,'COM results'!$D:$D,"CSC",'COM results'!$F:$F,J$2,'COM results'!$A:$A,"CHA",'COM results'!$B:$B,"VAR_Fout")+SUMIFS('COM results'!$G:$G,'COM results'!$D:$D,"CSC",'COM results'!$F:$F,J$2,'COM results'!$A:$A,"CHE",'COM results'!$B:$B,"VAR_Fout"))/U3 -> 0.015632613 | K4: =(SUMIFS('COM results'!$G:$G,'COM results'!$D:$D,"CSC",'COM results'!$F:$F,K$2,'COM results'!$A:$A,"NHP",'COM results'!$B:$B,"VAR_Fout")+SUMIFS('COM results'!$G:$G,'COM results'!$D:$D,"CSC",'COM results'!$F:$F,K$2,'COM results'!$A:$A,"NRC",'COM results'!$B:$B,"VAR_Fout")+SUMIFS('COM results'!$G:$G,'COM results'!$D:$D,"CSC",'COM results'!$F:$F,K$2,'COM results'!$A:$A,"CHA",'COM results'!$B:$B,"VAR_Fout")+SUMIFS('COM results'!$G:$G,'COM results'!$D:$D,"CSC",'COM results'!$F:$F,K$2,'COM results'!$A:$A,"CHE",'COM results'!$B:$B,"VAR_Fout"))/V3 -> 0.0043536624 | M4: CCK | N4: =SUMIFS('COM results'!$G:$G,'COM results'!$D:$D,$M4,'COM results'!$F:$F,N$2,'COM results'!$B:$B,"VAR_Fout") -> 10.5835 | O4: =SUMIFS('COM results'!$G:$G,'COM results'!$D:$D,$M4,'COM results'!$F:$F,O$2,'COM results'!$B:$B,"VAR_Fout") -> 27.632233 | P4: =SUMIFS('COM results'!$G:$G,'COM results'!$D:$D,$M4,'COM results'!$F:$F,P$2,'COM results'!$B:$B,"VAR_Fout") -> 31.347037 | Q4: =SUMIFS('COM results'!$G:$G,'COM results'!$D:$D,$M4,'COM results'!$F:$F,Q$2,'COM results'!$B:$B,"VAR_Fout") -> 15.198712 | R4: =SUMIFS('COM results'!$G:$G,'COM results'!$D:$D,$M4,'COM results'!$F:$F,R$2,'COM results'!$B:$B,"VAR_Fout") -> 44.235683 | S4: =SUMIFS('COM results'!$G:$G,'COM results'!$D:$D,$M4,'COM results'!$F:$F,S$2,'COM results'!$B:$B,"VAR_Fout") -> 12.064501 | T4: =SUMIFS('COM results'!$G:$G,'COM results'!$D:$D,$M4,'COM results'!$F:$F,T$2,'COM results'!$B:$B,"VAR_Fout") -> 28.030775 | U4: =SUMIFS('COM results'!$G:$G,'COM results'!$D:$D,$M4,'COM results'!$F:$F,U$2,'COM results'!$B:$B,"VAR_Fout") -> 12.253931 | V4: =SUMIFS('COM results'!$G:$G,'COM results'!$D:$D,$M4,'COM results'!$F:$F,V$2,'COM results'!$B:$B,"VAR_Fout") -> 32.914143
A5: S_CSCRF | B5: CSC-RF | C5: =(SUMIFS('COM results'!$G:$G,'COM results'!$D:$D,"CSC",'COM results'!$F:$F,C$2,'COM results'!$A:$A,"RAC",'COM results'!$B:$B,"VAR_Fout")+SUMIFS('COM results'!$G:$G,'COM results'!$D:$D,"CSC",'COM results'!$F:$F,C$2,'COM results'!$A:$A,"NRC",'COM results'!$B:$B,"VAR_Fout"))/N3 -> 0.4541391 | D5: =(SUMIFS('COM results'!$G:$G,'COM results'!$D:$D,"CSC",'COM results'!$F:$F,D$2,'COM results'!$A:$A,"RAC",'COM results'!$B:$B,"VAR_Fout")+SUMIFS('COM results'!$G:$G,'COM results'!$D:$D,"CSC",'COM results'!$F:$F,D$2,'COM results'!$A:$A,"NRC",'COM results'!$B:$B,"VAR_Fout"))/O3 -> 0.49719851 | E5: =(SUMIFS('COM results'!$G:$G,'COM results'!$D:$D,"CSC",'COM results'!$F:$F,E$2,'COM results'!$A:$A,"RAC",'COM results'!$B:$B,"VAR_Fout")+SUMIFS('COM results'!$G:$G,'COM results'!$D:$D,"CSC",'COM results'!$F:$F,E$2,'COM results'!$A:$A,"NRC",'COM results'!$B:$B,"VAR_Fout"))/P3 -> 0.45098583 | F5: =(SUMIFS('COM results'!$G:$G,'COM results'!$D:$D,"CSC",'COM results'!$F:$F,F$2,'COM results'!$A:$A,"RAC",'COM results'!$B:$B,"VAR_Fout")+SUMIFS('COM results'!$G:$G,'COM results'!$D:$D,"CSC",'COM results'!$F:$F,F$2,'COM results'!$A:$A,"NRC",'COM results'!$B:$B,"VAR_Fout"))/Q3 -> 0.49406009 | G5: =(SUMIFS('COM results'!$G:$G,'COM results'!$D:$D,"CSC",'COM results'!$F:$F,G$2,'COM results'!$A:$A,"RAC",'COM results'!$B:$B,"VAR_Fout")+SUMIFS('COM results'!$G:$G,'COM results'!$D:$D,"CSC",'COM results'!$F:$F,G$2,'COM results'!$A:$A,"NRC",'COM results'!$B:$B,"VAR_Fout"))/R3 -> 0.40490655 | H5: =(SUMIFS('COM results'!$G:$G,'COM results'!$D:$D,"CSC",'COM results'!$F:$F,H$2,'COM results'!$A:$A,"RAC",'COM results'!$B:$B,"VAR_Fout")+SUMIFS('COM results'!$G:$G,'COM results'!$D:$D,"CSC",'COM results'!$F:$F,H$2,'COM results'!$A:$A,"NRC",'COM results'!$B:$B,"VAR_Fout"))/S3 -> 0.47963166 | I5: =(SUMIFS('COM results'!$G:$G,'COM results'!$D:$D,"CSC",'COM results'!$F:$F,I$2,'COM results'!$A:$A,"RAC",'COM results'!$B:$B,"VAR_Fout")+SUMIFS('COM results'!$G:$G,'COM results'!$D:$D,"CSC",'COM results'!$F:$F,I$2,'COM results'!$A:$A,"NRC",'COM results'!$B:$B,"VAR_Fout"))/T3 -> 0.47525935 | J5: =(SUMIFS('COM results'!$G:$G,'COM results'!$D:$D,"CSC",'COM results'!$F:$F,J$2,'COM results'!$A:$A,"RAC",'COM results'!$B:$B,"VAR_Fout")+SUMIFS('COM results'!$G:$G,'COM results'!$D:$D,"CSC",'COM results'!$F:$F,J$2,'COM results'!$A:$A,"NRC",'COM results'!$B:$B,"VAR_Fout"))/U3 -> 0.43057837 | K5: =(SUMIFS('COM results'!$G:$G,'COM results'!$D:$D,"CSC",'COM results'!$F:$F,K$2,'COM results'!$A:$A,"RAC",'COM results'!$B:$B,"VAR_Fout")+SUMIFS('COM results'!$G:$G,'COM results'!$D:$D,"CSC",'COM results'!$F:$F,K$2,'COM results'!$A:$A,"NRC",'COM results'!$B:$B,"VAR_Fout"))/V3 -> 0.51468534 | M5: CSH | N5: =SUMIFS('COM results'!$G:$G,'COM results'!$D:$D,$M5,'COM results'!$F:$F,N$2,'COM results'!$B:$B,"VAR_Fout") -> 119.89631 | O5: =SUMIFS('COM results'!$G:$G,'COM results'!$D:$D,$M5,'COM results'!$F:$F,O$2,'COM results'!$B:$B,"VAR_Fout") -> 330.03368 | P5: =SUMIFS('COM results'!$G:$G,'COM results'!$D:$D,$M5,'COM results'!$F:$F,P$2,'COM results'!$B:$B,"VAR_Fout") -> 370.95042 | Q5: =SUMIFS('COM results'!$G:$G,'COM results'!$D:$D,$M5,'COM results'!$F:$F,Q$2,'COM results'!$B:$B,"VAR_Fout") -> 190.74813 | R5: =SUMIFS('COM results'!$G:$G,'COM results'!$D:$D,$M5,'COM results'!$F:$F,R$2,'COM results'!$B:$B,"VAR_Fout") -> 268.35339 | S5: =SUMIFS('COM results'!$G:$G,'COM results'!$D:$D,$M5,'COM results'!$F:$F,S$2,'COM results'!$B:$B,"VAR_Fout") -> 92.043402 | T5: =SUMIFS('COM results'!$G:$G,'COM results'!$D:$D,$M5,'COM results'!$F:$F,T$2,'COM results'!$B:$B,"VAR_Fout") -> 132.72046 | U5: =SUMIFS('COM results'!$G:$G,'COM results'!$D:$D,$M5,'COM results'!$F:$F,U$2,'COM results'!$B:$B,"VAR_Fout") -> 114.01735 | V5: =SUMIFS('COM results'!$G:$G,'COM results'!$D:$D,$M5,'COM results'!$F:$F,V$2,'COM results'!$B:$B,"VAR_Fout") -> 180.77738
A6: S_CSCCEN | B6: CSC-CEN | C6: =(SUMIFS('COM results'!$G:$G,'COM results'!$D:$D,"CSC",'COM results'!$F:$F,C$2,'COM results'!$A:$A,"CAC",'COM results'!$B:$B,"VAR_Fout")/N3) -> 0.091648478 | D6: =(SUMIFS('COM results'!$G:$G,'COM results'!$D:$D,"CSC",'COM results'!$F:$F,D$2,'COM results'!$A:$A,"CAC",'COM results'!$B:$B,"VAR_Fout")/O3) -> 0.082092542 | E6: =(SUMIFS('COM results'!$G:$G,'COM results'!$D:$D,"CSC",'COM results'!$F:$F,E$2,'COM results'!$A:$A,"CAC",'COM results'!$B:$B,"VAR_Fout")/P3) -> 0.17495477 | F6: =(SUMIFS('COM results'!$G:$G,'COM results'!$D:$D,"CSC",'COM results'!$F:$F,F$2,'COM results'!$A:$A,"CAC",'COM results'!$B:$B,"VAR_Fout")/Q3) -> 0.21696148 | G6: =(SUMIFS('COM results'!$G:$G,'COM results'!$D:$D,"CSC",'COM results'!$F:$F,G$2,'COM results'!$A:$A,"CAC",'COM results'!$B:$B,"VAR_Fout")/R3) -> 0.10271777 | H6: =(SUMIFS('COM results'!$G:$G,'COM results'!$D:$D,"CSC",'COM results'!$F:$F,H$2,'COM results'!$A:$A,"CAC",'COM results'!$B:$B,"VAR_Fout")/S3) -> 0.14742404 | I6: =(SUMIFS('COM results'!$G:$G,'COM results'!$D:$D,"CSC",'COM results'!$F:$F,I$2,'COM results'!$A:$A,"CAC",'COM results'!$B:$B,"VAR_Fout")/T3) -> 0.20061156 | J6: =(SUMIFS('COM results'!$G:$G,'COM results'!$D:$D,"CSC",'COM results'!$F:$F,J$2,'COM results'!$A:$A,"CAC",'COM results'!$B:$B,"VAR_Fout")/U3) -> 0.12255658 | K6: =(SUMIFS('COM results'!$G:$G,'COM results'!$D:$D,"CSC",'COM results'!$F:$F,K$2,'COM results'!$A:$A,"CAC",'COM results'!$B:$B,"VAR_Fout")/V3) -> 0.12447678 | M6: CWH | N6: =SUMIFS('COM results'!$G:$G,'COM results'!$D:$D,$M6,'COM results'!$F:$F,N$2,'COM results'!$B:$B,"VAR_Fout") -> 24.099554 | O6: =SUMIFS('COM results'!$G:$G,'COM results'!$D:$D,$M6,'COM results'!$F:$F,O$2,'COM results'!$B:$B,"VAR_Fout") -> 62.921012 | P6: =SUMIFS('COM results'!$G:$G,'COM results'!$D:$D,$M6,'COM results'!$F:$F,P$2,'COM results'!$B:$B,"VAR_Fout") -> 71.379944 | Q6: =SUMIFS('COM results'!$G:$G,'COM results'!$D:$D,$M6,'COM results'!$F:$F,Q$2,'COM results'!$B:$B,"VAR_Fout") -> 34.608797 | R6: =SUMIFS('COM results'!$G:$G,'COM results'!$D:$D,$M6,'COM results'!$F:$F,R$2,'COM results'!$B:$B,"VAR_Fout") -> 100.36265 | S6: =SUMIFS('COM results'!$G:$G,'COM results'!$D:$D,$M6,'COM results'!$F:$F,S$2,'COM results'!$B:$B,"VAR_Fout") -> 27.471923 | T6: =SUMIFS('COM results'!$G:$G,'COM results'!$D:$D,$M6,'COM results'!$F:$F,T$2,'COM results'!$B:$B,"VAR_Fout") -> 63.828526 | U6: =SUMIFS('COM results'!$G:$G,'COM results'!$D:$D,$M6,'COM results'!$F:$F,U$2,'COM results'!$B:$B,"VAR_Fout") -> 27.903273 | V6: =SUMIFS('COM results'!$G:$G,'COM results'!$D:$D,$M6,'COM results'!$F:$F,V$2,'COM results'!$B:$B,"VAR_Fout") -> 74.948381
