Workbook
Name _1_2007_InternetDataFile_ExistGenUnits: #REF!
Name AnswerData: #REF!
Name bprint: #REF!
Name cprint: #REF!
Name exch_rate: #REF!
Name fitfile: [1]MODEL!$D$38
Name INF: [1]MODEL!$H$14
Name PPP: [1]MODEL!$D$12
Name PPPEX: [1]MODEL!$D$13
Name rail_coal: #REF!

Sheet ANSv6.0-Technologies
A1: ANSWER-Technologies
B7: TechName | C7: TechDesc | D7: TACTUnit | E7: TCAPUnit | F7: Set Memberships | G7: Comment

Sheet ANSv6.0-Commodities
A1: ANSWER-Commodities
B7: CommName | C7: CommDesc | D7: CommUnit | E7: Set Memberships | F7: Comment

Sheet ANSv6.1-Commodities
A1: ANSWER-Commodities
B7: CommName | C7: CommDesc | D7: CommUnit | E7: Set Memberships | F7: Comment

Sheet ANSv6.1-Technologies
A1: ANSWER-Technologies
B7: TechName | C7: TechDesc | D7: TACTUnit | E7: TCAPUnit | F7: Set Memberships | G7: Comment

Sheet ANSv6.1-Constraints
A1: ANSWER-Constraints
B7: ConstrName | C7: ConstrDesc | D7: Units | E7: Set Memberships | F7: Comment

Sheet ANSv6.1-CommData
A1: ANSWER-CommData
B7: CommName | C7: CommDesc | D7: Units

Sheet ANSv6.1-TechData
A1: ANSWER-TechData
B7: TechName | C7: TechDesc | D7: Units | E7: CommIN | F7: CommOUT

Sheet ANSv6.1-ConstrData
A1: ANSWER-ConstrData
B7: ConstrName | C7: ConstrDesc | D7: Units | E7: TechName

Sheet AQ_TOT
A1: UC - All Regions/Each Period
B2: ~UC_Sets: R_S: AllRegions
B5: UC_N | C5: Pset_Set | D5: Cset_CN | E5: Year | F5: LimType | G5: UC_COMNET | H5: UC_RHSTS | I5: UC_RHSTS~0 | J5: UC_Desc
B6: AQREG_NOX_AllRegions | D6: ELCNOX | E6: 2010 | F6: UP | G6: 1 | H6: 3317 | I6: 5 | J6: NOX upper bound on the total emissions of All Regions
B7: AQREG_NOX_AllRegions | D7: ELCNOX | E7: 2055 | F7: UP | G7: 1 | H7: 3317 | I7: 5 | J7: NOX upper bound on the total emissions of All Regions
B8: AQREG_SO2_AllRegions | D8: ELCSO2 | E8: 2010 | F8: UP | G8: 1 | H8: 8119 | I8: 5 | J8: SO2 upper bound on the total emissions of All Regions
B9: AQREG_SO2_AllRegions | D9: ELCSO2 | E9: 2015 | F9: UP | G9: 1 | H9: 8119 | I9: 5 | J9: SO2 upper bound on the total emissions of All Regions
B10: AQREG_SO2_AllRegions | D10: ELCSO2 | E10: 2055 | F10: UP | G10: 1 | H10: 8119 | I10: 5 | J10: SO2 upper bound on the total emissions of All Regions

Sheet AQ_REG
A1: Trans - Insert
B2: ~TFM_INS
B3: TimeSlice | C3: LimType | D3: Attribute | E3: Year | F3: AllRegions | G3: R1 | H3: R2 | I3: R3 | J3: R4 | K3: R5 | L3: R6 | M3: R7 | N3: R8 | O3: R9 | P3: Pset_Set | Q3: Pset_PN | R3: Pset_PD | S3: Pset_CI | T3: Pset_CO | U3: Cset_Set | V3: Cset_CN | W3: Cset_CD
C4: UP | D4: COM_BNDNET | E4: 2010 | G4: 21 | H4: 279 | I4: 830 | J4: 523 | K4: 654 | L4: 432 | M4: 350 | N4: 436 | O4: 54 | V4: ELCNOX
C5: UP | D5: COM_BNDNET | E5: 2015 | G5: 23 | H5: 287 | I5: 836 | J5: 543 | K5: 665 | L5: 433 | M5: 355 | N5: 442 | O5: 54 | V5: ELCNOX
C6: UP | D6: COM_BNDNET | E6: 2010 | G6: 29 | H6: 1006 | I6: 2841 | J6: 828 | K6: 2067 | L6: 1103 | M6: 777 | N6: 256 | O6: 35 | V6: ELCSO2
C7: UP | D7: COM_BNDNET | E7: 2015 | G7: 30 | H7: 967 | I7: 2448 | J7: 876 | K7: 1923 | L7: 1054 | M7: 776 | N7: 257 | O7: 35 | V7: ELCSO2
C8: UP | D8: COM_BNDNET | E8: 2010 | G8: 5.57 | H8: 56.36 | I8: 91.85 | J8: 27.83 | K8: 107.15 | L8: 43.14 | M8: 30.62 | N8: 29.22 | O8: 6.26 | V8: ELCPM10

Sheet ANSv6.0-ConstrData
A1: ANSWER-ConstrData
B7: ConstrName | C7: ConstrDesc | D7: Units | E7: TechName

Sheet ANSv6.0-TechData
A1: ANSWER-TechData
B7: TechName | C7: TechDesc | D7: Units | E7: CommIN | F7: CommOUT

Sheet ANSv6.0-CommData
A1: ANSWER-CommData
B7: CommName | C7: CommDesc | D7: Units

Sheet ANSv6.0-Constraints
A1: ANSWER-Constraints
B7: ConstrName | C7: ConstrDesc | D7: Units | E7: Set Memberships | F7: Comment

Sheet DataSummary
B1: Summary of emissions data from sheets "2000", "2005", "2010-2015"
D3: CAIR | K3: No-CAIR
D4: NOx Emission (Ktonnes/yr) | K4: NOx Emissions (Ktonnes/yr)
B5: Region | C5: Name | D5: 2000 | E5: 2005 | F5: 2010 | G5: 2015 | I5: Region | J5: Name | K5: 2000 | L5: 2005 | M5: 2010 | N5: 2015
B6: 1 | C6: New England | D6: ='2000'!F74 -> 50.966442 | E6: ='2000'!G74 -> 34.235389 | F6: ='2010-2015'!D65 -> 19.850364 | G6: ='2010-2015'!H65 -> 21.600173 | I6: 1 | J6: New England | K6: =D6 -> 50.966442 | L6: =E6 -> 34.235389 | M6: ='2010-2015'!L65 -> 20.640927 | N6: ='2010-2015'!P65 -> 22.795796
B7: 2 | C7: Middle Atlantic | D7: ='2000'!F75 -> 290.81226 | E7: ='2000'!G75 -> 228.26703 | F7: ='2010-2015'!D66 -> 138.99942 | G7: ='2010-2015'!H66 -> 137.2267 | I7: 2 | J7: Middle Atlantic | K7: =D7 -> 290.81226 | L7: =E7 -> 228.26703 | M7: ='2010-2015'!L66 -> 278.95958 | N7: ='2010-2015'!P66 -> 286.85751
B8: 3 | C8: East North Central | D8: ='2000'!F76 -> 1092.2255 | E8: ='2000'!G76 -> 698.36868 | F8: ='2010-2015'!D67 -> 488.36742 | G8: ='2010-2015'!H67 -> 395.5334 | I8: 3 | J8: East North Central | K8: =D8 -> 1092.2255 | L8: =E8 -> 698.36868 | M8: ='2010-2015'!L67 -> 829.98635 | N8: ='2010-2015'!P67 -> 835.9302
B9: 4 | C9: West North Central | D9: ='2000'!F77 -> 498.34248 | E9: ='2000'!G77 -> 461.5228 | F9: ='2010-2015'!D68 -> 371.07455 | G9: ='2010-2015'!H68 -> 380.77884 | I9: 4 | J9: West North Central | K9: =D9 -> 498.34248 | L9: =E9 -> 461.5228 | M9: ='2010-2015'!L68 -> 522.61649 | N9: ='2010-2015'!P68 -> 542.53492
B10: 5 | C10: South Atlantic | D10: ='2000'!F78 -> 1048.1703 | E10: ='2000'!G78 -> 699.95686 | F10: ='2010-2015'!D69 -> 299.54408 | G10: ='2010-2015'!H69 -> 268.1358 | I10: 5 | J10: South Atlantic | K10: =D10 -> 1048.1703 | L10: =E10 -> 699.95686 | M10: ='2010-2015'!L69 -> 653.96651 | N10: ='2010-2015'!P69 -> 664.95311
B11: 6 | C11: East South Central | D11: ='2000'!F79 -> 585.91573 | E11: ='2000'!G79 -> 402.14973 | F11: ='2010-2015'!D70 -> 199.41021 | G11: ='2010-2015'!H70 -> 145.41044 | I11: 6 | J11: East South Central | K11: =D11 -> 585.91573 | L11: =E11 -> 402.14973 | M11: ='2010-2015'!L70 -> 431.8262 | N11: ='2010-2015'!P70 -> 432.71346
B12: 7 | C12: West South Central | D12: ='2000'!F80 -> 567.32044 | E12: ='2000'!G80 -> 327.56966 | F12: ='2010-2015'!D71 -> 323.4968 | G12: ='2010-2015'!H71 -> 245.54144 | I12: 7 | J12: West South Central | K12: =D12 -> 567.32044 | L12: =E12 -> 327.56966 | M12: ='2010-2015'!L71 -> 349.54511 | N12: ='2010-2015'!P71 -> 354.66494
B13: 8 | C13: Mountain | D13: ='2000'!F81 -> 452.98784 | E13: ='2000'!G81 -> 416.17887 | F13: ='2010-2015'!D72 -> 436.34282 | G13: ='2010-2015'!H72 -> 442.30225 | I13: 8 | J13: Mountain | K13: =D13 -> 452.98784 | L13: =E13 -> 416.17887 | M13: ='2010-2015'!L72 -> 436.01344 | N13: ='2010-2015'!P72 -> 441.90538
B14: 9 | C14: Pacific (incl AK, HI) | D14: ='2000'!F82 -> 64.452353 | E14: ='2000'!G82 -> 48.286891 | F14: ='2010-2015'!D73 -> 54.002507 | G14: ='2010-2015'!H73 -> 53.839311 | I14: 9 | J14: Pacific (incl AK, HI) | K14: =D14 -> 64.452353 | L14: =E14 -> 48.286891 | M14: ='2010-2015'!L73 -> 53.95264 | N14: ='2010-2015'!P73 -> 53.940852
D16: CAIR | K16: No-CAIR
D17: SO2 Emission (Ktonnes/yr) | K17: SO2 Emissions (Ktonnes/yr)
B18: Region | C18: Name | D18: 2000 | E18: 2005 | F18: 2010 | G18: 2015 | I18: Region | J18: Name | K18: 2000 | L18: 2005 | M18: 2010 | N18: 2015
B19: 1 | C19: New England | D19: ='2000'!D74 -> 191.31965 | E19: ='2000'!E74 -> 131.26915 | F19: ='2010-2015'!E65 -> 26.140696 | G19: ='2010-2015'!I65 -> 21.99706 | I19: 1 | J19: New England | K19: ='2000'!D74 -> 191.31965 | L19: =E19 -> 131.26915 | M19: ='2010-2015'!M65 -> 29.423399 | N19: ='2010-2015'!Q65 -> 29.975702
B20: 2 | C20: Middle Atlantic | D20: ='2000'!D75 -> 1159.9004 | E20: ='2000'!E75 -> 1103.9816 | F20: ='2010-2015'!E66 -> 289.33674 | G20: ='2010-2015'!I66 -> 286.09378 | I20: 2 | J20: Middle Atlantic | K20: =D20 -> 1159.9004 | L20: =E20 -> 1103.9816 | M20: ='2010-2015'!M66 -> 1005.87 | N20: ='2010-2015'!Q66 -> 967.00661
B21: 3 | C21: East North Central | D21: ='2000'!D76 -> 2794.7073 | E21: ='2000'!E76 -> 2544.3532 | F21: ='2010-2015'!E67 -> 1427.4024 | G21: ='2010-2015'!I67 -> 1340.9852 | I21: 3 | J21: East North Central | K21: =D21 -> 2794.7073 | L21: =E21 -> 2544.3532 | M21: ='2010-2015'!M67 -> 2840.9652 | N21: ='2010-2015'!Q67 -> 2448.2181
B22: 4 | C22: West North Central | D22: ='2000'!D77 -> 719.33774 | E22: ='2000'!E77 -> 778.33851 | F22: ='2010-2015'!E68 -> 643.28563 | G22: ='2010-2015'!I68 -> 690.12101 | I22: 4 | J22: West North Central | K22: =D22 -> 719.33774 | L22: =E22 -> 778.33851 | M22: ='2010-2015'!M68 -> 828.20075 | N22: ='2010-2015'!Q68 -> 875.67181
B23: 5 | C23: South Atlantic | D23: ='2000'!D78 -> 2580.2353 | E23: ='2000'!E78 -> 2483.8175 | F23: ='2010-2015'!E69 -> 1329.7703 | G23: ='2010-2015'!I69 -> 898.54268 | I23: 5 | J23: South Atlantic | K23: =D23 -> 2580.2353 | L23: =E23 -> 2483.8175 | M23: ='2010-2015'!M69 -> 2067.0498 | N23: ='2010-2015'!Q69 -> 1923.2537
B24: 6 | C24: East South Central | D24: ='2000'!D79 -> 1498.5832 | E24: ='2000'!E79 -> 1179.7865 | F24: ='2010-2015'!E70 -> 904.65939 | G24: ='2010-2015'!I70 -> 778.26248 | I24: 6 | J24: East South Central | K24: =D24 -> 1498.5832 | L24: =E24 -> 1179.7865 | M24: ='2010-2015'!M70 -> 1102.9162 | N24: ='2010-2015'!Q70 -> 1054.3873
B25: 7 | C25: West South Central | D25: ='2000'!D80 -> 758.76995 | E25: ='2000'!E80 -> 733.85008 | F25: ='2010-2015'!E71 -> 628.22139 | G25: ='2010-2015'!I71 -> 594.32278 | I25: 7 | J25: West South Central | K25: =D25 -> 758.76995 | L25: =E25 -> 733.85008 | M25: ='2010-2015'!M71 -> 776.51857 | N25: ='2010-2015'!Q71 -> 775.90929
B26: 8 | C26: Mountain | D26: ='2000'!D81 -> 370.41355 | E26: ='2000'!E81 -> 304.43152 | F26: ='2010-2015'!E72 -> 256.29507 | G26: ='2010-2015'!I72 -> 255.20761 | I26: 8 | J26: Mountain | K26: =D26 -> 370.41355 | L26: =E26 -> 304.43152 | M26: ='2010-2015'!M72 -> 256.36619 | N26: ='2010-2015'!Q72 -> 256.97057
B27: 9 | C27: Pacific (incl AK, HI) | D27: ='2000'!D82 -> 111.1918 | E27: ='2000'!E82 -> 36.08295 | F27: ='2010-2015'!E73 -> 34.91392 | G27: ='2010-2015'!I73 -> 34.91392 | I27: 9 | J27: Pacific (incl AK, HI) | K27: =D27 -> 111.1918 | L27: =E27 -> 36.08295 | M27: ='2010-2015'!M73 -> 34.91392 | N27: ='2010-2015'!Q73 -> 34.91392
B31: Data Sources
B32: 2000 and 2005 - U.S. EPA Clean Air Markets Division’s “Data and Maps” web page (http://camddataandmaps.epa.gov/gdm/index.cfm)
B33: 2010 and 2015 - U.S. EPA Clean Air Markets Division’s “Clean Air Interstate Rule” web page (http://www.epa.gov/cair/technical.html#proposedrule)
C34: Technical Support Documents
C35: "State-level emission inventory summaries for all criteria pollutants for each sector for years 2001, 2010, and 2015, base and control cases"
C36: TSD_Appendix_2010.xls
C37: TSD_Appendix_2015.xls

Sheet 2000
A1: Data source: U.S. EPA Clean Air Markets Division’s “Data and Maps” web page (http://camddataandmaps.epa.gov/gdm/index.cfm)
A2: Units: thousand short tons
D3: SO2 | F3: Nox | G3: CO2 | H3: MMBTU
A4: AL | B4: 2000 | C4: ARP | D4: 512074.66 | E4: 12 | F4: 181101.5 | G4: 88806364 | H4: 883657214
A5: AR | B5: 2000 | C5: ARP | D5: 75057.61 | E5: 12 | F5: 51787.459 | G5: 31917181 | H5: 334494128
A6: AZ | B6: 2000 | C6: ARP | D6: 71556.489 | E6: 12 | F6: 96490.407 | G6: 49404158 | H6: 504441312
A7: CA | B7: 2000 | C7: ARP | D7: 380.087 | E7: 12 | F7: 19867.831 | G7: 41068209 | H7: 688846298
A8: CO | B8: 2000 | C8: ARP | D8: 87176.319 | E8: 12 | F8: 70802.154 | G8: 41883007 | H8: 420328919
A9: CT | B9: 2000 | C9: ARP | D9: 36917.827 | E9: 12 | F9: 12090.081 | G9: 9747714.3 | H9: 122261948
A10: DC | B10: 2000 | C10: ARP | D10: 957.675 | E10: 12 | F10: 273.284 | G10: 173185.87 | H10: 2224628
A11: DE | B11: 2000 | C11: ARP | D11: 40290.542 | E11: 12 | F11: 10493.9 | G11: 6240205.4 | H11: 64581020
A12: FL | B12: 2000 | C12: ARP | D12: 570061.45 | E12: 12 | F12: 292508.2 | G12: 1.2761742e+08 | H12: 1435305518
A13: GA | B13: 2000 | C13: ARP | D13: 518745.61 | E13: 12 | F13: 184551.94 | G13: 85426769 | H13: 849463779
A14: IA | B14: 2000 | C14: ARP | D14: 137266.72 | E14: 12 | F14: 78662.635 | G14: 40307118 | H14: 392397401
A15: ID | B15: 2000 | C15: ARP | D15: 2.118 | E15: 12 | F15: 111.624 | G15: 419439.67 | H15: 7125406
... A52: WY | B52: 2000 | C52: ARP | D52: 80300.242 | E52: 12 | F52: 88814.077 | G52: 51178275 | H52: 496757429
A53: Total | D53: 11,202,079.3 | F53: 5,104,515.8 | G53: 2,451,561,151.4 | H53: 25,606,076,726
A55: From NEI
A56: HA | D56: 22486 | F56: 17691
A57: AK | D57: 1690 | F57: 4770
C58: Regional sums in annual short tons
D59: SO2 | E59: NOx | F59: CO2 | G59: MMBTU
C60: Region 1 | D60: 210890.26 | E60: 56179.941 | F60: 41139892 | G60: 480926522
C61: Region 2 | D61: 1278549.8 | E61: 320560.25 | F61: 1.806321e+08 | G61: 1897986001
C62: Region 3 | D62: 3080585.6 | E62: 1203952.3 | F62: 4.9925324e+08 | G62: 4913175710
C63: Region 4 | D63: 792920.79 | E63: 549319.31 | F63: 2.574356e+08 | G63: 2498849322
C64: Region 5 | D64: 2844174.7 | E64: 1155390.6 | F64: 4.9883055e+08 | G64: 5110951596
C65: Region 6 | D65: 1651877.4 | E65: 645850.67 | F65: 2.809001e+08 | G65: 2781184845
C66: Region 7 | D66: 836386.63 | E66: 625353.21 | F66: 3.7545117e+08 | G66: 4429784428
C67: Region 8 | D67: 408304.18 | E67: 499325.22 | F67: 2.5921911e+08 | G67: 2609251698
C68: Region 9 - A | D68: 98389.921 | E68: 48584.363 | F68: 58699388 | G68: 883966604
C69: Region 9 - B | D69: 24176 | E69: 22461
D70: 11226255 | E70: 5126976.8 | F70: 2.4515612e+09 | G70: 25606076726
C72: Converted to Million Metric Tonnes
D73: SO2 in 2000 | E73: SO2 in 2005 | F73: NOx in 2000 | G73: NOx in 2005
C74: Region 1 | D74: 191.31965 | E74: 131.26915 | F74: 50.966442 | G74: 34.235389
C75: Region 2 | D75: 1159.9004 | E75: 1103.9816 | F75: 290.81226 | G75: 228.26703
C76: Region 3 | D76: 2794.7073 | E76: 2544.3532 | F76: 1092.2255 | G76: 698.36868
C77: Region 4 | D77: 719.33774 | E77: 778.33851 | F77: 498.34248 | G77: 461.5228
C78: Region 5 | D78: 2580.2353 | E78: 2483.8175 | F78: 1048.1703 | G78: 699.95686
...

Sheet 2005
A1: Data source: U.S. EPA Clean Air Markets Division’s “Data and Maps” web page (http://camddataandmaps.epa.gov/gdm/index.cfm)
A2: Units: thousand short tons
D3: SO2 | F3: Nox | G3: CO2 | H3: MMBTU
A4: AL | B4: 2005 | C4: ARP | D4: 460072.09 | E4: 12 | F4: 133472.13 | G4: 91469200 | H4: 936856245
A5: AR | B5: 2005 | C5: ARP | D5: 66189.725 | E5: 12 | F5: 35334.609 | G5: 29182072 | H5: 305933324
A6: AZ | B6: 2005 | C6: ARP | D6: 52761.521 | E6: 12 | F6: 80790.027 | G6: 58265191 | H6: 657183741
A7: CA | B7: 2005 | C7: ARP | D7: 172.398 | E7: 12 | F7: 4356.617 | G7: 31660158 | H7: 530580198
A8: CO | B8: 2005 | C8: ARP | D8: 59337.064 | E8: 12 | F8: 67635.398 | G8: 46127713 | H8: 484875586
A9: CT | B9: 2005 | C9: ARP | D9: 7522.651 | E9: 12 | F9: 5859.34 | G9: 9645877.4 | H9: 127626562
A10: DC | B10: 2005 | C10: ARP | D10: 834.254 | E10: 12 | F10: 275.916 | G10: 187206.13 | H10: 2312926
A11: DE | B11: 2005 | C11: ARP | D11: 30580.158 | E11: 12 | F11: 11345.497 | G11: 6688310.3 | H11: 71722559
A12: FL | B12: 2005 | C12: ARP | D12: 415405.85 | E12: 12 | F12: 212007.63 | G12: 1.3650792e+08 | H12: 1637618680
A13: GA | B13: 2005 | C13: ARP | D13: 616169.37 | E13: 12 | F13: 111365.1 | G13: 94101034 | H13: 949440486
A14: IA | B14: 2005 | C14: ARP | D14: 126778.98 | E14: 12 | F14: 71502.102 | G14: 40411329 | H14: 401343182
A15: ID | B15: 2005 | C15: ARP | D15: 2.898 | E15: 12 | F15: 88.696 | G15: 574923.68 | H15: 9661652
... A52: WY | B52: 2005 | C52: ARP | D52: 86497.427 | E52: 12 | F52: 87731.521 | G52: 50055029 | H52: 488120742
A53: Total | D53: 10,222,639.6 | F53: 3,633,332.5 | G53: 2,539,948,947.3 | H53: 27,140,176,242
C55: Regional totals in short tons
D56: SO2 | F56: NOx | G56: CO2 | H56: MMBTU
C57: Region 1 | D57: 144697.03 | F57: 37737.422 | G57: 52340823 | H57: 695229230
C58: Region 2 | D58: 1216910.9 | F58: 251617.09 | G58: 1.9247188e+08 | H58: 2102992115
C59: Region 3 | D59: 2804622.1 | F59: 769806.74 | G59: 5.0821497e+08 | H59: 5045117456
C60: Region 4 | D60: 857956.91 | F60: 508733.25 | G60: 2.7206134e+08 | H60: 2670486276
C61: Region 5 | D61: 2737894.1 | F61: 771557.39 | G61: 5.1670206e+08 | H61: 5457221760
C62: Region 6 | D62: 1300470.2 | F62: 443286.74 | G62: 2.798847e+08 | H62: 2838642593
C63: Region 7 | D63: 808917.64 | F63: 361077.66 | G63: 3.8672463e+08 | H63: 4621792474
C64: Region 8 | D64: 335572.67 | F64: 458750.96 | G64: 2.7562577e+08 | H64: 2886794238
C65: Region 9 - A | D65: 15597.975 | F65: 30765.291 | G65: 55922776 | H65: 821900100
C66: Region 9 - B
D67: 10222640 | F67: 3633332.5 | G67: 2.5399489e+09 | H67: 27140176242

Sheet 2010-2015
A1: Data Source - U.S. EPA Clean Air Markets Division’s “Clean Air Interstate Rule” web page (http://www.epa.gov/cair/technical.html#proposedrule)
A2: Technical Support Documents
A3: "State-level emission inventory summaries for all criteria pollutants for each sector for years 2001, 2010, and 2015, base and control cases"
A4: TSD_Appendix_2010.xls
A5: TSD_Appendix_2015.xls
D8: CAIR | E8: (from TSD_Appendix_2010) | H8: CAIR | I8: (from TSD_Appendix_2015) | L8: non-CAIR | M8: (from TSD_Appendix_2010) | P8: non-CAIR (from TSD_Appendix_2015)
D9: NOx | E9: SO2 | H9: NOx | I9: SO2 | L9: NOx | M9: SO2 | P9: NOx | Q9: SO2
C10: Alabama | D10: 73687.256 | E10: 354453.7 | H10: 59250.214 | I10: 334172.8 | L10: 134133.59 | M10: 473042.9 | P10: 128591.62 | Q10: 415985.1
C11: Arizona | D11: 84483.26 | E11: 47778.7 | H11: 85860.54 | I11: 47778.7 | L11: 84567.455 | M11: 47778.7 | P11: 85975.223 | Q11: 47778.7
C12: Arkansas | D12: 38169.413 | E12: 77933.833 | H12: 8586.9462 | I12: 77934.609 | L12: 52511.288 | M12: 122666.91 | P12: 52785.702 | Q12: 122666.91
C13: California | D13: 17854.795 | E13: 17316.8 | H13: 19586.271 | I13: 17316.8 | L13: 17670.959 | M13: 17316.8 | P13: 19596.522 | Q13: 17316.8
C14: Colorado | D14: 82803.516 | E14: 73088.7 | H14: 83647.832 | I14: 73088.7 | L14: 82714.473 | M14: 73088.7 | P14: 83631.831 | Q14: 73088.7
C15: Connecticut | D15: 5172.3914 | E15: 5317.6 | H15: 5268.8903 | I15: 5317.6 | L15: 5168.3471 | M15: 6283.8 | P15: 5260.1903 | Q15: 6283.8
C16: Delaware | D16: 8545.3091 | E16: 34019.6 | H16: 9087.6638 | I16: 34574.2 | L16: 10270.81 | M16: 46355.4 | P16: 10843.349 | Q16: 48274.9
C17: District Of Columbia | D17: 30.237583 | E17: 0 | H17: 77.747592 | I17: 0 | L17: 41.752833 | M17: 0 | P17: 85.627633 | Q17: 0
C18: Florida | D18: 63134.971 | E18: 192948.1 | H18: 54558.464 | I18: 173798.6 | L18: 161845.7 | M18: 233241.3 | P18: 170803.07 | Q18: 230294.9
C19: Georgia | D19: 65104.5 | E19: 407670.9 | H19: 51837.729 | I19: 196833.4 | L19: 150582.39 | M19: 609153.7 | P19: 153294.66 | Q19: 600315.4
C20: Idaho | D20: 1194.0719 | E20: 0 | H20: 1229.1519 | I20: 0 | L20: 1197.3519 | M20: 0 | P20: 1229.1519 | Q20: 0
C21: Illinois | D21: 113863.96 | E21: 246120.5 | H21: 96049.372 | I21: 262562.7 | L21: 171443.21 | M21: 600835.6 | P21: 179581.06 | Q21: 539205.6
... C58: Wyoming | D58: 90499.808 | E58: 47275.6 | H58: 90502.396 | I58: 45792 | L58: 90499.806 | M58: 47275.7 | P58: 90502.324 | Q58: 47240.2
C59: (blank)
C60: Grand Total | D60: 2569519.2 | E60: 6106707.6 | H60: 2304175.5 | I60: 5401704.3 | L60: 3943437.9 | M60: 9856926.4 | P60: 4008240.5 | Q60: 9222097.2
D63: CAIR Emissions | H63: CAIR Emissions | L63: Non-CAIR Emissions | P63: Non-CAIR Emissions
D64: Nox 2010 | E64: So2 2010 | H64: Nox 2015 | I64: So2 2015 | L64: Nox 2010 | M64: So2 2010 | P64: Nox 2015 | Q64: So2 2015
C65: Region 1 | D65: 19.850364 | E65: 26.140696 | G65: Region 1 | H65: 21.600173 | I65: 21.99706 | K65: Region 1 | L65: 20.640927 | M65: 29.423399 | O65: Region 1 | P65: 22.795796 | Q65: 29.975702
C66: Region 2 | D66: 138.99942 | E66: 289.33674 | G66: Region 2 | H66: 137.2267 | I66: 286.09378 | K66: Region 2 | L66: 278.95958 | M66: 1005.87 | O66: Region 2 | P66: 286.85751 | Q66: 967.00661
C67: Region 3 | D67: 488.36742 | E67: 1427.4024 | G67: Region 3 | H67: 395.5334 | I67: 1340.9852 | K67: Region 3 | L67: 829.98635 | M67: 2840.9652 | O67: Region 3 | P67: 835.9302 | Q67: 2448.2181
C68: Region 4 | D68: 371.07455 | E68: 643.28563 | G68: Region 4 | H68: 380.77884 | I68: 690.12101 | K68: Region 4 | L68: 522.61649 | M68: 828.20075 | O68: Region 4 | P68: 542.53492 | Q68: 875.67181
C69: Region 5 | D69: 299.54408 | E69: 1329.7703 | G69: Region 5 | H69: 268.1358 | I69: 898.54268 | K69: Region 5 | L69: 653.96651 | M69: 2067.0498 | O69: Region 5 | P69: 664.95311 | Q69: 1923.2537
C70: Region 6 | D70: 199.41021 | E70: 904.65939 | G70: Region 6 | H70: 145.41044 | I70: 778.26248 | K70: Region 6 | L70: 431.8262 | M70: 1102.9162 | O70: Region 6 | P70: 432.71346 | Q70: 1054.3873
C71: Region 7 | D71: 323.4968 | E71: 628.22139 | G71: Region 7 | H71: 245.54144 | I71: 594.32278 | K71: Region 7 | L71: 349.54511 | M71: 776.51857 | O71: Region 7 | P71: 354.66494 | Q71: 775.90929
C72: Region 8 | D72: 436.34282 | E72: 256.29507 | G72: Region 8 | H72: 442.30225 | I72: 255.20761 | K72: Region 8 | L72: 436.01344 | M72: 256.36619 | O72: Region 8 | P72: 441.90538 | Q72: 256.97057
C73: Region 9a | D73: 54.002507 | E73: 34.91392 | G73: Region 9a | H73: 53.839311 | I73: 34.91392 | K73: Region 9a | L73: 53.95264 | M73: 34.91392 | O73: Region 9a | P73: 53.940852 | Q73: 34.91392

Sheet Conversions
A1: Heating Values (LHV) | E1: Standard Conversions
A2: Heat capacity | B2: KJ/kg | C2: Mbtu/ton | E2: from | F2: to | G2: multiply by
A3: Coal equivalent | B3: 29260 | E3: Mtce | F3: PJ | G3: 29.26
A4: Chinese coal | B4: 20908 | E4: Btu | F4: J | G4: 1055
A5: Petroleum | B5: 41800 | E5: kcal | F5: kJ | G5: 4.1868
A6: Natural gas | B6: 35500 | E6: kWh | F6: MJ | G6: 3.6
A7: Wood and wood waste | B7: 16051 | C7: =B7/$F$21/$F$17*2000/1000 -> 13.799744 | E7: ft3 | F7: m3 | G7: 0.0283
A8: Ag residues | B8: 14423 | C8: =B8/$F$21/$F$17*2000/1000 -> 12.400082 | E8: Trillion Btu | F8: PJ | G8: 1.055
A9: Switchgrass | B9: 14423 | C9: =B9/$F$21/$F$17*2000/1000 -> 12.400082
A10: LPG | B10: 47310 | C10: =B10/B3 -> 1.6168831
A11: DME | B11: 28500 | C11: =B11/B3 -> 0.97402597
A12: Methane Emission Parameters
A13: 1 Gg CH4 = | B13: =B14*B15/10^3 -> 0.0548392 | C13: PJ
A14: 1 Tg = | B14: 52 | C14: Bcf
A15: 1 Bcf = | B15: 1.0546 | C15: PJ | E15: 1 kg CH4= | F15: =B14*G7 -> 1.4716 | G15: m3
A16: 1 Tg = | B16: 5.7273 | C16: MMTCE | E16: 1scf NG= | F16: 928 | G16: Btu | H16: Lower heat value
A17: 1 MMT MSW = | B17: 11 | C17: PJ | E17: 1 Btu = | F17: 1055 | G17: J
A18: 1 m3 CH4 = | B18: 37 | C18: MJ | E18: 1scf NG= | F18: =F16*F17 -> 979040 | G18: J
A19: 1 $/TCE = | B19: =B16/B14/B15 -> 0.10443807 | C19: m$/PJ | E19: 1 m3 NG = | F19: =F18/G7/10^6 -> 34.595053 | G19: MJ
A20: 1 kg CH4 = | B20: 21 | C20: kg CO2 eq. | E20: 1 gal gasoline = | F20: 121.9 | G20: MJ
A21: Model Monetary Units | C21: 1995$US M | E21: 1 kg = | F21: 2.205 | G21: lb
A22: 1 short ton coal = | B22: 20 | C22: Million Btu
A23: 1 million short ton coal = | B23: =B22*1055*10^-3 -> 21.1 | C23: PJ
A24: ft3 CH4/short ton coal = | B24: =1/(B14*B23) -> 0.00091141086 | C24: kt/PJ
A25: 1 m3 CH4 = | B25: 0.662 | C25: kg CH4
A26: 1 GW = | B26: 31.536 | C26: PJa
A27: 1 million barrels oil = | B27: 5.8 | C27: PJ
A29: Emission Factors
A30: 1 PJ CH4 released = | B30: =1/Conversions!B13 -> 18.235131 | C30: kt CH4
A31: 1 PJ CH4 burned = | B31: =15.3*0.001 -> 0.0153 | C31: mt CO2 (carbon)
A32: 1 PJ MSW burned = | B32: =20*0.001 -> 0.02 | C32: mt CO2 (carbon)
A33: 1 kt CH4 burned = | B33: =12/16 -> 0.75 | C33: kt CO2 (carbon)
A35: GDP Deflators (Conversion to US$2005)
A36: Year | B36: Deflator | C36: Multiply By (for $2005)
A37: 1983 | B37: 57.603 | C37: =$B$59/B37 -> 1.7360207
A38: 1984 | B38: 59.766 | C38: =$B$59/B38 -> 1.6731921
A39: 1985 | B39: 61.576 | C39: =$B$59/B39 -> 1.6240094
A40: 1986 | B40: 62.937 | C40: =$B$59/B40 -> 1.5888905
A41: 1987 | B41: 64.764 | C41: =$B$59/B41 -> 1.5440677
A42: 1988 | B42: 66.988 | C42: =$B$59/B42 -> 1.4928047
...
